{
  "version": 8,
  "blockIdVersion": 11,
  "anchorX": 0,
  "anchorY": 0,
  "anchorZ": 0,
  "blocks": [
    {
      "x": -22,
      "y": 3,
      "z": -40,
      "name": "Plant_Leaves_Oak",
      "rotation": 3
    },
    {
      "x": -22,
      "y": 3,
      "z": -39,
      "name": "Plant_Leaves_Oak",
      "rotation": 3
    },
    {
      "x": -22,
      "y": 4,
      "z": -39,
      "name": "Plant_Leaves_Oak",
      "rotation": 3
    },
    {
      "x": -22,
      "y": 7,
      "z": -39,
      "name": "Plant_Leaves_Oak",
      "rotation": 3
    },
    {
      "x": -22,
      "y": 8,
      "z": -39,
      "name": "Plant_Leaves_Oak",
      "rotation": 3
    },
    {
      "x": -22,
      "y": 9,
      "z": -39,
      "name": "Plant_Leaves_Oak",
      "rotation": 3
    },
    {
      "x": -22,
      "y": 0,
      "z": -38,
      "name": "Plant_Leaves_Beech",
      "rotation": 3
    },
    {
      "x": -22,
      "y": 1,
      "z": -38,
      "name": "Plant_Leaves_Beech",
      "rotation": 3
    },
    {
      "x": -22,
      "y": 2,
      "z": -38,
      "name": "Plant_Leaves_Beech",
      "rotation": 3
    },
    {
      "x": -22,
      "y": 4,
      "z": -38,
      "name": "Plant_Leaves_Oak",
      "rotation": 3
    },
    {
      "x": -22,
      "y": 5,
      "z": -38,
      "name": "Plant_Leaves_Oak",
      "rotation": 3
    },
    {
      "x": -22,
      "y": 9,
      "z": -38,
      "name": "Plant_Leaves_Oak",
      "rotation": 3
    },
    {
      "x": -22,
      "y": 0,
      "z": -37,
      "name": "Plant_Leaves_Beech",
      "rotation": 3
    },
    {
      "x": -22,
      "y": 1,
      "z": -37,
      "name": "Plant_Leaves_Beech",
      "rotation": 3
    },
    {
      "x": -22,
      "y": 2,
      "z": -37,
      "name": "Plant_Leaves_Beech",
      "rotation": 3
    },
    {
      "x": -22,
      "y": 3,
      "z": -37,
      "name": "Plant_Leaves_Beech",
      "rotation": 3
    },
    {
      "x": -22,
      "y": 4,
      "z": -37,
      "name": "Wood_Oak_Branch_Long",
      "rotation": 4
    },
    {
      "x": -22,
      "y": 5,
      "z": -37,
      "name": "Plant_Leaves_Oak",
      "rotation": 3
    },
    {
      "x": -22,
      "y": 7,
      "z": -37,
      "name": "Plant_Leaves_Oak",
      "rotation": 3
    },
    {
      "x": -22,
      "y": 1,
      "z": -36,
      "name": "Plant_Leaves_Beech",
      "rotation": 3
    },
    {
      "x": -22,
      "y": 2,
      "z": -36,
      "name": "Plant_Leaves_Beech",
      "rotation": 3
    },
    {
      "x": -22,
      "y": 3,
      "z": -36,
      "name": "Plant_Leaves_Oak",
      "rotation": 3
    },
    {
      "x": -22,
      "y": 4,
      "z": -36,
      "name": "Wood_Oak_Trunk_Full",
      "rotation": 3
    },
    {
      "x": -22,
      "y": 5,
      "z": -36,
      "name": "Wood_Oak_Trunk_Full",
      "rotation": 3
    },
    {
      "x": -22,
      "y": 6,
      "z": -36,
      "name": "Plant_Leaves_Oak",
      "rotation": 3
    },
    {
      "x": -22,
      "y": 7,
      "z": -36,
      "name": "Plant_Leaves_Oak",
      "rotation": 3
    },
    {
      "x": -22,
      "y": 11,
      "z": -36,
      "name": "Plant_Leaves_Oak",
      "rotation": 3
    },
    {
      "x": -22,
      "y": 1,
      "z": -35,
      "name": "Plant_Leaves_Oak",
      "rotation": 3
    },
    {
      "x": -22,
      "y": 5,
      "z": -35,
      "name": "Wood_Oak_Branch_Long",
      "rotation": 4
    },
    {
      "x": -22,
      "y": 4,
      "z": -34,
      "name": "Plant_Leaves_Oak",
      "rotation": 3
    },
    {
      "x": -22,
      "y": 5,
      "z": -34,
      "name": "Wood_Oak_Branch_Long",
      "rotation": 4
    },
    {
      "x": -22,
      "y": 6,
      "z": -34,
      "name": "Plant_Leaves_Oak",
      "rotation": 3
    },
    {
      "x": -22,
      "y": 4,
      "z": -33,
      "name": "Plant_Leaves_Oak",
      "rotation": 3
    },
    {
      "x": -22,
      "y": 5,
      "z": -33,
      "name": "Plant_Leaves_Oak",
      "rotation": 3
    },
    {
      "x": -22,
      "y": 6,
      "z": -33,
      "name": "Plant_Leaves_Oak",
      "rotation": 3
    },
    {
      "x": -22,
      "y": 8,
      "z": -33,
      "name": "Plant_Leaves_Oak",
      "rotation": 3
    },
    {
      "x": -22,
      "y": 5,
      "z": -32,
      "name": "Plant_Leaves_Oak",
      "rotation": 3
    },
    {
      "x": -22,
      "y": 6,
      "z": -32,
      "name": "Plant_Leaves_Oak",
      "rotation": 3
    },
    {
      "x": -22,
      "y": 8,
      "z": -26,
      "name": "Plant_Leaves_Oak",
      "rotation": 2
    },
    {
      "x": -22,
      "y": 9,
      "z": -26,
      "name": "Plant_Leaves_Oak",
      "rotation": 2
    },
    {
      "x": -22,
      "y": 6,
      "z": -25,
      "name": "Plant_Leaves_Oak",
      "rotation": 2
    },
    {
      "x": -22,
      "y": 7,
      "z": -25,
      "name": "Plant_Leaves_Oak",
      "rotation": 2
    },
    {
      "x": -22,
      "y": 8,
      "z": -25,
      "name": "Wood_Oak_Branch_Long",
      "rotation": 7
    },
    {
      "x": -22,
      "y": 9,
      "z": -25,
      "name": "Plant_Leaves_Oak",
      "rotation": 2
    },
    {
      "x": -22,
      "y": 6,
      "z": -24,
      "name": "Plant_Leaves_Oak",
      "rotation": 2
    },
    {
      "x": -22,
      "y": 8,
      "z": -24,
      "name": "Plant_Leaves_Oak",
      "rotation": 2
    },
    {
      "x": -22,
      "y": 3,
      "z": -23,
      "name": "Plant_Leaves_Oak",
      "rotation": 2
    },
    {
      "x": -22,
      "y": 5,
      "z": -23,
      "name": "Plant_Leaves_Oak",
      "rotation": 2
    },
    {
      "x": -22,
      "y": 6,
      "z": -23,
      "name": "Plant_Leaves_Oak",
      "rotation": 2
    },
    {
      "x": -22,
      "y": 7,
      "z": -23,
      "name": "Plant_Leaves_Oak",
      "rotation": 2
    },
    {
      "x": -22,
      "y": 5,
      "z": -22,
      "name": "Plant_Leaves_Oak",
      "rotation": 2
    },
    {
      "x": -22,
      "y": 6,
      "z": -22,
      "name": "Plant_Leaves_Oak",
      "rotation": 2
    },
    {
      "x": -22,
      "y": 10,
      "z": -22,
      "name": "Plant_Leaves_Oak",
      "rotation": 2
    },
    {
      "x": -22,
      "y": 11,
      "z": -22,
      "name": "Plant_Leaves_Oak",
      "rotation": 2
    },
    {
      "x": -22,
      "y": 3,
      "z": -21,
      "name": "Wood_Oak_Trunk_Full",
      "rotation": 2
    },
    {
      "x": -22,
      "y": 5,
      "z": -21,
      "name": "Wood_Oak_Branch_Corner",
      "rotation": 1
    },
    {
      "x": -22,
      "y": 6,
      "z": -21,
      "name": "Plant_Leaves_Oak",
      "rotation": 2
    },
    {
      "x": -22,
      "y": 8,
      "z": -21,
      "name": "Wood_Oak_Trunk_Full",
      "rotation": 2
    },
    {
      "x": -22,
      "y": 10,
      "z": -21,
      "name": "Plant_Leaves_Oak",
      "rotation": 2
    },
    {
      "x": -22,
      "y": 11,
      "z": -21,
      "name": "Plant_Leaves_Oak",
      "rotation": 2
    },
    {
      "x": -22,
      "y": 3,
      "z": -20,
      "name": "Wood_Oak_Branch_Long",
      "rotation": 6
    },
    {
      "x": -22,
      "y": 4,
      "z": -20,
      "name": "Plant_Leaves_Oak",
      "rotation": 2
    },
    {
      "x": -22,
      "y": 6,
      "z": -20,
      "name": "Plant_Leaves_Oak",
      "rotation": 2
    },
    {
      "x": -22,
      "y": 8,
      "z": -20,
      "name": "Wood_Oak_Branch_Long",
      "rotation": 6
    },
    {
      "x": -22,
      "y": 10,
      "z": -20,
      "name": "Plant_Leaves_Oak",
      "rotation": 2
    },
    {
      "x": -22,
      "y": 11,
      "z": -20,
      "name": "Plant_Leaves_Oak",
      "rotation": 2
    },
    {
      "x": -22,
      "y": 3,
      "z": -19,
      "name": "Wood_Oak_Branch_Corner"
    },
    {
      "x": -22,
      "y": 4,
      "z": -19,
      "name": "Wood_Oak_Branch_Long",
      "rotation": 2
    },
    {
      "x": -22,
      "y": 5,
      "z": -19,
      "name": "Plant_Leaves_Birch"
    },
    {
      "x": -22,
      "y": 6,
      "z": -19,
      "name": "Plant_Leaves_Birch"
    },
    {
      "x": -22,
      "y": 8,
      "z": -19,
      "name": "Wood_Oak_Branch_Long",
      "rotation": 6
    },
    {
      "x": -22,
      "y": 10,
      "z": -19,
      "name": "Plant_Leaves_Oak",
      "rotation": 2
    },
    {
      "x": -22,
      "y": 2,
      "z": -18,
      "name": "Plant_Leaves_Birch"
    },
    {
      "x": -22,
      "y": 4,
      "z": -18,
      "name": "Plant_Leaves_Birch"
    },
    {
      "x": -22,
      "y": 7,
      "z": -18,
      "name": "Plant_Leaves_Birch"
    },
    {
      "x": -22,
      "y": 8,
      "z": -18,
      "name": "Wood_Oak_Branch_Corner"
    },
    {
      "x": -22,
      "y": 9,
      "z": -18,
      "name": "Wood_Oak_Branch_Long",
      "rotation": 2
    },
    {
      "x": -22,
      "y": 10,
      "z": -18,
      "name": "Plant_Leaves_Oak",
      "rotation": 2
    },
    {
      "x": -22,
      "y": 11,
      "z": -18,
      "name": "Plant_Leaves_Oak",
      "rotation": 2
    },
    {
      "x": -22,
      "y": 4,
      "z": -17,
      "name": "Plant_Leaves_Oak",
      "rotation": 2
    },
    {
      "x": -22,
      "y": 5,
      "z": -17,
      "name": "Wood_Birch_Branch_Corner",
      "rotation": 2
    },
    {
      "x": -22,
      "y": 6,
      "z": -17,
      "name": "Wood_Birch_Branch_Long"
    },
    {
      "x": -22,
      "y": 7,
      "z": -17,
      "name": "Wood_Birch_Branch_Long"
    },
    {
      "x": -22,
      "y": 8,
      "z": -17,
      "name": "Plant_Leaves_Oak",
      "rotation": 2
    },
    {
      "x": -22,
      "y": 9,
      "z": -17,
      "name": "Plant_Leaves_Oak",
      "rotation": 2
    },
    {
      "x": -22,
      "y": 10,
      "z": -17,
      "name": "Plant_Leaves_Oak",
      "rotation": 2
    },
    {
      "x": -22,
      "y": 1,
      "z": -16,
      "name": "Wood_Birch_Trunk_Full"
    },
    {
      "x": -22,
      "y": 2,
      "z": -16,
      "name": "Wood_Birch_Trunk"
    },
    {
      "x": -22,
      "y": 3,
      "z": -16,
      "name": "Wood_Birch_Trunk"
    },
    {
      "x": -22,
      "y": 4,
      "z": -16,
      "name": "Wood_Birch_Trunk"
    },
    {
      "x": -22,
      "y": 5,
      "z": -16,
      "name": "Wood_Birch_Trunk_Full"
    },
    {
      "x": -22,
      "y": 6,
      "z": -16,
      "name": "Wood_Birch_Branch_Long"
    },
    {
      "x": -22,
      "y": 7,
      "z": -16,
      "name": "Wood_Birch_Branch_Long"
    },
    {
      "x": -22,
      "y": 8,
      "z": -16,
      "name": "Plant_Leaves_Birch"
    },
    {
      "x": -22,
      "y": 9,
      "z": -16,
      "name": "Plant_Leaves_Birch"
    },
    {
      "x": -22,
      "y": 10,
      "z": -16,
      "name": "Plant_Leaves_Birch"
    },
    {
      "x": -22,
      "y": 11,
      "z": -16,
      "name": "Plant_Leaves_Birch"
    },
    {
      "x": -22,
      "y": 7,
      "z": -15,
      "name": "Plant_Leaves_Birch"
    },
    {
      "x": -22,
      "y": 8,
      "z": -15,
      "name": "Plant_Leaves_Birch"
    },
    {
      "x": -22,
      "y": 9,
      "z": -15,
      "name": "Plant_Leaves_Birch"
    },
    {
      "x": -22,
      "y": 10,
      "z": -15,
      "name": "Plant_Leaves_Birch"
    },
    {
      "x": -22,
      "y": 11,
      "z": -15,
      "name": "Plant_Leaves_Birch"
    },
    {
      "x": -22,
      "y": 4,
      "z": -14,
      "name": "Plant_Leaves_Birch"
    },
    {
      "x": -22,
      "y": 5,
      "z": -14,
      "name": "Plant_Leaves_Birch"
    },
    {
      "x": -22,
      "y": 9,
      "z": -14,
      "name": "Plant_Leaves_Birch"
    },
    {
      "x": -22,
      "y": 10,
      "z": -14,
      "name": "Plant_Leaves_Birch"
    },
    {
      "x": -22,
      "y": 3,
      "z": -13,
      "name": "Plant_Leaves_Birch"
    },
    {
      "x": -22,
      "y": 4,
      "z": -13,
      "name": "Plant_Leaves_Birch"
    },
    {
      "x": -22,
      "y": 7,
      "z": -13,
      "name": "Plant_Leaves_Birch"
    },
    {
      "x": -22,
      "y": 9,
      "z": -13,
      "name": "Plant_Leaves_Birch"
    },
    {
      "x": -22,
      "y": 1,
      "z": -12,
      "name": "Plant_Leaves_Birch"
    },
    {
      "x": -22,
      "y": 1,
      "z": 9,
      "name": "Plant_Leaves_Birch",
      "rotation": 3
    },
    {
      "x": -22,
      "y": 2,
      "z": 9,
      "name": "Plant_Leaves_Birch",
      "rotation": 3
    },
    {
      "x": -22,
      "y": 3,
      "z": 9,
      "name": "Plant_Leaves_Birch",
      "rotation": 3
    },
    {
      "x": -22,
      "y": 4,
      "z": 9,
      "name": "Plant_Leaves_Birch",
      "rotation": 3
    },
    {
      "x": -22,
      "y": 5,
      "z": 9,
      "name": "Plant_Leaves_Birch",
      "rotation": 3
    },
    {
      "x": -22,
      "y": 6,
      "z": 9,
      "name": "Plant_Leaves_Birch",
      "rotation": 3
    },
    {
      "x": -22,
      "y": 7,
      "z": 9,
      "name": "Plant_Leaves_Birch",
      "rotation": 3
    },
    {
      "x": -22,
      "y": 1,
      "z": 10,
      "name": "Plant_Leaves_Birch",
      "rotation": 3
    },
    {
      "x": -22,
      "y": 2,
      "z": 10,
      "name": "Plant_Leaves_Birch",
      "rotation": 3
    },
    {
      "x": -22,
      "y": 5,
      "z": 10,
      "name": "Plant_Leaves_Birch",
      "rotation": 3
    },
    {
      "x": -22,
      "y": 7,
      "z": 10,
      "name": "Plant_Leaves_Birch",
      "rotation": 3
    },
    {
      "x": -22,
      "y": 8,
      "z": 10,
      "name": "Plant_Leaves_Birch",
      "rotation": 3
    },
    {
      "x": -22,
      "y": 10,
      "z": 10,
      "name": "Plant_Leaves_Birch",
      "rotation": 3
    },
    {
      "x": -22,
      "y": 0,
      "z": 11,
      "name": "Plant_Leaves_Birch",
      "rotation": 3
    },
    {
      "x": -22,
      "y": 1,
      "z": 11,
      "name": "Plant_Leaves_Birch",
      "rotation": 3
    },
    {
      "x": -22,
      "y": 2,
      "z": 11,
      "name": "Plant_Leaves_Birch",
      "rotation": 3
    },
    {
      "x": -22,
      "y": 4,
      "z": 11,
      "name": "Plant_Leaves_Birch",
      "rotation": 3
    },
    {
      "x": -22,
      "y": 10,
      "z": 11,
      "name": "Plant_Leaves_Birch",
      "rotation": 3
    },
    {
      "x": -22,
      "y": 11,
      "z": 11,
      "name": "Plant_Leaves_Birch",
      "rotation": 3
    },
    {
      "x": -22,
      "y": 0,
      "z": 12,
      "name": "Plant_Leaves_Birch",
      "rotation": 3
    },
    {
      "x": -22,
      "y": 1,
      "z": 12,
      "name": "Plant_Leaves_Birch",
      "rotation": 3
    },
    {
      "x": -22,
      "y": 2,
      "z": 12,
      "name": "Plant_Leaves_Birch",
      "rotation": 3
    },
    {
      "x": -22,
      "y": 5,
      "z": 12,
      "name": "Plant_Leaves_Birch",
      "rotation": 3
    },
    {
      "x": -22,
      "y": 6,
      "z": 12,
      "name": "Plant_Leaves_Birch",
      "rotation": 3
    },
    {
      "x": -22,
      "y": 7,
      "z": 12,
      "name": "Plant_Leaves_Birch",
      "rotation": 3
    },
    {
      "x": -22,
      "y": 8,
      "z": 12,
      "name": "Plant_Leaves_Birch",
      "rotation": 3
    },
    {
      "x": -22,
      "y": 9,
      "z": 12,
      "name": "Plant_Leaves_Birch",
      "rotation": 3
    },
    {
      "x": -22,
      "y": 10,
      "z": 12,
      "name": "Plant_Leaves_Birch",
      "rotation": 3
    },
    {
      "x": -22,
      "y": 11,
      "z": 12,
      "name": "Plant_Leaves_Birch",
      "rotation": 3
    },
    {
      "x": -22,
      "y": 12,
      "z": 12,
      "name": "Plant_Leaves_Birch",
      "rotation": 3
    },
    {
      "x": -22,
      "y": 0,
      "z": 13,
      "name": "Plant_Leaves_Birch",
      "rotation": 3
    },
    {
      "x": -22,
      "y": 1,
      "z": 13,
      "name": "Plant_Leaves_Birch",
      "rotation": 3
    },
    {
      "x": -22,
      "y": 2,
      "z": 13,
      "name": "Plant_Leaves_Birch",
      "rotation": 3
    },
    {
      "x": -22,
      "y": 3,
      "z": 13,
      "name": "Plant_Leaves_Birch",
      "rotation": 3
    },
    {
      "x": -22,
      "y": 4,
      "z": 13,
      "name": "Plant_Leaves_Birch",
      "rotation": 3
    },
    {
      "x": -22,
      "y": 5,
      "z": 13,
      "name": "Plant_Leaves_Birch",
      "rotation": 3
    },
    {
      "x": -22,
      "y": 7,
      "z": 13,
      "name": "Plant_Leaves_Birch",
      "rotation": 3
    },
    {
      "x": -22,
      "y": 8,
      "z": 13,
      "name": "Plant_Leaves_Birch",
      "rotation": 3
    },
    {
      "x": -22,
      "y": 9,
      "z": 13,
      "name": "Plant_Leaves_Birch",
      "rotation": 3
    },
    {
      "x": -22,
      "y": 10,
      "z": 13,
      "name": "Plant_Leaves_Birch",
      "rotation": 3
    },
    {
      "x": -22,
      "y": 11,
      "z": 13,
      "name": "Plant_Leaves_Birch",
      "rotation": 3
    },
    {
      "x": -22,
      "y": 4,
      "z": 14,
      "name": "Plant_Leaves_Birch",
      "rotation": 3
    },
    {
      "x": -22,
      "y": 5,
      "z": 14,
      "name": "Plant_Leaves_Birch",
      "rotation": 3
    },
    {
      "x": -22,
      "y": 6,
      "z": 14,
      "name": "Plant_Leaves_Birch",
      "rotation": 3
    },
    {
      "x": -22,
      "y": 7,
      "z": 14,
      "name": "Plant_Leaves_Birch",
      "rotation": 3
    },
    {
      "x": -22,
      "y": 5,
      "z": 15,
      "name": "Plant_Leaves_Birch",
      "rotation": 3
    },
    {
      "x": -22,
      "y": 6,
      "z": 15,
      "name": "Plant_Leaves_Birch",
      "rotation": 3
    },
    {
      "x": -22,
      "y": 8,
      "z": 15,
      "name": "Plant_Leaves_Birch",
      "rotation": 3
    },
    {
      "x": -22,
      "y": 3,
      "z": 19,
      "name": "Plant_Leaves_Beech",
      "rotation": 2
    },
    {
      "x": -22,
      "y": 4,
      "z": 19,
      "name": "Plant_Leaves_Beech",
      "rotation": 2
    },
    {
      "x": -22,
      "y": 4,
      "z": 20,
      "name": "Plant_Leaves_Beech",
      "rotation": 2
    },
    {
      "x": -22,
      "y": 6,
      "z": 20,
      "name": "Plant_Leaves_Beech",
      "rotation": 2
    },
    {
      "x": -22,
      "y": 7,
      "z": 20,
      "name": "Plant_Leaves_Beech",
      "rotation": 2
    },
    {
      "x": -22,
      "y": 12,
      "z": 20,
      "name": "Plant_Leaves_Beech",
      "rotation": 2
    },
    {
      "x": -22,
      "y": 6,
      "z": 21,
      "name": "Wood_Beech_Branch_Corner",
      "rotation": 1
    },
    {
      "x": -22,
      "y": 7,
      "z": 21,
      "name": "Plant_Leaves_Beech",
      "rotation": 2
    },
    {
      "x": -22,
      "y": 11,
      "z": 21,
      "name": "Plant_Leaves_Beech",
      "rotation": 2
    },
    {
      "x": -22,
      "y": 12,
      "z": 21,
      "name": "Plant_Leaves_Beech",
      "rotation": 2
    },
    {
      "x": -22,
      "y": 8,
      "z": 22,
      "name": "Plant_Leaves_Beech",
      "rotation": 2
    },
    {
      "x": -22,
      "y": 9,
      "z": 22,
      "name": "Plant_Leaves_Beech",
      "rotation": 2
    },
    {
      "x": -22,
      "y": 11,
      "z": 22,
      "name": "Plant_Leaves_Beech",
      "rotation": 2
    },
    {
      "x": -22,
      "y": 12,
      "z": 22,
      "name": "Plant_Leaves_Beech",
      "rotation": 2
    },
    {
      "x": -22,
      "y": 13,
      "z": 22,
      "name": "Plant_Leaves_Beech",
      "rotation": 2
    },
    {
      "x": -22,
      "y": 3,
      "z": 23,
      "name": "Wood_Beech_Branch_Long",
      "rotation": 7
    },
    {
      "x": -22,
      "y": 8,
      "z": 23,
      "name": "Wood_Beech_Branch_Long",
      "rotation": 7
    },
    {
      "x": -22,
      "y": 9,
      "z": 23,
      "name": "Plant_Leaves_Beech",
      "rotation": 2
    },
    {
      "x": -22,
      "y": 11,
      "z": 23,
      "name": "Wood_Beech_Branch_Corner",
      "rotation": 1
    },
    {
      "x": -22,
      "y": 12,
      "z": 23,
      "name": "Plant_Leaves_Beech",
      "rotation": 2
    },
    {
      "x": -22,
      "y": 13,
      "z": 23,
      "name": "Plant_Leaves_Beech",
      "rotation": 2
    },
    {
      "x": -22,
      "y": 8,
      "z": 24,
      "name": "Plant_Leaves_Beech",
      "rotation": 2
    },
    {
      "x": -22,
      "y": 9,
      "z": 24,
      "name": "Plant_Leaves_Beech",
      "rotation": 2
    },
    {
      "x": -22,
      "y": 11,
      "z": 24,
      "name": "Plant_Leaves_Beech",
      "rotation": 2
    },
    {
      "x": -22,
      "y": 12,
      "z": 24,
      "name": "Plant_Leaves_Beech",
      "rotation": 2
    },
    {
      "x": -22,
      "y": 13,
      "z": 24,
      "name": "Plant_Leaves_Beech",
      "rotation": 2
    },
    {
      "x": -22,
      "y": 6,
      "z": 25,
      "name": "Plant_Leaves_Beech",
      "rotation": 2
    },
    {
      "x": -22,
      "y": 11,
      "z": 25,
      "name": "Plant_Leaves_Beech",
      "rotation": 2
    },
    {
      "x": -22,
      "y": 12,
      "z": 25,
      "name": "Plant_Leaves_Beech",
      "rotation": 2
    },
    {
      "x": -22,
      "y": 6,
      "z": 26,
      "name": "Plant_Leaves_Beech",
      "rotation": 2
    },
    {
      "x": -22,
      "y": 7,
      "z": 26,
      "name": "Plant_Leaves_Beech",
      "rotation": 2
    },
    {
      "x": -22,
      "y": 8,
      "z": 26,
      "name": "Plant_Leaves_Beech",
      "rotation": 2
    },
    {
      "x": -22,
      "y": 7,
      "z": 27,
      "name": "Plant_Leaves_Beech",
      "rotation": 2
    },
    {
      "x": -22,
      "y": 4,
      "z": 53,
      "name": "Plant_Leaves_Birch"
    },
    {
      "x": -22,
      "y": 5,
      "z": 53,
      "name": "Plant_Leaves_Birch"
    },
    {
      "x": -22,
      "y": 2,
      "z": 54,
      "name": "Plant_Leaves_Birch"
    },
    {
      "x": -22,
      "y": 3,
      "z": 54,
      "name": "Plant_Leaves_Birch"
    },
    {
      "x": -22,
      "y": 4,
      "z": 54,
      "name": "Plant_Leaves_Birch"
    },
    {
      "x": -22,
      "y": 5,
      "z": 54,
      "name": "Plant_Leaves_Birch"
    },
    {
      "x": -22,
      "y": 6,
      "z": 54,
      "name": "Plant_Leaves_Birch"
    },
    {
      "x": -22,
      "y": 7,
      "z": 54,
      "name": "Plant_Leaves_Birch"
    },
    {
      "x": -22,
      "y": 4,
      "z": 55,
      "name": "Plant_Leaves_Birch"
    },
    {
      "x": -22,
      "y": 5,
      "z": 55,
      "name": "Plant_Leaves_Birch"
    },
    {
      "x": -22,
      "y": 0,
      "z": 56,
      "name": "Plant_Flower_Common_Red2"
    },
    {
      "x": -22,
      "y": 0,
      "z": 57,
      "name": "Soil_Grass_Full"
    },
    {
      "x": -22,
      "y": 1,
      "z": 57,
      "name": "Plant_Bush_Green"
    },
    {
      "x": -22,
      "y": 0,
      "z": 58,
      "name": "Soil_Grass_Full"
    },
    {
      "x": -22,
      "y": 1,
      "z": 58,
      "name": "Plant_Bush_Green"
    },
    {
      "x": -22,
      "y": 0,
      "z": 59,
      "name": "Soil_Grass_Full"
    },
    {
      "x": -22,
      "y": 0,
      "z": 60,
      "name": "Soil_Grass_Full"
    },
    {
      "x": -22,
      "y": 1,
      "z": 60,
      "name": "*Plant_Crop_Berry_Block_State_Definitions_StageFinal"
    },
    {
      "x": -22,
      "y": 0,
      "z": 61,
      "name": "Soil_Dirt"
    },
    {
      "x": -22,
      "y": 1,
      "z": 61,
      "name": "Soil_Grass_Full"
    },
    {
      "x": -22,
      "y": 2,
      "z": 61,
      "name": "Plant_Flower_Common_Red2"
    },
    {
      "x": -22,
      "y": 0,
      "z": 62,
      "name": "Soil_Dirt"
    },
    {
      "x": -22,
      "y": 1,
      "z": 62,
      "name": "Soil_Grass_Full"
    },
    {
      "x": -22,
      "y": 0,
      "z": 63,
      "name": "Soil_Dirt"
    },
    {
      "x": -22,
      "y": 1,
      "z": 63,
      "name": "Soil_Grass_Full"
    },
    {
      "x": -22,
      "y": 2,
      "z": 63,
      "name": "Plant_Grass_Lush_Short"
    },
    {
      "x": -22,
      "y": 0,
      "z": 64,
      "name": "Soil_Dirt"
    },
    {
      "x": -22,
      "y": 1,
      "z": 64,
      "name": "Soil_Grass_Full"
    },
    {
      "x": -22,
      "y": 2,
      "z": 64,
      "name": "Plant_Grass_Lush_Short"
    },
    {
      "x": -22,
      "y": 0,
      "z": 65,
      "name": "Soil_Dirt"
    },
    {
      "x": -22,
      "y": 1,
      "z": 65,
      "name": "Soil_Grass_Full"
    },
    {
      "x": -22,
      "y": 0,
      "z": 66,
      "name": "Soil_Dirt"
    },
    {
      "x": -22,
      "y": 1,
      "z": 66,
      "name": "Soil_Grass_Full"
    },
    {
      "x": -22,
      "y": 2,
      "z": 66,
      "name": "Plant_Grass_Sharp_Short"
    },
    {
      "x": -21,
      "y": 9,
      "z": -39,
      "name": "Plant_Leaves_Oak",
      "rotation": 3
    },
    {
      "x": -21,
      "y": 4,
      "z": -38,
      "name": "Plant_Leaves_Oak",
      "rotation": 3
    },
    {
      "x": -21,
      "y": 7,
      "z": -38,
      "name": "Plant_Leaves_Oak",
      "rotation": 3
    },
    {
      "x": -21,
      "y": 4,
      "z": -37,
      "name": "Plant_Leaves_Oak",
      "rotation": 3
    },
    {
      "x": -21,
      "y": 6,
      "z": -37,
      "name": "Plant_Leaves_Oak",
      "rotation": 3
    },
    {
      "x": -21,
      "y": 7,
      "z": -37,
      "name": "Plant_Leaves_Oak",
      "rotation": 3
    },
    {
      "x": -21,
      "y": 8,
      "z": -37,
      "name": "Plant_Leaves_Oak",
      "rotation": 3
    },
    {
      "x": -21,
      "y": 1,
      "z": -36,
      "name": "Plant_Leaves_Oak",
      "rotation": 3
    },
    {
      "x": -21,
      "y": 2,
      "z": -36,
      "name": "Plant_Leaves_Oak",
      "rotation": 3
    },
    {
      "x": -21,
      "y": 4,
      "z": -36,
      "name": "Plant_Leaves_Oak",
      "rotation": 3
    },
    {
      "x": -21,
      "y": 5,
      "z": -36,
      "name": "Wood_Oak_Branch_Corner",
      "rotation": 1
    },
    {
      "x": -21,
      "y": 6,
      "z": -36,
      "name": "Wood_Oak_Branch_Corner",
      "rotation": 9
    },
    {
      "x": -21,
      "y": 7,
      "z": -36,
      "name": "Plant_Leaves_Oak",
      "rotation": 3
    },
    {
      "x": -21,
      "y": 8,
      "z": -36,
      "name": "Plant_Leaves_Oak",
      "rotation": 3
    },
    {
      "x": -21,
      "y": 2,
      "z": -35,
      "name": "Plant_Leaves_Oak",
      "rotation": 3
    },
    {
      "x": -21,
      "y": 6,
      "z": -35,
      "name": "Plant_Leaves_Oak",
      "rotation": 3
    },
    {
      "x": -21,
      "y": 7,
      "z": -35,
      "name": "Plant_Leaves_Oak",
      "rotation": 3
    },
    {
      "x": -21,
      "y": 5,
      "z": -34,
      "name": "Plant_Leaves_Oak",
      "rotation": 3
    },
    {
      "x": -21,
      "y": 5,
      "z": -33,
      "name": "Plant_Leaves_Oak",
      "rotation": 3
    },
    {
      "x": -21,
      "y": 6,
      "z": -33,
      "name": "Plant_Leaves_Oak",
      "rotation": 3
    },
    {
      "x": -21,
      "y": 5,
      "z": -32,
      "name": "Plant_Leaves_Oak",
      "rotation": 3
    },
    {
      "x": -21,
      "y": 8,
      "z": -26,
      "name": "Plant_Leaves_Oak",
      "rotation": 2
    },
    {
      "x": -21,
      "y": 7,
      "z": -25,
      "name": "Plant_Leaves_Oak",
      "rotation": 2
    },
    {
      "x": -21,
      "y": 8,
      "z": -25,
      "name": "Plant_Leaves_Oak",
      "rotation": 2
    },
    {
      "x": -21,
      "y": 9,
      "z": -25,
      "name": "Plant_Leaves_Oak",
      "rotation": 2
    },
    {
      "x": -21,
      "y": 6,
      "z": -24,
      "name": "Plant_Leaves_Oak",
      "rotation": 2
    },
    {
      "x": -21,
      "y": 7,
      "z": -24,
      "name": "Plant_Leaves_Oak",
      "rotation": 2
    },
    {
      "x": -21,
      "y": 8,
      "z": -24,
      "name": "Plant_Leaves_Oak",
      "rotation": 2
    },
    {
      "x": -21,
      "y": 3,
      "z": -22,
      "name": "Plant_Leaves_Oak",
      "rotation": 2
    },
    {
      "x": -21,
      "y": 8,
      "z": -22,
      "name": "Plant_Leaves_Oak",
      "rotation": 2
    },
    {
      "x": -21,
      "y": 9,
      "z": -22,
      "name": "Plant_Leaves_Oak",
      "rotation": 2
    },
    {
      "x": -21,
      "y": 3,
      "z": -21,
      "name": "Wood_Oak_Branch_Long",
      "rotation": 7
    },
    {
      "x": -21,
      "y": 4,
      "z": -21,
      "name": "Plant_Leaves_Oak",
      "rotation": 2
    },
    {
      "x": -21,
      "y": 6,
      "z": -21,
      "name": "Plant_Leaves_Oak",
      "rotation": 2
    },
    {
      "x": -21,
      "y": 8,
      "z": -21,
      "name": "Wood_Oak_Branch_Corner",
      "rotation": 1
    },
    {
      "x": -21,
      "y": 9,
      "z": -21,
      "name": "Wood_Oak_Branch_Corner",
      "rotation": 9
    },
    {
      "x": -21,
      "y": 11,
      "z": -21,
      "name": "Plant_Leaves_Oak",
      "rotation": 2
    },
    {
      "x": -21,
      "y": 3,
      "z": -20,
      "name": "Plant_Leaves_Oak",
      "rotation": 2
    },
    {
      "x": -21,
      "y": 4,
      "z": -20,
      "name": "Plant_Leaves_Birch"
    },
    {
      "x": -21,
      "y": 10,
      "z": -20,
      "name": "Plant_Leaves_Oak",
      "rotation": 2
    },
    {
      "x": -21,
      "y": 2,
      "z": -19,
      "name": "Plant_Leaves_Birch"
    },
    {
      "x": -21,
      "y": 3,
      "z": -19,
      "name": "Plant_Leaves_Birch"
    },
    {
      "x": -21,
      "y": 4,
      "z": -19,
      "name": "Plant_Leaves_Birch"
    },
    {
      "x": -21,
      "y": 6,
      "z": -19,
      "name": "Plant_Leaves_Birch"
    },
    {
      "x": -21,
      "y": 8,
      "z": -19,
      "name": "Plant_Leaves_Oak",
      "rotation": 2
    },
    {
      "x": -21,
      "y": 1,
      "z": -18,
      "name": "Plant_Leaves_Birch"
    },
    {
      "x": -21,
      "y": 3,
      "z": -18,
      "name": "Plant_Leaves_Birch"
    },
    {
      "x": -21,
      "y": 4,
      "z": -18,
      "name": "Plant_Leaves_Oak",
      "rotation": 2
    },
    {
      "x": -21,
      "y": 5,
      "z": -18,
      "name": "Plant_Leaves_Oak",
      "rotation": 2
    },
    {
      "x": -21,
      "y": 8,
      "z": -18,
      "name": "Plant_Leaves_Birch"
    },
    {
      "x": -21,
      "y": 9,
      "z": -18,
      "name": "Plant_Leaves_Oak",
      "rotation": 2
    },
    {
      "x": -21,
      "y": 10,
      "z": -18,
      "name": "Plant_Leaves_Oak",
      "rotation": 2
    },
    {
      "x": -21,
      "y": 4,
      "z": -17,
      "name": "Plant_Leaves_Oak",
      "rotation": 2
    },
    {
      "x": -21,
      "y": 7,
      "z": -17,
      "name": "Plant_Leaves_Birch"
    },
    {
      "x": -21,
      "y": 8,
      "z": -17,
      "name": "Plant_Leaves_Birch"
    },
    {
      "x": -21,
      "y": 9,
      "z": -17,
      "name": "Plant_Leaves_Birch"
    },
    {
      "x": -21,
      "y": 1,
      "z": -16,
      "name": "Wood_Birch_Trunk_Full"
    },
    {
      "x": -21,
      "y": 9,
      "z": -16,
      "name": "Plant_Leaves_Birch"
    },
    {
      "x": -21,
      "y": 11,
      "z": -16,
      "name": "Plant_Leaves_Birch"
    },
    {
      "x": -21,
      "y": 12,
      "z": -16,
      "name": "Plant_Leaves_Birch"
    },
    {
      "x": -21,
      "y": 6,
      "z": -15,
      "name": "Wood_Birch_Branch_Corner",
      "rotation": 3
    },
    {
      "x": -21,
      "y": 7,
      "z": -15,
      "name": "Wood_Birch_Branch_Long"
    },
    {
      "x": -21,
      "y": 8,
      "z": -15,
      "name": "Wood_Birch_Branch_Long"
    },
    {
      "x": -21,
      "y": 9,
      "z": -15,
      "name": "Wood_Birch_Branch_Long"
    },
    {
      "x": -21,
      "y": 10,
      "z": -15,
      "name": "Plant_Leaves_Birch"
    },
    {
      "x": -21,
      "y": 11,
      "z": -15,
      "name": "Plant_Leaves_Birch"
    },
    {
      "x": -21,
      "y": 12,
      "z": -15,
      "name": "Plant_Leaves_Birch"
    },
    {
      "x": -21,
      "y": 13,
      "z": -15,
      "name": "Plant_Leaves_Birch"
    },
    {
      "x": -21,
      "y": 1,
      "z": -14,
      "name": "Wood_Birch_Branch_Corner",
      "rotation": 3
    },
    {
      "x": -21,
      "y": 2,
      "z": -14,
      "name": "Wood_Birch_Branch_Long"
    },
    {
      "x": -21,
      "y": 3,
      "z": -14,
      "name": "Wood_Birch_Branch_Long"
    },
    {
      "x": -21,
      "y": 4,
      "z": -14,
      "name": "Plant_Leaves_Birch"
    },
    {
      "x": -21,
      "y": 5,
      "z": -14,
      "name": "Plant_Leaves_Birch"
    },
    {
      "x": -21,
      "y": 6,
      "z": -14,
      "name": "Plant_Leaves_Birch"
    },
    {
      "x": -21,
      "y": 7,
      "z": -14,
      "name": "Plant_Leaves_Birch"
    },
    {
      "x": -21,
      "y": 10,
      "z": -14,
      "name": "Plant_Leaves_Birch"
    },
    {
      "x": -21,
      "y": 11,
      "z": -14,
      "name": "Plant_Leaves_Birch"
    },
    {
      "x": -21,
      "y": 12,
      "z": -14,
      "name": "Plant_Leaves_Birch"
    },
    {
      "x": -21,
      "y": 2,
      "z": -13,
      "name": "Plant_Leaves_Birch"
    },
    {
      "x": -21,
      "y": 3,
      "z": -13,
      "name": "Plant_Leaves_Birch"
    },
    {
      "x": -21,
      "y": 4,
      "z": -13,
      "name": "Plant_Leaves_Birch"
    },
    {
      "x": -21,
      "y": 5,
      "z": -13,
      "name": "Plant_Leaves_Birch"
    },
    {
      "x": -21,
      "y": 6,
      "z": -13,
      "name": "Plant_Leaves_Birch"
    },
    {
      "x": -21,
      "y": 7,
      "z": -13,
      "name": "Plant_Leaves_Birch"
    },
    {
      "x": -21,
      "y": 9,
      "z": -13,
      "name": "Plant_Leaves_Birch"
    },
    {
      "x": -21,
      "y": 10,
      "z": -13,
      "name": "Plant_Leaves_Birch"
    },
    {
      "x": -21,
      "y": 1,
      "z": -12,
      "name": "Plant_Leaves_Birch"
    },
    {
      "x": -21,
      "y": 2,
      "z": -12,
      "name": "Plant_Leaves_Birch"
    },
    {
      "x": -21,
      "y": 3,
      "z": -12,
      "name": "Plant_Leaves_Birch"
    },
    {
      "x": -21,
      "y": 4,
      "z": -12,
      "name": "Plant_Leaves_Birch"
    },
    {
      "x": -21,
      "y": 5,
      "z": 10,
      "name": "Plant_Leaves_Birch",
      "rotation": 3
    },
    {
      "x": -21,
      "y": 6,
      "z": 10,
      "name": "Plant_Leaves_Birch",
      "rotation": 3
    },
    {
      "x": -21,
      "y": 2,
      "z": 11,
      "name": "Plant_Leaves_Birch",
      "rotation": 3
    },
    {
      "x": -21,
      "y": 3,
      "z": 11,
      "name": "Plant_Leaves_Birch",
      "rotation": 3
    },
    {
      "x": -21,
      "y": 4,
      "z": 11,
      "name": "Plant_Leaves_Birch",
      "rotation": 3
    },
    {
      "x": -21,
      "y": 5,
      "z": 11,
      "name": "Plant_Leaves_Birch",
      "rotation": 3
    },
    {
      "x": -21,
      "y": 7,
      "z": 11,
      "name": "Plant_Leaves_Birch",
      "rotation": 3
    },
    {
      "x": -21,
      "y": 8,
      "z": 11,
      "name": "Plant_Leaves_Birch",
      "rotation": 3
    },
    {
      "x": -21,
      "y": 0,
      "z": 12,
      "name": "Plant_Leaves_Birch",
      "rotation": 3
    },
    {
      "x": -21,
      "y": 1,
      "z": 12,
      "name": "Plant_Leaves_Birch",
      "rotation": 3
    },
    {
      "x": -21,
      "y": 2,
      "z": 12,
      "name": "Plant_Leaves_Birch",
      "rotation": 3
    },
    {
      "x": -21,
      "y": 3,
      "z": 12,
      "name": "Plant_Leaves_Birch",
      "rotation": 3
    },
    {
      "x": -21,
      "y": 4,
      "z": 12,
      "name": "Plant_Leaves_Birch",
      "rotation": 3
    },
    {
      "x": -21,
      "y": 5,
      "z": 12,
      "name": "Plant_Leaves_Birch",
      "rotation": 3
    },
    {
      "x": -21,
      "y": 6,
      "z": 12,
      "name": "Plant_Leaves_Birch",
      "rotation": 3
    },
    {
      "x": -21,
      "y": 7,
      "z": 12,
      "name": "Plant_Leaves_Birch",
      "rotation": 3
    },
    {
      "x": -21,
      "y": 8,
      "z": 12,
      "name": "Plant_Leaves_Birch",
      "rotation": 3
    },
    {
      "x": -21,
      "y": 9,
      "z": 12,
      "name": "Plant_Leaves_Birch",
      "rotation": 3
    },
    {
      "x": -21,
      "y": 4,
      "z": 13,
      "name": "Plant_Leaves_Birch",
      "rotation": 3
    },
    {
      "x": -21,
      "y": 5,
      "z": 13,
      "name": "Plant_Leaves_Birch",
      "rotation": 3
    },
    {
      "x": -21,
      "y": 7,
      "z": 13,
      "name": "Plant_Leaves_Birch",
      "rotation": 3
    },
    {
      "x": -21,
      "y": 8,
      "z": 13,
      "name": "Plant_Leaves_Birch",
      "rotation": 3
    },
    {
      "x": -21,
      "y": 3,
      "z": 20,
      "name": "Plant_Leaves_Beech",
      "rotation": 2
    },
    {
      "x": -21,
      "y": 4,
      "z": 20,
      "name": "Plant_Leaves_Beech",
      "rotation": 2
    },
    {
      "x": -21,
      "y": 6,
      "z": 20,
      "name": "Plant_Leaves_Beech",
      "rotation": 2
    },
    {
      "x": -21,
      "y": 7,
      "z": 20,
      "name": "Plant_Leaves_Beech",
      "rotation": 2
    },
    {
      "x": -21,
      "y": 6,
      "z": 21,
      "name": "Plant_Leaves_Beech",
      "rotation": 2
    },
    {
      "x": -21,
      "y": 7,
      "z": 21,
      "name": "Plant_Leaves_Beech",
      "rotation": 2
    },
    {
      "x": -21,
      "y": 11,
      "z": 21,
      "name": "Plant_Leaves_Beech",
      "rotation": 2
    },
    {
      "x": -21,
      "y": 6,
      "z": 22,
      "name": "Plant_Leaves_Beech",
      "rotation": 2
    },
    {
      "x": -21,
      "y": 8,
      "z": 22,
      "name": "Plant_Leaves_Beech",
      "rotation": 2
    },
    {
      "x": -21,
      "y": 9,
      "z": 22,
      "name": "Plant_Leaves_Beech",
      "rotation": 2
    },
    {
      "x": -21,
      "y": 11,
      "z": 22,
      "name": "Plant_Leaves_Beech",
      "rotation": 2
    },
    {
      "x": -21,
      "y": 12,
      "z": 22,
      "name": "Plant_Leaves_Beech",
      "rotation": 2
    },
    {
      "x": -21,
      "y": 3,
      "z": 23,
      "name": "Wood_Beech_Branch_Long",
      "rotation": 7
    },
    {
      "x": -21,
      "y": 7,
      "z": 23,
      "name": "Plant_Leaves_Beech",
      "rotation": 2
    },
    {
      "x": -21,
      "y": 8,
      "z": 23,
      "name": "Plant_Leaves_Beech",
      "rotation": 2
    },
    {
      "x": -21,
      "y": 9,
      "z": 23,
      "name": "Plant_Leaves_Beech",
      "rotation": 2
    },
    {
      "x": -21,
      "y": 11,
      "z": 23,
      "name": "Plant_Leaves_Beech",
      "rotation": 2
    },
    {
      "x": -21,
      "y": 12,
      "z": 23,
      "name": "Plant_Leaves_Beech",
      "rotation": 2
    },
    {
      "x": -21,
      "y": 3,
      "z": 24,
      "name": "Plant_Leaves_Beech",
      "rotation": 2
    },
    {
      "x": -21,
      "y": 7,
      "z": 24,
      "name": "Plant_Leaves_Beech",
      "rotation": 2
    },
    {
      "x": -21,
      "y": 8,
      "z": 24,
      "name": "Plant_Leaves_Beech",
      "rotation": 2
    },
    {
      "x": -21,
      "y": 9,
      "z": 24,
      "name": "Plant_Leaves_Beech",
      "rotation": 2
    },
    {
      "x": -21,
      "y": 11,
      "z": 24,
      "name": "Plant_Leaves_Beech",
      "rotation": 2
    },
    {
      "x": -21,
      "y": 12,
      "z": 24,
      "name": "Plant_Leaves_Beech",
      "rotation": 2
    },
    {
      "x": -21,
      "y": 3,
      "z": 25,
      "name": "Plant_Leaves_Beech",
      "rotation": 2
    },
    {
      "x": -21,
      "y": 7,
      "z": 25,
      "name": "Plant_Leaves_Beech",
      "rotation": 2
    },
    {
      "x": -21,
      "y": 3,
      "z": 26,
      "name": "Plant_Leaves_Beech",
      "rotation": 2
    },
    {
      "x": -21,
      "y": 4,
      "z": 26,
      "name": "Plant_Leaves_Beech",
      "rotation": 2
    },
    {
      "x": -21,
      "y": 3,
      "z": 27,
      "name": "Plant_Leaves_Beech",
      "rotation": 2
    },
    {
      "x": -21,
      "y": 0,
      "z": 53,
      "name": "Plant_Grass_Lush_Short"
    },
    {
      "x": -21,
      "y": 0,
      "z": 56,
      "name": "Soil_Leaves"
    },
    {
      "x": -21,
      "y": 1,
      "z": 56,
      "name": "Plant_Bush_Green"
    },
    {
      "x": -21,
      "y": 0,
      "z": 57,
      "name": "Soil_Grass_Full"
    },
    {
      "x": -21,
      "y": 0,
      "z": 58,
      "name": "Soil_Grass_Full"
    },
    {
      "x": -21,
      "y": 1,
      "z": 58,
      "name": "Plant_Bush_Green"
    },
    {
      "x": -21,
      "y": 0,
      "z": 59,
      "name": "Soil_Grass_Full"
    },
    {
      "x": -21,
      "y": 0,
      "z": 60,
      "name": "Soil_Dirt"
    },
    {
      "x": -21,
      "y": 1,
      "z": 60,
      "name": "Soil_Grass_Full"
    },
    {
      "x": -21,
      "y": 2,
      "z": 60,
      "name": "*Plant_Crop_Berry_Block_State_Definitions_StageFinal"
    },
    {
      "x": -21,
      "y": 0,
      "z": 61,
      "name": "Soil_Dirt"
    },
    {
      "x": -21,
      "y": 1,
      "z": 61,
      "name": "Soil_Grass_Full"
    },
    {
      "x": -21,
      "y": 0,
      "z": 62,
      "name": "Soil_Dirt"
    },
    {
      "x": -21,
      "y": 1,
      "z": 62,
      "name": "Soil_Grass_Full"
    },
    {
      "x": -21,
      "y": 0,
      "z": 63,
      "name": "Soil_Dirt"
    },
    {
      "x": -21,
      "y": 1,
      "z": 63,
      "name": "Soil_Grass_Full"
    },
    {
      "x": -21,
      "y": 2,
      "z": 63,
      "name": "Plant_Grass_Sharp_Short"
    },
    {
      "x": -21,
      "y": 0,
      "z": 64,
      "name": "Soil_Dirt"
    },
    {
      "x": -21,
      "y": 1,
      "z": 64,
      "name": "Soil_Grass_Full"
    },
    {
      "x": -21,
      "y": 2,
      "z": 64,
      "name": "Plant_Grass_Lush_Short"
    },
    {
      "x": -21,
      "y": 0,
      "z": 65,
      "name": "Soil_Dirt"
    },
    {
      "x": -21,
      "y": 1,
      "z": 65,
      "name": "Soil_Grass_Full"
    },
    {
      "x": -21,
      "y": 2,
      "z": 65,
      "name": "Plant_Grass_Sharp"
    },
    {
      "x": -21,
      "y": 0,
      "z": 66,
      "name": "Soil_Dirt"
    },
    {
      "x": -21,
      "y": 1,
      "z": 66,
      "name": "Soil_Grass_Full"
    },
    {
      "x": -20,
      "y": 6,
      "z": -37,
      "name": "Plant_Leaves_Oak",
      "rotation": 3
    },
    {
      "x": -20,
      "y": 7,
      "z": -37,
      "name": "Plant_Leaves_Oak",
      "rotation": 3
    },
    {
      "x": -20,
      "y": 6,
      "z": -36,
      "name": "Plant_Leaves_Oak",
      "rotation": 3
    },
    {
      "x": -20,
      "y": 7,
      "z": -36,
      "name": "Plant_Leaves_Oak",
      "rotation": 3
    },
    {
      "x": -20,
      "y": 6,
      "z": -35,
      "name": "Plant_Leaves_Oak",
      "rotation": 3
    },
    {
      "x": -20,
      "y": 5,
      "z": -33,
      "name": "Plant_Leaves_Oak",
      "rotation": 3
    },
    {
      "x": -20,
      "y": 8,
      "z": -25,
      "name": "Plant_Leaves_Oak",
      "rotation": 2
    },
    {
      "x": -20,
      "y": 9,
      "z": -23,
      "name": "Plant_Leaves_Oak",
      "rotation": 2
    },
    {
      "x": -20,
      "y": 3,
      "z": -22,
      "name": "Plant_Leaves_Oak",
      "rotation": 2
    },
    {
      "x": -20,
      "y": 9,
      "z": -22,
      "name": "Plant_Leaves_Oak",
      "rotation": 2
    },
    {
      "x": -20,
      "y": 3,
      "z": -21,
      "name": "Plant_Leaves_Oak",
      "rotation": 2
    },
    {
      "x": -20,
      "y": 4,
      "z": -21,
      "name": "Plant_Leaves_Oak",
      "rotation": 2
    },
    {
      "x": -20,
      "y": 5,
      "z": -21,
      "name": "Plant_Leaves_Oak",
      "rotation": 2
    },
    {
      "x": -20,
      "y": 8,
      "z": -21,
      "name": "Plant_Leaves_Oak",
      "rotation": 2
    },
    {
      "x": -20,
      "y": 9,
      "z": -21,
      "name": "Wood_Oak_Branch_Long",
      "rotation": 7
    },
    {
      "x": -20,
      "y": 10,
      "z": -21,
      "name": "Plant_Leaves_Oak",
      "rotation": 2
    },
    {
      "x": -20,
      "y": 3,
      "z": -20,
      "name": "Plant_Leaves_Oak",
      "rotation": 2
    },
    {
      "x": -20,
      "y": 5,
      "z": -20,
      "name": "Plant_Leaves_Oak",
      "rotation": 2
    },
    {
      "x": -20,
      "y": 9,
      "z": -20,
      "name": "Plant_Leaves_Oak",
      "rotation": 2
    },
    {
      "x": -20,
      "y": 1,
      "z": -19,
      "name": "Plant_Leaves_Birch"
    },
    {
      "x": -20,
      "y": 2,
      "z": -19,
      "name": "Plant_Leaves_Birch"
    },
    {
      "x": -20,
      "y": 3,
      "z": -19,
      "name": "Plant_Leaves_Birch"
    },
    {
      "x": -20,
      "y": 4,
      "z": -19,
      "name": "Plant_Leaves_Birch"
    },
    {
      "x": -20,
      "y": 5,
      "z": -19,
      "name": "Plant_Leaves_Birch"
    },
    {
      "x": -20,
      "y": 6,
      "z": -19,
      "name": "Plant_Leaves_Birch"
    },
    {
      "x": -20,
      "y": 7,
      "z": -19,
      "name": "Plant_Leaves_Birch"
    },
    {
      "x": -20,
      "y": 9,
      "z": -19,
      "name": "Plant_Leaves_Oak",
      "rotation": 2
    },
    {
      "x": -20,
      "y": 1,
      "z": -18,
      "name": "Plant_Leaves_Birch"
    },
    {
      "x": -20,
      "y": 4,
      "z": -18,
      "name": "Plant_Leaves_Birch"
    },
    {
      "x": -20,
      "y": 5,
      "z": -18,
      "name": "Plant_Leaves_Birch"
    },
    {
      "x": -20,
      "y": 6,
      "z": -18,
      "name": "Plant_Leaves_Birch"
    },
    {
      "x": -20,
      "y": 7,
      "z": -18,
      "name": "Plant_Leaves_Birch"
    },
    {
      "x": -20,
      "y": 8,
      "z": -18,
      "name": "Plant_Leaves_Birch"
    },
    {
      "x": -20,
      "y": 1,
      "z": -17,
      "name": "Wood_Birch_Trunk_Full"
    },
    {
      "x": -20,
      "y": 2,
      "z": -17,
      "name": "Wood_Birch_Branch_Long"
    },
    {
      "x": -20,
      "y": 3,
      "z": -17,
      "name": "Wood_Birch_Branch_Long"
    },
    {
      "x": -20,
      "y": 4,
      "z": -17,
      "name": "Wood_Birch_Branch_Long"
    },
    {
      "x": -20,
      "y": 5,
      "z": -17,
      "name": "Wood_Birch_Branch_Long"
    },
    {
      "x": -20,
      "y": 7,
      "z": -17,
      "name": "Plant_Leaves_Birch"
    },
    {
      "x": -20,
      "y": 8,
      "z": -17,
      "name": "Plant_Leaves_Birch"
    },
    {
      "x": -20,
      "y": 9,
      "z": -17,
      "name": "Plant_Leaves_Birch"
    },
    {
      "x": -20,
      "y": 10,
      "z": -17,
      "name": "Plant_Leaves_Birch"
    },
    {
      "x": -20,
      "y": 0,
      "z": -16,
      "name": "Wood_Birch_Trunk"
    },
    {
      "x": -20,
      "y": 1,
      "z": -16,
      "name": "Wood_Birch_Trunk"
    },
    {
      "x": -20,
      "y": 2,
      "z": -16,
      "name": "Wood_Birch_Trunk"
    },
    {
      "x": -20,
      "y": 3,
      "z": -16,
      "name": "Wood_Birch_Trunk_Full"
    },
    {
      "x": -20,
      "y": 11,
      "z": -16,
      "name": "Plant_Leaves_Birch"
    },
    {
      "x": -20,
      "y": 12,
      "z": -16,
      "name": "Plant_Leaves_Birch"
    },
    {
      "x": -20,
      "y": 1,
      "z": -15,
      "name": "Wood_Birch_Trunk_Full"
    },
    {
      "x": -20,
      "y": 3,
      "z": -15,
      "name": "Wood_Birch_Trunk_Full"
    },
    {
      "x": -20,
      "y": 4,
      "z": -15,
      "name": "Wood_Birch_Trunk"
    },
    {
      "x": -20,
      "y": 5,
      "z": -15,
      "name": "Wood_Birch_Trunk"
    },
    {
      "x": -20,
      "y": 6,
      "z": -15,
      "name": "Wood_Birch_Trunk_Full"
    },
    {
      "x": -20,
      "y": 7,
      "z": -15,
      "name": "Wood_Birch_Trunk_Full"
    },
    {
      "x": -20,
      "y": 8,
      "z": -15,
      "name": "Wood_Birch_Branch_Long"
    },
    {
      "x": -20,
      "y": 9,
      "z": -15,
      "name": "Wood_Birch_Branch_Long"
    },
    {
      "x": -20,
      "y": 10,
      "z": -15,
      "name": "Wood_Birch_Branch_Long"
    },
    {
      "x": -20,
      "y": 11,
      "z": -15,
      "name": "Wood_Birch_Branch_Long"
    },
    {
      "x": -20,
      "y": 12,
      "z": -15,
      "name": "Wood_Birch_Branch_Long"
    },
    {
      "x": -20,
      "y": 13,
      "z": -15,
      "name": "Plant_Leaves_Birch"
    },
    {
      "x": -20,
      "y": 1,
      "z": -14,
      "name": "Wood_Birch_Trunk_Full"
    },
    {
      "x": -20,
      "y": 2,
      "z": -14,
      "name": "Wood_Birch_Branch_Long"
    },
    {
      "x": -20,
      "y": 3,
      "z": -14,
      "name": "Wood_Birch_Branch_Long"
    },
    {
      "x": -20,
      "y": 4,
      "z": -14,
      "name": "Wood_Birch_Branch_Long"
    },
    {
      "x": -20,
      "y": 5,
      "z": -14,
      "name": "Wood_Birch_Branch_Long"
    },
    {
      "x": -20,
      "y": 6,
      "z": -14,
      "name": "Plant_Leaves_Birch"
    },
    {
      "x": -20,
      "y": 7,
      "z": -14,
      "name": "Plant_Leaves_Birch"
    },
    {
      "x": -20,
      "y": 8,
      "z": -14,
      "name": "Plant_Leaves_Birch"
    },
    {
      "x": -20,
      "y": 10,
      "z": -14,
      "name": "Plant_Leaves_Birch"
    },
    {
      "x": -20,
      "y": 11,
      "z": -14,
      "name": "Plant_Leaves_Birch"
    },
    {
      "x": -20,
      "y": 12,
      "z": -14,
      "name": "Plant_Leaves_Birch"
    },
    {
      "x": -20,
      "y": 13,
      "z": -14,
      "name": "Plant_Leaves_Birch"
    },
    {
      "x": -20,
      "y": 0,
      "z": -13,
      "name": "Plant_Leaves_Birch"
    },
    {
      "x": -20,
      "y": 1,
      "z": -13,
      "name": "Wood_Birch_Branch_Corner"
    },
    {
      "x": -20,
      "y": 2,
      "z": -13,
      "name": "Wood_Birch_Branch_Long"
    },
    {
      "x": -20,
      "y": 3,
      "z": -13,
      "name": "Wood_Birch_Branch_Long"
    },
    {
      "x": -20,
      "y": 5,
      "z": -13,
      "name": "Plant_Leaves_Birch"
    },
    {
      "x": -20,
      "y": 6,
      "z": -13,
      "name": "Plant_Leaves_Birch"
    },
    {
      "x": -20,
      "y": 7,
      "z": -13,
      "name": "Plant_Leaves_Birch"
    },
    {
      "x": -20,
      "y": 8,
      "z": -13,
      "name": "Plant_Leaves_Birch"
    },
    {
      "x": -20,
      "y": 9,
      "z": -13,
      "name": "Plant_Leaves_Birch"
    },
    {
      "x": -20,
      "y": 10,
      "z": -13,
      "name": "Plant_Leaves_Birch"
    },
    {
      "x": -20,
      "y": 11,
      "z": -13,
      "name": "Plant_Leaves_Birch"
    },
    {
      "x": -20,
      "y": 0,
      "z": -12,
      "name": "Plant_Leaves_Birch"
    },
    {
      "x": -20,
      "y": 1,
      "z": -12,
      "name": "Plant_Leaves_Birch"
    },
    {
      "x": -20,
      "y": 2,
      "z": -12,
      "name": "Plant_Leaves_Birch"
    },
    {
      "x": -20,
      "y": 3,
      "z": -12,
      "name": "Plant_Leaves_Birch"
    },
    {
      "x": -20,
      "y": 4,
      "z": -12,
      "name": "Plant_Leaves_Birch"
    },
    {
      "x": -20,
      "y": 5,
      "z": -12,
      "name": "Plant_Leaves_Birch"
    },
    {
      "x": -20,
      "y": 2,
      "z": -11,
      "name": "Plant_Leaves_Birch"
    },
    {
      "x": -20,
      "y": 5,
      "z": 11,
      "name": "Plant_Leaves_Birch",
      "rotation": 3
    },
    {
      "x": -20,
      "y": 4,
      "z": 21,
      "name": "Plant_Leaves_Beech",
      "rotation": 2
    },
    {
      "x": -20,
      "y": 6,
      "z": 21,
      "name": "Plant_Leaves_Beech",
      "rotation": 2
    },
    {
      "x": -20,
      "y": 3,
      "z": 22,
      "name": "Plant_Leaves_Beech",
      "rotation": 2
    },
    {
      "x": -20,
      "y": 4,
      "z": 22,
      "name": "Plant_Leaves_Beech",
      "rotation": 2
    },
    {
      "x": -20,
      "y": 5,
      "z": 22,
      "name": "Plant_Leaves_Beech",
      "rotation": 2
    },
    {
      "x": -20,
      "y": 3,
      "z": 23,
      "name": "Wood_Beech_Branch_Corner",
      "rotation": 1
    },
    {
      "x": -20,
      "y": 4,
      "z": 23,
      "name": "Plant_Leaves_Beech",
      "rotation": 2
    },
    {
      "x": -20,
      "y": 5,
      "z": 23,
      "name": "Plant_Leaves_Beech",
      "rotation": 2
    },
    {
      "x": -20,
      "y": 6,
      "z": 23,
      "name": "Plant_Leaves_Beech",
      "rotation": 2
    },
    {
      "x": -20,
      "y": 8,
      "z": 23,
      "name": "Plant_Leaves_Beech",
      "rotation": 2
    },
    {
      "x": -20,
      "y": 3,
      "z": 24,
      "name": "Plant_Leaves_Beech",
      "rotation": 2
    },
    {
      "x": -20,
      "y": 4,
      "z": 24,
      "name": "Plant_Leaves_Beech",
      "rotation": 2
    },
    {
      "x": -20,
      "y": 5,
      "z": 24,
      "name": "Plant_Leaves_Beech",
      "rotation": 2
    },
    {
      "x": -20,
      "y": 7,
      "z": 24,
      "name": "Plant_Leaves_Beech",
      "rotation": 2
    },
    {
      "x": -20,
      "y": 8,
      "z": 24,
      "name": "Plant_Leaves_Beech",
      "rotation": 2
    },
    {
      "x": -20,
      "y": 3,
      "z": 25,
      "name": "Plant_Leaves_Beech",
      "rotation": 2
    },
    {
      "x": -20,
      "y": 4,
      "z": 25,
      "name": "Plant_Leaves_Beech",
      "rotation": 2
    },
    {
      "x": -20,
      "y": 7,
      "z": 25,
      "name": "Plant_Leaves_Beech",
      "rotation": 2
    },
    {
      "x": -20,
      "y": 3,
      "z": 26,
      "name": "Plant_Leaves_Beech",
      "rotation": 2
    },
    {
      "x": -20,
      "y": 4,
      "z": 26,
      "name": "Plant_Leaves_Beech",
      "rotation": 2
    },
    {
      "x": -20,
      "y": 0,
      "z": 53,
      "name": "Plant_Bush_Green"
    },
    {
      "x": -20,
      "y": 13,
      "z": 53,
      "name": "Plant_Leaves_Oak"
    },
    {
      "x": -20,
      "y": 11,
      "z": 54,
      "name": "Plant_Leaves_Oak"
    },
    {
      "x": -20,
      "y": 0,
      "z": 55,
      "name": "Soil_Grass_Full"
    },
    {
      "x": -20,
      "y": 11,
      "z": 55,
      "name": "Plant_Leaves_Oak"
    },
    {
      "x": -20,
      "y": 12,
      "z": 55,
      "name": "Plant_Leaves_Oak"
    },
    {
      "x": -20,
      "y": 13,
      "z": 55,
      "name": "Plant_Leaves_Oak"
    },
    {
      "x": -20,
      "y": 0,
      "z": 56,
      "name": "Soil_Grass_Full"
    },
    {
      "x": -20,
      "y": 10,
      "z": 56,
      "name": "Plant_Leaves_Oak"
    },
    {
      "x": -20,
      "y": 12,
      "z": 56,
      "name": "Plant_Leaves_Oak"
    },
    {
      "x": -20,
      "y": 0,
      "z": 57,
      "name": "Soil_Grass_Full"
    },
    {
      "x": -20,
      "y": 8,
      "z": 57,
      "name": "Plant_Leaves_Oak"
    },
    {
      "x": -20,
      "y": 11,
      "z": 57,
      "name": "Plant_Leaves_Oak"
    },
    {
      "x": -20,
      "y": 0,
      "z": 58,
      "name": "Soil_Grass_Full"
    },
    {
      "x": -20,
      "y": 1,
      "z": 58,
      "name": "Plant_Bush_Green"
    },
    {
      "x": -20,
      "y": 7,
      "z": 58,
      "name": "Plant_Leaves_Oak"
    },
    {
      "x": -20,
      "y": 0,
      "z": 59,
      "name": "Soil_Dirt"
    },
    {
      "x": -20,
      "y": 1,
      "z": 59,
      "name": "Soil_Grass_Full"
    },
    {
      "x": -20,
      "y": 2,
      "z": 59,
      "name": "Plant_Bush_Green"
    },
    {
      "x": -20,
      "y": 0,
      "z": 60,
      "name": "Soil_Dirt"
    },
    {
      "x": -20,
      "y": 1,
      "z": 60,
      "name": "Soil_Grass_Full"
    },
    {
      "x": -20,
      "y": 0,
      "z": 61,
      "name": "Soil_Dirt"
    },
    {
      "x": -20,
      "y": 1,
      "z": 61,
      "name": "Soil_Grass_Full"
    },
    {
      "x": -20,
      "y": 2,
      "z": 61,
      "name": "Plant_Grass_Sharp"
    },
    {
      "x": -20,
      "y": 0,
      "z": 62,
      "name": "Soil_Dirt"
    },
    {
      "x": -20,
      "y": 1,
      "z": 62,
      "name": "Soil_Grass_Full"
    },
    {
      "x": -20,
      "y": 0,
      "z": 63,
      "name": "Soil_Dirt"
    },
    {
      "x": -20,
      "y": 1,
      "z": 63,
      "name": "Soil_Grass_Full"
    },
    {
      "x": -20,
      "y": 0,
      "z": 64,
      "name": "Soil_Dirt"
    },
    {
      "x": -20,
      "y": 1,
      "z": 64,
      "name": "Soil_Grass_Full"
    },
    {
      "x": -20,
      "y": 2,
      "z": 64,
      "name": "Plant_Grass_Sharp_Short"
    },
    {
      "x": -20,
      "y": 0,
      "z": 65,
      "name": "Soil_Dirt"
    },
    {
      "x": -20,
      "y": 1,
      "z": 65,
      "name": "Soil_Grass_Full"
    },
    {
      "x": -20,
      "y": 0,
      "z": 66,
      "name": "Soil_Dirt"
    },
    {
      "x": -20,
      "y": 1,
      "z": 66,
      "name": "Soil_Grass_Full"
    },
    {
      "x": -20,
      "y": 2,
      "z": 66,
      "name": "Plant_Grass_Lush_Short"
    },
    {
      "x": -19,
      "y": 6,
      "z": -36,
      "name": "Plant_Leaves_Oak",
      "rotation": 3
    },
    {
      "x": -19,
      "y": 0,
      "z": -23,
      "name": "Plant_Leaves_Beech",
      "rotation": 1
    },
    {
      "x": -19,
      "y": 1,
      "z": -23,
      "name": "Plant_Leaves_Beech",
      "rotation": 1
    },
    {
      "x": -19,
      "y": 2,
      "z": -23,
      "name": "Plant_Leaves_Beech",
      "rotation": 1
    },
    {
      "x": -19,
      "y": 0,
      "z": -22,
      "name": "Plant_Leaves_Beech",
      "rotation": 1
    },
    {
      "x": -19,
      "y": 1,
      "z": -22,
      "name": "Plant_Leaves_Beech",
      "rotation": 1
    },
    {
      "x": -19,
      "y": 2,
      "z": -22,
      "name": "Plant_Leaves_Beech",
      "rotation": 1
    },
    {
      "x": -19,
      "y": 9,
      "z": -22,
      "name": "Plant_Leaves_Oak",
      "rotation": 2
    },
    {
      "x": -19,
      "y": 0,
      "z": -21,
      "name": "Plant_Leaves_Beech",
      "rotation": 1
    },
    {
      "x": -19,
      "y": 4,
      "z": -21,
      "name": "Plant_Leaves_Oak",
      "rotation": 2
    },
    {
      "x": -19,
      "y": 9,
      "z": -21,
      "name": "Plant_Leaves_Oak",
      "rotation": 2
    },
    {
      "x": -19,
      "y": 5,
      "z": -20,
      "name": "Plant_Leaves_Oak",
      "rotation": 2
    },
    {
      "x": -19,
      "y": 9,
      "z": -20,
      "name": "Plant_Leaves_Oak",
      "rotation": 2
    },
    {
      "x": -19,
      "y": 3,
      "z": -19,
      "name": "Plant_Leaves_Birch"
    },
    {
      "x": -19,
      "y": 4,
      "z": -19,
      "name": "Plant_Leaves_Birch"
    },
    {
      "x": -19,
      "y": 6,
      "z": -19,
      "name": "Plant_Leaves_Birch"
    },
    {
      "x": -19,
      "y": 1,
      "z": -18,
      "name": "Plant_Leaves_Birch"
    },
    {
      "x": -19,
      "y": 2,
      "z": -18,
      "name": "Plant_Leaves_Birch"
    },
    {
      "x": -19,
      "y": 3,
      "z": -18,
      "name": "Plant_Leaves_Birch"
    },
    {
      "x": -19,
      "y": 4,
      "z": -18,
      "name": "Plant_Leaves_Birch"
    },
    {
      "x": -19,
      "y": 6,
      "z": -18,
      "name": "Plant_Leaves_Birch"
    },
    {
      "x": -19,
      "y": 7,
      "z": -18,
      "name": "Plant_Leaves_Birch"
    },
    {
      "x": -19,
      "y": 8,
      "z": -17,
      "name": "Plant_Leaves_Birch"
    },
    {
      "x": -19,
      "y": 9,
      "z": -17,
      "name": "Plant_Leaves_Birch"
    },
    {
      "x": -19,
      "y": 1,
      "z": -16,
      "name": "Wood_Birch_Trunk_Full"
    },
    {
      "x": -19,
      "y": 2,
      "z": -16,
      "name": "Wood_Birch_Branch_Long"
    },
    {
      "x": -19,
      "y": 3,
      "z": -16,
      "name": "Wood_Birch_Branch_Long"
    },
    {
      "x": -19,
      "y": 4,
      "z": -16,
      "name": "Wood_Birch_Branch_Long"
    },
    {
      "x": -19,
      "y": 5,
      "z": -16,
      "name": "Wood_Birch_Branch_Long"
    },
    {
      "x": -19,
      "y": 8,
      "z": -16,
      "name": "Plant_Leaves_Birch"
    },
    {
      "x": -19,
      "y": 11,
      "z": -16,
      "name": "Plant_Leaves_Birch"
    },
    {
      "x": -19,
      "y": 7,
      "z": -15,
      "name": "Wood_Birch_Branch_Corner",
      "rotation": 1
    },
    {
      "x": -19,
      "y": 8,
      "z": -15,
      "name": "Wood_Birch_Branch_Long"
    },
    {
      "x": -19,
      "y": 9,
      "z": -15,
      "name": "Wood_Birch_Branch_Long"
    },
    {
      "x": -19,
      "y": 10,
      "z": -15,
      "name": "Wood_Birch_Branch_Long"
    },
    {
      "x": -19,
      "y": 11,
      "z": -15,
      "name": "Plant_Leaves_Birch"
    },
    {
      "x": -19,
      "y": 12,
      "z": -15,
      "name": "Plant_Leaves_Birch"
    },
    {
      "x": -19,
      "y": 2,
      "z": -14,
      "name": "Plant_Leaves_Birch"
    },
    {
      "x": -19,
      "y": 6,
      "z": -14,
      "name": "Plant_Leaves_Birch"
    },
    {
      "x": -19,
      "y": 7,
      "z": -14,
      "name": "Plant_Leaves_Birch"
    },
    {
      "x": -19,
      "y": 11,
      "z": -14,
      "name": "Plant_Leaves_Birch"
    },
    {
      "x": -19,
      "y": 12,
      "z": -14,
      "name": "Plant_Leaves_Birch"
    },
    {
      "x": -19,
      "y": 3,
      "z": -13,
      "name": "Plant_Leaves_Birch"
    },
    {
      "x": -19,
      "y": 4,
      "z": -13,
      "name": "Plant_Leaves_Birch"
    },
    {
      "x": -19,
      "y": 5,
      "z": -13,
      "name": "Plant_Leaves_Birch"
    },
    {
      "x": -19,
      "y": 8,
      "z": -13,
      "name": "Plant_Leaves_Birch"
    },
    {
      "x": -19,
      "y": 9,
      "z": -13,
      "name": "Plant_Leaves_Birch"
    },
    {
      "x": -19,
      "y": 0,
      "z": -12,
      "name": "Plant_Leaves_Birch"
    },
    {
      "x": -19,
      "y": 1,
      "z": -12,
      "name": "Plant_Leaves_Birch"
    },
    {
      "x": -19,
      "y": 3,
      "z": 22,
      "name": "Plant_Leaves_Beech",
      "rotation": 2
    },
    {
      "x": -19,
      "y": 4,
      "z": 22,
      "name": "Plant_Leaves_Beech",
      "rotation": 2
    },
    {
      "x": -19,
      "y": 3,
      "z": 23,
      "name": "Plant_Leaves_Beech",
      "rotation": 2
    },
    {
      "x": -19,
      "y": 4,
      "z": 23,
      "name": "Plant_Leaves_Beech",
      "rotation": 2
    },
    {
      "x": -19,
      "y": 5,
      "z": 23,
      "name": "Plant_Leaves_Beech",
      "rotation": 2
    },
    {
      "x": -19,
      "y": 3,
      "z": 24,
      "name": "Plant_Leaves_Beech",
      "rotation": 2
    },
    {
      "x": -19,
      "y": 4,
      "z": 24,
      "name": "Plant_Leaves_Beech",
      "rotation": 2
    },
    {
      "x": -19,
      "y": 3,
      "z": 25,
      "name": "Plant_Leaves_Beech",
      "rotation": 2
    },
    {
      "x": -19,
      "y": 5,
      "z": 50,
      "name": "Plant_Leaves_Oak"
    },
    {
      "x": -19,
      "y": 6,
      "z": 50,
      "name": "Plant_Leaves_Oak"
    },
    {
      "x": -19,
      "y": 0,
      "z": 51,
      "name": "Plant_Grass_Sharp"
    },
    {
      "x": -19,
      "y": 5,
      "z": 51,
      "name": "Plant_Leaves_Oak"
    },
    {
      "x": -19,
      "y": 6,
      "z": 51,
      "name": "Plant_Leaves_Oak"
    },
    {
      "x": -19,
      "y": 8,
      "z": 51,
      "name": "Plant_Leaves_Oak"
    },
    {
      "x": -19,
      "y": 0,
      "z": 52,
      "name": "Plant_Grass_Sharp"
    },
    {
      "x": -19,
      "y": 4,
      "z": 52,
      "name": "Plant_Leaves_Oak"
    },
    {
      "x": -19,
      "y": 6,
      "z": 52,
      "name": "Plant_Leaves_Oak"
    },
    {
      "x": -19,
      "y": 7,
      "z": 52,
      "name": "Plant_Leaves_Oak"
    },
    {
      "x": -19,
      "y": 11,
      "z": 52,
      "name": "Plant_Leaves_Oak"
    },
    {
      "x": -19,
      "y": 12,
      "z": 52,
      "name": "Plant_Leaves_Oak"
    },
    {
      "x": -19,
      "y": 13,
      "z": 52,
      "name": "Plant_Leaves_Oak"
    },
    {
      "x": -19,
      "y": 0,
      "z": 53,
      "name": "Plant_Grass_Sharp_Tall"
    },
    {
      "x": -19,
      "y": 5,
      "z": 53,
      "name": "Plant_Leaves_Oak"
    },
    {
      "x": -19,
      "y": 8,
      "z": 53,
      "name": "Plant_Leaves_Oak"
    },
    {
      "x": -19,
      "y": 10,
      "z": 53,
      "name": "Plant_Leaves_Oak"
    },
    {
      "x": -19,
      "y": 11,
      "z": 53,
      "name": "Plant_Leaves_Oak"
    },
    {
      "x": -19,
      "y": 13,
      "z": 53,
      "name": "Plant_Leaves_Oak"
    },
    {
      "x": -19,
      "y": 14,
      "z": 53,
      "name": "Plant_Leaves_Oak"
    },
    {
      "x": -19,
      "y": 0,
      "z": 54,
      "name": "Soil_Grass_Full"
    },
    {
      "x": -19,
      "y": 1,
      "z": 54,
      "name": "Plant_Bush_Green"
    },
    {
      "x": -19,
      "y": 5,
      "z": 54,
      "name": "Plant_Leaves_Oak"
    },
    {
      "x": -19,
      "y": 9,
      "z": 54,
      "name": "Plant_Leaves_Oak"
    },
    {
      "x": -19,
      "y": 10,
      "z": 54,
      "name": "Plant_Leaves_Oak"
    },
    {
      "x": -19,
      "y": 11,
      "z": 54,
      "name": "Plant_Leaves_Oak"
    },
    {
      "x": -19,
      "y": 13,
      "z": 54,
      "name": "Plant_Leaves_Oak"
    },
    {
      "x": -19,
      "y": 14,
      "z": 54,
      "name": "Plant_Leaves_Oak"
    },
    {
      "x": -19,
      "y": 0,
      "z": 55,
      "name": "Soil_Grass_Full"
    },
    {
      "x": -19,
      "y": 9,
      "z": 55,
      "name": "Plant_Leaves_Oak"
    },
    {
      "x": -19,
      "y": 10,
      "z": 55,
      "name": "Plant_Leaves_Oak"
    },
    {
      "x": -19,
      "y": 11,
      "z": 55,
      "name": "Plant_Leaves_Oak"
    },
    {
      "x": -19,
      "y": 12,
      "z": 55,
      "name": "Plant_Leaves_Oak"
    },
    {
      "x": -19,
      "y": 13,
      "z": 55,
      "name": "Plant_Leaves_Oak"
    },
    {
      "x": -19,
      "y": 14,
      "z": 55,
      "name": "Plant_Leaves_Oak"
    },
    {
      "x": -19,
      "y": 0,
      "z": 56,
      "name": "Soil_Grass_Full"
    },
    {
      "x": -19,
      "y": 7,
      "z": 56,
      "name": "Plant_Leaves_Oak"
    },
    {
      "x": -19,
      "y": 8,
      "z": 56,
      "name": "Plant_Leaves_Oak"
    },
    {
      "x": -19,
      "y": 9,
      "z": 56,
      "name": "Plant_Leaves_Oak"
    },
    {
      "x": -19,
      "y": 10,
      "z": 56,
      "name": "Plant_Leaves_Oak"
    },
    {
      "x": -19,
      "y": 11,
      "z": 56,
      "name": "Plant_Leaves_Oak"
    },
    {
      "x": -19,
      "y": 12,
      "z": 56,
      "name": "Plant_Leaves_Oak"
    },
    {
      "x": -19,
      "y": 13,
      "z": 56,
      "name": "Plant_Leaves_Oak"
    },
    {
      "x": -19,
      "y": 0,
      "z": 57,
      "name": "Soil_Grass_Full"
    },
    {
      "x": -19,
      "y": 1,
      "z": 57,
      "name": "Plant_Bush_Green"
    },
    {
      "x": -19,
      "y": 6,
      "z": 57,
      "name": "Plant_Leaves_Oak"
    },
    {
      "x": -19,
      "y": 7,
      "z": 57,
      "name": "Plant_Leaves_Oak"
    },
    {
      "x": -19,
      "y": 8,
      "z": 57,
      "name": "Plant_Leaves_Oak"
    },
    {
      "x": -19,
      "y": 9,
      "z": 57,
      "name": "Plant_Leaves_Oak"
    },
    {
      "x": -19,
      "y": 10,
      "z": 57,
      "name": "Plant_Leaves_Oak"
    },
    {
      "x": -19,
      "y": 11,
      "z": 57,
      "name": "Plant_Leaves_Oak"
    },
    {
      "x": -19,
      "y": 12,
      "z": 57,
      "name": "Plant_Leaves_Oak"
    },
    {
      "x": -19,
      "y": 13,
      "z": 57,
      "name": "Plant_Leaves_Oak"
    },
    {
      "x": -19,
      "y": 14,
      "z": 57,
      "name": "Plant_Leaves_Oak"
    },
    {
      "x": -19,
      "y": 0,
      "z": 58,
      "name": "Soil_Dirt"
    },
    {
      "x": -19,
      "y": 1,
      "z": 58,
      "name": "Soil_Grass_Full"
    },
    {
      "x": -19,
      "y": 5,
      "z": 58,
      "name": "Plant_Leaves_Oak"
    },
    {
      "x": -19,
      "y": 6,
      "z": 58,
      "name": "Plant_Leaves_Oak"
    },
    {
      "x": -19,
      "y": 7,
      "z": 58,
      "name": "Plant_Leaves_Oak"
    },
    {
      "x": -19,
      "y": 8,
      "z": 58,
      "name": "Plant_Leaves_Oak"
    },
    {
      "x": -19,
      "y": 9,
      "z": 58,
      "name": "Plant_Leaves_Oak"
    },
    {
      "x": -19,
      "y": 11,
      "z": 58,
      "name": "Plant_Leaves_Oak"
    },
    {
      "x": -19,
      "y": 12,
      "z": 58,
      "name": "Plant_Leaves_Oak"
    },
    {
      "x": -19,
      "y": 0,
      "z": 59,
      "name": "Soil_Dirt"
    },
    {
      "x": -19,
      "y": 1,
      "z": 59,
      "name": "Soil_Grass_Full"
    },
    {
      "x": -19,
      "y": 5,
      "z": 59,
      "name": "Plant_Leaves_Oak"
    },
    {
      "x": -19,
      "y": 6,
      "z": 59,
      "name": "Plant_Leaves_Oak"
    },
    {
      "x": -19,
      "y": 7,
      "z": 59,
      "name": "Plant_Leaves_Oak"
    },
    {
      "x": -19,
      "y": 8,
      "z": 59,
      "name": "Plant_Leaves_Oak"
    },
    {
      "x": -19,
      "y": 9,
      "z": 59,
      "name": "Plant_Leaves_Oak"
    },
    {
      "x": -19,
      "y": 12,
      "z": 59,
      "name": "Plant_Leaves_Oak"
    },
    {
      "x": -19,
      "y": 0,
      "z": 60,
      "name": "Soil_Dirt"
    },
    {
      "x": -19,
      "y": 1,
      "z": 60,
      "name": "Soil_Grass_Full"
    },
    {
      "x": -19,
      "y": 2,
      "z": 60,
      "name": "*Plant_Crop_Berry_Block_State_Definitions_StageFinal"
    },
    {
      "x": -19,
      "y": 8,
      "z": 60,
      "name": "Plant_Leaves_Oak"
    },
    {
      "x": -19,
      "y": 0,
      "z": 61,
      "name": "Soil_Dirt"
    },
    {
      "x": -19,
      "y": 1,
      "z": 61,
      "name": "Soil_Grass_Full"
    },
    {
      "x": -19,
      "y": 2,
      "z": 61,
      "name": "Plant_Grass_Sharp"
    },
    {
      "x": -19,
      "y": 0,
      "z": 62,
      "name": "Soil_Dirt"
    },
    {
      "x": -19,
      "y": 1,
      "z": 62,
      "name": "Soil_Grass_Full"
    },
    {
      "x": -19,
      "y": 2,
      "z": 62,
      "name": "Plant_Grass_Sharp"
    },
    {
      "x": -19,
      "y": 0,
      "z": 63,
      "name": "Soil_Dirt"
    },
    {
      "x": -19,
      "y": 1,
      "z": 63,
      "name": "Soil_Grass_Full"
    },
    {
      "x": -19,
      "y": 0,
      "z": 64,
      "name": "Soil_Dirt"
    },
    {
      "x": -19,
      "y": 1,
      "z": 64,
      "name": "Soil_Grass_Full"
    },
    {
      "x": -19,
      "y": 0,
      "z": 65,
      "name": "Soil_Dirt"
    },
    {
      "x": -19,
      "y": 1,
      "z": 65,
      "name": "Soil_Grass_Full"
    },
    {
      "x": -19,
      "y": 0,
      "z": 66,
      "name": "Soil_Dirt"
    },
    {
      "x": -19,
      "y": 1,
      "z": 66,
      "name": "Soil_Grass_Full"
    },
    {
      "x": -19,
      "y": 2,
      "z": 66,
      "name": "Plant_Grass_Sharp"
    },
    {
      "x": -18,
      "y": 0,
      "z": -24,
      "name": "Plant_Leaves_Beech",
      "rotation": 1
    },
    {
      "x": -18,
      "y": 1,
      "z": -24,
      "name": "Plant_Leaves_Beech",
      "rotation": 1
    },
    {
      "x": -18,
      "y": 0,
      "z": -23,
      "name": "Plant_Leaves_Beech",
      "rotation": 1
    },
    {
      "x": -18,
      "y": 1,
      "z": -23,
      "name": "Plant_Leaves_Beech",
      "rotation": 1
    },
    {
      "x": -18,
      "y": 2,
      "z": -23,
      "name": "Plant_Leaves_Beech",
      "rotation": 1
    },
    {
      "x": -18,
      "y": 0,
      "z": -22,
      "name": "Plant_Leaves_Beech",
      "rotation": 1
    },
    {
      "x": -18,
      "y": 1,
      "z": -22,
      "name": "Plant_Leaves_Beech",
      "rotation": 1
    },
    {
      "x": -18,
      "y": 2,
      "z": -22,
      "name": "Wood_Beech_Branch_Long",
      "rotation": 5
    },
    {
      "x": -18,
      "y": 3,
      "z": -22,
      "name": "Plant_Leaves_Beech",
      "rotation": 1
    },
    {
      "x": -18,
      "y": 0,
      "z": -21,
      "name": "Plant_Leaves_Beech",
      "rotation": 1
    },
    {
      "x": -18,
      "y": 1,
      "z": -21,
      "name": "Plant_Leaves_Beech",
      "rotation": 1
    },
    {
      "x": -18,
      "y": 2,
      "z": -21,
      "name": "Plant_Leaves_Beech",
      "rotation": 1
    },
    {
      "x": -18,
      "y": 3,
      "z": -21,
      "name": "Plant_Leaves_Beech",
      "rotation": 1
    },
    {
      "x": -18,
      "y": 3,
      "z": -18,
      "name": "Plant_Leaves_Birch"
    },
    {
      "x": -18,
      "y": 4,
      "z": -18,
      "name": "Plant_Leaves_Birch"
    },
    {
      "x": -18,
      "y": 5,
      "z": -18,
      "name": "Plant_Leaves_Birch"
    },
    {
      "x": -18,
      "y": 6,
      "z": -18,
      "name": "Plant_Leaves_Birch"
    },
    {
      "x": -18,
      "y": 1,
      "z": -17,
      "name": "Plant_Leaves_Birch"
    },
    {
      "x": -18,
      "y": 2,
      "z": -17,
      "name": "Plant_Leaves_Birch"
    },
    {
      "x": -18,
      "y": 3,
      "z": -17,
      "name": "Plant_Leaves_Birch"
    },
    {
      "x": -18,
      "y": 1,
      "z": -16,
      "name": "Plant_Leaves_Birch"
    },
    {
      "x": -18,
      "y": 4,
      "z": -16,
      "name": "Plant_Leaves_Birch"
    },
    {
      "x": -18,
      "y": 5,
      "z": -16,
      "name": "Plant_Leaves_Birch"
    },
    {
      "x": -18,
      "y": 6,
      "z": -16,
      "name": "Plant_Leaves_Birch"
    },
    {
      "x": -18,
      "y": 7,
      "z": -16,
      "name": "Plant_Leaves_Birch"
    },
    {
      "x": -18,
      "y": 8,
      "z": -16,
      "name": "Plant_Leaves_Birch"
    },
    {
      "x": -18,
      "y": 9,
      "z": -16,
      "name": "Plant_Leaves_Birch"
    },
    {
      "x": -18,
      "y": 10,
      "z": -16,
      "name": "Plant_Leaves_Birch"
    },
    {
      "x": -18,
      "y": 1,
      "z": -15,
      "name": "Plant_Leaves_Birch"
    },
    {
      "x": -18,
      "y": 2,
      "z": -15,
      "name": "Plant_Leaves_Birch"
    },
    {
      "x": -18,
      "y": 3,
      "z": -15,
      "name": "Plant_Leaves_Birch"
    },
    {
      "x": -18,
      "y": 4,
      "z": -15,
      "name": "Plant_Leaves_Birch"
    },
    {
      "x": -18,
      "y": 6,
      "z": -15,
      "name": "Plant_Leaves_Birch"
    },
    {
      "x": -18,
      "y": 7,
      "z": -15,
      "name": "Plant_Leaves_Birch"
    },
    {
      "x": -18,
      "y": 8,
      "z": -15,
      "name": "Plant_Leaves_Birch"
    },
    {
      "x": -18,
      "y": 9,
      "z": -15,
      "name": "Plant_Leaves_Birch"
    },
    {
      "x": -18,
      "y": 10,
      "z": -15,
      "name": "Plant_Leaves_Birch"
    },
    {
      "x": -18,
      "y": 11,
      "z": -15,
      "name": "Plant_Leaves_Birch"
    },
    {
      "x": -18,
      "y": 3,
      "z": -14,
      "name": "Plant_Leaves_Birch"
    },
    {
      "x": -18,
      "y": 4,
      "z": -14,
      "name": "Plant_Leaves_Birch"
    },
    {
      "x": -18,
      "y": 5,
      "z": -14,
      "name": "Plant_Leaves_Birch"
    },
    {
      "x": -18,
      "y": 6,
      "z": -14,
      "name": "Plant_Leaves_Birch"
    },
    {
      "x": -18,
      "y": 7,
      "z": -14,
      "name": "Plant_Leaves_Birch"
    },
    {
      "x": -18,
      "y": 9,
      "z": -14,
      "name": "Plant_Leaves_Birch"
    },
    {
      "x": -18,
      "y": 10,
      "z": -14,
      "name": "Plant_Leaves_Birch"
    },
    {
      "x": -18,
      "y": 2,
      "z": -13,
      "name": "Plant_Leaves_Birch"
    },
    {
      "x": -18,
      "y": 3,
      "z": -13,
      "name": "Plant_Leaves_Birch"
    },
    {
      "x": -18,
      "y": 3,
      "z": 1,
      "name": "Plant_Leaves_Beech"
    },
    {
      "x": -18,
      "y": 3,
      "z": 2,
      "name": "Plant_Leaves_Beech"
    },
    {
      "x": -18,
      "y": 4,
      "z": 2,
      "name": "Plant_Leaves_Beech"
    },
    {
      "x": -18,
      "y": 3,
      "z": 3,
      "name": "Plant_Leaves_Beech"
    },
    {
      "x": -18,
      "y": 4,
      "z": 3,
      "name": "Plant_Leaves_Beech"
    },
    {
      "x": -18,
      "y": 5,
      "z": 3,
      "name": "Plant_Leaves_Beech"
    },
    {
      "x": -18,
      "y": 3,
      "z": 4,
      "name": "Plant_Leaves_Beech"
    },
    {
      "x": -18,
      "y": 4,
      "z": 4,
      "name": "Plant_Leaves_Beech"
    },
    {
      "x": -18,
      "y": 0,
      "z": 30,
      "name": "Plant_Grass_Sharp"
    },
    {
      "x": -18,
      "y": 0,
      "z": 31,
      "name": "Plant_Flower_Tall_Purple"
    },
    {
      "x": -18,
      "y": 5,
      "z": 49,
      "name": "Plant_Leaves_Oak"
    },
    {
      "x": -18,
      "y": 4,
      "z": 50,
      "name": "Plant_Leaves_Oak"
    },
    {
      "x": -18,
      "y": 5,
      "z": 50,
      "name": "Plant_Leaves_Oak"
    },
    {
      "x": -18,
      "y": 6,
      "z": 50,
      "name": "Plant_Leaves_Oak"
    },
    {
      "x": -18,
      "y": 9,
      "z": 50,
      "name": "Plant_Leaves_Oak"
    },
    {
      "x": -18,
      "y": 11,
      "z": 50,
      "name": "Plant_Leaves_Oak"
    },
    {
      "x": -18,
      "y": 0,
      "z": 51,
      "name": "Plant_Grass_Sharp"
    },
    {
      "x": -18,
      "y": 5,
      "z": 51,
      "name": "Plant_Leaves_Oak"
    },
    {
      "x": -18,
      "y": 6,
      "z": 51,
      "name": "Plant_Leaves_Oak"
    },
    {
      "x": -18,
      "y": 7,
      "z": 51,
      "name": "Plant_Leaves_Oak"
    },
    {
      "x": -18,
      "y": 8,
      "z": 51,
      "name": "Plant_Leaves_Oak"
    },
    {
      "x": -18,
      "y": 9,
      "z": 51,
      "name": "Plant_Leaves_Oak"
    },
    {
      "x": -18,
      "y": 10,
      "z": 51,
      "name": "Plant_Leaves_Oak"
    },
    {
      "x": -18,
      "y": 11,
      "z": 51,
      "name": "Plant_Leaves_Oak"
    },
    {
      "x": -18,
      "y": 0,
      "z": 52,
      "name": "Plant_Grass_Sharp_Wild"
    },
    {
      "x": -18,
      "y": 4,
      "z": 52,
      "name": "Plant_Leaves_Oak"
    },
    {
      "x": -18,
      "y": 5,
      "z": 52,
      "name": "Plant_Leaves_Oak"
    },
    {
      "x": -18,
      "y": 6,
      "z": 52,
      "name": "Plant_Leaves_Oak"
    },
    {
      "x": -18,
      "y": 7,
      "z": 52,
      "name": "Wood_Oak_Branch_Long",
      "rotation": 5
    },
    {
      "x": -18,
      "y": 8,
      "z": 52,
      "name": "Plant_Leaves_Oak"
    },
    {
      "x": -18,
      "y": 9,
      "z": 52,
      "name": "Plant_Leaves_Oak"
    },
    {
      "x": -18,
      "y": 11,
      "z": 52,
      "name": "Plant_Leaves_Oak"
    },
    {
      "x": -18,
      "y": 12,
      "z": 52,
      "name": "Plant_Leaves_Oak"
    },
    {
      "x": -18,
      "y": 13,
      "z": 52,
      "name": "Plant_Leaves_Oak"
    },
    {
      "x": -18,
      "y": 0,
      "z": 53,
      "name": "Soil_Grass_Full"
    },
    {
      "x": -18,
      "y": 1,
      "z": 53,
      "name": "Plant_Grass_Sharp_Tall"
    },
    {
      "x": -18,
      "y": 4,
      "z": 53,
      "name": "Plant_Leaves_Oak"
    },
    {
      "x": -18,
      "y": 5,
      "z": 53,
      "name": "Plant_Leaves_Oak"
    },
    {
      "x": -18,
      "y": 8,
      "z": 53,
      "name": "Plant_Leaves_Oak"
    },
    {
      "x": -18,
      "y": 11,
      "z": 53,
      "name": "Plant_Leaves_Oak"
    },
    {
      "x": -18,
      "y": 12,
      "z": 53,
      "name": "Plant_Leaves_Oak"
    },
    {
      "x": -18,
      "y": 13,
      "z": 53,
      "name": "Plant_Leaves_Oak"
    },
    {
      "x": -18,
      "y": 0,
      "z": 54,
      "name": "Soil_Grass_Full"
    },
    {
      "x": -18,
      "y": 4,
      "z": 54,
      "name": "Plant_Leaves_Oak"
    },
    {
      "x": -18,
      "y": 5,
      "z": 54,
      "name": "Plant_Leaves_Oak"
    },
    {
      "x": -18,
      "y": 6,
      "z": 54,
      "name": "Plant_Leaves_Oak"
    },
    {
      "x": -18,
      "y": 7,
      "z": 54,
      "name": "Plant_Leaves_Oak"
    },
    {
      "x": -18,
      "y": 13,
      "z": 54,
      "name": "Plant_Leaves_Oak"
    },
    {
      "x": -18,
      "y": 14,
      "z": 54,
      "name": "Plant_Leaves_Oak"
    },
    {
      "x": -18,
      "y": 15,
      "z": 54,
      "name": "Plant_Leaves_Oak"
    },
    {
      "x": -18,
      "y": 0,
      "z": 55,
      "name": "Soil_Leaves"
    },
    {
      "x": -18,
      "y": 5,
      "z": 55,
      "name": "Plant_Leaves_Oak"
    },
    {
      "x": -18,
      "y": 6,
      "z": 55,
      "name": "Plant_Leaves_Oak"
    },
    {
      "x": -18,
      "y": 7,
      "z": 55,
      "name": "Plant_Leaves_Oak"
    },
    {
      "x": -18,
      "y": 13,
      "z": 55,
      "name": "Plant_Leaves_Oak"
    },
    {
      "x": -18,
      "y": 14,
      "z": 55,
      "name": "Plant_Leaves_Oak"
    },
    {
      "x": -18,
      "y": 15,
      "z": 55,
      "name": "Plant_Leaves_Oak"
    },
    {
      "x": -18,
      "y": 0,
      "z": 56,
      "name": "Soil_Grass_Full"
    },
    {
      "x": -18,
      "y": 1,
      "z": 56,
      "name": "Plant_Flower_Common_Yellow2"
    },
    {
      "x": -18,
      "y": 5,
      "z": 56,
      "name": "Plant_Leaves_Oak"
    },
    {
      "x": -18,
      "y": 6,
      "z": 56,
      "name": "Plant_Leaves_Oak"
    },
    {
      "x": -18,
      "y": 7,
      "z": 56,
      "name": "Plant_Leaves_Oak"
    },
    {
      "x": -18,
      "y": 13,
      "z": 56,
      "name": "Plant_Leaves_Oak"
    },
    {
      "x": -18,
      "y": 14,
      "z": 56,
      "name": "Plant_Leaves_Oak"
    },
    {
      "x": -18,
      "y": 15,
      "z": 56,
      "name": "Plant_Leaves_Oak"
    },
    {
      "x": -18,
      "y": 0,
      "z": 57,
      "name": "Soil_Dirt"
    },
    {
      "x": -18,
      "y": 1,
      "z": 57,
      "name": "Soil_Grass_Full"
    },
    {
      "x": -18,
      "y": 4,
      "z": 57,
      "name": "Plant_Leaves_Oak"
    },
    {
      "x": -18,
      "y": 6,
      "z": 57,
      "name": "Plant_Leaves_Oak"
    },
    {
      "x": -18,
      "y": 7,
      "z": 57,
      "name": "Plant_Leaves_Oak"
    },
    {
      "x": -18,
      "y": 8,
      "z": 57,
      "name": "Plant_Leaves_Oak"
    },
    {
      "x": -18,
      "y": 9,
      "z": 57,
      "name": "Wood_Oak_Branch_Corner",
      "rotation": 3
    },
    {
      "x": -18,
      "y": 10,
      "z": 57,
      "name": "Wood_Oak_Branch_Long"
    },
    {
      "x": -18,
      "y": 11,
      "z": 57,
      "name": "Wood_Oak_Branch_Long"
    },
    {
      "x": -18,
      "y": 12,
      "z": 57,
      "name": "Plant_Leaves_Oak"
    },
    {
      "x": -18,
      "y": 13,
      "z": 57,
      "name": "Plant_Leaves_Oak"
    },
    {
      "x": -18,
      "y": 0,
      "z": 58,
      "name": "Soil_Dirt"
    },
    {
      "x": -18,
      "y": 1,
      "z": 58,
      "name": "Soil_Grass_Full"
    },
    {
      "x": -18,
      "y": 4,
      "z": 58,
      "name": "Plant_Leaves_Oak"
    },
    {
      "x": -18,
      "y": 5,
      "z": 58,
      "name": "Plant_Leaves_Oak"
    },
    {
      "x": -18,
      "y": 6,
      "z": 58,
      "name": "Plant_Leaves_Oak"
    },
    {
      "x": -18,
      "y": 7,
      "z": 58,
      "name": "Plant_Leaves_Oak"
    },
    {
      "x": -18,
      "y": 8,
      "z": 58,
      "name": "Plant_Leaves_Oak"
    },
    {
      "x": -18,
      "y": 9,
      "z": 58,
      "name": "Plant_Leaves_Oak"
    },
    {
      "x": -18,
      "y": 10,
      "z": 58,
      "name": "Plant_Leaves_Oak"
    },
    {
      "x": -18,
      "y": 11,
      "z": 58,
      "name": "Plant_Leaves_Oak"
    },
    {
      "x": -18,
      "y": 12,
      "z": 58,
      "name": "Plant_Leaves_Oak"
    },
    {
      "x": -18,
      "y": 13,
      "z": 58,
      "name": "Plant_Leaves_Oak"
    },
    {
      "x": -18,
      "y": 0,
      "z": 59,
      "name": "Soil_Dirt"
    },
    {
      "x": -18,
      "y": 1,
      "z": 59,
      "name": "Soil_Grass_Full"
    },
    {
      "x": -18,
      "y": 4,
      "z": 59,
      "name": "Plant_Leaves_Oak"
    },
    {
      "x": -18,
      "y": 5,
      "z": 59,
      "name": "Plant_Leaves_Oak"
    },
    {
      "x": -18,
      "y": 6,
      "z": 59,
      "name": "Plant_Leaves_Oak"
    },
    {
      "x": -18,
      "y": 7,
      "z": 59,
      "name": "Plant_Leaves_Oak"
    },
    {
      "x": -18,
      "y": 8,
      "z": 59,
      "name": "Plant_Leaves_Oak"
    },
    {
      "x": -18,
      "y": 9,
      "z": 59,
      "name": "Plant_Leaves_Oak"
    },
    {
      "x": -18,
      "y": 10,
      "z": 59,
      "name": "Plant_Leaves_Oak"
    },
    {
      "x": -18,
      "y": 12,
      "z": 59,
      "name": "Plant_Leaves_Oak"
    },
    {
      "x": -18,
      "y": 13,
      "z": 59,
      "name": "Plant_Leaves_Oak"
    },
    {
      "x": -18,
      "y": 14,
      "z": 59,
      "name": "Plant_Leaves_Oak"
    },
    {
      "x": -18,
      "y": 0,
      "z": 60,
      "name": "Soil_Dirt"
    },
    {
      "x": -18,
      "y": 1,
      "z": 60,
      "name": "Soil_Grass_Full"
    },
    {
      "x": -18,
      "y": 4,
      "z": 60,
      "name": "Plant_Leaves_Oak"
    },
    {
      "x": -18,
      "y": 5,
      "z": 60,
      "name": "Plant_Leaves_Oak"
    },
    {
      "x": -18,
      "y": 6,
      "z": 60,
      "name": "Plant_Leaves_Oak"
    },
    {
      "x": -18,
      "y": 7,
      "z": 60,
      "name": "Plant_Leaves_Oak"
    },
    {
      "x": -18,
      "y": 8,
      "z": 60,
      "name": "Plant_Leaves_Oak"
    },
    {
      "x": -18,
      "y": 9,
      "z": 60,
      "name": "Plant_Leaves_Oak"
    },
    {
      "x": -18,
      "y": 12,
      "z": 60,
      "name": "Plant_Leaves_Oak"
    },
    {
      "x": -18,
      "y": 13,
      "z": 60,
      "name": "Plant_Leaves_Oak"
    },
    {
      "x": -18,
      "y": 0,
      "z": 61,
      "name": "Soil_Dirt"
    },
    {
      "x": -18,
      "y": 1,
      "z": 61,
      "name": "Soil_Grass_Full"
    },
    {
      "x": -18,
      "y": 2,
      "z": 61,
      "name": "Plant_Bush_Green"
    },
    {
      "x": -18,
      "y": 5,
      "z": 61,
      "name": "Plant_Leaves_Oak"
    },
    {
      "x": -18,
      "y": 0,
      "z": 62,
      "name": "Soil_Dirt"
    },
    {
      "x": -18,
      "y": 1,
      "z": 62,
      "name": "Soil_Grass_Full"
    },
    {
      "x": -18,
      "y": 2,
      "z": 62,
      "name": "Plant_Grass_Sharp"
    },
    {
      "x": -18,
      "y": 0,
      "z": 63,
      "name": "Soil_Dirt"
    },
    {
      "x": -18,
      "y": 1,
      "z": 63,
      "name": "Soil_Grass_Full"
    },
    {
      "x": -18,
      "y": 2,
      "z": 63,
      "name": "Plant_Grass_Sharp"
    },
    {
      "x": -18,
      "y": 0,
      "z": 64,
      "name": "Soil_Dirt"
    },
    {
      "x": -18,
      "y": 1,
      "z": 64,
      "name": "Soil_Grass_Full"
    },
    {
      "x": -18,
      "y": 0,
      "z": 65,
      "name": "Soil_Dirt"
    },
    {
      "x": -18,
      "y": 1,
      "z": 65,
      "name": "Soil_Grass_Full"
    },
    {
      "x": -18,
      "y": 0,
      "z": 66,
      "name": "Soil_Dirt"
    },
    {
      "x": -18,
      "y": 1,
      "z": 66,
      "name": "Soil_Grass_Full"
    },
    {
      "x": -17,
      "y": 0,
      "z": -25,
      "name": "Plant_Leaves_Beech",
      "rotation": 1
    },
    {
      "x": -17,
      "y": 1,
      "z": -25,
      "name": "Plant_Leaves_Beech",
      "rotation": 1
    },
    {
      "x": -17,
      "y": 0,
      "z": -24,
      "name": "Plant_Leaves_Beech",
      "rotation": 1
    },
    {
      "x": -17,
      "y": 1,
      "z": -24,
      "name": "Plant_Leaves_Beech",
      "rotation": 1
    },
    {
      "x": -17,
      "y": 2,
      "z": -24,
      "name": "Plant_Leaves_Beech",
      "rotation": 1
    },
    {
      "x": -17,
      "y": 3,
      "z": -24,
      "name": "Plant_Leaves_Beech",
      "rotation": 1
    },
    {
      "x": -17,
      "y": 3,
      "z": -23,
      "name": "Plant_Leaves_Beech",
      "rotation": 1
    },
    {
      "x": -17,
      "y": 1,
      "z": -22,
      "name": "Wood_Beech_Branch_Corner",
      "rotation": 3
    },
    {
      "x": -17,
      "y": 2,
      "z": -22,
      "name": "Wood_Beech_Branch_Corner",
      "rotation": 11
    },
    {
      "x": -17,
      "y": 3,
      "z": -22,
      "name": "Plant_Leaves_Beech",
      "rotation": 1
    },
    {
      "x": -17,
      "y": 4,
      "z": -22,
      "name": "Plant_Leaves_Beech",
      "rotation": 1
    },
    {
      "x": -17,
      "y": 3,
      "z": -21,
      "name": "Plant_Leaves_Beech",
      "rotation": 1
    },
    {
      "x": -17,
      "y": 4,
      "z": -21,
      "name": "Plant_Leaves_Beech",
      "rotation": 1
    },
    {
      "x": -17,
      "y": 0,
      "z": -20,
      "name": "Plant_Leaves_Beech",
      "rotation": 1
    },
    {
      "x": -17,
      "y": 1,
      "z": -20,
      "name": "Plant_Leaves_Beech",
      "rotation": 1
    },
    {
      "x": -17,
      "y": 3,
      "z": -20,
      "name": "Plant_Leaves_Beech",
      "rotation": 1
    },
    {
      "x": -17,
      "y": 4,
      "z": -18,
      "name": "Plant_Leaves_Birch"
    },
    {
      "x": -17,
      "y": 2,
      "z": -17,
      "name": "Plant_Leaves_Birch"
    },
    {
      "x": -17,
      "y": 3,
      "z": -17,
      "name": "Plant_Leaves_Birch"
    },
    {
      "x": -17,
      "y": 4,
      "z": -17,
      "name": "Plant_Leaves_Birch"
    },
    {
      "x": -17,
      "y": 6,
      "z": -17,
      "name": "Plant_Leaves_Birch"
    },
    {
      "x": -17,
      "y": 1,
      "z": -16,
      "name": "Plant_Leaves_Birch"
    },
    {
      "x": -17,
      "y": 2,
      "z": -16,
      "name": "Plant_Leaves_Birch"
    },
    {
      "x": -17,
      "y": 3,
      "z": -16,
      "name": "Plant_Leaves_Birch"
    },
    {
      "x": -17,
      "y": 4,
      "z": -16,
      "name": "Plant_Leaves_Birch"
    },
    {
      "x": -17,
      "y": 5,
      "z": -16,
      "name": "Plant_Leaves_Birch"
    },
    {
      "x": -17,
      "y": 6,
      "z": -16,
      "name": "Plant_Leaves_Birch"
    },
    {
      "x": -17,
      "y": 7,
      "z": -16,
      "name": "Plant_Leaves_Birch"
    },
    {
      "x": -17,
      "y": 3,
      "z": -15,
      "name": "Plant_Leaves_Birch"
    },
    {
      "x": -17,
      "y": 4,
      "z": -15,
      "name": "Plant_Leaves_Birch"
    },
    {
      "x": -17,
      "y": 6,
      "z": -15,
      "name": "Plant_Leaves_Birch"
    },
    {
      "x": -17,
      "y": 3,
      "z": 0,
      "name": "Plant_Leaves_Beech"
    },
    {
      "x": -17,
      "y": 4,
      "z": 0,
      "name": "Plant_Leaves_Beech"
    },
    {
      "x": -17,
      "y": 3,
      "z": 1,
      "name": "Plant_Leaves_Beech"
    },
    {
      "x": -17,
      "y": 4,
      "z": 1,
      "name": "Plant_Leaves_Beech"
    },
    {
      "x": -17,
      "y": 7,
      "z": 1,
      "name": "Plant_Leaves_Beech"
    },
    {
      "x": -17,
      "y": 3,
      "z": 2,
      "name": "Plant_Leaves_Beech"
    },
    {
      "x": -17,
      "y": 4,
      "z": 2,
      "name": "Plant_Leaves_Beech"
    },
    {
      "x": -17,
      "y": 5,
      "z": 2,
      "name": "Plant_Leaves_Beech"
    },
    {
      "x": -17,
      "y": 7,
      "z": 2,
      "name": "Plant_Leaves_Beech"
    },
    {
      "x": -17,
      "y": 8,
      "z": 2,
      "name": "Plant_Leaves_Beech"
    },
    {
      "x": -17,
      "y": 3,
      "z": 3,
      "name": "Wood_Beech_Branch_Corner",
      "rotation": 3
    },
    {
      "x": -17,
      "y": 4,
      "z": 3,
      "name": "Plant_Leaves_Beech"
    },
    {
      "x": -17,
      "y": 5,
      "z": 3,
      "name": "Plant_Leaves_Beech"
    },
    {
      "x": -17,
      "y": 6,
      "z": 3,
      "name": "Plant_Leaves_Beech"
    },
    {
      "x": -17,
      "y": 8,
      "z": 3,
      "name": "Plant_Leaves_Beech"
    },
    {
      "x": -17,
      "y": 3,
      "z": 4,
      "name": "Plant_Leaves_Beech"
    },
    {
      "x": -17,
      "y": 4,
      "z": 4,
      "name": "Plant_Leaves_Beech"
    },
    {
      "x": -17,
      "y": 5,
      "z": 4,
      "name": "Plant_Leaves_Beech"
    },
    {
      "x": -17,
      "y": 4,
      "z": 5,
      "name": "Plant_Leaves_Beech"
    },
    {
      "x": -17,
      "y": 6,
      "z": 5,
      "name": "Plant_Leaves_Beech"
    },
    {
      "x": -17,
      "y": 5,
      "z": 22,
      "name": "Plant_Leaves_Birch",
      "rotation": 2
    },
    {
      "x": -17,
      "y": 6,
      "z": 22,
      "name": "Plant_Leaves_Birch",
      "rotation": 2
    },
    {
      "x": -17,
      "y": 3,
      "z": 23,
      "name": "Plant_Leaves_Birch",
      "rotation": 2
    },
    {
      "x": -17,
      "y": 4,
      "z": 23,
      "name": "Plant_Leaves_Birch",
      "rotation": 2
    },
    {
      "x": -17,
      "y": 5,
      "z": 23,
      "name": "Plant_Leaves_Birch",
      "rotation": 2
    },
    {
      "x": -17,
      "y": 6,
      "z": 23,
      "name": "Plant_Leaves_Birch",
      "rotation": 2
    },
    {
      "x": -17,
      "y": 7,
      "z": 23,
      "name": "Plant_Leaves_Birch",
      "rotation": 2
    },
    {
      "x": -17,
      "y": 8,
      "z": 23,
      "name": "Plant_Leaves_Birch",
      "rotation": 2
    },
    {
      "x": -17,
      "y": 5,
      "z": 24,
      "name": "Plant_Leaves_Birch",
      "rotation": 2
    },
    {
      "x": -17,
      "y": 6,
      "z": 24,
      "name": "Plant_Leaves_Birch",
      "rotation": 2
    },
    {
      "x": -17,
      "y": 0,
      "z": 29,
      "name": "Plant_Grass_Sharp"
    },
    {
      "x": -17,
      "y": 6,
      "z": 32,
      "name": "Plant_Leaves_Beech"
    },
    {
      "x": -17,
      "y": 0,
      "z": 33,
      "name": "Plant_Flower_Tall_Purple"
    },
    {
      "x": -17,
      "y": 6,
      "z": 33,
      "name": "Plant_Leaves_Beech"
    },
    {
      "x": -17,
      "y": 7,
      "z": 33,
      "name": "Plant_Leaves_Beech"
    },
    {
      "x": -17,
      "y": 6,
      "z": 34,
      "name": "Plant_Leaves_Beech"
    },
    {
      "x": -17,
      "y": 7,
      "z": 34,
      "name": "Plant_Leaves_Beech"
    },
    {
      "x": -17,
      "y": 8,
      "z": 34,
      "name": "Plant_Leaves_Beech"
    },
    {
      "x": -17,
      "y": 6,
      "z": 35,
      "name": "Plant_Leaves_Beech"
    },
    {
      "x": -17,
      "y": 7,
      "z": 35,
      "name": "Plant_Leaves_Beech"
    },
    {
      "x": -17,
      "y": 6,
      "z": 49,
      "name": "Plant_Leaves_Oak"
    },
    {
      "x": -17,
      "y": 7,
      "z": 49,
      "name": "Plant_Leaves_Oak"
    },
    {
      "x": -17,
      "y": 0,
      "z": 50,
      "name": "Plant_Grass_Sharp"
    },
    {
      "x": -17,
      "y": 4,
      "z": 50,
      "name": "Plant_Leaves_Oak"
    },
    {
      "x": -17,
      "y": 5,
      "z": 50,
      "name": "Plant_Leaves_Oak"
    },
    {
      "x": -17,
      "y": 6,
      "z": 50,
      "name": "Plant_Leaves_Oak"
    },
    {
      "x": -17,
      "y": 7,
      "z": 50,
      "name": "Plant_Leaves_Oak"
    },
    {
      "x": -17,
      "y": 8,
      "z": 50,
      "name": "Plant_Leaves_Oak"
    },
    {
      "x": -17,
      "y": 9,
      "z": 50,
      "name": "Plant_Leaves_Oak"
    },
    {
      "x": -17,
      "y": 10,
      "z": 50,
      "name": "Plant_Leaves_Oak"
    },
    {
      "x": -17,
      "y": 12,
      "z": 50,
      "name": "Plant_Leaves_Oak"
    },
    {
      "x": -17,
      "y": 13,
      "z": 50,
      "name": "Plant_Leaves_Oak"
    },
    {
      "x": -17,
      "y": 14,
      "z": 50,
      "name": "Plant_Leaves_Oak"
    },
    {
      "x": -17,
      "y": 4,
      "z": 51,
      "name": "Plant_Leaves_Oak"
    },
    {
      "x": -17,
      "y": 5,
      "z": 51,
      "name": "Plant_Leaves_Oak"
    },
    {
      "x": -17,
      "y": 6,
      "z": 51,
      "name": "Plant_Leaves_Oak"
    },
    {
      "x": -17,
      "y": 7,
      "z": 51,
      "name": "Wood_Oak_Trunk_Full"
    },
    {
      "x": -17,
      "y": 8,
      "z": 51,
      "name": "Plant_Leaves_Oak"
    },
    {
      "x": -17,
      "y": 9,
      "z": 51,
      "name": "Plant_Leaves_Oak"
    },
    {
      "x": -17,
      "y": 10,
      "z": 51,
      "name": "Plant_Leaves_Oak"
    },
    {
      "x": -17,
      "y": 11,
      "z": 51,
      "name": "Plant_Leaves_Oak"
    },
    {
      "x": -17,
      "y": 12,
      "z": 51,
      "name": "Plant_Leaves_Oak"
    },
    {
      "x": -17,
      "y": 13,
      "z": 51,
      "name": "Plant_Leaves_Oak"
    },
    {
      "x": -17,
      "y": 14,
      "z": 51,
      "name": "Plant_Leaves_Oak"
    },
    {
      "x": -17,
      "y": 0,
      "z": 52,
      "name": "Soil_Grass_Full"
    },
    {
      "x": -17,
      "y": 1,
      "z": 52,
      "name": "Plant_Grass_Sharp"
    },
    {
      "x": -17,
      "y": 3,
      "z": 52,
      "name": "Plant_Leaves_Oak"
    },
    {
      "x": -17,
      "y": 4,
      "z": 52,
      "name": "Plant_Leaves_Oak"
    },
    {
      "x": -17,
      "y": 5,
      "z": 52,
      "name": "Plant_Leaves_Oak"
    },
    {
      "x": -17,
      "y": 6,
      "z": 52,
      "name": "Wood_Oak_Trunk_Full",
      "rotation": 5
    },
    {
      "x": -17,
      "y": 7,
      "z": 52,
      "name": "Wood_Oak_Trunk_Full"
    },
    {
      "x": -17,
      "y": 13,
      "z": 52,
      "name": "Plant_Leaves_Oak"
    },
    {
      "x": -17,
      "y": 15,
      "z": 52,
      "name": "Plant_Leaves_Oak"
    },
    {
      "x": -17,
      "y": 16,
      "z": 52,
      "name": "Plant_Leaves_Oak"
    },
    {
      "x": -17,
      "y": 0,
      "z": 53,
      "name": "Soil_Grass_Full"
    },
    {
      "x": -17,
      "y": 1,
      "z": 53,
      "name": "Plant_Grass_Sharp"
    },
    {
      "x": -17,
      "y": 4,
      "z": 53,
      "name": "Plant_Leaves_Oak"
    },
    {
      "x": -17,
      "y": 5,
      "z": 53,
      "name": "Plant_Leaves_Oak"
    },
    {
      "x": -17,
      "y": 6,
      "z": 53,
      "name": "Plant_Leaves_Oak"
    },
    {
      "x": -17,
      "y": 12,
      "z": 53,
      "name": "Wood_Oak_Branch_Corner",
      "rotation": 3
    },
    {
      "x": -17,
      "y": 13,
      "z": 53,
      "name": "Wood_Oak_Branch_Long"
    },
    {
      "x": -17,
      "y": 14,
      "z": 53,
      "name": "Plant_Leaves_Oak"
    },
    {
      "x": -17,
      "y": 15,
      "z": 53,
      "name": "Plant_Leaves_Oak"
    },
    {
      "x": -17,
      "y": 16,
      "z": 53,
      "name": "Plant_Leaves_Oak"
    },
    {
      "x": -17,
      "y": 0,
      "z": 54,
      "name": "Soil_Grass_Full"
    },
    {
      "x": -17,
      "y": 5,
      "z": 54,
      "name": "Plant_Leaves_Oak"
    },
    {
      "x": -17,
      "y": 15,
      "z": 54,
      "name": "Plant_Leaves_Oak"
    },
    {
      "x": -17,
      "y": 16,
      "z": 54,
      "name": "Plant_Leaves_Oak"
    },
    {
      "x": -17,
      "y": 17,
      "z": 54,
      "name": "Plant_Leaves_Oak"
    },
    {
      "x": -17,
      "y": 0,
      "z": 55,
      "name": "Soil_Grass_Full"
    },
    {
      "x": -17,
      "y": 1,
      "z": 55,
      "name": "Plant_Bush_Green"
    },
    {
      "x": -17,
      "y": 5,
      "z": 55,
      "name": "Plant_Leaves_Oak"
    },
    {
      "x": -17,
      "y": 15,
      "z": 55,
      "name": "Plant_Leaves_Oak"
    },
    {
      "x": -17,
      "y": 0,
      "z": 56,
      "name": "Soil_Dirt"
    },
    {
      "x": -17,
      "y": 1,
      "z": 56,
      "name": "Soil_Grass_Full"
    },
    {
      "x": -17,
      "y": 2,
      "z": 56,
      "name": "Plant_Bush_Green"
    },
    {
      "x": -17,
      "y": 5,
      "z": 56,
      "name": "Plant_Leaves_Oak"
    },
    {
      "x": -17,
      "y": 15,
      "z": 56,
      "name": "Plant_Leaves_Oak"
    },
    {
      "x": -17,
      "y": 0,
      "z": 57,
      "name": "Soil_Dirt"
    },
    {
      "x": -17,
      "y": 1,
      "z": 57,
      "name": "Soil_Grass_Full"
    },
    {
      "x": -17,
      "y": 2,
      "z": 57,
      "name": "Plant_Grass_Sharp"
    },
    {
      "x": -17,
      "y": 4,
      "z": 57,
      "name": "Plant_Leaves_Oak"
    },
    {
      "x": -17,
      "y": 6,
      "z": 57,
      "name": "Plant_Leaves_Oak"
    },
    {
      "x": -17,
      "y": 9,
      "z": 57,
      "name": "Wood_Oak_Trunk_Full"
    },
    {
      "x": -17,
      "y": 14,
