{
  "version": 8,
  "blockIdVersion": 11,
  "anchorX": 0,
  "anchorY": 0,
  "anchorZ": 0,
  "blocks": [
    {
      "x": -18,
      "y": 0,
      "z": -65,
      "name": "Soil_Dirt"
    },
    {
      "x": -18,
      "y": 1,
      "z": -65,
      "name": "Soil_Grass_Full"
    },
    {
      "x": -18,
      "y": 0,
      "z": -64,
      "name": "Soil_Dirt"
    },
    {
      "x": -18,
      "y": 1,
      "z": -64,
      "name": "Soil_Grass_Full"
    },
    {
      "x": -18,
      "y": 0,
      "z": -63,
      "name": "Soil_Dirt"
    },
    {
      "x": -18,
      "y": 1,
      "z": -63,
      "name": "Soil_Grass_Full"
    },
    {
      "x": -18,
      "y": 0,
      "z": -62,
      "name": "Soil_Dirt"
    },
    {
      "x": -18,
      "y": 1,
      "z": -62,
      "name": "Soil_Grass_Full"
    },
    {
      "x": -18,
      "y": 0,
      "z": -61,
      "name": "Soil_Dirt"
    },
    {
      "x": -18,
      "y": 1,
      "z": -61,
      "name": "Soil_Grass_Full"
    },
    {
      "x": -18,
      "y": 0,
      "z": -60,
      "name": "Soil_Dirt"
    },
    {
      "x": -18,
      "y": 1,
      "z": -60,
      "name": "Soil_Grass_Full"
    },
    {
      "x": -18,
      "y": 0,
      "z": -59,
      "name": "Soil_Dirt"
    },
    {
      "x": -18,
      "y": 1,
      "z": -59,
      "name": "Soil_Grass_Full"
    },
    {
      "x": -18,
      "y": 0,
      "z": -58,
      "name": "Soil_Dirt"
    },
    {
      "x": -18,
      "y": 1,
      "z": -58,
      "name": "Soil_Grass_Full"
    },
    {
      "x": -18,
      "y": 0,
      "z": -57,
      "name": "Soil_Dirt"
    },
    {
      "x": -18,
      "y": 1,
      "z": -57,
      "name": "Soil_Grass_Full"
    },
    {
      "x": -18,
      "y": 0,
      "z": -56,
      "name": "Soil_Dirt"
    },
    {
      "x": -18,
      "y": 1,
      "z": -56,
      "name": "Soil_Grass_Full"
    },
    {
      "x": -18,
      "y": 0,
      "z": -55,
      "name": "Soil_Dirt"
    },
    {
      "x": -18,
      "y": 1,
      "z": -55,
      "name": "Soil_Grass_Full"
    },
    {
      "x": -18,
      "y": 0,
      "z": -54,
      "name": "Soil_Dirt"
    },
    {
      "x": -18,
      "y": 1,
      "z": -54,
      "name": "Soil_Grass_Full"
    },
    {
      "x": -18,
      "y": 0,
      "z": -53,
      "name": "Soil_Dirt"
    },
    {
      "x": -18,
      "y": 1,
      "z": -53,
      "name": "Soil_Grass_Full"
    },
    {
      "x": -18,
      "y": 0,
      "z": -52,
      "name": "Soil_Dirt"
    },
    {
      "x": -18,
      "y": 1,
      "z": -52,
      "name": "Soil_Grass_Full"
    },
    {
      "x": -18,
      "y": 0,
      "z": -51,
      "name": "Soil_Dirt"
    },
    {
      "x": -18,
      "y": 1,
      "z": -51,
      "name": "Soil_Grass_Full"
    },
    {
      "x": -18,
      "y": 0,
      "z": -50,
      "name": "Soil_Dirt"
    },
    {
      "x": -18,
      "y": 1,
      "z": -50,
      "name": "Soil_Grass_Full"
    },
    {
      "x": -18,
      "y": 2,
      "z": -50,
      "name": "Plant_Grass_Sharp"
    },
    {
      "x": -18,
      "y": 0,
      "z": -49,
      "name": "Soil_Dirt"
    },
    {
      "x": -18,
      "y": 1,
      "z": -49,
      "name": "Soil_Grass_Full"
    },
    {
      "x": -18,
      "y": 2,
      "z": -49,
      "name": "Plant_Grass_Sharp"
    },
    {
      "x": -18,
      "y": 0,
      "z": -48,
      "name": "Soil_Dirt"
    },
    {
      "x": -18,
      "y": 1,
      "z": -48,
      "name": "Soil_Grass_Full"
    },
    {
      "x": -18,
      "y": 2,
      "z": -48,
      "name": "Plant_Grass_Sharp"
    },
    {
      "x": -18,
      "y": 0,
      "z": -47,
      "name": "Soil_Dirt"
    },
    {
      "x": -18,
      "y": 1,
      "z": -47,
      "name": "Soil_Grass_Full"
    },
    {
      "x": -18,
      "y": 2,
      "z": -47,
      "name": "Plant_Grass_Sharp"
    },
    {
      "x": -18,
      "y": 0,
      "z": -46,
      "name": "Soil_Dirt"
    },
    {
      "x": -18,
      "y": 1,
      "z": -46,
      "name": "Soil_Grass_Full"
    },
    {
      "x": -18,
      "y": 2,
      "z": -46,
      "name": "Plant_Grass_Sharp_Tall"
    },
    {
      "x": -18,
      "y": 0,
      "z": -45,
      "name": "Soil_Dirt"
    },
    {
      "x": -18,
      "y": 1,
      "z": -45,
      "name": "Soil_Grass_Full"
    },
    {
      "x": -18,
      "y": 2,
      "z": -45,
      "name": "Plant_Grass_Sharp"
    },
    {
      "x": -18,
      "y": 0,
      "z": -44,
      "name": "Soil_Dirt"
    },
    {
      "x": -18,
      "y": 1,
      "z": -44,
      "name": "Soil_Grass_Full"
    },
    {
      "x": -18,
      "y": 2,
      "z": -44,
      "name": "Plant_Grass_Sharp"
    },
    {
      "x": -18,
      "y": 0,
      "z": -43,
      "name": "Soil_Dirt"
    },
    {
      "x": -18,
      "y": 1,
      "z": -43,
      "name": "Soil_Grass_Full"
    },
    {
      "x": -18,
      "y": 0,
      "z": -42,
      "name": "Soil_Dirt"
    },
    {
      "x": -18,
      "y": 1,
      "z": -42,
      "name": "Soil_Grass_Full"
    },
    {
      "x": -18,
      "y": 0,
      "z": -41,
      "name": "Soil_Dirt"
    },
    {
      "x": -18,
      "y": 1,
      "z": -41,
      "name": "Soil_Grass_Full"
    },
    {
      "x": -18,
      "y": 0,
      "z": -40,
      "name": "Soil_Dirt"
    },
    {
      "x": -18,
      "y": 1,
      "z": -40,
      "name": "Soil_Grass_Full"
    },
    {
      "x": -18,
      "y": 0,
      "z": -39,
      "name": "Soil_Dirt"
    },
    {
      "x": -18,
      "y": 1,
      "z": -39,
      "name": "Soil_Grass_Full"
    },
    {
      "x": -18,
      "y": 0,
      "z": -38,
      "name": "Soil_Dirt"
    },
    {
      "x": -18,
      "y": 1,
      "z": -38,
      "name": "Soil_Grass_Full"
    },
    {
      "x": -18,
      "y": 0,
      "z": -37,
      "name": "Soil_Dirt"
    },
    {
      "x": -18,
      "y": 1,
      "z": -37,
      "name": "Soil_Grass_Full"
    },
    {
      "x": -18,
      "y": 0,
      "z": -36,
      "name": "Soil_Dirt"
    },
    {
      "x": -18,
      "y": 1,
      "z": -36,
      "name": "Soil_Grass_Full"
    },
    {
      "x": -18,
      "y": 0,
      "z": -35,
      "name": "Soil_Grass_Full"
    },
    {
      "x": -18,
      "y": 0,
      "z": -34,
      "name": "Soil_Grass_Full"
    },
    {
      "x": -18,
      "y": 0,
      "z": -33,
      "name": "Soil_Grass_Full"
    },
    {
      "x": -18,
      "y": 1,
      "z": -33,
      "name": "Plant_Bush",
      "components": {
        "Components": {
          "FarmingBlock": {
            "SpreadRate": 0.0
          }
        }
      },
      "rotation": 3
    },
    {
      "x": -18,
      "y": 0,
      "z": -32,
      "name": "Soil_Grass_Full"
    },
    {
      "x": -18,
      "y": 1,
      "z": -32,
      "name": "Plant_Bush",
      "components": {
        "Components": {
          "FarmingBlock": {
            "SpreadRate": 0.0
          }
        }
      },
      "rotation": 3
    },
    {
      "x": -18,
      "y": 0,
      "z": -31,
      "name": "Soil_Grass_Full"
    },
    {
      "x": -18,
      "y": 1,
      "z": -31,
      "name": "Plant_Bush",
      "components": {
        "Components": {
          "FarmingBlock": {
            "SpreadRate": 0.0
          }
        }
      },
      "rotation": 3
    },
    {
      "x": -18,
      "y": 0,
      "z": -30,
      "name": "Soil_Grass_Full"
    },
    {
      "x": -18,
      "y": 0,
      "z": -29,
      "name": "Soil_Grass_Full"
    },
    {
      "x": -18,
      "y": 0,
      "z": -28,
      "name": "Soil_Gravel"
    },
    {
      "x": -18,
      "y": 0,
      "z": -27,
      "name": "Soil_Grass_Full"
    },
    {
      "x": -18,
      "y": 0,
      "z": -26,
      "name": "Soil_Grass_Full"
    },
    {
      "x": -18,
      "y": 0,
      "z": -25,
      "name": "Soil_Grass_Full"
    },
    {
      "x": -18,
      "y": 0,
      "z": -24,
      "name": "Soil_Grass_Full"
    },
    {
      "x": -18,
      "y": 0,
      "z": -23,
      "name": "Soil_Grass_Full"
    },
    {
      "x": -18,
      "y": 0,
      "z": -22,
      "name": "Soil_Grass_Full"
    },
    {
      "x": -18,
      "y": 0,
      "z": -21,
      "name": "Soil_Grass_Full"
    },
    {
      "x": -18,
      "y": 0,
      "z": -20,
      "name": "Soil_Grass_Full"
    },
    {
      "x": -18,
      "y": 0,
      "z": -19,
      "name": "Soil_Grass_Full"
    },
    {
      "x": -18,
      "y": 0,
      "z": -18,
      "name": "Soil_Grass_Full"
    },
    {
      "x": -18,
      "y": 0,
      "z": -17,
      "name": "Soil_Grass_Full"
    },
    {
      "x": -18,
      "y": 0,
      "z": -16,
      "name": "Soil_Grass_Full"
    },
    {
      "x": -18,
      "y": 0,
      "z": -15,
      "name": "Soil_Grass_Full"
    },
    {
      "x": -18,
      "y": 0,
      "z": -8,
      "name": "Plant_Grass_Sharp_Short"
    },
    {
      "x": -18,
      "y": 0,
      "z": -5,
      "name": "Plant_Grass_Lush_Short"
    },
    {
      "x": -18,
      "y": 0,
      "z": -1,
      "name": "Plant_Grass_Sharp_Short"
    },
    {
      "x": -18,
      "y": 0,
      "z": 1,
      "name": "Soil_Grass_Full"
    },
    {
      "x": -18,
      "y": 1,
      "z": 1,
      "name": "Plant_Grass_Sharp"
    },
    {
      "x": -18,
      "y": 0,
      "z": 2,
      "name": "Soil_Grass_Full"
    },
    {
      "x": -18,
      "y": 0,
      "z": 3,
      "name": "Soil_Grass_Full"
    },
    {
      "x": -18,
      "y": 0,
      "z": 4,
      "name": "Soil_Grass_Full"
    },
    {
      "x": -18,
      "y": 0,
      "z": 5,
      "name": "Soil_Grass_Full"
    },
    {
      "x": -18,
      "y": 1,
      "z": 5,
      "name": "Plant_Grass_Sharp"
    },
    {
      "x": -18,
      "y": 0,
      "z": 6,
      "name": "Soil_Grass_Full"
    },
    {
      "x": -18,
      "y": 0,
      "z": 7,
      "name": "Soil_Grass_Full"
    },
    {
      "x": -18,
      "y": 0,
      "z": 8,
      "name": "Soil_Grass_Full"
    },
    {
      "x": -18,
      "y": 0,
      "z": 9,
      "name": "Soil_Grass_Full"
    },
    {
      "x": -18,
      "y": 0,
      "z": 10,
      "name": "Soil_Grass_Full"
    },
    {
      "x": -18,
      "y": 0,
      "z": 11,
      "name": "Soil_Grass_Full"
    },
    {
      "x": -18,
      "y": 0,
      "z": 12,
      "name": "Soil_Grass_Full"
    },
    {
      "x": -18,
      "y": 0,
      "z": 13,
      "name": "Soil_Grass_Full"
    },
    {
      "x": -18,
      "y": 0,
      "z": 14,
      "name": "Soil_Grass_Full"
    },
    {
      "x": -18,
      "y": 0,
      "z": 15,
      "name": "Soil_Dirt"
    },
    {
      "x": -18,
      "y": 1,
      "z": 15,
      "name": "Soil_Grass_Full"
    },
    {
      "x": -18,
      "y": 2,
      "z": 15,
      "name": "Plant_Grass_Sharp_Short"
    },
    {
      "x": -18,
      "y": 0,
      "z": 16,
      "name": "Soil_Dirt"
    },
    {
      "x": -18,
      "y": 1,
      "z": 16,
      "name": "Soil_Grass_Full"
    },
    {
      "x": -18,
      "y": 2,
      "z": 16,
      "name": "Plant_Grass_Lush_Short"
    },
    {
      "x": -18,
      "y": 0,
      "z": 17,
      "name": "Soil_Dirt"
    },
    {
      "x": -18,
      "y": 1,
      "z": 17,
      "name": "Soil_Grass_Full"
    },
    {
      "x": -18,
      "y": 0,
      "z": 18,
      "name": "Soil_Dirt"
    },
    {
      "x": -18,
      "y": 1,
      "z": 18,
      "name": "Soil_Grass_Full"
    },
    {
      "x": -18,
      "y": 0,
      "z": 19,
      "name": "Soil_Dirt"
    },
    {
      "x": -18,
      "y": 1,
      "z": 19,
      "name": "Soil_Grass_Full"
    },
    {
      "x": -18,
      "y": 0,
      "z": 20,
      "name": "Soil_Dirt"
    },
    {
      "x": -18,
      "y": 1,
      "z": 20,
      "name": "Soil_Grass_Full"
    },
    {
      "x": -18,
      "y": 0,
      "z": 21,
      "name": "Soil_Dirt"
    },
    {
      "x": -18,
      "y": 1,
      "z": 21,
      "name": "Soil_Grass_Full"
    },
    {
      "x": -18,
      "y": 2,
      "z": 21,
      "name": "Plant_Grass_Sharp"
    },
    {
      "x": -18,
      "y": 0,
      "z": 22,
      "name": "Soil_Dirt"
    },
    {
      "x": -18,
      "y": 1,
      "z": 22,
      "name": "Soil_Grass_Full"
    },
    {
      "x": -18,
      "y": 0,
      "z": 23,
      "name": "Soil_Dirt"
    },
    {
      "x": -18,
      "y": 1,
      "z": 23,
      "name": "Soil_Grass_Full"
    },
    {
      "x": -18,
      "y": 0,
      "z": 24,
      "name": "Soil_Dirt"
    },
    {
      "x": -18,
      "y": 1,
      "z": 24,
      "name": "Soil_Grass_Full"
    },
    {
      "x": -18,
      "y": 0,
      "z": 25,
      "name": "Soil_Dirt"
    },
    {
      "x": -18,
      "y": 1,
      "z": 25,
      "name": "Soil_Grass_Full"
    },
    {
      "x": -18,
      "y": 0,
      "z": 26,
      "name": "Soil_Dirt"
    },
    {
      "x": -18,
      "y": 1,
      "z": 26,
      "name": "Soil_Grass_Full"
    },
    {
      "x": -18,
      "y": 0,
      "z": 27,
      "name": "Soil_Dirt"
    },
    {
      "x": -18,
      "y": 1,
      "z": 27,
      "name": "Soil_Grass_Full"
    },
    {
      "x": -18,
      "y": 2,
      "z": 27,
      "name": "Plant_Grass_Lush_Short"
    },
    {
      "x": -18,
      "y": 0,
      "z": 28,
      "name": "Soil_Dirt"
    },
    {
      "x": -18,
      "y": 1,
      "z": 28,
      "name": "Soil_Dirt"
    },
    {
      "x": -18,
      "y": 2,
      "z": 28,
      "name": "Soil_Grass_Full"
    },
    {
      "x": -18,
      "y": 3,
      "z": 28,
      "name": "Plant_Grass_Sharp"
    },
    {
      "x": -18,
      "y": 0,
      "z": 29,
      "name": "Soil_Dirt"
    },
    {
      "x": -18,
      "y": 1,
      "z": 29,
      "name": "Soil_Dirt"
    },
    {
      "x": -18,
      "y": 2,
      "z": 29,
      "name": "Soil_Grass_Full"
    },
    {
      "x": -18,
      "y": 3,
      "z": 29,
      "name": "Plant_Grass_Sharp"
    },
    {
      "x": -18,
      "y": 0,
      "z": 30,
      "name": "Soil_Dirt"
    },
    {
      "x": -18,
      "y": 1,
      "z": 30,
      "name": "Soil_Dirt"
    },
    {
      "x": -18,
      "y": 2,
      "z": 30,
      "name": "Soil_Grass_Full"
    },
    {
      "x": -18,
      "y": 3,
      "z": 30,
      "name": "Plant_Grass_Sharp"
    },
    {
      "x": -18,
      "y": 0,
      "z": 31,
      "name": "Soil_Dirt"
    },
    {
      "x": -18,
      "y": 1,
      "z": 31,
      "name": "Soil_Dirt"
    },
    {
      "x": -18,
      "y": 2,
      "z": 31,
      "name": "Soil_Grass_Full"
    },
    {
      "x": -18,
      "y": 3,
      "z": 31,
      "name": "Plant_Grass_Sharp"
    },
    {
      "x": -18,
      "y": 0,
      "z": 32,
      "name": "Soil_Dirt"
    },
    {
      "x": -18,
      "y": 1,
      "z": 32,
      "name": "Soil_Dirt"
    },
    {
      "x": -18,
      "y": 2,
      "z": 32,
      "name": "Soil_Grass_Full"
    },
    {
      "x": -18,
      "y": 3,
      "z": 32,
      "name": "Plant_Grass_Sharp"
    },
    {
      "x": -18,
      "y": 0,
      "z": 33,
      "name": "Soil_Dirt"
    },
    {
      "x": -18,
      "y": 1,
      "z": 33,
      "name": "Soil_Dirt"
    },
    {
      "x": -18,
      "y": 2,
      "z": 33,
      "name": "Soil_Grass_Full"
    },
    {
      "x": -18,
      "y": 3,
      "z": 33,
      "name": "Plant_Grass_Sharp_Wild"
    },
    {
      "x": -18,
      "y": 0,
      "z": 34,
      "name": "Soil_Dirt"
    },
    {
      "x": -18,
      "y": 1,
      "z": 34,
      "name": "Soil_Dirt"
    },
    {
      "x": -18,
      "y": 2,
      "z": 34,
      "name": "Soil_Grass_Full"
    },
    {
      "x": -18,
      "y": 3,
      "z": 34,
      "name": "Plant_Grass_Sharp_Tall"
    },
    {
      "x": -18,
      "y": 0,
      "z": 35,
      "name": "Soil_Dirt"
    },
    {
      "x": -18,
      "y": 1,
      "z": 35,
      "name": "Soil_Dirt"
    },
    {
      "x": -18,
      "y": 2,
      "z": 35,
      "name": "Soil_Grass_Full"
    },
    {
      "x": -18,
      "y": 0,
      "z": 36,
      "name": "Soil_Dirt"
    },
    {
      "x": -18,
      "y": 1,
      "z": 36,
      "name": "Soil_Dirt"
    },
    {
      "x": -18,
      "y": 2,
      "z": 36,
      "name": "Soil_Grass_Full"
    },
    {
      "x": -18,
      "y": 3,
      "z": 36,
      "name": "Plant_Grass_Sharp_Wild"
    },
    {
      "x": -18,
      "y": 0,
      "z": 37,
      "name": "Soil_Dirt"
    },
    {
      "x": -18,
      "y": 1,
      "z": 37,
      "name": "Soil_Dirt"
    },
    {
      "x": -18,
      "y": 2,
      "z": 37,
      "name": "Soil_Grass_Full"
    },
    {
      "x": -18,
      "y": 3,
      "z": 37,
      "name": "Plant_Grass_Sharp_Tall"
    },
    {
      "x": -18,
      "y": 0,
      "z": 38,
      "name": "Soil_Dirt"
    },
    {
      "x": -18,
      "y": 1,
      "z": 38,
      "name": "Soil_Dirt"
    },
    {
      "x": -18,
      "y": 2,
      "z": 38,
      "name": "Soil_Grass_Full"
    },
    {
      "x": -18,
      "y": 3,
      "z": 38,
      "name": "Plant_Grass_Sharp"
    },
    {
      "x": -18,
      "y": 0,
      "z": 39,
      "name": "Soil_Dirt"
    },
    {
      "x": -18,
      "y": 1,
      "z": 39,
      "name": "Soil_Dirt"
    },
    {
      "x": -18,
      "y": 2,
      "z": 39,
      "name": "Soil_Grass_Full"
    },
    {
      "x": -18,
      "y": 3,
      "z": 39,
      "name": "Plant_Grass_Sharp"
    },
    {
      "x": -18,
      "y": 0,
      "z": 40,
      "name": "Soil_Dirt"
    },
    {
      "x": -18,
      "y": 1,
      "z": 40,
      "name": "Soil_Dirt"
    },
    {
      "x": -18,
      "y": 2,
      "z": 40,
      "name": "Soil_Grass_Full"
    },
    {
      "x": -18,
      "y": 3,
      "z": 40,
      "name": "Plant_Grass_Lush_Short"
    },
    {
      "x": -18,
      "y": 0,
      "z": 41,
      "name": "Soil_Dirt"
    },
    {
      "x": -18,
      "y": 1,
      "z": 41,
      "name": "Soil_Dirt"
    },
    {
      "x": -18,
      "y": 2,
      "z": 41,
      "name": "Soil_Grass_Full"
    },
    {
      "x": -18,
      "y": 0,
      "z": 42,
      "name": "Soil_Dirt"
    },
    {
      "x": -18,
      "y": 1,
      "z": 42,
      "name": "Soil_Dirt"
    },
    {
      "x": -18,
      "y": 2,
      "z": 42,
      "name": "Soil_Grass_Full"
    },
    {
      "x": -18,
      "y": 3,
      "z": 42,
      "name": "Plant_Grass_Lush_Short"
    },
    {
      "x": -18,
      "y": 0,
      "z": 43,
      "name": "Soil_Dirt"
    },
    {
      "x": -18,
      "y": 1,
      "z": 43,
      "name": "Soil_Dirt"
    },
    {
      "x": -18,
      "y": 2,
      "z": 43,
      "name": "Soil_Grass_Full"
    },
    {
      "x": -18,
      "y": 3,
      "z": 43,
      "name": "Plant_Grass_Sharp_Short"
    },
    {
      "x": -18,
      "y": 0,
      "z": 44,
      "name": "Soil_Dirt"
    },
    {
      "x": -18,
      "y": 1,
      "z": 44,
      "name": "Soil_Dirt"
    },
    {
      "x": -18,
      "y": 2,
      "z": 44,
      "name": "Soil_Grass_Full"
    },
    {
      "x": -18,
      "y": 3,
      "z": 44,
      "name": "Plant_Grass_Sharp"
    },
    {
      "x": -18,
      "y": 0,
      "z": 45,
      "name": "Soil_Dirt"
    },
    {
      "x": -18,
      "y": 1,
      "z": 45,
      "name": "Soil_Dirt"
    },
    {
      "x": -18,
      "y": 2,
      "z": 45,
      "name": "Soil_Grass_Full"
    },
    {
      "x": -18,
      "y": 3,
      "z": 45,
      "name": "Plant_Grass_Sharp"
    },
    {
      "x": -18,
      "y": 0,
      "z": 46,
      "name": "Soil_Dirt"
    },
    {
      "x": -18,
      "y": 1,
      "z": 46,
      "name": "Soil_Dirt"
    },
    {
      "x": -18,
      "y": 2,
      "z": 46,
      "name": "Soil_Grass_Full"
    },
    {
      "x": -18,
      "y": 3,
      "z": 46,
      "name": "Plant_Grass_Lush_Short"
    },
    {
      "x": -18,
      "y": 0,
      "z": 47,
      "name": "Soil_Dirt"
    },
    {
      "x": -18,
      "y": 1,
      "z": 47,
      "name": "Soil_Dirt"
    },
    {
      "x": -18,
      "y": 2,
      "z": 47,
      "name": "Soil_Grass_Full"
    },
    {
      "x": -18,
      "y": 3,
      "z": 47,
      "name": "Plant_Grass_Lush_Short"
    },
    {
      "x": -18,
      "y": 0,
      "z": 48,
      "name": "Soil_Dirt"
    },
    {
      "x": -18,
      "y": 1,
      "z": 48,
      "name": "Soil_Dirt"
    },
    {
      "x": -18,
      "y": 2,
      "z": 48,
      "name": "Soil_Grass_Full"
    },
    {
      "x": -18,
      "y": 0,
      "z": 49,
      "name": "Soil_Dirt"
    },
    {
      "x": -18,
      "y": 1,
      "z": 49,
      "name": "Soil_Dirt"
    },
    {
      "x": -18,
      "y": 2,
      "z": 49,
      "name": "Soil_Grass_Full"
    },
    {
      "x": -18,
      "y": 3,
      "z": 49,
      "name": "Plant_Grass_Sharp"
    },
    {
      "x": -18,
      "y": 0,
      "z": 50,
      "name": "Soil_Dirt"
    },
    {
      "x": -18,
      "y": 1,
      "z": 50,
      "name": "Soil_Dirt"
    },
    {
      "x": -18,
      "y": 2,
      "z": 50,
      "name": "Soil_Grass_Full"
    },
    {
      "x": -18,
      "y": 3,
      "z": 50,
      "name": "Plant_Grass_Lush_Short"
    },
    {
      "x": -18,
      "y": 0,
      "z": 51,
      "name": "Soil_Dirt"
    },
    {
      "x": -18,
      "y": 1,
      "z": 51,
      "name": "Soil_Dirt"
    },
    {
      "x": -18,
      "y": 2,
      "z": 51,
      "name": "Soil_Grass_Full"
    },
    {
      "x": -18,
      "y": 3,
      "z": 51,
      "name": "Plant_Grass_Sharp"
    },
    {
      "x": -18,
      "y": 0,
      "z": 52,
      "name": "Soil_Dirt"
    },
    {
      "x": -18,
      "y": 1,
      "z": 52,
      "name": "Soil_Grass_Full"
    },
    {
      "x": -18,
      "y": 2,
      "z": 52,
      "name": "Plant_Grass_Sharp"
    },
    {
      "x": -18,
      "y": 0,
      "z": 53,
      "name": "Soil_Dirt"
    },
    {
      "x": -18,
      "y": 1,
      "z": 53,
      "name": "Soil_Grass_Full"
    },
    {
      "x": -18,
      "y": 2,
      "z": 53,
      "name": "Plant_Grass_Sharp"
    },
    {
      "x": -18,
      "y": 0,
      "z": 54,
      "name": "Soil_Dirt"
    },
    {
      "x": -18,
      "y": 1,
      "z": 54,
      "name": "Soil_Grass_Full"
    },
    {
      "x": -18,
      "y": 0,
      "z": 55,
      "name": "Soil_Dirt"
    },
    {
      "x": -18,
      "y": 1,
      "z": 55,
      "name": "Soil_Grass_Full"
    },
    {
      "x": -18,
      "y": 2,
      "z": 55,
      "name": "Plant_Grass_Sharp"
    },
    {
      "x": -18,
      "y": 0,
      "z": 56,
      "name": "Soil_Dirt"
    },
    {
      "x": -18,
      "y": 1,
      "z": 56,
      "name": "Soil_Grass_Full"
    },
    {
      "x": -18,
      "y": 2,
      "z": 56,
      "name": "Plant_Grass_Sharp"
    },
    {
      "x": -18,
      "y": 0,
      "z": 57,
      "name": "Soil_Dirt"
    },
    {
      "x": -18,
      "y": 1,
      "z": 57,
      "name": "Soil_Grass_Full"
    },
    {
      "x": -18,
      "y": 2,
      "z": 57,
      "name": "Plant_Grass_Sharp_Tall"
    },
    {
      "x": -18,
      "y": 0,
      "z": 58,
      "name": "Soil_Dirt"
    },
    {
      "x": -18,
      "y": 1,
      "z": 58,
      "name": "Soil_Grass_Full"
    },
    {
      "x": -18,
      "y": 2,
      "z": 58,
      "name": "Plant_Grass_Sharp"
    },
    {
      "x": -18,
      "y": 0,
      "z": 59,
      "name": "Soil_Dirt"
    },
    {
      "x": -18,
      "y": 1,
      "z": 59,
      "name": "Soil_Grass_Full"
    },
    {
      "x": -18,
      "y": 2,
      "z": 59,
      "name": "Plant_Bush"
    },
    {
      "x": -18,
      "y": 0,
      "z": 60,
      "name": "Soil_Dirt"
    },
    {
      "x": -18,
      "y": 1,
      "z": 60,
      "name": "Soil_Grass_Full"
    },
    {
      "x": -18,
      "y": 2,
      "z": 60,
      "name": "Plant_Grass_Lush_Short"
    },
    {
      "x": -18,
      "y": 0,
      "z": 61,
      "name": "Soil_Dirt"
    },
    {
      "x": -18,
      "y": 1,
      "z": 61,
      "name": "Soil_Grass_Full"
    },
    {
      "x": -18,
      "y": 0,
      "z": 62,
      "name": "Soil_Dirt"
    },
    {
      "x": -18,
      "y": 1,
      "z": 62,
      "name": "Soil_Grass_Full"
    },
    {
      "x": -18,
      "y": 0,
      "z": 63,
      "name": "Soil_Dirt"
    },
    {
      "x": -18,
      "y": 1,
      "z": 63,
      "name": "Soil_Grass_Full"
    },
    {
      "x": -18,
      "y": 0,
      "z": 64,
      "name": "Soil_Grass_Full"
    },
    {
      "x": -18,
      "y": 0,
      "z": 65,
      "name": "Soil_Grass_Full"
    },
    {
      "x": -18,
      "y": 0,
      "z": 66,
      "name": "Soil_Grass_Full"
    },
    {
      "x": -17,
      "y": 0,
      "z": -65,
      "name": "Soil_Dirt"
    },
    {
      "x": -17,
      "y": 1,
      "z": -65,
      "name": "Soil_Grass_Full"
    },
    {
      "x": -17,
      "y": 0,
      "z": -64,
      "name": "Soil_Dirt"
    },
    {
      "x": -17,
      "y": 1,
      "z": -64,
      "name": "Soil_Grass_Full"
    },
    {
      "x": -17,
      "y": 0,
      "z": -63,
      "name": "Soil_Dirt"
    },
    {
      "x": -17,
      "y": 1,
      "z": -63,
      "name": "Soil_Grass_Full"
    },
    {
      "x": -17,
      "y": 0,
      "z": -62,
      "name": "Soil_Dirt"
    },
    {
      "x": -17,
      "y": 1,
      "z": -62,
      "name": "Soil_Grass_Full"
    },
    {
      "x": -17,
      "y": 0,
      "z": -61,
      "name": "Soil_Dirt"
    },
    {
      "x": -17,
      "y": 1,
      "z": -61,
      "name": "Soil_Grass_Full"
    },
    {
      "x": -17,
      "y": 0,
      "z": -60,
      "name": "Soil_Dirt"
    },
    {
      "x": -17,
      "y": 1,
      "z": -60,
      "name": "Soil_Grass_Full"
    },
    {
      "x": -17,
      "y": 0,
      "z": -59,
      "name": "Soil_Dirt"
    },
    {
      "x": -17,
      "y": 1,
      "z": -59,
      "name": "Soil_Grass_Full"
    },
    {
      "x": -17,
      "y": 0,
      "z": -58,
      "name": "Soil_Dirt"
    },
    {
      "x": -17,
      "y": 1,
      "z": -58,
      "name": "Soil_Grass_Full"
    },
    {
      "x": -17,
      "y": 0,
      "z": -57,
      "name": "Soil_Dirt"
    },
    {
      "x": -17,
      "y": 1,
      "z": -57,
      "name": "Soil_Grass_Full"
    },
    {
      "x": -17,
      "y": 0,
      "z": -56,
      "name": "Soil_Dirt"
    },
    {
      "x": -17,
      "y": 1,
      "z": -56,
      "name": "Soil_Grass_Full"
    },
    {
      "x": -17,
      "y": 0,
      "z": -55,
      "name": "Soil_Dirt"
    },
    {
      "x": -17,
      "y": 1,
      "z": -55,
      "name": "Soil_Grass_Full"
    },
    {
      "x": -17,
      "y": 0,
      "z": -54,
      "name": "Soil_Dirt"
    },
    {
      "x": -17,
      "y": 1,
      "z": -54,
      "name": "Soil_Grass_Full"
    },
    {
      "x": -17,
      "y": 0,
      "z": -53,
      "name": "Soil_Dirt"
    },
    {
      "x": -17,
      "y": 1,
      "z": -53,
      "name": "Soil_Grass_Full"
    },
    {
      "x": -17,
      "y": 2,
      "z": -53,
      "name": "Plant_Bush"
    },
    {
      "x": -17,
      "y": 0,
      "z": -52,
      "name": "Soil_Dirt"
    },
    {
      "x": -17,
      "y": 1,
      "z": -52,
      "name": "Soil_Grass_Full"
    },
    {
      "x": -17,
      "y": 2,
      "z": -52,
      "name": "Plant_Bush"
    },
    {
      "x": -17,
      "y": 0,
      "z": -51,
      "name": "Soil_Dirt"
    },
    {
      "x": -17,
      "y": 1,
      "z": -51,
      "name": "Soil_Grass_Full"
    },
    {
      "x": -17,
      "y": 0,
      "z": -50,
      "name": "Soil_Dirt"
    },
    {
      "x": -17,
      "y": 1,
      "z": -50,
      "name": "Soil_Grass_Full"
    },
    {
      "x": -17,
      "y": 2,
      "z": -50,
      "name": "Plant_Grass_Sharp"
    },
    {
      "x": -17,
      "y": 0,
      "z": -49,
      "name": "Soil_Dirt"
    },
    {
      "x": -17,
      "y": 1,
      "z": -49,
      "name": "Soil_Grass_Full"
    },
    {
      "x": -17,
      "y": 2,
      "z": -49,
      "name": "Plant_Grass_Sharp"
    },
    {
      "x": -17,
      "y": 0,
      "z": -48,
      "name": "Soil_Dirt"
    },
    {
      "x": -17,
      "y": 1,
      "z": -48,
      "name": "Soil_Grass_Full"
    },
    {
      "x": -17,
      "y": 2,
      "z": -48,
      "name": "Plant_Grass_Sharp_Tall"
    },
    {
      "x": -17,
      "y": 0,
      "z": -47,
      "name": "Soil_Dirt"
    },
    {
      "x": -17,
      "y": 1,
      "z": -47,
      "name": "Soil_Grass_Full"
    },
    {
      "x": -17,
      "y": 2,
      "z": -47,
      "name": "Plant_Grass_Sharp"
    },
    {
      "x": -17,
      "y": 0,
      "z": -46,
      "name": "Soil_Dirt"
    },
    {
      "x": -17,
      "y": 1,
      "z": -46,
      "name": "Soil_Grass_Full"
    },
    {
      "x": -17,
      "y": 0,
      "z": -45,
      "name": "Soil_Dirt"
    },
    {
      "x": -17,
      "y": 1,
      "z": -45,
      "name": "Soil_Grass_Full"
    },
    {
      "x": -17,
      "y": 2,
      "z": -45,
      "name": "Plant_Grass_Sharp"
    },
    {
      "x": -17,
      "y": 0,
      "z": -44,
      "name": "Soil_Dirt"
    },
    {
      "x": -17,
      "y": 1,
      "z": -44,
      "name": "Soil_Grass_Full"
    },
    {
      "x": -17,
      "y": 0,
      "z": -43,
      "name": "Soil_Dirt"
    },
    {
      "x": -17,
      "y": 1,
      "z": -43,
      "name": "Soil_Grass_Full"
    },
    {
      "x": -17,
      "y": 2,
      "z": -43,
      "name": "Plant_Grass_Sharp"
    },
    {
      "x": -17,
      "y": 0,
      "z": -42,
      "name": "Soil_Dirt"
    },
    {
      "x": -17,
      "y": 1,
      "z": -42,
      "name": "Soil_Grass_Full"
    },
    {
      "x": -17,
      "y": 2,
      "z": -42,
      "name": "Plant_Grass_Sharp"
    },
    {
      "x": -17,
      "y": 0,
      "z": -41,
      "name": "Soil_Dirt"
    },
    {
      "x": -17,
      "y": 1,
      "z": -41,
      "name": "Soil_Grass_Full"
    },
    {
      "x": -17,
      "y": 2,
      "z": -41,
      "name": "Plant_Grass_Sharp"
    },
    {
      "x": -17,
      "y": 0,
      "z": -40,
      "name": "Soil_Dirt"
    },
    {
      "x": -17,
      "y": 1,
      "z": -40,
      "name": "Soil_Grass_Full"
    },
    {
      "x": -17,
      "y": 0,
      "z": -39,
      "name": "Soil_Dirt"
    },
    {
      "x": -17,
      "y": 1,
      "z": -39,
      "name": "Soil_Grass_Full"
    },
    {
      "x": -17,
      "y": 0,
      "z": -38,
      "name": "Soil_Dirt"
    },
    {
      "x": -17,
      "y": 1,
      "z": -38,
      "name": "Soil_Grass_Full"
    },
    {
      "x": -17,
      "y": 0,
      "z": -37,
      "name": "Soil_Dirt"
    },
    {
      "x": -17,
      "y": 1,
      "z": -37,
      "name": "Soil_Grass_Full"
    },
    {
      "x": -17,
      "y": 0,
      "z": -36,
      "name": "Soil_Dirt"
    },
    {
      "x": -17,
      "y": 1,
      "z": -36,
      "name": "Soil_Grass_Full"
    },
    {
      "x": -17,
      "y": 0,
      "z": -35,
      "name": "Soil_Dirt"
    },
    {
      "x": -17,
      "y": 1,
      "z": -35,
      "name": "Soil_Grass_Full"
    },
    {
      "x": -17,
      "y": 0,
      "z": -34,
      "name": "Soil_Grass_Full"
    },
    {
      "x": -17,
      "y": 1,
      "z": -34,
      "name": "Plant_Bush",
      "components": {
        "Components": {
          "FarmingBlock": {
            "SpreadRate": 0.0
          }
        }
      },
      "rotation": 3
    },
    {
      "x": -17,
      "y": 0,
      "z": -33,
      "name": "Soil_Grass_Full"
    },
    {
      "x": -17,
      "y": 1,
      "z": -33,
      "name": "Plant_Bush",
      "components": {
        "Components": {
          "FarmingBlock": {
            "SpreadRate": 0.0
          }
        }
      },
      "rotation": 3
    },
    {
      "x": -17,
      "y": 0,
      "z": -32,
      "name": "Soil_Grass_Full"
    },
    {
      "x": -17,
      "y": 1,
      "z": -32,
      "name": "Plant_Bush",
      "components": {
        "Components": {
          "FarmingBlock": {
            "SpreadRate": 0.0
          }
        }
      },
      "rotation": 3
    },
    {
      "x": -17,
      "y": 2,
      "z": -32,
      "name": "Plant_Bush",
      "components": {
        "Components": {
          "FarmingBlock": {
            "SpreadRate": 0.0
          }
        }
      },
      "rotation": 3
    },
    {
      "x": -17,
      "y": 0,
      "z": -31,
      "name": "Soil_Grass_Full"
    },
    {
      "x": -17,
      "y": 1,
      "z": -31,
      "name": "Plant_Bush",
      "components": {
        "Components": {
          "FarmingBlock": {
            "SpreadRate": 0.0
          }
        }
      },
      "rotation": 3
    },
    {
      "x": -17,
      "y": 0,
      "z": -30,
      "name": "Soil_Grass_Full"
    },
    {
      "x": -17,
      "y": 0,
      "z": -29,
      "name": "Soil_Grass_Full"
    },
    {
      "x": -17,
      "y": 0,
      "z": -28,
      "name": "Soil_Grass_Full"
    },
    {
      "x": -17,
      "y": 0,
      "z": -27,
      "name": "Soil_Grass_Full"
    },
    {
      "x": -17,
      "y": 0,
      "z": -26,
      "name": "Soil_Grass_Full"
    },
    {
      "x": -17,
      "y": 0,
      "z": -25,
      "name": "Soil_Grass_Full"
    },
    {
      "x": -17,
      "y": 0,
      "z": -24,
      "name": "Soil_Grass_Full"
    },
    {
      "x": -17,
      "y": 0,
      "z": -23,
      "name": "Soil_Grass_Full"
    },
    {
      "x": -17,
      "y": 0,
      "z": -22,
      "name": "Soil_Grass_Full"
    },
    {
      "x": -17,
      "y": 0,
      "z": -21,
      "name": "Soil_Grass_Full"
    },
    {
      "x": -17,
      "y": 0,
      "z": -20,
      "name": "Soil_Grass_Full"
    },
    {
      "x": -17,
      "y": 0,
      "z": -19,
      "name": "Soil_Grass_Full"
    },
    {
      "x": -17,
      "y": 0,
      "z": -18,
      "name": "Soil_Grass_Full"
    },
    {
      "x": -17,
      "y": 0,
      "z": -17,
      "name": "Soil_Grass_Full"
    },
    {
      "x": -17,
      "y": 0,
      "z": -16,
      "name": "Soil_Grass_Full"
    },
    {
      "x": -17,
      "y": 0,
      "z": -8,
      "name": "Plant_Grass_Sharp"
    },
    {
      "x": -17,
      "y": 0,
      "z": -7,
      "name": "Plant_Grass_Sharp"
    },
    {
      "x": -17,
      "y": 0,
      "z": 1,
      "name": "Soil_Grass_Full"
    },
    {
      "x": -17,
      "y": 1,
      "z": 1,
      "name": "Plant_Bush"
    },
    {
      "x": -17,
      "y": 0,
      "z": 2,
      "name": "Soil_Grass_Full"
    },
    {
      "x": -17,
      "y": 0,
      "z": 3,
      "name": "Soil_Grass_Full"
    },
    {
      "x": -17,
      "y": 0,
      "z": 4,
      "name": "Soil_Grass_Full"
    },
    {
      "x": -17,
      "y": 0,
      "z": 5,
      "name": "Soil_Grass_Full"
    },
    {
      "x": -17,
      "y": 1,
      "z": 5,
      "name": "Plant_Grass_Sharp"
    },
    {
      "x": -17,
      "y": 0,
      "z": 6,
      "name": "Soil_Grass_Full"
    },
    {
      "x": -17,
      "y": 1,
      "z": 6,
      "name": "Plant_Grass_Sharp"
    },
    {
      "x": -17,
      "y": 0,
      "z": 7,
      "name": "Soil_Grass_Full"
    },
    {
      "x": -17,
      "y": 1,
      "z": 7,
      "name": "Plant_Flower_Common_Red2"
    },
    {
      "x": -17,
      "y": 0,
      "z": 8,
      "name": "Soil_Grass_Full"
    },
    {
      "x": -17,
      "y": 1,
      "z": 8,
      "name": "Plant_Flower_Common_Red2"
    },
    {
      "x": -17,
      "y": 0,
      "z": 9,
      "name": "Soil_Grass_Full"
    },
    {
      "x": -17,
      "y": 0,
      "z": 10,
      "name": "Soil_Grass_Full"
    },
    {
      "x": -17,
      "y": 0,
      "z": 11,
      "name": "Soil_Grass_Full"
    },
    {
      "x": -17,
      "y": 0,
      "z": 12,
      "name": "Soil_Grass_Full"
    },
    {
      "x": -17,
      "y": 0,
      "z": 13,
      "name": "Soil_Grass_Full"
    },
    {
      "x": -17,
      "y": 0,
      "z": 14,
      "name": "Soil_Grass_Full"
    },
    {
      "x": -17,
      "y": 0,
      "z": 15,
      "name": "Soil_Dirt"
    },
    {
      "x": -17,
      "y": 1,
      "z": 15,
      "name": "Soil_Grass_Full"
    },
    {
      "x": -17,
      "y": 2,
      "z": 15,
      "name": "Plant_Grass_Sharp_Short"
    },
    {
      "x": -17,
      "y": 0,
      "z": 16,
      "name": "Soil_Dirt"
    },
    {
      "x": -17,
      "y": 1,
      "z": 16,
      "name": "Soil_Grass_Full"
    },
    {
      "x": -17,
      "y": 2,
      "z": 16,
      "name": "Plant_Grass_Lush_Short"
    },
    {
      "x": -17,
      "y": 0,
      "z": 17,
      "name": "Soil_Dirt"
    },
    {
      "x": -17,
      "y": 1,
      "z": 17,
      "name": "Soil_Grass_Full"
    },
    {
      "x": -17,
      "y": 0,
      "z": 18,
      "name": "Soil_Dirt"
    },
    {
      "x": -17,
      "y": 1,
      "z": 18,
      "name": "Soil_Grass_Full"
    },
    {
      "x": -17,
      "y": 0,
      "z": 19,
      "name": "Soil_Dirt"
    },
    {
      "x": -17,
      "y": 1,
      "z": 19,
      "name": "Soil_Grass_Full"
    },
    {
      "x": -17,
      "y": 0,
      "z": 20,
      "name": "Soil_Dirt"
    },
    {
      "x": -17,
      "y": 1,
      "z": 20,
      "name": "Soil_Grass_Full"
    },
    {
      "x": -17,
      "y": 2,
      "z": 20,
      "name": "Plant_Grass_Lush_Short"
    },
    {
      "x": -17,
      "y": 0,
      "z": 21,
      "name": "Soil_Dirt"
    },
    {
      "x": -17,
      "y": 1,
      "z": 21,
      "name": "Soil_Grass_Full"
    },
    {
      "x": -17,
      "y": 0,
      "z": 22,
      "name": "Soil_Dirt"
    },
    {
      "x": -17,
      "y": 1,
      "z": 22,
      "name": "Soil_Grass_Full"
    },
    {
      "x": -17,
      "y": 0,
      "z": 23,
      "name": "Soil_Dirt"
    },
    {
      "x": -17,
      "y": 1,
      "z": 23,
      "name": "Soil_Grass_Full"
    },
    {
      "x": -17,
      "y": 2,
      "z": 23,
      "name": "Plant_Grass_Lush_Short"
    },
    {
      "x": -17,
      "y": 0,
      "z": 24,
      "name": "Soil_Dirt"
    },
    {
      "x": -17,
      "y": 1,
      "z": 24,
      "name": "Soil_Grass_Full"
    },
    {
      "x": -17,
      "y": 2,
      "z": 24,
      "name": "Plant_Grass_Lush_Short"
    },
    {
      "x": -17,
      "y": 0,
      "z": 25,
      "name": "Soil_Dirt"
    },
    {
      "x": -17,
      "y": 1,
      "z": 25,
      "name": "Soil_Grass_Full"
    },
    {
      "x": -17,
      "y": 0,
      "z": 26,
      "name": "Soil_Dirt"
    },
    {
      "x": -17,
      "y": 1,
      "z": 26,
      "name": "Soil_Grass_Full"
    },
    {
      "x": -17,
      "y": 0,
      "z": 27,
      "name": "Soil_Dirt"
    },
    {
      "x": -17,
      "y": 1,
      "z": 27,
      "name": "Soil_Grass_Full"
    },
    {
      "x": -17,
      "y": 0,
      "z": 28,
      "name": "Soil_Dirt"
    },
    {
      "x": -17,
      "y": 1,
      "z": 28,
      "name": "Soil_Dirt"
    },
    {
      "x": -17,
      "y": 2,
      "z": 28,
      "name": "Soil_Grass_Full"
    },
    {
      "x": -17,
      "y": 0,
      "z": 29,
      "name": "Soil_Dirt"
    },
    {
      "x": -17,
      "y": 1,
      "z": 29,
      "name": "Soil_Dirt"
    },
    {
      "x": -17,
      "y": 2,
      "z": 29,
      "name": "Soil_Grass_Full"
    },
    {
      "x": -17,
      "y": 3,
      "z": 29,
      "name": "Plant_Grass_Sharp"
    },
    {
      "x": -17,
      "y": 0,
      "z": 30,
      "name": "Soil_Dirt"
    },
    {
      "x": -17,
      "y": 1,
      "z": 30,
      "name": "Soil_Dirt"
    },
    {
      "x": -17,
      "y": 2,
      "z": 30,
      "name": "Soil_Grass_Full"
    },
    {
      "x": -17,
      "y": 3,
      "z": 30,
      "name": "Plant_Grass_Sharp"
    },
    {
      "x": -17,
      "y": 0,
      "z": 31,
      "name": "Soil_Dirt"
    },
    {
      "x": -17,
      "y": 1,
      "z": 31,
      "name": "Soil_Dirt"
    },
    {
      "x": -17,
      "y": 2,
      "z": 31,
      "name": "Soil_Grass_Full"
    },
    {
      "x": -17,
      "y": 3,
      "z": 31,
      "name": "Plant_Grass_Sharp"
    },
    {
      "x": -17,
      "y": 0,
      "z": 32,
      "name": "Soil_Dirt"
    },
    {
      "x": -17,
      "y": 1,
      "z": 32,
      "name": "Soil_Dirt"
    },
    {
      "x": -17,
      "y": 2,
      "z": 32,
      "name": "Soil_Grass_Full"
    },
    {
      "x": -17,
      "y": 0,
      "z": 33,
      "name": "Soil_Dirt"
    },
    {
      "x": -17,
      "y": 1,
      "z": 33,
      "name": "Soil_Dirt"
    },
    {
      "x": -17,
      "y": 2,
      "z": 33,
      "name": "Soil_Grass_Full"
    },
    {
      "x": -17,
      "y": 3,
      "z": 33,
      "name": "Plant_Grass_Sharp_Tall"
    },
    {
      "x": -17,
      "y": 0,
      "z": 34,
      "name": "Soil_Dirt"
    },
    {
      "x": -17,
      "y": 1,
      "z": 34,
      "name": "Soil_Dirt"
    },
    {
      "x": -17,
      "y": 2,
      "z": 34,
      "name": "Soil_Grass_Full"
    },
    {
      "x": -17,
      "y": 3,
      "z": 34,
      "name": "Plant_Grass_Sharp"
    },
    {
      "x": -17,
      "y": 0,
      "z": 35,
      "name": "Soil_Dirt"
    },
    {
      "x": -17,
      "y": 1,
      "z": 35,
      "name": "Soil_Dirt"
    },
    {
      "x": -17,
      "y": 2,
      "z": 35,
      "name": "Soil_Grass_Full"
    },
    {
      "x": -17,
      "y": 3,
      "z": 35,
      "name": "Plant_Grass_Sharp"
    },
    {
      "x": -17,
      "y": 0,
      "z": 36,
      "name": "Soil_Dirt"
    },
    {
      "x": -17,
      "y": 1,
      "z": 36,
      "name": "Soil_Dirt"
    },
    {
      "x": -17,
      "y": 2,
      "z": 36,
      "name": "Soil_Grass_Full"
    },
    {
      "x": -17,
      "y": 3,
      "z": 36,
      "name": "Plant_Grass_Sharp"
    },
    {
      "x": -17,
      "y": 0,
      "z": 37,
      "name": "Soil_Dirt"
    },
    {
      "x": -17,
      "y": 1,
      "z": 37,
      "name": "Soil_Dirt"
    },
    {
      "x": -17,
      "y": 2,
      "z": 37,
      "name": "Soil_Grass_Full"
    },
    {
      "x": -17,
      "y": 3,
      "z": 37,
      "name": "Plant_Grass_Sharp"
    },
    {
      "x": -17,
      "y": 0,
      "z": 38,
      "name": "Soil_Dirt"
    },
    {
      "x": -17,
      "y": 1,
      "z": 38,
      "name": "Soil_Dirt"
    },
    {
      "x": -17,
      "y": 2,
      "z": 38,
      "name": "Soil_Grass_Full"
    },
    {
      "x": -17,
      "y": 3,
      "z": 38,
      "name": "Plant_Grass_Sharp"
    },
    {
      "x": -17,
      "y": 0,
      "z": 39,
      "name": "Soil_Dirt"
    },
    {
      "x": -17,
      "y": 1,
      "z": 39,
      "name": "Soil_Dirt"
    },
    {
      "x": -17,
      "y": 2,
      "z": 39,
      "name": "Soil_Grass_Full"
    },
    {
      "x": -17,
      "y": 3,
      "z": 39,
      "name": "Plant_Grass_Sharp"
    },
    {
      "x": -17,
      "y": 0,
      "z": 40,
      "name": "Soil_Dirt"
    },
    {
      "x": -17,
      "y": 1,
      "z": 40,
      "name": "Soil_Dirt"
    },
    {
      "x": -17,
      "y": 2,
      "z": 40,
      "name": "Soil_Grass_Full"
    },
    {
      "x": -17,
      "y": 3,
      "z": 40,
      "name": "Plant_Grass_Sharp_Short"
    },
    {
      "x": -17,
      "y": 0,
      "z": 41,
      "name": "Soil_Dirt"
    },
    {
      "x": -17,
      "y": 1,
      "z": 41,
      "name": "Soil_Dirt"
    },
    {
      "x": -17,
      "y": 2,
      "z": 41,
      "name": "Soil_Grass_Full"
    },
    {
      "x": -17,
      "y": 3,
      "z": 41,
      "name": "Plant_Grass_Lush_Short"
    },
    {
      "x": -17,
      "y": 0,
      "z": 42,
      "name": "Soil_Dirt"
    },
    {
      "x": -17,
      "y": 1,
      "z": 42,
      "name": "Soil_Dirt"
    },
    {
      "x": -17,
      "y": 2,
      "z": 42,
      "name": "Soil_Grass_Full"
    },
    {
      "x": -17,
      "y": 3,
      "z": 42,
      "name": "Plant_Bush"
    },
    {
      "x": -17,
      "y": 0,
      "z": 43,
      "name": "Soil_Dirt"
    },
    {
      "x": -17,
      "y": 1,
      "z": 43,
      "name": "Soil_Dirt"
    },
    {
      "x": -17,
      "y": 2,
      "z": 43,
      "name": "Soil_Grass_Full"
    },
    {
      "x": -17,
      "y": 3,
      "z": 43,
      "name": "Plant_Bush"
    },
    {
      "x": -17,
      "y": 0,
      "z": 44,
      "name": "Soil_Dirt"
    },
    {
      "x": -17,
      "y": 1,
      "z": 44,
      "name": "Soil_Dirt"
    },
    {
      "x": -17,
      "y": 2,
      "z": 44,
      "name": "Soil_Grass_Full"
    },
    {
      "x": -17,
      "y": 0,
      "z": 45,
      "name": "Soil_Dirt"
    },
    {
      "x": -17,
      "y": 1,
      "z": 45,
      "name": "Soil_Dirt"
    },
    {
      "x": -17,
      "y": 2,
      "z": 45,
      "name": "Soil_Grass_Full"
    },
    {
      "x": -17,
      "y": 0,
      "z": 46,
      "name": "Soil_Dirt"
    },
    {
      "x": -17,
      "y": 1,
      "z": 46,
      "name": "Soil_Dirt"
    },
    {
      "x": -17,
      "y": 2,
      "z": 46,
      "name": "Soil_Grass_Full"
    },
    {
      "x": -17,
      "y": 3,
      "z": 46,
      "name": "Plant_Grass_Lush_Short"
    },
    {
      "x": -17,
      "y": 0,
      "z": 47,
      "name": "Soil_Dirt"
    },
    {
      "x": -17,
      "y": 1,
      "z": 47,
      "name": "Soil_Dirt"
    },
    {
      "x": -17,
      "y": 2,
      "z": 47,
      "name": "Soil_Grass_Full"
    },
    {
      "x": -17,
      "y": 3,
      "z": 47,
      "name": "Plant_Grass_Lush_Short"
    },
    {
      "x": -17,
      "y": 0,
      "z": 48,
      "name": "Soil_Dirt"
    },
    {
      "x": -17,
      "y": 1,
      "z": 48,
      "name": "Soil_Dirt"
    },
    {
      "x": -17,
      "y": 2,
      "z": 48,
      "name": "Soil_Grass_Full"
    },
    {
      "x": -17,
      "y": 3,
      "z": 48,
      "name": "Plant_Grass_Sharp"
    },
    {
      "x": -17,
      "y": 0,
      "z": 49,
      "name": "Soil_Dirt"
    },
    {
      "x": -17,
      "y": 1,
      "z": 49,
      "name": "Soil_Dirt"
    },
    {
      "x": -17,
      "y": 2,
      "z": 49,
      "name": "Soil_Grass_Full"
    },
    {
      "x": -17,
      "y": 0,
      "z": 50,
      "name": "Soil_Dirt"
    },
    {
      "x": -17,
      "y": 1,
      "z": 50,
      "name": "Soil_Dirt"
    },
    {
      "x": -17,
      "y": 2,
      "z": 50,
      "name": "Soil_Grass_Full"
    },
    {
      "x": -17,
      "y": 3,
      "z": 50,
      "name": "Plant_Grass_Lush_Short"
    },
    {
      "x": -17,
      "y": 0,
      "z": 51,
      "name": "Soil_Dirt"
    },
    {
      "x": -17,
      "y": 1,
      "z": 51,
      "name": "Soil_Dirt"
    },
    {
      "x": -17,
      "y": 2,
      "z": 51,
      "name": "Soil_Grass_Full"
    },
    {
      "x": -17,
      "y": 0,
      "z": 52,
      "name": "Soil_Dirt"
    },
    {
      "x": -17,
      "y": 1,
      "z": 52,
      "name": "Soil_Dirt"
    },
    {
      "x": -17,
      "y": 2,
      "z": 52,
      "name": "Soil_Grass_Full"
    },
    {
      "x": -17,
      "y": 3,
      "z": 52,
      "name": "Plant_Grass_Sharp"
    },
    {
      "x": -17,
      "y": 0,
      "z": 53,
      "name": "Soil_Dirt"
    },
    {
      "x": -17,
      "y": 1,
      "z": 53,
      "name": "Soil_Grass_Full"
    },
    {
      "x": -17,
      "y": 2,
      "z": 53,
      "name": "Plant_Grass_Sharp"
    },
    {
      "x": -17,
      "y": 0,
      "z": 54,
      "name": "Soil_Dirt"
    },
    {
      "x": -17,
      "y": 1,
      "z": 54,
      "name": "Soil_Grass_Full"
    },
    {
      "x": -17,
      "y": 2,
      "z": 54,
      "name": "Plant_Grass_Sharp"
    },
    {
      "x": -17,
      "y": 0,
      "z": 55,
      "name": "Soil_Dirt"
    },
    {
      "x": -17,
      "y": 1,
      "z": 55,
      "name": "Soil_Grass_Full"
    },
    {
      "x": -17,
      "y": 2,
      "z": 55,
      "name": "Plant_Grass_Sharp"
    },
    {
      "x": -17,
      "y": 0,
      "z": 56,
      "name": "Soil_Dirt"
    },
    {
      "x": -17,
      "y": 1,
      "z": 56,
      "name": "Soil_Grass_Full"
    },
    {
      "x": -17,
      "y": 2,
      "z": 56,
      "name": "Plant_Grass_Sharp"
    },
    {
      "x": -17,
      "y": 0,
      "z": 57,
      "name": "Soil_Dirt"
    },
    {
      "x": -17,
      "y": 1,
      "z": 57,
      "name": "Soil_Grass_Full"
    },
    {
      "x": -17,
      "y": 2,
      "z": 57,
      "name": "Plant_Grass_Sharp_Tall"
    },
    {
      "x": -17,
      "y": 0,
      "z": 58,
      "name": "Soil_Dirt"
    },
    {
      "x": -17,
      "y": 1,
      "z": 58,
      "name": "Soil_Grass_Full"
    },
    {
      "x": -17,
      "y": 2,
      "z": 58,
      "name": "Plant_Bush"
    },
    {
      "x": -17,
      "y": 0,
      "z": 59,
      "name": "Soil_Dirt"
    },
    {
      "x": -17,
      "y": 1,
      "z": 59,
      "name": "Soil_Grass_Full"
    },
    {
      "x": -17,
      "y": 2,
      "z": 59,
      "name": "Plant_Grass_Lush_Short"
    },
    {
      "x": -17,
      "y": 0,
      "z": 60,
      "name": "Soil_Dirt"
    },
    {
      "x": -17,
      "y": 1,
      "z": 60,
      "name": "Soil_Grass_Full"
    },
    {
      "x": -17,
      "y": 0,
      "z": 61,
      "name": "Soil_Dirt"
    },
    {
      "x": -17,
      "y": 1,
      "z": 61,
      "name": "Soil_Grass_Full"
    },
    {
      "x": -17,
      "y": 0,
      "z": 62,
      "name": "Soil_Dirt"
    },
    {
      "x": -17,
      "y": 1,
      "z": 62,
      "name": "Soil_Grass_Full"
    },
    {
      "x": -17,
      "y": 0,
      "z": 63,
      "name": "Soil_Grass_Full"
    },
    {
      "x": -17,
      "y": 0,
      "z": 64,
      "name": "Soil_Grass_Full"
    },
    {
      "x": -17,
      "y": 0,
      "z": 65,
      "name": "Soil_Grass_Full"
    },
    {
      "x": -17,
      "y": 0,
      "z": 66,
      "name": "Soil_Grass_Full"
    },
    {
      "x": -16,
      "y": 0,
      "z": -65,
      "name": "Soil_Dirt"
    },
    {
      "x": -16,
      "y": 1,
      "z": -65,
      "name": "Soil_Grass_Full"
    },
    {
      "x": -16,
      "y": 0,
      "z": -64,
      "name": "Soil_Dirt"
    },
    {
      "x": -16,
      "y": 1,
      "z": -64,
      "name": "Soil_Grass_Full"
    },
    {
      "x": -16,
      "y": 0,
      "z": -63,
      "name": "Soil_Dirt"
    },
    {
      "x": -16,
      "y": 1,
      "z": -63,
      "name": "Soil_Grass_Full"
    },
    {
      "x": -16,
      "y": 0,
      "z": -62,
      "name": "Soil_Dirt"
    },
    {
      "x": -16,
      "y": 1,
      "z": -62,
      "name": "Soil_Grass_Full"
    },
    {
      "x": -16,
      "y": 0,
      "z": -61,
      "name": "Soil_Dirt"
    },
    {
      "x": -16,
      "y": 1,
      "z": -61,
      "name": "Soil_Grass_Full"
    },
    {
      "x": -16,
      "y": 0,
      "z": -60,
      "name": "Soil_Dirt"
    },
    {
      "x": -16,
      "y": 1,
      "z": -60,
      "name": "Soil_Grass_Full"
    },
    {
      "x": -16,
      "y": 0,
      "z": -59,
      "name": "Soil_Dirt"
    },
    {
      "x": -16,
      "y": 1,
      "z": -59,
      "name": "Soil_Grass_Full"
    },
    {
      "x": -16,
      "y": 0,
      "z": -58,
      "name": "Soil_Dirt"
    },
    {
      "x": -16,
      "y": 1,
      "z": -58,
      "name": "Soil_Grass_Full"
    },
    {
      "x": -16,
      "y": 0,
      "z": -57,
      "name": "Soil_Dirt"
    },
    {
      "x": -16,
      "y": 1,
      "z": -57,
      "name": "Soil_Grass_Full"
    },
    {
      "x": -16,
      "y": 0,
      "z": -56,
      "name": "Soil_Dirt"
    },
    {
      "x": -16,
      "y": 1,
      "z": -56,
      "name": "Soil_Grass_Full"
    },
    {
      "x": -16,
      "y": 0,
      "z": -55,
      "name": "Soil_Dirt"
    },
    {
      "x": -16,
      "y": 1,
      "z": -55,
      "name": "Soil_Grass_Full"
    },
    {
      "x": -16,
      "y": 0,
      "z": -54,
      "name": "Soil_Dirt"
    },
    {
      "x": -16,
      "y": 1,
      "z": -54,
      "name": "Soil_Grass_Full"
    },
    {
      "x": -16,
      "y": 0,
      "z": -53,
      "name": "Soil_Dirt"
    },
    {
      "x": -16,
      "y": 1,
      "z": -53,
      "name": "Soil_Grass_Full"
    },
    {
      "x": -16,
      "y": 2,
      "z": -53,
      "name": "Plant_Bush"
    },
    {
      "x": -16,
      "y": 0,
      "z": -52,
      "name": "Soil_Dirt"
    },
    {
      "x": -16,
      "y": 1,
      "z": -52,
      "name": "Soil_Grass_Full"
    },
    {
      "x": -16,
      "y": 2,
      "z": -52,
      "name": "Plant_Bush"
    },
    {
      "x": -16,
      "y": 0,
      "z": -51,
      "name": "Soil_Dirt"
    },
    {
      "x": -16,
      "y": 1,
      "z": -51,
      "name": "Soil_Grass_Full"
    },
    {
      "x": -16,
      "y": 2,
      "z": -51,
      "name": "Plant_Bush"
    },
    {
      "x": -16,
      "y": 0,
      "z": -50,
      "name": "Soil_Dirt"
    },
    {
      "x": -16,
      "y": 1,
      "z": -50,
      "name": "Soil_Grass_Full"
    },
    {
      "x": -16,
      "y": 0,
      "z": -49,
      "name": "Soil_Dirt"
    },
    {
      "x": -16,
      "y": 1,
      "z": -49,
      "name": "Soil_Grass_Full"
    },
    {
      "x": -16,
      "y": 0,
      "z": -48,
      "name": "Soil_Dirt"
    },
    {
      "x": -16,
      "y": 1,
      "z": -48,
      "name": "Soil_Grass_Full"
    },
    {
      "x": -16,
      "y": 0,
      "z": -47,
      "name": "Soil_Dirt"
    },
    {
      "x": -16,
      "y": 1,
      "z": -47,
      "name": "Soil_Grass_Full"
    },
    {
      "x": -16,
      "y": 0,
      "z": -46,
      "name": "Soil_Dirt"
    },
    {
      "x": -16,
      "y": 1,
      "z": -46,
      "name": "Soil_Grass_Full"
    },
    {
      "x": -16,
      "y": 0,
      "z": -45,
      "name": "Soil_Dirt"
    },
    {
      "x": -16,
      "y": 1,
      "z": -45,
      "name": "Soil_Grass_Full"
    },
    {
      "x": -16,
      "y": 2,
      "z": -45,
      "name": "Plant_Grass_Sharp"
    },
    {
      "x": -16,
      "y": 0,
      "z": -44,
      "name": "Soil_Dirt"
    },
    {
      "x": -16,
      "y": 1,
      "z": -44,
      "name": "Soil_Grass_Full"
    },
    {
      "x": -16,
      "y": 0,
      "z": -43,
      "name": "Soil_Dirt"
    },
    {
      "x": -16,
      "y": 1,
      "z": -43,
      "name": "Soil_Grass_Full"
    },
    {
      "x": -16,
      "y": 2,
      "z": -43,
      "name": "Plant_Grass_Sharp"
    },
    {
      "x": -16,
      "y": 0,
      "z": -42,
      "name": "Soil_Dirt"
    },
    {
      "x": -16,
      "y": 1,
      "z": -42,
      "name": "Soil_Grass_Full"
    },
    {
      "x": -16,
      "y": 2,
      "z": -42,
      "name": "Plant_Grass_Sharp"
    },
    {
      "x": -16,
      "y": 0,
      "z": -41,
      "name": "Soil_Dirt"
    },
    {
      "x": -16,
      "y": 1,
      "z": -41,
      "name": "Soil_Grass_Full"
    },
    {
      "x": -16,
      "y": 2,
      "z": -41,
      "name": "Plant_Grass_Sharp"
    },
    {
      "x": -16,
      "y": 0,
      "z": -40,
      "name": "Soil_Dirt"
    },
    {
      "x": -16,
      "y": 1,
      "z": -40,
      "name": "Soil_Grass_Full"
    },
    {
      "x": -16,
      "y": 2,
      "z": -40,
      "name": "Plant_Grass_Sharp"
    },
    {
      "x": -16,
      "y": 0,
      "z": -39,
      "name": "Soil_Dirt"
    },
    {
      "x": -16,
      "y": 1,
      "z": -39,
      "name": "Soil_Grass_Full"
    },
    {
      "x": -16,
      "y": 2,
      "z": -39,
      "name": "Plant_Grass_Sharp"
    },
    {
      "x": -16,
      "y": 0,
      "z": -38,
      "name": "Soil_Dirt"
    },
    {
      "x": -16,
      "y": 1,
      "z": -38,
      "name": "Soil_Grass_Full"
    },
    {
      "x": -16,
      "y": 2,
      "z": -38,
      "name": "Plant_Grass_Sharp"
    },
    {
      "x": -16,
      "y": 0,
      "z": -37,
      "name": "Soil_Dirt"
    },
    {
      "x": -16,
      "y": 1,
      "z": -37,
      "name": "Soil_Grass_Full"
    },
    {
      "x": -16,
      "y": 2,
      "z": -37,
      "name": "Plant_Grass_Sharp"
    },
    {
      "x": -16,
      "y": 0,
      "z": -36,
      "name": "Soil_Dirt"
    },
    {
      "x": -16,
      "y": 1,
      "z": -36,
      "name": "Soil_Grass_Full"
    },
    {
      "x": -16,
      "y": 0,
      "z": -35,
      "name": "Soil_Dirt"
    },
    {
      "x": -16,
      "y": 1,
      "z": -35,
      "name": "Rock_Stone",
      "rotation": 3
    },
    {
      "x": -16,
      "y": 2,
      "z": -35,
      "name": "Rubble_Stone",
      "rotation": 3
    },
    {
      "x": -16,
      "y": 0,
      "z": -34,
      "name": "Rock_Stone",
      "rotation": 3
    },
    {
      "x": -16,
      "y": 1,
      "z": -34,
      "name": "Rock_Stone",
      "rotation": 3
    },
    {
      "x": -16,
      "y": 2,
      "z": -34,
      "name": "Rock_Stone",
      "rotation": 3
    },
    {
      "x": -16,
      "y": 3,
      "z": -34,
      "name": "Rubble_Stone",
      "rotation": 3
    },
    {
      "x": -16,
      "y": 0,
      "z": -33,
      "name": "Soil_Dirt"
    },
    {
      "x": -16,
      "y": 1,
      "z": -33,
      "name": "Rock_Stone",
      "rotation": 3
    },
    {
      "x": -16,
      "y": 2,
      "z": -33,
      "name": "Rock_Stone",
      "rotation": 3
    },
    {
      "x": -16,
      "y": 3,
      "z": -33,
      "name": "*Plant_Crop_Berry_Block_State_Definitions_StageFinal",
      "rotation": 3
    },
    {
      "x": -16,
      "y": 0,
      "z": -32,
      "name": "Soil_Grass_Full"
    },
    {
      "x": -16,
      "y": 1,
      "z": -32,
      "name": "Plant_Bush",
      "components": {
        "Components": {
          "FarmingBlock": {
            "SpreadRate": 0.0
          }
        }
      },
      "rotation": 3
    },
    {
      "x": -16,
      "y": 0,
      "z": -31,
      "name": "Soil_Grass_Full"
    },
    {
      "x": -16,
      "y": 0,
      "z": -30,
      "name": "Soil_Grass_Full"
    },
    {
      "x": -16,
      "y": 1,
      "z": -30,
      "name": "Plant_Bush",
      "components": {
        "Components": {
          "FarmingBlock": {
            "SpreadRate": 0.0
          }
        }
      },
      "rotation": 3
    },
    {
      "x": -16,
      "y": 0,
      "z": -29,
      "name": "Soil_Grass_Full"
    },
    {
      "x": -16,
      "y": 0,
      "z": -28,
      "name": "Soil_Grass_Full"
    },
    {
      "x": -16,
      "y": 0,
      "z": -27,
      "name": "Soil_Grass_Full"
    },
    {
      "x": -16,
      "y": 0,
      "z": -26,
      "name": "Soil_Grass_Full"
    },
    {
      "x": -16,
      "y": 0,
      "z": -25,
      "name": "Soil_Grass_Full"
    },
    {
      "x": -16,
      "y": 0,
      "z": -24,
      "name": "Soil_Grass_Full"
    },
    {
      "x": -16,
      "y": 0,
      "z": -23,
      "name": "Soil_Grass_Full"
    },
    {
      "x": -16,
      "y": 0,
      "z": -22,
      "name": "Soil_Grass_Full"
    },
    {
      "x": -16,
      "y": 0,
      "z": -21,
      "name": "Soil_Grass_Full"
    },
    {
      "x": -16,
      "y": 0,
      "z": -20,
      "name": "Soil_Grass_Full"
    },
    {
      "x": -16,
      "y": 0,
      "z": -19,
      "name": "Soil_Grass_Full"
    },
    {
      "x": -16,
      "y": 0,
      "z": -18,
      "name": "Soil_Grass_Full"
    },
    {
      "x": -16,
      "y": 0,
      "z": -17,
      "name": "Soil_Grass_Full"
    },
    {
      "x": -16,
      "y": 0,
      "z": -5,
      "name": "Plant_Grass_Lush_Short"
    },
    {
      "x": -16,
      "y": 0,
      "z": 0,
      "name": "Plant_Grass_Lush_Short"
    },
    {
      "x": -16,
      "y": 0,
      "z": 1,
      "name": "Plant_Grass_Lush_Short"
    },
    {
      "x": -16,
      "y": 0,
      "z": 2,
      "name": "Soil_Grass_Full"
    },
    {
      "x": -16,
      "y": 1,
      "z": 2,
      "name": "*Plant_Crop_Berry_Block_State_Definitions_StageFinal"
    },
    {
      "x": -16,
      "y": 0,
      "z": 3,
      "name": "Soil_Grass_Full"
    },
    {
      "x": -16,
      "y": 0,
      "z": 4,
      "name": "Soil_Grass_Full"
    },
    {
      "x": -16,
      "y": 0,
      "z": 5,
      "name": "Soil_Grass_Full"
    },
    {
      "x": -16,
      "y": 1,
      "z": 5,
      "name": "Plant_Grass_Sharp"
    },
    {
      "x": -16,
      "y": 0,
      "z": 6,
      "name": "Soil_Grass_Full"
    },
    {
      "x": -16,
      "y": 1,
      "z": 6,
      "name": "Plant_Grass_Sharp"
    },
    {
      "x": -16,
      "y": 0,
      "z": 7,
      "name": "Soil_Grass_Full"
    },
    {
      "x": -16,
      "y": 1,
      "z": 7,
      "name": "Plant_Grass_Sharp"
    },
    {
      "x": -16,
      "y": 0,
      "z": 8,
      "name": "Soil_Grass_Full"
    },
    {
      "x": -16,
      "y": 1,
      "z": 8,
      "name": "Plant_Grass_Sharp"
    },
    {
      "x": -16,
      "y": 0,
      "z": 9,
      "name": "Soil_Grass_Full"
    },
    {
      "x": -16,
      "y": 1,
      "z": 9,
      "name": "Plant_Grass_Sharp"
    },
    {
      "x": -16,
      "y": 0,
      "z": 10,
      "name": "Soil_Grass_Full"
    },
    {
      "x": -16,
      "y": 0,
      "z": 11,
      "name": "Soil_Grass_Full"
    },
    {
      "x": -16,
      "y": 0,
      "z": 12,
      "name": "Soil_Grass_Full"
    },
    {
      "x": -16,
      "y": 0,
      "z": 13,
      "name": "Soil_Grass_Full"
    },
    {
      "x": -16,
      "y": 0,
      "z": 14,
      "name": "Soil_Grass_Full"
    },
    {
      "x": -16,
      "y": 0,
      "z": 15,
      "name": "Soil_Dirt"
    },
    {
      "x": -16,
      "y": 1,
      "z": 15,
      "name": "Soil_Grass_Full"
    },
    {
      "x": -16,
      "y": 0,
      "z": 16,
      "name": "Soil_Dirt"
    },
    {
      "x": -16,
      "y": 1,
      "z": 16,
      "name": "Soil_Grass_Full"
    },
    {
      "x": -16,
      "y": 0,
      "z": 17,
      "name": "Soil_Dirt"
    },
    {
      "x": -16,
      "y": 1,
      "z": 17,
      "name": "Soil_Grass_Full"
    },
    {
      "x": -16,
      "y": 0,
      "z": 18,
      "name": "Soil_Dirt"
    },
    {
      "x": -16,
      "y": 1,
      "z": 18,
      "name": "Soil_Grass_Full"
    },
    {
      "x": -16,
      "y": 0,
      "z": 19,
      "name": "Soil_Dirt"
    },
    {
      "x": -16,
      "y": 1,
      "z": 19,
      "name": "Soil_Grass_Full"
    },
    {
      "x": -16,
      "y": 2,
      "z": 19,
      "name": "Plant_Grass_Sharp"
    },
    {
      "x": -16,
      "y": 0,
      "z": 20,
      "name": "Soil_Dirt"
    },
    {
      "x": -16,
      "y": 1,
      "z": 20,
      "name": "Soil_Grass_Full"
    },
    {
      "x": -16,
      "y": 0,
      "z": 21,
      "name": "Soil_Dirt"
    },
    {
      "x": -16,
      "y": 1,
      "z": 21,
      "name": "Soil_Grass_Full"
    },
    {
      "x": -16,
      "y": 0,
      "z": 22,
      "name": "Soil_Dirt"
    },
    {
      "x": -16,
      "y": 1,
      "z": 22,
      "name": "Soil_Grass_Full"
    },
    {
      "x": -16,
      "y": 2,
      "z": 22,
      "name": "Plant_Grass_Sharp_Short"
    },
    {
      "x": -16,
      "y": 0,
      "z": 23,
      "name": "Soil_Dirt"
    },
    {
      "x": -16,
      "y": 1,
      "z": 23,
      "name": "Soil_Grass_Full"
    },
    {
      "x": -16,
      "y": 2,
      "z": 23,
      "name": "Plant_Grass_Sharp_Short"
    },
    {
      "x": -16,
      "y": 0,
      "z": 24,
      "name": "Soil_Dirt"
    },
    {
      "x": -16,
      "y": 1,
      "z": 24,
      "name": "Soil_Grass_Full"
    },
    {
      "x": -16,
      "y": 2,
      "z": 24,
      "name": "Plant_Grass_Sharp"
    },
    {
      "x": -16,
      "y": 0,
      "z": 25,
      "name": "Soil_Dirt"
    },
    {
      "x": -16,
      "y": 1,
      "z": 25,
      "name": "Soil_Grass_Full"
    },
    {
      "x": -16,
      "y": 2,
      "z": 25,
      "name": "Plant_Grass_Sharp"
    },
    {
      "x": -16,
      "y": 0,
      "z": 26,
      "name": "Soil_Dirt"
    },
    {
      "x": -16,
      "y": 1,
      "z": 26,
      "name": "Soil_Grass_Full"
    },
    {
      "x": -16,
      "y": 2,
      "z": 26,
      "name": "Plant_Grass_Lush_Short"
    },
    {
      "x": -16,
      "y": 0,
      "z": 27,
      "name": "Soil_Dirt"
    },
    {
      "x": -16,
      "y": 1,
      "z": 27,
      "name": "Soil_Grass_Full"
    },
    {
      "x": -16,
      "y": 0,
      "z": 28,
      "name": "Soil_Dirt"
    },
    {
      "x": -16,
      "y": 1,
      "z": 28,
      "name": "Soil_Dirt"
    },
    {
      "x": -16,
      "y": 2,
      "z": 28,
      "name": "Soil_Grass_Full"
    },
    {
      "x": -16,
      "y": 0,
      "z": 29,
      "name": "Soil_Dirt"
    },
    {
      "x": -16,
      "y": 1,
      "z": 29,
      "name": "Soil_Dirt"
    },
    {
      "x": -16,
      "y": 2,
      "z": 29,
      "name": "Soil_Grass_Full"
    },
    {
      "x": -16,
      "y": 0,
      "z": 30,
      "name": "Soil_Dirt"
    },
    {
      "x": -16,
      "y": 1,
      "z": 30,
      "name": "Soil_Dirt"
    },
    {
      "x": -16,
      "y": 2,
      "z": 30,
      "name": "Soil_Grass_Full"
    },
    {
      "x": -16,
      "y": 3,
      "z": 30,
      "name": "Plant_Grass_Sharp"
    },
    {
      "x": -16,
      "y": 0,
      "z": 31,
      "name": "Soil_Dirt"
    },
    {
      "x": -16,
      "y": 1,
      "z": 31,
      "name": "Soil_Dirt"
    },
    {
      "x": -16,
      "y": 2,
      "z": 31,
      "name": "Soil_Grass_Full"
    },
    {
      "x": -16,
      "y": 3,
      "z": 31,
      "name": "Plant_Grass_Sharp"
    },
    {
      "x": -16,
      "y": 0,
      "z": 32,
      "name": "Soil_Dirt"
    },
    {
      "x": -16,
      "y": 1,
      "z": 32,
      "name": "Soil_Dirt"
    },
    {
      "x": -16,
      "y": 2,
      "z": 32,
      "name": "Soil_Grass_Full"
    },
    {
      "x": -16,
      "y": 3,
      "z": 32,
      "name": "Plant_Grass_Sharp_Tall"
    },
    {
      "x": -16,
      "y": 0,
      "z": 33,
      "name": "Soil_Dirt"
    },
    {
      "x": -16,
      "y": 1,
      "z": 33,
      "name": "Soil_Dirt"
    },
    {
      "x": -16,
      "y": 2,
      "z": 33,
      "name": "Soil_Grass_Full"
    },
    {
      "x": -16,
      "y": 3,
      "z": 33,
      "name": "Plant_Grass_Sharp"
    },
    {
      "x": -16,
      "y": 0,
      "z": 34,
      "name": "Soil_Dirt"
    },
    {
      "x": -16,
      "y": 1,
      "z": 34,
      "name": "Soil_Dirt"
    },
    {
      "x": -16,
      "y": 2,
      "z": 34,
      "name": "Soil_Grass_Full"
    },
    {
      "x": -16,
      "y": 0,
      "z": 35,
      "name": "Soil_Dirt"
    },
    {
      "x": -16,
      "y": 1,
      "z": 35,
      "name": "Soil_Dirt"
    },
    {
      "x": -16,
      "y": 2,
      "z": 35,
      "name": "Soil_Grass_Full"
    },
    {
      "x": -16,
      "y": 3,
      "z": 35,
      "name": "Plant_Grass_Sharp"
    },
    {
      "x": -16,
      "y": 0,
      "z": 36,
      "name": "Soil_Dirt"
    },
    {
      "x": -16,
      "y": 1,
      "z": 36,
      "name": "Soil_Dirt"
    },
    {
      "x": -16,
      "y": 2,
      "z": 36,
      "name": "Soil_Grass_Full"
    },
    {
      "x": -16,
      "y": 3,
      "z": 36,
      "name": "Plant_Grass_Sharp"
    },
    {
      "x": -16,
      "y": 0,
      "z": 37,
      "name": "Soil_Dirt"
    },
    {
      "x": -16,
      "y": 1,
      "z": 37,
      "name": "Soil_Dirt"
    },
    {
      "x": -16,
      "y": 2,
      "z": 37,
      "name": "Soil_Grass_Full"
    },
    {
      "x": -16,
      "y": 3,
      "z": 37,
      "name": "Plant_Grass_Sharp"
    },
    {
      "x": -16,
      "y": 0,
      "z": 38,
      "name": "Soil_Dirt"
    },
    {
      "x": -16,
      "y": 1,
      "z": 38,
      "name": "Soil_Dirt"
    },
    {
      "x": -16,
      "y": 2,
      "z": 38,
      "name": "Soil_Grass_Full"
    },
    {
      "x": -16,
      "y": 0,
      "z": 39,
      "name": "Soil_Dirt"
    },
    {
      "x": -16,
      "y": 1,
      "z": 39,
      "name": "Soil_Dirt"
    },
    {
      "x": -16,
      "y": 2,
      "z": 39,
      "name": "Soil_Grass_Full"
    },
    {
      "x": -16,
      "y": 0,
      "z": 40,
      "name": "Soil_Dirt"
    },
    {
      "x": -16,
      "y": 1,
      "z": 40,
      "name": "Soil_Dirt"
    },
    {
      "x": -16,
      "y": 2,
      "z": 40,
      "name": "Soil_Grass_Full"
    },
    {
      "x": -16,
      "y": 0,
      "z": 41,
      "name": "Soil_Dirt"
    },
    {
      "x": -16,
      "y": 1,
      "z": 41,
      "name": "Soil_Dirt"
    },
    {
      "x": -16,
      "y": 2,
      "z": 41,
      "name": "Soil_Grass_Full"
    },
    {
      "x": -16,
      "y": 0,
      "z": 42,
      "name": "Soil_Dirt"
    },
    {
      "x": -16,
      "y": 1,
      "z": 42,
      "name": "Soil_Dirt"
    },
    {
      "x": -16,
      "y": 2,
      "z": 42,
      "name": "Soil_Grass_Full"
    },
    {
      "x": -16,
      "y": 3,
      "z": 42,
      "name": "Plant_Bush"
    },
    {
      "x": -16,
      "y": 0,
      "z": 43,
      "name": "Soil_Dirt"
    },
    {
      "x": -16,
      "y": 1,
      "z": 43,
      "name": "Soil_Dirt"
    },
    {
      "x": -16,
      "y": 2,
      "z": 43,
      "name": "Soil_Grass_Full"
    },
    {
      "x": -16,
      "y": 3,
      "z": 43,
      "name": "Plant_Bush"
    },
    {
      "x": -16,
      "y": 0,
      "z": 44,
      "name": "Soil_Dirt"
    },
    {
      "x": -16,
      "y": 1,
      "z": 44,
      "name": "Soil_Dirt"
    },
    {
      "x": -16,
      "y": 2,
      "z": 44,
      "name": "Soil_Grass_Full"
    },
    {
      "x": -16,
      "y": 0,
      "z": 45,
      "name": "Soil_Dirt"
    },
    {
      "x": -16,
      "y": 1,
      "z": 45,
      "name": "Soil_Dirt"
    },
    {
      "x": -16,
      "y": 2,
      "z": 45,
      "name": "Soil_Grass_Full"
    },
    {
      "x": -16,
      "y": 0,
      "z": 46,
      "name": "Soil_Dirt"
    },
    {
      "x": -16,
      "y": 1,
      "z": 46,
      "name": "Soil_Dirt"
    },
    {
      "x": -16,
      "y": 2,
      "z": 46,
      "name": "Soil_Grass_Full"
    },
    {
      "x": -16,
      "y": 0,
      "z": 47,
      "name": "Soil_Dirt"
    },
    {
      "x": -16,
      "y": 1,
      "z": 47,
      "name": "Soil_Dirt"
    },
    {
      "x": -16,
      "y": 2,
      "z": 47,
      "name": "Soil_Grass_Full"
    },
    {
      "x": -16,
      "y": 0,
      "z": 48,
      "name": "Soil_Dirt"
    },
    {
      "x": -16,
      "y": 1,
      "z": 48,
      "name": "Soil_Dirt"
    },
    {
      "x": -16,
      "y": 2,
      "z": 48,
      "name": "Soil_Grass_Full"
    },
    {
      "x": -16,
      "y": 0,
      "z": 49,
      "name": "Soil_Dirt"
    },
    {
      "x": -16,
      "y": 1,
      "z": 49,
      "name": "Soil_Dirt"
    },
    {
      "x": -16,
      "y": 2,
      "z": 49,
      "name": "Soil_Grass_Full"
    },
    {
      "x": -16,
      "y": 0,
      "z": 50,
      "name": "Soil_Dirt"
    },
    {
      "x": -16,
      "y": 1,
      "z": 50,
      "name": "Soil_Dirt"
    },
    {
      "x": -16,
      "y": 2,
      "z": 50,
      "name": "Soil_Grass_Full"
    },
    {
      "x": -16,
      "y": 0,
      "z": 51,
      "name": "Soil_Dirt"
    },
    {
      "x": -16,
      "y": 1,
      "z": 51,
      "name": "Soil_Dirt"
    },
    {
      "x": -16,
      "y": 2,
      "z": 51,
      "name": "Soil_Grass_Full"
    },
    {
      "x": -16,
      "y": 3,
      "z": 51,
      "name": "Plant_Grass_Lush_Short"
    },
    {
      "x": -16,
      "y": 0,
      "z": 52,
      "name": "Soil_Dirt"
    },
    {
      "x": -16,
      "y": 1,
      "z": 52,
      "name": "Soil_Dirt"
    },
    {
      "x": -16,
      "y": 2,
      "z": 52,
      "name": "Soil_Grass_Full"
    },
    {
      "x": -16,
      "y": 3,
      "z": 52,
      "name": "Plant_Grass_Sharp_Short"
    },
    {
      "x": -16,
      "y": 0,
      "z": 53,
      "name": "Soil_Dirt"
    },
    {
      "x": -16,
      "y": 1,
      "z": 53,
      "name": "Soil_Grass_Full"
    },
    {
      "x": -16,
      "y": 2,
      "z": 53,
      "name": "Plant_Grass_Lush_Short"
    },
    {
      "x": -16,
      "y": 0,
      "z": 54,
      "name": "Soil_Dirt"
    },
    {
      "x": -16,
      "y": 1,
      "z": 54,
      "name": "Soil_Grass_Full"
    },
    {
      "x": -16,
      "y": 2,
      "z": 54,
      "name": "Plant_Grass_Sharp"
    },
    {
      "x": -16,
      "y": 0,
      "z": 55,
      "name": "Soil_Dirt"
    },
    {
      "x": -16,
      "y": 1,
      "z": 55,
      "name": "Soil_Grass_Full"
    },
    {
      "x": -16,
      "y": 2,
      "z": 55,
      "name": "Plant_Grass_Sharp"
    },
    {
      "x": -16,
      "y": 0,
      "z": 56,
      "name": "Soil_Dirt"
    },
    {
      "x": -16,
      "y": 1,
      "z": 56,
      "name": "Soil_Grass_Full"
    },
    {
      "x": -16,
      "y": 0,
      "z": 57,
      "name": "Soil_Dirt"
    },
    {
      "x": -16,
      "y": 1,
      "z": 57,
      "name": "Soil_Grass_Full"
    },
    {
      "x": -16,
      "y": 2,
      "z": 57,
      "name": "Plant_Grass_Sharp"
    },
    {
      "x": -16,
      "y": 0,
      "z": 58,
      "name": "Soil_Dirt"
    },
    {
      "x": -16,
      "y": 1,
      "z": 58,
      "name": "Soil_Grass_Full"
    },
    {
      "x": -16,
      "y": 2,
      "z": 58,
      "name": "Plant_Grass_Lush_Short"
    },
    {
      "x": -16,
      "y": 0,
      "z": 59,
      "name": "Soil_Dirt"
    },
    {
      "x": -16,
      "y": 1,
      "z": 59,
      "name": "Soil_Grass_Full"
    },
    {
      "x": -16,
      "y": 2,
      "z": 59,
      "name": "Plant_Grass_Sharp_Short"
    },
    {
      "x": -16,
      "y": 0,
      "z": 60,
      "name": "Soil_Dirt"
    },
    {
      "x": -16,
      "y": 1,
      "z": 60,
      "name": "Soil_Grass_Full"
    },
    {
      "x": -16,
      "y": 2,
      "z": 60,
      "name": "Plant_Grass_Lush_Short"
    },
    {
      "x": -16,
      "y": 0,
      "z": 61,
      "name": "Soil_Dirt"
    },
    {
      "x": -16,
      "y": 1,
      "z": 61,
      "name": "Soil_Grass_Full"
    },
    {
      "x": -16,
      "y": 0,
      "z": 62,
      "name": "Soil_Dirt"
    },
    {
      "x": -16,
      "y": 1,
      "z": 62,
      "name": "Soil_Grass_Full"
    },
    {
      "x": -16,
      "y": 0,
      "z": 63,
      "name": "Soil_Grass_Full"
    },
    {
      "x": -16,
      "y": 0,
      "z": 64,
      "name": "Soil_Grass_Full"
    },
    {
      "x": -16,
      "y": 0,
      "z": 65,
      "name": "Soil_Grass_Full"
    },
    {
      "x": -16,
      "y": 0,
      "z": 66,
      "name": "Soil_Grass_Full"
    },
    {
      "x": -15,
      "y": 0,
      "z": -65,
      "name": "Soil_Dirt"
    },
    {
      "x": -15,
      "y": 1,
      "z": -65,
      "name": "Soil_Grass_Full"
    },
    {
      "x": -15,
      "y": 0,
      "z": -64,
      "name": "Soil_Dirt"
    },
    {
      "x": -15,
      "y": 1,
      "z": -64,
      "name": "Soil_Grass_Full"
    },
    {
      "x": -15,
      "y": 0,
      "z": -63,
      "name": "Soil_Dirt"
    },
    {
      "x": -15,
      "y": 1,
      "z": -63,
      "name": "Soil_Grass_Full"
    },
    {
      "x": -15,
      "y": 0,
      "z": -62,
      "name": "Soil_Dirt"
    },
    {
      "x": -15,
      "y": 1,
      "z": -62,
      "name": "Soil_Grass_Full"
    },
    {
      "x": -15,
      "y": 0,
      "z": -61,
      "name": "Soil_Dirt"
    },
    {
      "x": -15,
      "y": 1,
      "z": -61,
      "name": "Soil_Grass_Full"
    },
    {
      "x": -15,
      "y": 0,
      "z": -60,
      "name": "Soil_Dirt"
    },
    {
      "x": -15,
      "y": 1,
      "z": -60,
      "name": "Soil_Dirt"
    },
    {
      "x": -15,
      "y": 2,
      "z": -60,
      "name": "Soil_Grass_Full"
    },
    {
      "x": -15,
      "y": 0,
      "z": -59,
      "name": "Soil_Dirt"
    },
    {
      "x": -15,
      "y": 1,
      "z": -59,
      "name": "Soil_Grass_Full"
    },
    {
      "x": -15,
      "y": 0,
      "z": -58,
      "name": "Soil_Dirt"
    },
    {
      "x": -15,
      "y": 1,
      "z": -58,
      "name": "Soil_Dirt"
    },
    {
      "x": -15,
      "y": 2,
      "z": -58,
      "name": "Soil_Grass_Full"
    },
    {
      "x": -15,
      "y": 0,
      "z": -57,
      "name": "Soil_Dirt"
    },
    {
      "x": -15,
      "y": 1,
      "z": -57,
      "name": "Soil_Dirt"
    },
    {
      "x": -15,
      "y": 2,
      "z": -57,
      "name": "Soil_Grass_Full"
    },
    {
      "x": -15,
      "y": 0,
      "z": -56,
      "name": "Soil_Dirt"
    },
    {
      "x": -15,
      "y": 1,
      "z": -56,
      "name": "Soil_Dirt"
    },
    {
      "x": -15,
      "y": 2,
      "z": -56,
      "name": "Soil_Grass_Full"
    },
    {
      "x": -15,
      "y": 0,
      "z": -55,
      "name": "Soil_Dirt"
    },
    {
      "x": -15,
      "y": 1,
      "z": -55,
      "name": "Soil_Dirt"
    },
    {
      "x": -15,
      "y": 2,
      "z": -55,
      "name": "Soil_Grass_Full"
    },
    {
      "x": -15,
      "y": 0,
      "z": -54,
      "name": "Soil_Dirt"
    },
    {
      "x": -15,
      "y": 1,
      "z": -54,
      "name": "Soil_Dirt"
    },
    {
      "x": -15,
      "y": 2,
      "z": -54,
      "name": "Soil_Grass_Full"
    },
    {
      "x": -15,
      "y": 0,
      "z": -53,
      "name": "Soil_Dirt"
    },
    {
      "x": -15,
      "y": 1,
      "z": -53,
      "name": "Soil_Dirt"
    },
    {
      "x": -15,
      "y": 2,
      "z": -53,
      "name": "Soil_Grass_Full"
    },
    {
      "x": -15,
      "y": 0,
      "z": -52,
      "name": "Soil_Dirt"
    },
    {
      "x": -15,
      "y": 1,
      "z": -52,
      "name": "Soil_Dirt"
    },
    {
      "x": -15,
      "y": 2,
      "z": -52,
      "name": "Soil_Grass_Full"
    },
    {
      "x": -15,
      "y": 3,
      "z": -52,
      "name": "Plant_Bush"
    },
    {
      "x": -15,
      "y": 0,
      "z": -51,
      "name": "Soil_Dirt"
    },
    {
      "x": -15,
      "y": 1,
      "z": -51,
      "name": "Soil_Grass_Full"
    },
    {
      "x": -15,
      "y": 2,
      "z": -51,
      "name": "Plant_Bush"
    },
    {
      "x": -15,
      "y": 0,
      "z": -50,
      "name": "Soil_Dirt"
    },
    {
      "x": -15,
      "y": 1,
      "z": -50,
      "name": "Soil_Grass_Full"
    },
    {
      "x": -15,
      "y": 0,
      "z": -49,
      "name": "Soil_Dirt"
    },
    {
      "x": -15,
      "y": 1,
      "z": -49,
      "name": "Soil_Grass_Full"
    },
    {
      "x": -15,
      "y": 0,
      "z": -48,
      "name": "Soil_Dirt"
    },
    {
      "x": -15,
      "y": 1,
      "z": -48,
      "name": "Soil_Grass_Full"
    },
    {
      "x": -15,
      "y": 0,
      "z": -47,
      "name": "Soil_Dirt"
    },
    {
      "x": -15,
      "y": 1,
      "z": -47,
      "name": "Soil_Grass_Full"
    },
    {
      "x": -15,
      "y": 0,
      "z": -46,
      "name": "Soil_Dirt"
    },
    {
      "x": -15,
      "y": 1,
      "z": -46,
      "name": "Soil_Grass_Full"
    },
    {
      "x": -15,
      "y": 0,
      "z": -45,
      "name": "Soil_Dirt"
    },
    {
      "x": -15,
      "y": 1,
      "z": -45,
      "name": "Soil_Grass_Full"
    },
    {
      "x": -15,
      "y": 0,
      "z": -44,
      "name": "Soil_Dirt"
    },
    {
      "x": -15,
      "y": 1,
      "z": -44,
      "name": "Soil_Grass_Full"
    },
    {
      "x": -15,
      "y": 0,
      "z": -43,
      "name": "Soil_Dirt"
    },
    {
      "x": -15,
      "y": 1,
      "z": -43,
      "name": "Soil_Grass_Full"
    },
    {
      "x": -15,
      "y": 2,
      "z": -43,
      "name": "Plant_Grass_Sharp"
    },
    {
      "x": -15,
      "y": 0,
      "z": -42,
      "name": "Soil_Dirt"
    },
    {
      "x": -15,
      "y": 1,
      "z": -42,
      "name": "Soil_Grass_Full"
    },
    {
      "x": -15,
      "y": 2,
      "z": -42,
      "name": "Plant_Grass_Sharp"
    },
    {
      "x": -15,
      "y": 0,
      "z": -41,
      "name": "Soil_Dirt"
    },
    {
      "x": -15,
      "y": 1,
      "z": -41,
      "name": "Soil_Grass_Full"
    },
    {
      "x": -15,
      "y": 2,
      "z": -41,
      "name": "Plant_Grass_Sharp"
    },
    {
      "x": -15,
      "y": 0,
      "z": -40,
      "name": "Soil_Dirt"
    },
    {
      "x": -15,
      "y": 1,
      "z": -40,
      "name": "Soil_Grass_Full"
    },
    {
      "x": -15,
      "y": 2,
      "z": -40,
      "name": "Plant_Grass_Sharp"
    },
    {
      "x": -15,
      "y": 0,
      "z": -39,
      "name": "Soil_Dirt"
    },
    {
      "x": -15,
      "y": 1,
      "z": -39,
      "name": "Soil_Grass_Full"
    },
    {
      "x": -15,
      "y": 2,
      "z": -39,
      "name": "Plant_Grass_Sharp"
    },
    {
      "x": -15,
      "y": 0,
      "z": -38,
      "name": "Soil_Dirt"
    },
    {
      "x": -15,
      "y": 1,
      "z": -38,
      "name": "Soil_Grass_Full"
    },
    {
      "x": -15,
      "y": 2,
      "z": -38,
      "name": "Plant_Grass_Sharp_Tall"
    },
    {
      "x": -15,
      "y": 0,
      "z": -37,
      "name": "Soil_Dirt"
    },
    {
      "x": -15,
      "y": 1,
      "z": -37,
      "name": "Soil_Grass_Full"
    },
    {
      "x": -15,
      "y": 0,
      "z": -36,
      "name": "Soil_Dirt"
    },
    {
      "x": -15,
      "y": 1,
      "z": -36,
      "name": "Soil_Grass_Full"
    },
    {
      "x": -15,
      "y": 0,
      "z": -35,
      "name": "Rock_Stone",
      "rotation": 3
    },
    {
      "x": -15,
      "y": 1,
      "z": -35,
      "name": "Rock_Stone",
      "rotation": 3
    },
    {
      "x": -15,
      "y": 2,
      "z": -35,
      "name": "Plant_Bush",
      "components": {
        "Components": {
          "FarmingBlock": {
            "SpreadRate": 0.0
          }
        }
      },
      "rotation": 3
    },
    {
      "x": -15,
      "y": 0,
      "z": -34,
      "name": "Rock_Stone",
      "rotation": 3
    },
    {
      "x": -15,
      "y": 1,
      "z": -34,
      "name": "Rock_Stone",
      "rotation": 3
    },
    {
      "x": -15,
      "y": 2,
      "z": -34,
      "name": "Rock_Stone",
      "rotation": 3
    },
    {
      "x": -15,
      "y": 3,
      "z": -34,
      "name": "Rubble_Stone",
      "rotation": 3
    },
    {
      "x": -15,
      "y": 0,
      "z": -33,
      "name": "Rock_Stone",
      "rotation": 3
    },
    {
      "x": -15,
      "y": 1,
      "z": -33,
      "name": "Rock_Stone",
      "rotation": 3
    },
    {
      "x": -15,
      "y": 2,
      "z": -33,
      "name": "Rock_Stone",
      "rotation": 3
    },
    {
      "x": -15,
      "y": 3,
      "z": -33,
      "name": "Plant_Bush",
      "components": {
        "Components": {
          "FarmingBlock": {
            "SpreadRate": 0.0
          }
        }
      },
      "rotation": 3
    },
    {
      "x": -15,
      "y": 0,
      "z": -32,
      "name": "Rock_Stone",
      "rotation": 3
    },
    {
      "x": -15,
      "y": 1,
      "z": -32,
      "name": "Rock_Stone",
      "rotation": 3
    },
    {
      "x": -15,
      "y": 0,
      "z": -31,
      "name": "Soil_Grass_Full"
    },
    {
      "x": -15,
      "y": 0,
      "z": -30,
      "name": "Soil_Grass_Full"
    },
    {
      "x": -15,
      "y": 1,
      "z": -30,
      "name": "Plant_Bush",
      "components": {
        "Components": {
          "FarmingBlock": {
            "SpreadRate": 0.0
          }
        }
      },
      "rotation": 3
    },
    {
      "x": -15,
      "y": 0,
      "z": -29,
      "name": "Soil_Grass_Full"
    },
    {
      "x": -15,
      "y": 0,
      "z": -28,
      "name": "Soil_Grass_Full"
    },
    {
      "x": -15,
      "y": 0,
      "z": -27,
      "name": "Soil_Grass_Full"
    },
    {
      "x": -15,
      "y": 0,
      "z": -26,
      "name": "Soil_Grass_Full"
    },
    {
      "x": -15,
      "y": 0,
      "z": -25,
      "name": "Soil_Grass_Full"
    },
    {
      "x": -15,
      "y": 0,
      "z": -24,
      "name": "Soil_Grass_Full"
    },
    {
      "x": -15,
      "y": 0,
      "z": -23,
      "name": "Soil_Grass_Full"
    },
    {
      "x": -15,
      "y": 0,
      "z": -22,
      "name": "Soil_Grass_Full"
    },
    {
      "x": -15,
      "y": 0,
      "z": -21,
      "name": "Soil_Grass_Full"
    },
    {
      "x": -15,
      "y": 0,
      "z": -20,
      "name": "Soil_Grass_Full"
    },
    {
      "x": -15,
      "y": 5,
      "z": -20,
      "name": "Plant_Leaves_Birch",
      "rotation": 2
    },
    {
      "x": -15,
      "y": 0,
      "z": -19,
      "name": "Soil_Grass_Full"
    },
    {
      "x": -15,
      "y": 0,
      "z": -18,
      "name": "Soil_Grass_Full"
    },
    {
      "x": -15,
      "y": 0,
      "z": -1,
      "name": "Plant_Grass_Lush_Short"
    },
    {
      "x": -15,
      "y": 0,
      "z": 0,
      "name": "Plant_Bush"
    },
    {
      "x": -15,
      "y": 0,
      "z": 1,
      "name": "*Plant_Crop_Berry_Block_State_Definitions_StageFinal"
    },
    {
      "x": -15,
      "y": 0,
      "z": 6,
      "name": "Plant_Grass_Sharp"
    },
    {
      "x": -15,
      "y": 0,
      "z": 7,
      "name": "Soil_Grass_Full"
    },
    {
      "x": -15,
      "y": 1,
      "z": 7,
      "name": "Plant_Grass_Sharp"
    },
    {
      "x": -15,
      "y": 0,
      "z": 8,
      "name": "Soil_Grass_Full"
    },
    {
      "x": -15,
      "y": 1,
      "z": 8,
      "name": "Plant_Grass_Sharp"
    },
    {
      "x": -15,
      "y": 0,
      "z": 9,
      "name": "Soil_Grass_Full"
    },
    {
      "x": -15,
      "y": 0,
      "z": 10,
      "name": "Soil_Grass_Full"
    },
    {
      "x": -15,
      "y": 1,
      "z": 10,
      "name": "Plant_Grass_Lush_Short"
    },
    {
      "x": -15,
      "y": 0,
      "z": 11,
      "name": "Soil_Grass_Full"
    },
    {
      "x": -15,
      "y": 1,
      "z": 11,
      "name": "Plant_Grass_Sharp_Short"
    },
    {
      "x": -15,
      "y": 0,
      "z": 12,
      "name": "Soil_Grass_Full"
    },
    {
      "x": -15,
      "y": 0,
      "z": 13,
      "name": "Soil_Grass_Full"
    },
    {
      "x": -15,
      "y": 1,
      "z": 13,
      "name": "Plant_Grass_Sharp"
    },
    {
      "x": -15,
      "y": 0,
      "z": 14,
      "name": "Soil_Grass_Full"
    },
    {
      "x": -15,
      "y": 0,
      "z": 15,
      "name": "Soil_Dirt"
    },
    {
      "x": -15,
      "y": 1,
      "z": 15,
      "name": "Soil_Grass_Full"
    },
    {
      "x": -15,
      "y": 0,
      "z": 16,
      "name": "Soil_Dirt"
    },
    {
      "x": -15,
      "y": 1,
      "z": 16,
      "name": "Soil_Grass_Full"
    },
    {
      "x": -15,
      "y": 0,
      "z": 17,
      "name": "Soil_Dirt"
    },
    {
      "x": -15,
      "y": 1,
      "z": 17,
      "name": "Soil_Grass_Full"
    },
    {
      "x": -15,
      "y": 0,
      "z": 18,
      "name": "Soil_Dirt"
    },
    {
      "x": -15,
      "y": 1,
      "z": 18,
      "name": "Soil_Grass_Full"
    },
    {
      "x": -15,
      "y": 0,
      "z": 19,
      "name": "Soil_Dirt"
    },
    {
      "x": -15,
      "y": 1,
      "z": 19,
      "name": "Soil_Grass_Full"
    },
    {
      "x": -15,
      "y": 0,
      "z": 20,
      "name": "Soil_Dirt"
    },
    {
      "x": -15,
      "y": 1,
      "z": 20,
      "name": "Soil_Grass_Full"
    },
    {
      "x": -15,
      "y": 2,
      "z": 20,
      "name": "Plant_Grass_Sharp_Short"
    },
    {
      "x": -15,
      "y": 0,
      "z": 21,
      "name": "Soil_Dirt"
    },
    {
      "x": -15,
      "y": 1,
      "z": 21,
      "name": "Soil_Grass_Full"
    },
    {
      "x": -15,
      "y": 2,
      "z": 21,
      "name": "Plant_Grass_Sharp_Short"
    },
    {
      "x": -15,
      "y": 0,
      "z": 22,
      "name": "Soil_Dirt"
    },
    {
      "x": -15,
      "y": 1,
      "z": 22,
      "name": "Soil_Grass_Full"
    },
    {
      "x": -15,
      "y": 2,
      "z": 22,
      "name": "Plant_Grass_Lush_Short"
    },
    {
      "x": -15,
      "y": 0,
      "z": 23,
      "name": "Soil_Dirt"
    },
    {
      "x": -15,
      "y": 1,
      "z": 23,
      "name": "Soil_Grass_Full"
    },
    {
      "x": -15,
      "y": 2,
      "z": 23,
      "name": "Plant_Grass_Lush_Short"
    },
    {
      "x": -15,
      "y": 0,
      "z": 24,
      "name": "Soil_Dirt"
    },
    {
      "x": -15,
      "y": 1,
      "z": 24,
      "name": "Soil_Grass_Full"
    },
    {
      "x": -15,
      "y": 2,
      "z": 24,
      "name": "Plant_Grass_Lush_Short"
    },
    {
      "x": -15,
      "y": 0,
      "z": 25,
      "name": "Soil_Dirt"
    },
    {
      "x": -15,
      "y": 1,
      "z": 25,
      "name": "Soil_Grass_Full"
    },
    {
      "x": -15,
      "y": 0,
      "z": 26,
      "name": "Soil_Dirt"
    },
    {
      "x": -15,
      "y": 1,
      "z": 26,
      "name": "Soil_Grass_Full"
    },
    {
      "x": -15,
      "y": 2,
      "z": 26,
      "name": "Plant_Grass_Lush_Short"
    },
    {
      "x": -15,
      "y": 0,
      "z": 27,
      "name": "Soil_Dirt"
    },
    {
      "x": -15,
      "y": 1,
      "z": 27,
      "name": "Soil_Grass_Full"
    },
    {
      "x": -15,
      "y": 0,
      "z": 28,
      "name": "Soil_Dirt"
    },
    {
      "x": -15,
      "y": 1,
      "z": 28,
      "name": "Soil_Dirt"
    },
    {
      "x": -15,
      "y": 2,
      "z": 28,
      "name": "Soil_Grass_Full"
    },
    {
      "x": -15,
      "y": 0,
      "z": 29,
      "name": "Soil_Dirt"
    },
    {
      "x": -15,
      "y": 1,
      "z": 29,
      "name": "Soil_Dirt"
    },
    {
      "x": -15,
      "y": 2,
      "z": 29,
      "name": "Soil_Grass_Full"
    },
    {
      "x": -15,
      "y": 0,
      "z": 30,
      "name": "Soil_Dirt"
    },
    {
      "x": -15,
      "y": 1,
      "z": 30,
      "name": "Soil_Dirt"
    },
    {
      "x": -15,
      "y": 2,
      "z": 30,
      "name": "Soil_Grass_Full"
    },
    {
      "x": -15,
      "y": 0,
      "z": 31,
      "name": "Soil_Dirt"
    },
    {
      "x": -15,
      "y": 1,
      "z": 31,
      "name": "Soil_Dirt"
    },
    {
      "x": -15,
      "y": 2,
      "z": 31,
      "name": "Soil_Grass_Full"
    },
    {
      "x": -15,
      "y": 3,
      "z": 31,
      "name": "Plant_Grass_Sharp"
    },
    {
      "x": -15,
      "y": 0,
      "z": 32,
      "name": "Soil_Dirt"
    },
    {
      "x": -15,
      "y": 1,
      "z": 32,
      "name": "Soil_Dirt"
    },
    {
      "x": -15,
      "y": 2,
      "z": 32,
      "name": "Soil_Grass_Full"
    },
    {
      "x": -15,
      "y": 3,
      "z": 32,
      "name": "Plant_Grass_Sharp_Tall"
    },
    {
      "x": -15,
      "y": 0,
      "z": 33,
      "name": "Soil_Dirt"
    },
    {
      "x": -15,
      "y": 1,
      "z": 33,
      "name": "Soil_Dirt"
    },
    {
      "x": -15,
      "y": 2,
      "z": 33,
      "name": "Soil_Grass_Full"
    },
    {
      "x": -15,
      "y": 3,
      "z": 33,
      "name": "Plant_Grass_Sharp"
    },
    {
      "x": -15,
      "y": 0,
      "z": 34,
      "name": "Soil_Dirt"
    },
    {
      "x": -15,
      "y": 1,
      "z": 34,
      "name": "Soil_Dirt"
    },
    {
      "x": -15,
      "y": 2,
      "z": 34,
      "name": "Soil_Grass_Full"
    },
    {
      "x": -15,
      "y": 0,
      "z": 35,
      "name": "Soil_Dirt"
    },
    {
      "x": -15,
      "y": 1,
      "z": 35,
      "name": "Soil_Dirt"
    },
    {
      "x": -15,
      "y": 2,
      "z": 35,
      "name": "Soil_Grass_Full"
    },
    {
      "x": -15,
      "y": 0,
      "z": 36,
      "name": "Soil_Dirt"
    },
    {
      "x": -15,
      "y": 1,
      "z": 36,
      "name": "Soil_Dirt"
    },
    {
      "x": -15,
      "y": 2,
      "z": 36,
      "name": "Soil_Grass_Full"
    },
    {
      "x": -15,
      "y": 0,
      "z": 37,
      "name": "Soil_Dirt"
    },
    {
      "x": -15,
      "y": 1,
      "z": 37,
      "name": "Soil_Dirt"
    },
    {
      "x": -15,
      "y": 2,
      "z": 37,
      "name": "Soil_Grass_Full"
    },
    {
      "x": -15,
      "y": 0,
      "z": 38,
      "name": "Soil_Dirt"
    },
    {
      "x": -15,
      "y": 1,
      "z": 38,
      "name": "Soil_Dirt"
    },
    {
      "x": -15,
      "y": 2,
      "z": 38,
      "name": "Soil_Grass_Full"
    },
    {
      "x": -15,
      "y": 0,
      "z": 39,
      "name": "Soil_Dirt"
    },
    {
      "x": -15,
      "y": 1,
      "z": 39,
      "name": "Soil_Dirt"
    },
    {
      "x": -15,
      "y": 2,
      "z": 39,
      "name": "Soil_Grass_Full"
    },
    {
      "x": -15,
      "y": 0,
      "z": 40,
      "name": "Soil_Dirt"
    },
    {
      "x": -15,
      "y": 1,
      "z": 40,
      "name": "Soil_Dirt"
    },
    {
      "x": -15,
      "y": 2,
      "z": 40,
      "name": "Soil_Grass_Full"
    },
    {
      "x": -15,
      "y": 3,
      "z": 40,
      "name": "Plant_Grass_Sharp"
    },
    {
      "x": -15,
      "y": 0,
      "z": 41,
      "name": "Soil_Dirt"
    },
    {
      "x": -15,
      "y": 1,
      "z": 41,
      "name": "Soil_Dirt"
    },
    {
      "x": -15,
      "y": 2,
      "z": 41,
      "name": "Soil_Grass_Full"
    },
    {
      "x": -15,
      "y": 3,
      "z": 41,
      "name": "Plant_Grass_Sharp"
    },
    {
      "x": -15,
      "y": 0,
      "z": 42,
      "name": "Soil_Dirt"
    },
    {
      "x": -15,
      "y": 1,
      "z": 42,
      "name": "Soil_Dirt"
    },
    {
      "x": -15,
      "y": 2,
      "z": 42,
      "name": "Soil_Grass_Full"
    },
    {
      "x": -15,
      "y": 3,
      "z": 42,
      "name": "Plant_Bush"
    },
    {
      "x": -15,
      "y": 0,
      "z": 43,
      "name": "Soil_Dirt"
    },
    {
      "x": -15,
      "y": 1,
      "z": 43,
      "name": "Soil_Dirt"
    },
    {
      "x": -15,
      "y": 2,
      "z": 43,
      "name": "Soil_Grass_Full"
    },
    {
      "x": -15,
      "y": 3,
      "z": 43,
      "name": "Plant_Bush"
    },
    {
      "x": -15,
      "y": 0,
      "z": 44,
      "name": "Soil_Dirt"
    },
    {
      "x": -15,
      "y": 1,
      "z": 44,
      "name": "Soil_Dirt"
    },
    {
      "x": -15,
      "y": 2,
      "z": 44,
      "name": "Soil_Grass_Full"
    },
    {
      "x": -15,
      "y": 3,
      "z": 44,
      "name": "Plant_Grass_Lush_Short"
    },
    {
      "x": -15,
      "y": 0,
      "z": 45,
      "name": "Soil_Dirt"
    },
    {
      "x": -15,
      "y": 1,
      "z": 45,
      "name": "Soil_Dirt"
    },
    {
      "x": -15,
      "y": 2,
      "z": 45,
      "name": "Soil_Grass_Full"
    },
    {
      "x": -15,
      "y": 0,
      "z": 46,
      "name": "Soil_Dirt"
    },
    {
      "x": -15,
      "y": 1,
      "z": 46,
      "name": "Soil_Dirt"
    },
    {
      "x": -15,
      "y": 2,
      "z": 46,
      "name": "Soil_Grass_Full"
    },
    {
      "x": -15,
      "y": 0,
      "z": 47,
      "name": "Soil_Dirt"
    },
    {
      "x": -15,
      "y": 1,
      "z": 47,
      "name": "Soil_Dirt"
    },
    {
      "x": -15,
      "y": 2,
      "z": 47,
      "name": "Soil_Grass_Full"
    },
    {
      "x": -15,
      "y": 0,
      "z": 48,
      "name": "Soil_Dirt"
    },
    {
      "x": -15,
      "y": 1,
      "z": 48,
      "name": "Soil_Dirt"
    },
    {
      "x": -15,
      "y": 2,
      "z": 48,
      "name": "Soil_Grass_Full"
    },
    {
      "x": -15,
      "y": 0,
      "z": 49,
      "name": "Soil_Dirt"
    },
    {
      "x": -15,
      "y": 1,
      "z": 49,
      "name": "Soil_Dirt"
    },
    {
      "x": -15,
      "y": 2,
      "z": 49,
      "name": "Soil_Grass_Full"
    },
    {
      "x": -15,
      "y": 0,
      "z": 50,
      "name": "Soil_Dirt"
    },
    {
      "x": -15,
      "y": 1,
      "z": 50,
      "name": "Soil_Dirt"
    },
    {
      "x": -15,
      "y": 2,
      "z": 50,
      "name": "Soil_Grass_Full"
    },
    {
      "x": -15,
      "y": 0,
      "z": 51,
      "name": "Soil_Dirt"
    },
    {
      "x": -15,
      "y": 1,
      "z": 51,
      "name": "Soil_Dirt"
    },
    {
      "x": -15,
      "y": 2,
      "z": 51,
      "name": "Soil_Grass_Full"
    },
    {
      "x": -15,
      "y": 0,
      "z": 52,
      "name": "Soil_Dirt"
    },
    {
      "x": -15,
      "y": 1,
      "z": 52,
      "name": "Soil_Dirt"
    },
    {
      "x": -15,
      "y": 2,
      "z": 52,
      "name": "Soil_Grass_Full"
    },
    {
      "x": -15,
      "y": 3,
      "z": 52,
      "name": "Plant_Grass_Sharp_Short"
    },
    {
      "x": -15,
      "y": 0,
      "z": 53,
      "name": "Soil_Dirt"
    },
    {
      "x": -15,
      "y": 1,
      "z": 53,
      "name": "Soil_Grass_Full"
    },
    {
      "x": -15,
      "y": 2,
      "z": 53,
      "name": "Plant_Grass_Sharp"
    },
    {
      "x": -15,
      "y": 0,
      "z": 54,
      "name": "Soil_Dirt"
    },
    {
      "x": -15,
      "y": 1,
      "z": 54,
      "name": "Soil_Grass_Full"
    },
    {
      "x": -15,
      "y": 0,
      "z": 55,
      "name": "Soil_Dirt"
    },
    {
      "x": -15,
      "y": 1,
      "z": 55,
      "name": "Soil_Grass_Full"
    },
    {
      "x": -15,
      "y": 0,
      "z": 56,
      "name": "Soil_Dirt"
    },
    {
      "x": -15,
      "y": 1,
      "z": 56,
      "name": "Soil_Grass_Full"
    },
    {
      "x": -15,
      "y": 2,
      "z": 56,
      "name": "Plant_Grass_Lush_Short"
    },
    {
      "x": -15,
      "y": 0,
      "z": 57,
      "name": "Soil_Dirt"
    },
    {
      "x": -15,
      "y": 1,
      "z": 57,
      "name": "Soil_Grass_Full"
    },
    {
      "x": -15,
      "y": 2,
      "z": 57,
      "name": "Plant_Grass_Sharp"
    },
    {
      "x": -15,
      "y": 0,
      "z": 58,
      "name": "Soil_Dirt"
    },
    {
      "x": -15,
      "y": 1,
      "z": 58,
      "name": "Soil_Grass_Full"
    },
    {
      "x": -15,
      "y": 2,
      "z": 58,
      "name": "Plant_Grass_Lush_Short"
    },
    {
      "x": -15,
      "y": 0,
      "z": 59,
      "name": "Soil_Dirt"
    },
    {
      "x": -15,
      "y": 1,
      "z": 59,
      "name": "Soil_Grass_Full"
    },
    {
      "x": -15,
      "y": 2,
      "z": 59,
      "name": "Plant_Grass_Lush_Short"
    },
    {
      "x": -15,
      "y": 0,
      "z": 60,
      "name": "Soil_Dirt"
    },
    {
      "x": -15,
      "y": 1,
      "z": 60,
      "name": "Soil_Grass_Full"
    },
    {
      "x": -15,
      "y": 2,
      "z": 60,
      "name": "Plant_Grass_Sharp_Short"
    },
    {
      "x": -15,
      "y": 0,
      "z": 61,
      "name": "Soil_Dirt"
    },
    {
      "x": -15,
      "y": 1,
      "z": 61,
      "name": "Soil_Grass_Full"
    },
    {
      "x": -15,
      "y": 0,
      "z": 62,
      "name": "Soil_Gravel"
    },
    {
      "x": -15,
      "y": 0,
      "z": 63,
      "name": "Soil_Gravel"
    },
    {
      "x": -15,
      "y": 0,
      "z": 64,
      "name": "Soil_Gravel"
    },
    {
      "x": -15,
      "y": 0,
      "z": 65,
      "name": "Soil_Gravel"
    },
    {
      "x": -15,
      "y": 0,
      "z": 66,
      "name": "Soil_Grass_Full"
    },
    {
      "x": -14,
      "y": 0,
      "z": -65,
      "name": "Soil_Dirt"
    },
    {
      "x": -14,
      "y": 1,
      "z": -65,
      "name": "Soil_Grass_Full"
    },
    {
      "x": -14,
      "y": 0,
      "z": -64,
      "name": "Soil_Dirt"
    },
    {
      "x": -14,
      "y": 1,
      "z": -64,
      "name": "Soil_Grass_Full"
    },
    {
      "x": -14,
      "y": 0,
      "z": -63,
      "name": "Soil_Dirt"
    },
    {
      "x": -14,
      "y": 1,
      "z": -63,
      "name": "Soil_Dirt"
    },
    {
      "x": -14,
      "y": 2,
      "z": -63,
      "name": "Soil_Grass_Full"
    },
    {
      "x": -14,
      "y": 0,
      "z": -62,
      "name": "Soil_Dirt"
    },
    {
      "x": -14,
      "y": 1,
      "z": -62,
      "name": "Soil_Dirt"
    },
    {
      "x": -14,
      "y": 2,
      "z": -62,
      "name": "Soil_Grass_Full"
    },
    {
      "x": -14,
      "y": 0,
      "z": -61,
      "name": "Soil_Dirt"
    },
    {
      "x": -14,
      "y": 1,
      "z": -61,
      "name": "Soil_Dirt"
    },
    {
      "x": -14,
      "y": 2,
      "z": -61,
      "name": "Soil_Grass_Full"
    },
    {
      "x": -14,
      "y": 0,
      "z": -60,
      "name": "Soil_Dirt"
    },
    {
      "x": -14,
      "y": 1,
      "z": -60,
      "name": "Soil_Dirt"
    },
    {
      "x": -14,
      "y": 2,
      "z": -60,
      "name": "Soil_Grass_Full"
    },
    {
      "x": -14,
      "y": 0,
      "z": -59,
      "name": "Soil_Dirt"
    },
    {
      "x": -14,
      "y": 1,
      "z": -59,
      "name": "Soil_Dirt"
    },
    {
      "x": -14,
      "y": 2,
      "z": -59,
      "name": "Soil_Grass_Full"
    },
    {
      "x": -14,
      "y": 0,
      "z": -58,
      "name": "Soil_Dirt"
    },
    {
      "x": -14,
      "y": 1,
      "z": -58,
      "name": "Soil_Dirt"
    },
    {
      "x": -14,
      "y": 2,
      "z": -58,
      "name": "Soil_Grass_Full"
    },
    {
      "x": -14,
      "y": 0,
      "z": -57,
