{
  "version": 8,
  "blockIdVersion": 11,
  "anchorX": 0,
  "anchorY": 0,
  "anchorZ": 0,
  "blocks": [
    {
      "x": -35,
      "y": 0,
      "z": -7,
      "name": "Rock_Stone"
    },
    {
      "x": -35,
      "y": 1,
      "z": -7,
      "name": "Rock_Stone"
    },
    {
      "x": -35,
      "y": 2,
      "z": -7,
      "name": "Rock_Stone"
    },
    {
      "x": -35,
      "y": 3,
      "z": -7,
      "name": "Rock_Stone"
    },
    {
      "x": -35,
      "y": 4,
      "z": -7,
      "name": "Rock_Stone"
    },
    {
      "x": -35,
      "y": 5,
      "z": -7,
      "name": "Rock_Stone"
    },
    {
      "x": -35,
      "y": 6,
      "z": -7,
      "name": "Rock_Stone"
    },
    {
      "x": -35,
      "y": 7,
      "z": -7,
      "name": "Rock_Stone"
    },
    {
      "x": -35,
      "y": 8,
      "z": -7,
      "name": "Rock_Stone"
    },
    {
      "x": -35,
      "y": 9,
      "z": -7,
      "name": "Rock_Stone"
    },
    {
      "x": -35,
      "y": 10,
      "z": -7,
      "name": "Rock_Stone"
    },
    {
      "x": -35,
      "y": 11,
      "z": -7,
      "name": "Rock_Stone"
    },
    {
      "x": -35,
      "y": 12,
      "z": -7,
      "name": "Soil_Dirt"
    },
    {
      "x": -35,
      "y": 13,
      "z": -7,
      "name": "Soil_Dirt"
    },
    {
      "x": -35,
      "y": 14,
      "z": -7,
      "name": "Soil_Dirt"
    },
    {
      "x": -35,
      "y": 15,
      "z": -7,
      "name": "Soil_Dirt"
    },
    {
      "x": -35,
      "y": 16,
      "z": -7,
      "name": "Rock_Basalt_Brick_Smooth",
      "rotation": 2
    },
    {
      "x": -35,
      "y": 17,
      "z": -7,
      "name": "Empty"
    },
    {
      "x": -35,
      "y": 18,
      "z": -7,
      "name": "Empty"
    },
    {
      "x": -35,
      "y": 19,
      "z": -7,
      "name": "Empty"
    },
    {
      "x": -35,
      "y": 20,
      "z": -7,
      "name": "Empty"
    },
    {
      "x": -35,
      "y": 21,
      "z": -7,
      "name": "Empty"
    },
    {
      "x": -35,
      "y": 22,
      "z": -7,
      "name": "Empty"
    },
    {
      "x": -35,
      "y": 23,
      "z": -7,
      "name": "Empty"
    },
    {
      "x": -35,
      "y": 0,
      "z": -6,
      "name": "Rock_Stone"
    },
    {
      "x": -35,
      "y": 1,
      "z": -6,
      "name": "Rock_Stone"
    },
    {
      "x": -35,
      "y": 2,
      "z": -6,
      "name": "Rock_Stone"
    },
    {
      "x": -35,
      "y": 3,
      "z": -6,
      "name": "Rock_Stone"
    },
    {
      "x": -35,
      "y": 4,
      "z": -6,
      "name": "Rock_Stone"
    },
    {
      "x": -35,
      "y": 5,
      "z": -6,
      "name": "Rock_Stone"
    },
    {
      "x": -35,
      "y": 6,
      "z": -6,
      "name": "Rock_Stone"
    },
    {
      "x": -35,
      "y": 7,
      "z": -6,
      "name": "Rock_Stone"
    },
    {
      "x": -35,
      "y": 8,
      "z": -6,
      "name": "Rock_Stone"
    },
    {
      "x": -35,
      "y": 9,
      "z": -6,
      "name": "Rock_Stone"
    },
    {
      "x": -35,
      "y": 10,
      "z": -6,
      "name": "Rock_Stone"
    },
    {
      "x": -35,
      "y": 11,
      "z": -6,
      "name": "Rock_Stone"
    },
    {
      "x": -35,
      "y": 12,
      "z": -6,
      "name": "Soil_Dirt"
    },
    {
      "x": -35,
      "y": 13,
      "z": -6,
      "name": "Soil_Dirt"
    },
    {
      "x": -35,
      "y": 14,
      "z": -6,
      "name": "Soil_Dirt"
    },
    {
      "x": -35,
      "y": 15,
      "z": -6,
      "name": "Soil_Dirt"
    },
    {
      "x": -35,
      "y": 16,
      "z": -6,
      "name": "Rock_Basalt_Brick_Smooth",
      "rotation": 2
    },
    {
      "x": -35,
      "y": 17,
      "z": -6,
      "name": "Empty"
    },
    {
      "x": -35,
      "y": 18,
      "z": -6,
      "name": "Empty"
    },
    {
      "x": -35,
      "y": 19,
      "z": -6,
      "name": "Empty"
    },
    {
      "x": -35,
      "y": 20,
      "z": -6,
      "name": "Empty"
    },
    {
      "x": -35,
      "y": 21,
      "z": -6,
      "name": "Empty"
    },
    {
      "x": -35,
      "y": 22,
      "z": -6,
      "name": "Empty"
    },
    {
      "x": -35,
      "y": 23,
      "z": -6,
      "name": "Empty"
    },
    {
      "x": -35,
      "y": 0,
      "z": -5,
      "name": "Rock_Stone"
    },
    {
      "x": -35,
      "y": 1,
      "z": -5,
      "name": "Rock_Stone"
    },
    {
      "x": -35,
      "y": 2,
      "z": -5,
      "name": "Rock_Stone"
    },
    {
      "x": -35,
      "y": 3,
      "z": -5,
      "name": "Rock_Stone"
    },
    {
      "x": -35,
      "y": 4,
      "z": -5,
      "name": "Rock_Stone"
    },
    {
      "x": -35,
      "y": 5,
      "z": -5,
      "name": "Rock_Stone"
    },
    {
      "x": -35,
      "y": 6,
      "z": -5,
      "name": "Rock_Stone"
    },
    {
      "x": -35,
      "y": 7,
      "z": -5,
      "name": "Rock_Stone"
    },
    {
      "x": -35,
      "y": 8,
      "z": -5,
      "name": "Rock_Stone"
    },
    {
      "x": -35,
      "y": 9,
      "z": -5,
      "name": "Rock_Stone"
    },
    {
      "x": -35,
      "y": 10,
      "z": -5,
      "name": "Rock_Stone"
    },
    {
      "x": -35,
      "y": 11,
      "z": -5,
      "name": "Rock_Stone"
    },
    {
      "x": -35,
      "y": 12,
      "z": -5,
      "name": "Soil_Dirt"
    },
    {
      "x": -35,
      "y": 13,
      "z": -5,
      "name": "Soil_Dirt"
    },
    {
      "x": -35,
      "y": 14,
      "z": -5,
      "name": "Soil_Dirt"
    },
    {
      "x": -35,
      "y": 15,
      "z": -5,
      "name": "Soil_Dirt"
    },
    {
      "x": -35,
      "y": 16,
      "z": -5,
      "name": "Rock_Basalt_Brick_Smooth",
      "rotation": 2
    },
    {
      "x": -35,
      "y": 17,
      "z": -5,
      "name": "Empty"
    },
    {
      "x": -35,
      "y": 18,
      "z": -5,
      "name": "Empty"
    },
    {
      "x": -35,
      "y": 19,
      "z": -5,
      "name": "Empty"
    },
    {
      "x": -35,
      "y": 20,
      "z": -5,
      "name": "Empty"
    },
    {
      "x": -35,
      "y": 21,
      "z": -5,
      "name": "Empty"
    },
    {
      "x": -35,
      "y": 22,
      "z": -5,
      "name": "Empty"
    },
    {
      "x": -35,
      "y": 23,
      "z": -5,
      "name": "Empty"
    },
    {
      "x": -35,
      "y": 0,
      "z": -4,
      "name": "Rock_Stone"
    },
    {
      "x": -35,
      "y": 1,
      "z": -4,
      "name": "Rock_Stone"
    },
    {
      "x": -35,
      "y": 2,
      "z": -4,
      "name": "Rock_Stone"
    },
    {
      "x": -35,
      "y": 3,
      "z": -4,
      "name": "Rock_Stone"
    },
    {
      "x": -35,
      "y": 4,
      "z": -4,
      "name": "Rock_Stone"
    },
    {
      "x": -35,
      "y": 5,
      "z": -4,
      "name": "Rock_Stone"
    },
    {
      "x": -35,
      "y": 6,
      "z": -4,
      "name": "Rock_Stone"
    },
    {
      "x": -35,
      "y": 7,
      "z": -4,
      "name": "Rock_Stone"
    },
    {
      "x": -35,
      "y": 8,
      "z": -4,
      "name": "Rock_Stone"
    },
    {
      "x": -35,
      "y": 9,
      "z": -4,
      "name": "Rock_Stone"
    },
    {
      "x": -35,
      "y": 10,
      "z": -4,
      "name": "Rock_Stone"
    },
    {
      "x": -35,
      "y": 11,
      "z": -4,
      "name": "Rock_Stone"
    },
    {
      "x": -35,
      "y": 12,
      "z": -4,
      "name": "Soil_Dirt"
    },
    {
      "x": -35,
      "y": 13,
      "z": -4,
      "name": "Soil_Dirt"
    },
    {
      "x": -35,
      "y": 14,
      "z": -4,
      "name": "Soil_Dirt"
    },
    {
      "x": -35,
      "y": 15,
      "z": -4,
      "name": "Soil_Dirt"
    },
    {
      "x": -35,
      "y": 16,
      "z": -4,
      "name": "Rock_Basalt_Brick_Smooth",
      "rotation": 2
    },
    {
      "x": -35,
      "y": 17,
      "z": -4,
      "name": "Empty"
    },
    {
      "x": -35,
      "y": 18,
      "z": -4,
      "name": "Empty"
    },
    {
      "x": -35,
      "y": 19,
      "z": -4,
      "name": "Empty"
    },
    {
      "x": -35,
      "y": 20,
      "z": -4,
      "name": "Empty"
    },
    {
      "x": -35,
      "y": 21,
      "z": -4,
      "name": "Empty"
    },
    {
      "x": -35,
      "y": 22,
      "z": -4,
      "name": "Empty"
    },
    {
      "x": -35,
      "y": 23,
      "z": -4,
      "name": "Empty"
    },
    {
      "x": -35,
      "y": 0,
      "z": -3,
      "name": "Rock_Stone"
    },
    {
      "x": -35,
      "y": 1,
      "z": -3,
      "name": "Rock_Stone"
    },
    {
      "x": -35,
      "y": 2,
      "z": -3,
      "name": "Rock_Stone"
    },
    {
      "x": -35,
      "y": 3,
      "z": -3,
      "name": "Rock_Stone"
    },
    {
      "x": -35,
      "y": 4,
      "z": -3,
      "name": "Rock_Stone"
    },
    {
      "x": -35,
      "y": 5,
      "z": -3,
      "name": "Rock_Stone"
    },
    {
      "x": -35,
      "y": 6,
      "z": -3,
      "name": "Rock_Stone"
    },
    {
      "x": -35,
      "y": 7,
      "z": -3,
      "name": "Rock_Stone"
    },
    {
      "x": -35,
      "y": 8,
      "z": -3,
      "name": "Rock_Stone"
    },
    {
      "x": -35,
      "y": 9,
      "z": -3,
      "name": "Rock_Stone"
    },
    {
      "x": -35,
      "y": 10,
      "z": -3,
      "name": "Rock_Stone"
    },
    {
      "x": -35,
      "y": 11,
      "z": -3,
      "name": "Rock_Stone"
    },
    {
      "x": -35,
      "y": 12,
      "z": -3,
      "name": "Soil_Dirt"
    },
    {
      "x": -35,
      "y": 13,
      "z": -3,
      "name": "Soil_Dirt"
    },
    {
      "x": -35,
      "y": 14,
      "z": -3,
      "name": "Soil_Dirt"
    },
    {
      "x": -35,
      "y": 15,
      "z": -3,
      "name": "Soil_Dirt"
    },
    {
      "x": -35,
      "y": 16,
      "z": -3,
      "name": "Rock_Basalt_Brick_Smooth",
      "rotation": 2
    },
    {
      "x": -35,
      "y": 17,
      "z": -3,
      "name": "Empty"
    },
    {
      "x": -35,
      "y": 18,
      "z": -3,
      "name": "Empty"
    },
    {
      "x": -35,
      "y": 19,
      "z": -3,
      "name": "Empty"
    },
    {
      "x": -35,
      "y": 20,
      "z": -3,
      "name": "Empty"
    },
    {
      "x": -35,
      "y": 21,
      "z": -3,
      "name": "Empty"
    },
    {
      "x": -35,
      "y": 22,
      "z": -3,
      "name": "Empty"
    },
    {
      "x": -35,
      "y": 23,
      "z": -3,
      "name": "Empty"
    },
    {
      "x": -35,
      "y": 0,
      "z": -2,
      "name": "Rock_Stone"
    },
    {
      "x": -35,
      "y": 1,
      "z": -2,
      "name": "Rock_Stone"
    },
    {
      "x": -35,
      "y": 2,
      "z": -2,
      "name": "Rock_Stone"
    },
    {
      "x": -35,
      "y": 3,
      "z": -2,
      "name": "Rock_Stone"
    },
    {
      "x": -35,
      "y": 4,
      "z": -2,
      "name": "Rock_Stone"
    },
    {
      "x": -35,
      "y": 5,
      "z": -2,
      "name": "Rock_Stone"
    },
    {
      "x": -35,
      "y": 6,
      "z": -2,
      "name": "Rock_Stone"
    },
    {
      "x": -35,
      "y": 7,
      "z": -2,
      "name": "Rock_Stone"
    },
    {
      "x": -35,
      "y": 8,
      "z": -2,
      "name": "Rock_Stone"
    },
    {
      "x": -35,
      "y": 9,
      "z": -2,
      "name": "Rock_Stone"
    },
    {
      "x": -35,
      "y": 10,
      "z": -2,
      "name": "Rock_Stone"
    },
    {
      "x": -35,
      "y": 11,
      "z": -2,
      "name": "Rock_Stone"
    },
    {
      "x": -35,
      "y": 12,
      "z": -2,
      "name": "Soil_Dirt"
    },
    {
      "x": -35,
      "y": 13,
      "z": -2,
      "name": "Soil_Dirt"
    },
    {
      "x": -35,
      "y": 14,
      "z": -2,
      "name": "Soil_Dirt"
    },
    {
      "x": -35,
      "y": 15,
      "z": -2,
      "name": "Soil_Dirt"
    },
    {
      "x": -35,
      "y": 16,
      "z": -2,
      "name": "Rock_Basalt_Brick_Smooth",
      "rotation": 2
    },
    {
      "x": -35,
      "y": 17,
      "z": -2,
      "name": "Rock_Basalt_Brick_Smooth",
      "rotation": 2
    },
    {
      "x": -35,
      "y": 18,
      "z": -2,
      "name": "Rock_Basalt_Brick_Smooth",
      "rotation": 2
    },
    {
      "x": -35,
      "y": 19,
      "z": -2,
      "name": "Rock_Basalt_Brick_Smooth",
      "rotation": 2
    },
    {
      "x": -35,
      "y": 20,
      "z": -2,
      "name": "Rock_Basalt_Brick_Smooth",
      "rotation": 2
    },
    {
      "x": -35,
      "y": 21,
      "z": -2,
      "name": "Empty"
    },
    {
      "x": -35,
      "y": 22,
      "z": -2,
      "name": "Empty"
    },
    {
      "x": -35,
      "y": 23,
      "z": -2,
      "name": "Empty"
    },
    {
      "x": -35,
      "y": 0,
      "z": -1,
      "name": "Rock_Stone"
    },
    {
      "x": -35,
      "y": 1,
      "z": -1,
      "name": "Rock_Stone"
    },
    {
      "x": -35,
      "y": 2,
      "z": -1,
      "name": "Rock_Stone"
    },
    {
      "x": -35,
      "y": 3,
      "z": -1,
      "name": "Rock_Stone"
    },
    {
      "x": -35,
      "y": 4,
      "z": -1,
      "name": "Rock_Stone"
    },
    {
      "x": -35,
      "y": 5,
      "z": -1,
      "name": "Rock_Stone"
    },
    {
      "x": -35,
      "y": 6,
      "z": -1,
      "name": "Rock_Stone"
    },
    {
      "x": -35,
      "y": 7,
      "z": -1,
      "name": "Rock_Stone"
    },
    {
      "x": -35,
      "y": 8,
      "z": -1,
      "name": "Rock_Stone"
    },
    {
      "x": -35,
      "y": 9,
      "z": -1,
      "name": "Rock_Stone"
    },
    {
      "x": -35,
      "y": 10,
      "z": -1,
      "name": "Rock_Stone"
    },
    {
      "x": -35,
      "y": 11,
      "z": -1,
      "name": "Rock_Stone"
    },
    {
      "x": -35,
      "y": 12,
      "z": -1,
      "name": "Soil_Dirt"
    },
    {
      "x": -35,
      "y": 13,
      "z": -1,
      "name": "Soil_Dirt"
    },
    {
      "x": -35,
      "y": 14,
      "z": -1,
      "name": "Soil_Dirt"
    },
    {
      "x": -35,
      "y": 15,
      "z": -1,
      "name": "Soil_Dirt"
    },
    {
      "x": -35,
      "y": 16,
      "z": -1,
      "name": "Rock_Basalt_Brick_Smooth",
      "rotation": 2
    },
    {
      "x": -35,
      "y": 17,
      "z": -1,
      "name": "Empty"
    },
    {
      "x": -35,
      "y": 18,
      "z": -1,
      "name": "Empty"
    },
    {
      "x": -35,
      "y": 19,
      "z": -1,
      "name": "Empty"
    },
    {
      "x": -35,
      "y": 20,
      "z": -1,
      "name": "Rock_Basalt_Brick_Smooth",
      "rotation": 2
    },
    {
      "x": -35,
      "y": 21,
      "z": -1,
      "name": "Empty"
    },
    {
      "x": -35,
      "y": 22,
      "z": -1,
      "name": "Empty"
    },
    {
      "x": -35,
      "y": 23,
      "z": -1,
      "name": "Empty"
    },
    {
      "x": -35,
      "y": 0,
      "z": 0,
      "name": "Rock_Stone"
    },
    {
      "x": -35,
      "y": 1,
      "z": 0,
      "name": "Rock_Stone"
    },
    {
      "x": -35,
      "y": 2,
      "z": 0,
      "name": "Rock_Stone"
    },
    {
      "x": -35,
      "y": 3,
      "z": 0,
      "name": "Rock_Stone"
    },
    {
      "x": -35,
      "y": 4,
      "z": 0,
      "name": "Rock_Stone"
    },
    {
      "x": -35,
      "y": 5,
      "z": 0,
      "name": "Rock_Stone"
    },
    {
      "x": -35,
      "y": 6,
      "z": 0,
      "name": "Rock_Stone"
    },
    {
      "x": -35,
      "y": 7,
      "z": 0,
      "name": "Rock_Stone"
    },
    {
      "x": -35,
      "y": 8,
      "z": 0,
      "name": "Rock_Stone"
    },
    {
      "x": -35,
      "y": 9,
      "z": 0,
      "name": "Rock_Stone"
    },
    {
      "x": -35,
      "y": 10,
      "z": 0,
      "name": "Rock_Stone"
    },
    {
      "x": -35,
      "y": 11,
      "z": 0,
      "name": "Rock_Stone"
    },
    {
      "x": -35,
      "y": 12,
      "z": 0,
      "name": "Soil_Dirt"
    },
    {
      "x": -35,
      "y": 13,
      "z": 0,
      "name": "Soil_Dirt"
    },
    {
      "x": -35,
      "y": 14,
      "z": 0,
      "name": "Soil_Dirt"
    },
    {
      "x": -35,
      "y": 15,
      "z": 0,
      "name": "Soil_Dirt"
    },
    {
      "x": -35,
      "y": 16,
      "z": 0,
      "name": "Rock_Basalt_Brick_Smooth",
      "rotation": 2
    },
    {
      "x": -35,
      "y": 17,
      "z": 0,
      "name": "Empty"
    },
    {
      "x": -35,
      "y": 18,
      "z": 0,
      "name": "Empty"
    },
    {
      "x": -35,
      "y": 19,
      "z": 0,
      "name": "Empty"
    },
    {
      "x": -35,
      "y": 20,
      "z": 0,
      "name": "Rock_Basalt_Brick_Smooth",
      "rotation": 2
    },
    {
      "x": -35,
      "y": 21,
      "z": 0,
      "name": "Empty"
    },
    {
      "x": -35,
      "y": 22,
      "z": 0,
      "name": "Empty"
    },
    {
      "x": -35,
      "y": 23,
      "z": 0,
      "name": "Empty"
    },
    {
      "x": -35,
      "y": 0,
      "z": 1,
      "name": "Rock_Stone"
    },
    {
      "x": -35,
      "y": 1,
      "z": 1,
      "name": "Rock_Stone"
    },
    {
      "x": -35,
      "y": 2,
      "z": 1,
      "name": "Rock_Stone"
    },
    {
      "x": -35,
      "y": 3,
      "z": 1,
      "name": "Rock_Stone"
    },
    {
      "x": -35,
      "y": 4,
      "z": 1,
      "name": "Rock_Stone"
    },
    {
      "x": -35,
      "y": 5,
      "z": 1,
      "name": "Rock_Stone"
    },
    {
      "x": -35,
      "y": 6,
      "z": 1,
      "name": "Rock_Stone"
    },
    {
      "x": -35,
      "y": 7,
      "z": 1,
      "name": "Rock_Stone"
    },
    {
      "x": -35,
      "y": 8,
      "z": 1,
      "name": "Rock_Stone"
    },
    {
      "x": -35,
      "y": 9,
      "z": 1,
      "name": "Rock_Stone"
    },
    {
      "x": -35,
      "y": 10,
      "z": 1,
      "name": "Rock_Stone"
    },
    {
      "x": -35,
      "y": 11,
      "z": 1,
      "name": "Rock_Stone"
    },
    {
      "x": -35,
      "y": 12,
      "z": 1,
      "name": "Soil_Dirt"
    },
    {
      "x": -35,
      "y": 13,
      "z": 1,
      "name": "Soil_Dirt"
    },
    {
      "x": -35,
      "y": 14,
      "z": 1,
      "name": "Soil_Dirt"
    },
    {
      "x": -35,
      "y": 15,
      "z": 1,
      "name": "Soil_Dirt"
    },
    {
      "x": -35,
      "y": 16,
      "z": 1,
      "name": "Rock_Basalt_Brick_Smooth",
      "rotation": 2
    },
    {
      "x": -35,
      "y": 17,
      "z": 1,
      "name": "Empty"
    },
    {
      "x": -35,
      "y": 18,
      "z": 1,
      "name": "Empty"
    },
    {
      "x": -35,
      "y": 19,
      "z": 1,
      "name": "Empty"
    },
    {
      "x": -35,
      "y": 20,
      "z": 1,
      "name": "Rock_Basalt_Brick_Smooth",
      "rotation": 2
    },
    {
      "x": -35,
      "y": 21,
      "z": 1,
      "name": "Empty"
    },
    {
      "x": -35,
      "y": 22,
      "z": 1,
      "name": "Empty"
    },
    {
      "x": -35,
      "y": 23,
      "z": 1,
      "name": "Empty"
    },
    {
      "x": -35,
      "y": 0,
      "z": 2,
      "name": "Rock_Stone"
    },
    {
      "x": -35,
      "y": 1,
      "z": 2,
      "name": "Rock_Stone"
    },
    {
      "x": -35,
      "y": 2,
      "z": 2,
      "name": "Rock_Stone"
    },
    {
      "x": -35,
      "y": 3,
      "z": 2,
      "name": "Rock_Stone"
    },
    {
      "x": -35,
      "y": 4,
      "z": 2,
      "name": "Rock_Stone"
    },
    {
      "x": -35,
      "y": 5,
      "z": 2,
      "name": "Rock_Stone"
    },
    {
      "x": -35,
      "y": 6,
      "z": 2,
      "name": "Rock_Stone"
    },
    {
      "x": -35,
      "y": 7,
      "z": 2,
      "name": "Rock_Stone"
    },
    {
      "x": -35,
      "y": 8,
      "z": 2,
      "name": "Rock_Stone"
    },
    {
      "x": -35,
      "y": 9,
      "z": 2,
      "name": "Rock_Stone"
    },
    {
      "x": -35,
      "y": 10,
      "z": 2,
      "name": "Rock_Stone"
    },
    {
      "x": -35,
      "y": 11,
      "z": 2,
      "name": "Rock_Stone"
    },
    {
      "x": -35,
      "y": 12,
      "z": 2,
      "name": "Soil_Dirt"
    },
    {
      "x": -35,
      "y": 13,
      "z": 2,
      "name": "Soil_Dirt"
    },
    {
      "x": -35,
      "y": 14,
      "z": 2,
      "name": "Soil_Dirt"
    },
    {
      "x": -35,
      "y": 15,
      "z": 2,
      "name": "Soil_Dirt"
    },
    {
      "x": -35,
      "y": 16,
      "z": 2,
      "name": "Rock_Basalt_Brick_Smooth",
      "rotation": 2
    },
    {
      "x": -35,
      "y": 17,
      "z": 2,
      "name": "Rock_Basalt_Brick_Smooth",
      "rotation": 2
    },
    {
      "x": -35,
      "y": 18,
      "z": 2,
      "name": "Rock_Basalt_Brick_Smooth",
      "rotation": 2
    },
    {
      "x": -35,
      "y": 19,
      "z": 2,
      "name": "Rock_Basalt_Brick_Smooth",
      "rotation": 2
    },
    {
      "x": -35,
      "y": 20,
      "z": 2,
      "name": "Rock_Basalt_Brick_Smooth",
      "rotation": 2
    },
    {
      "x": -35,
      "y": 21,
      "z": 2,
      "name": "Empty"
    },
    {
      "x": -35,
      "y": 22,
      "z": 2,
      "name": "Empty"
    },
    {
      "x": -35,
      "y": 23,
      "z": 2,
      "name": "Empty"
    },
    {
      "x": -35,
      "y": 0,
      "z": 3,
      "name": "Rock_Stone"
    },
    {
      "x": -35,
      "y": 1,
      "z": 3,
      "name": "Rock_Stone"
    },
    {
      "x": -35,
      "y": 2,
      "z": 3,
      "name": "Rock_Stone"
    },
    {
      "x": -35,
      "y": 3,
      "z": 3,
      "name": "Rock_Stone"
    },
    {
      "x": -35,
      "y": 4,
      "z": 3,
      "name": "Rock_Stone"
    },
    {
      "x": -35,
      "y": 5,
      "z": 3,
      "name": "Rock_Stone"
    },
    {
      "x": -35,
      "y": 6,
      "z": 3,
      "name": "Rock_Stone"
    },
    {
      "x": -35,
      "y": 7,
      "z": 3,
      "name": "Rock_Stone"
    },
    {
      "x": -35,
      "y": 8,
      "z": 3,
      "name": "Rock_Stone"
    },
    {
      "x": -35,
      "y": 9,
      "z": 3,
      "name": "Rock_Stone"
    },
    {
      "x": -35,
      "y": 10,
      "z": 3,
      "name": "Rock_Stone"
    },
    {
      "x": -35,
      "y": 11,
      "z": 3,
      "name": "Rock_Stone"
    },
    {
      "x": -35,
      "y": 12,
      "z": 3,
      "name": "Soil_Dirt"
    },
    {
      "x": -35,
      "y": 13,
      "z": 3,
      "name": "Soil_Dirt"
    },
    {
      "x": -35,
      "y": 14,
      "z": 3,
      "name": "Soil_Dirt"
    },
    {
      "x": -35,
      "y": 15,
      "z": 3,
      "name": "Soil_Dirt"
    },
    {
      "x": -35,
      "y": 16,
      "z": 3,
      "name": "Rock_Basalt_Brick_Smooth",
      "rotation": 2
    },
    {
      "x": -35,
      "y": 17,
      "z": 3,
      "name": "Empty"
    },
    {
      "x": -35,
      "y": 18,
      "z": 3,
      "name": "Empty"
    },
    {
      "x": -35,
      "y": 19,
      "z": 3,
      "name": "Empty"
    },
    {
      "x": -35,
      "y": 20,
      "z": 3,
      "name": "Empty"
    },
    {
      "x": -35,
      "y": 21,
      "z": 3,
      "name": "Empty"
    },
    {
      "x": -35,
      "y": 22,
      "z": 3,
      "name": "Empty"
    },
    {
      "x": -35,
      "y": 23,
      "z": 3,
      "name": "Empty"
    },
    {
      "x": -35,
      "y": 0,
      "z": 4,
      "name": "Rock_Stone"
    },
    {
      "x": -35,
      "y": 1,
      "z": 4,
      "name": "Rock_Stone"
    },
    {
      "x": -35,
      "y": 2,
      "z": 4,
      "name": "Rock_Stone"
    },
    {
      "x": -35,
      "y": 3,
      "z": 4,
      "name": "Rock_Stone"
    },
    {
      "x": -35,
      "y": 4,
      "z": 4,
      "name": "Rock_Stone"
    },
    {
      "x": -35,
      "y": 5,
      "z": 4,
      "name": "Rock_Stone"
    },
    {
      "x": -35,
      "y": 6,
      "z": 4,
      "name": "Rock_Stone"
    },
    {
      "x": -35,
      "y": 7,
      "z": 4,
      "name": "Rock_Stone"
    },
    {
      "x": -35,
      "y": 8,
      "z": 4,
      "name": "Rock_Stone"
    },
    {
      "x": -35,
      "y": 9,
      "z": 4,
      "name": "Rock_Stone"
    },
    {
      "x": -35,
      "y": 10,
      "z": 4,
      "name": "Rock_Stone"
    },
    {
      "x": -35,
      "y": 11,
      "z": 4,
      "name": "Rock_Stone"
    },
    {
      "x": -35,
      "y": 12,
      "z": 4,
      "name": "Soil_Dirt"
    },
    {
      "x": -35,
      "y": 13,
      "z": 4,
      "name": "Soil_Dirt"
    },
    {
      "x": -35,
      "y": 14,
      "z": 4,
      "name": "Soil_Dirt"
    },
    {
      "x": -35,
      "y": 15,
      "z": 4,
      "name": "Soil_Dirt"
    },
    {
      "x": -35,
      "y": 16,
      "z": 4,
      "name": "Rock_Basalt_Brick_Smooth",
      "rotation": 2
    },
    {
      "x": -35,
      "y": 17,
      "z": 4,
      "name": "Empty"
    },
    {
      "x": -35,
      "y": 18,
      "z": 4,
      "name": "Empty"
    },
    {
      "x": -35,
      "y": 19,
      "z": 4,
      "name": "Empty"
    },
    {
      "x": -35,
      "y": 20,
      "z": 4,
      "name": "Empty"
    },
    {
      "x": -35,
      "y": 21,
      "z": 4,
      "name": "Empty"
    },
    {
      "x": -35,
      "y": 22,
      "z": 4,
      "name": "Empty"
    },
    {
      "x": -35,
      "y": 23,
      "z": 4,
      "name": "Empty"
    },
    {
      "x": -35,
      "y": 0,
      "z": 5,
      "name": "Rock_Stone"
    },
    {
      "x": -35,
      "y": 1,
      "z": 5,
      "name": "Rock_Stone"
    },
    {
      "x": -35,
      "y": 2,
      "z": 5,
      "name": "Rock_Stone"
    },
    {
      "x": -35,
      "y": 3,
      "z": 5,
      "name": "Rock_Stone"
    },
    {
      "x": -35,
      "y": 4,
      "z": 5,
      "name": "Rock_Stone"
    },
    {
      "x": -35,
      "y": 5,
      "z": 5,
      "name": "Rock_Stone"
    },
    {
      "x": -35,
      "y": 6,
      "z": 5,
      "name": "Rock_Stone"
    },
    {
      "x": -35,
      "y": 7,
      "z": 5,
      "name": "Rock_Stone"
    },
    {
      "x": -35,
      "y": 8,
      "z": 5,
      "name": "Rock_Stone"
    },
    {
      "x": -35,
      "y": 9,
      "z": 5,
      "name": "Rock_Stone"
    },
    {
      "x": -35,
      "y": 10,
      "z": 5,
      "name": "Rock_Stone"
    },
    {
      "x": -35,
      "y": 11,
      "z": 5,
      "name": "Rock_Stone"
    },
    {
      "x": -35,
      "y": 12,
      "z": 5,
      "name": "Soil_Dirt"
    },
    {
      "x": -35,
      "y": 13,
      "z": 5,
      "name": "Soil_Dirt"
    },
    {
      "x": -35,
      "y": 14,
      "z": 5,
      "name": "Soil_Dirt"
    },
    {
      "x": -35,
      "y": 15,
      "z": 5,
      "name": "Soil_Dirt"
    },
    {
      "x": -35,
      "y": 16,
      "z": 5,
      "name": "Rock_Basalt_Brick_Smooth",
      "rotation": 2
    },
    {
      "x": -35,
      "y": 17,
      "z": 5,
      "name": "Empty"
    },
    {
      "x": -35,
      "y": 18,
      "z": 5,
      "name": "Empty"
    },
    {
      "x": -35,
      "y": 19,
      "z": 5,
      "name": "Empty"
    },
    {
      "x": -35,
      "y": 20,
      "z": 5,
      "name": "Empty"
    },
    {
      "x": -35,
      "y": 21,
      "z": 5,
      "name": "Empty"
    },
    {
      "x": -35,
      "y": 22,
      "z": 5,
      "name": "Empty"
    },
    {
      "x": -35,
      "y": 23,
      "z": 5,
      "name": "Empty"
    },
    {
      "x": -35,
      "y": 0,
      "z": 6,
      "name": "Rock_Stone"
    },
    {
      "x": -35,
      "y": 1,
      "z": 6,
      "name": "Rock_Stone"
    },
    {
      "x": -35,
      "y": 2,
      "z": 6,
      "name": "Rock_Stone"
    },
    {
      "x": -35,
      "y": 3,
      "z": 6,
      "name": "Rock_Stone"
    },
    {
      "x": -35,
      "y": 4,
      "z": 6,
      "name": "Rock_Stone"
    },
    {
      "x": -35,
      "y": 5,
      "z": 6,
      "name": "Rock_Stone"
    },
    {
      "x": -35,
      "y": 6,
      "z": 6,
      "name": "Rock_Stone"
    },
    {
      "x": -35,
      "y": 7,
      "z": 6,
      "name": "Rock_Stone"
    },
    {
      "x": -35,
      "y": 8,
      "z": 6,
      "name": "Rock_Stone"
    },
    {
      "x": -35,
      "y": 9,
      "z": 6,
      "name": "Rock_Stone"
    },
    {
      "x": -35,
      "y": 10,
      "z": 6,
      "name": "Rock_Stone"
    },
    {
      "x": -35,
      "y": 11,
      "z": 6,
      "name": "Rock_Stone"
    },
    {
      "x": -35,
      "y": 12,
      "z": 6,
      "name": "Soil_Dirt"
    },
    {
      "x": -35,
      "y": 13,
      "z": 6,
      "name": "Soil_Dirt"
    },
    {
      "x": -35,
      "y": 14,
      "z": 6,
      "name": "Soil_Dirt"
    },
    {
      "x": -35,
      "y": 15,
      "z": 6,
      "name": "Soil_Dirt"
    },
    {
      "x": -35,
      "y": 16,
      "z": 6,
      "name": "Rock_Basalt_Brick_Smooth",
      "rotation": 2
    },
    {
      "x": -35,
      "y": 17,
      "z": 6,
      "name": "Empty"
    },
    {
      "x": -35,
      "y": 18,
      "z": 6,
      "name": "Empty"
    },
    {
      "x": -35,
      "y": 19,
      "z": 6,
      "name": "Empty"
    },
    {
      "x": -35,
      "y": 20,
      "z": 6,
      "name": "Empty"
    },
    {
      "x": -35,
      "y": 21,
      "z": 6,
      "name": "Empty"
    },
    {
      "x": -35,
      "y": 22,
      "z": 6,
      "name": "Empty"
    },
    {
      "x": -35,
      "y": 23,
      "z": 6,
      "name": "Empty"
    },
    {
      "x": -35,
      "y": 0,
      "z": 7,
      "name": "Rock_Stone"
    },
    {
      "x": -35,
      "y": 1,
      "z": 7,
      "name": "Rock_Stone"
    },
    {
      "x": -35,
      "y": 2,
      "z": 7,
      "name": "Rock_Stone"
    },
    {
      "x": -35,
      "y": 3,
      "z": 7,
      "name": "Rock_Stone"
    },
    {
      "x": -35,
      "y": 4,
      "z": 7,
      "name": "Rock_Stone"
    },
    {
      "x": -35,
      "y": 5,
      "z": 7,
      "name": "Rock_Stone"
    },
    {
      "x": -35,
      "y": 6,
      "z": 7,
      "name": "Rock_Stone"
    },
    {
      "x": -35,
      "y": 7,
      "z": 7,
      "name": "Rock_Stone"
    },
    {
      "x": -35,
      "y": 8,
      "z": 7,
      "name": "Rock_Stone"
    },
    {
      "x": -35,
      "y": 9,
      "z": 7,
      "name": "Rock_Stone"
    },
    {
      "x": -35,
      "y": 10,
      "z": 7,
      "name": "Rock_Stone"
    },
    {
      "x": -35,
      "y": 11,
      "z": 7,
      "name": "Rock_Stone"
    },
    {
      "x": -35,
      "y": 12,
      "z": 7,
      "name": "Soil_Dirt"
    },
    {
      "x": -35,
      "y": 13,
      "z": 7,
      "name": "Soil_Dirt"
    },
    {
      "x": -35,
      "y": 14,
      "z": 7,
      "name": "Soil_Dirt"
    },
    {
      "x": -35,
      "y": 15,
      "z": 7,
      "name": "Soil_Dirt"
    },
    {
      "x": -35,
      "y": 16,
      "z": 7,
      "name": "Rock_Basalt_Brick_Smooth",
      "rotation": 2
    },
    {
      "x": -35,
      "y": 17,
      "z": 7,
      "name": "Empty"
    },
    {
      "x": -35,
      "y": 18,
      "z": 7,
      "name": "Empty"
    },
    {
      "x": -35,
      "y": 19,
      "z": 7,
      "name": "Empty"
    },
    {
      "x": -35,
      "y": 20,
      "z": 7,
      "name": "Empty"
    },
    {
      "x": -35,
      "y": 21,
      "z": 7,
      "name": "Empty"
    },
    {
      "x": -35,
      "y": 22,
      "z": 7,
      "name": "Empty"
    },
    {
      "x": -35,
      "y": 23,
      "z": 7,
      "name": "Empty"
    },
    {
      "x": -34,
      "y": 0,
      "z": -7,
      "name": "Rock_Stone"
    },
    {
      "x": -34,
      "y": 1,
      "z": -7,
      "name": "Rock_Stone"
    },
    {
      "x": -34,
      "y": 2,
      "z": -7,
      "name": "Rock_Stone"
    },
    {
      "x": -34,
      "y": 3,
      "z": -7,
      "name": "Rock_Stone"
    },
    {
      "x": -34,
      "y": 4,
      "z": -7,
      "name": "Rock_Stone"
    },
    {
      "x": -34,
      "y": 5,
      "z": -7,
      "name": "Rock_Stone"
    },
    {
      "x": -34,
      "y": 6,
      "z": -7,
      "name": "Rock_Stone"
    },
    {
      "x": -34,
      "y": 7,
      "z": -7,
      "name": "Rock_Stone"
    },
    {
      "x": -34,
      "y": 8,
      "z": -7,
      "name": "Rock_Stone"
    },
    {
      "x": -34,
      "y": 9,
      "z": -7,
      "name": "Rock_Stone"
    },
    {
      "x": -34,
      "y": 10,
      "z": -7,
      "name": "Rock_Stone"
    },
    {
      "x": -34,
      "y": 11,
      "z": -7,
      "name": "Rock_Stone"
    },
    {
      "x": -34,
      "y": 12,
      "z": -7,
      "name": "Soil_Dirt"
    },
    {
      "x": -34,
      "y": 13,
      "z": -7,
      "name": "Soil_Dirt"
    },
    {
      "x": -34,
      "y": 14,
      "z": -7,
      "name": "Soil_Dirt"
    },
    {
      "x": -34,
      "y": 15,
      "z": -7,
      "name": "Soil_Dirt"
    },
    {
      "x": -34,
      "y": 16,
      "z": -7,
      "name": "Rock_Basalt_Brick_Smooth",
      "rotation": 2
    },
    {
      "x": -34,
      "y": 17,
      "z": -7,
      "name": "Empty"
    },
    {
      "x": -34,
      "y": 18,
      "z": -7,
      "name": "Empty"
    },
    {
      "x": -34,
      "y": 19,
      "z": -7,
      "name": "Empty"
    },
    {
      "x": -34,
      "y": 20,
      "z": -7,
      "name": "Empty"
    },
    {
      "x": -34,
      "y": 21,
      "z": -7,
      "name": "Empty"
    },
    {
      "x": -34,
      "y": 22,
      "z": -7,
      "name": "Empty"
    },
    {
      "x": -34,
      "y": 23,
      "z": -7,
      "name": "Empty"
    },
    {
      "x": -34,
      "y": 0,
      "z": -6,
      "name": "Rock_Stone"
    },
    {
      "x": -34,
      "y": 1,
      "z": -6,
      "name": "Rock_Stone"
    },
    {
      "x": -34,
      "y": 2,
      "z": -6,
      "name": "Rock_Stone"
    },
    {
      "x": -34,
      "y": 3,
      "z": -6,
      "name": "Rock_Stone"
    },
    {
      "x": -34,
      "y": 4,
      "z": -6,
      "name": "Rock_Stone"
    },
    {
      "x": -34,
      "y": 5,
      "z": -6,
      "name": "Rock_Stone"
    },
    {
      "x": -34,
      "y": 6,
      "z": -6,
      "name": "Rock_Stone"
    },
    {
      "x": -34,
      "y": 7,
      "z": -6,
      "name": "Rock_Stone"
    },
    {
      "x": -34,
      "y": 8,
      "z": -6,
      "name": "Rock_Stone"
    },
    {
      "x": -34,
      "y": 9,
      "z": -6,
      "name": "Rock_Stone"
    },
    {
      "x": -34,
      "y": 10,
      "z": -6,
      "name": "Rock_Stone"
    },
    {
      "x": -34,
      "y": 11,
      "z": -6,
      "name": "Rock_Stone"
    },
    {
      "x": -34,
      "y": 12,
      "z": -6,
      "name": "Soil_Dirt"
    },
    {
      "x": -34,
      "y": 13,
      "z": -6,
      "name": "Soil_Dirt"
    },
    {
      "x": -34,
      "y": 14,
      "z": -6,
      "name": "Soil_Dirt"
    },
    {
      "x": -34,
      "y": 15,
      "z": -6,
      "name": "Soil_Dirt"
    },
    {
      "x": -34,
      "y": 16,
      "z": -6,
      "name": "Rock_Basalt_Brick_Smooth",
      "rotation": 2
    },
    {
      "x": -34,
      "y": 17,
      "z": -6,
      "name": "Empty"
    },
    {
      "x": -34,
      "y": 18,
      "z": -6,
      "name": "Empty"
    },
    {
      "x": -34,
      "y": 19,
      "z": -6,
      "name": "Empty"
    },
    {
      "x": -34,
      "y": 20,
      "z": -6,
      "name": "Empty"
    },
    {
      "x": -34,
      "y": 21,
      "z": -6,
      "name": "Empty"
    },
    {
      "x": -34,
      "y": 22,
      "z": -6,
      "name": "Empty"
    },
    {
      "x": -34,
      "y": 23,
      "z": -6,
      "name": "Empty"
    },
    {
      "x": -34,
      "y": 0,
      "z": -5,
      "name": "Rock_Stone"
    },
    {
      "x": -34,
      "y": 1,
      "z": -5,
      "name": "Rock_Stone"
    },
    {
      "x": -34,
      "y": 2,
      "z": -5,
      "name": "Rock_Stone"
    },
    {
      "x": -34,
      "y": 3,
      "z": -5,
      "name": "Rock_Stone"
    },
    {
      "x": -34,
      "y": 4,
      "z": -5,
      "name": "Rock_Stone"
    },
    {
      "x": -34,
      "y": 5,
      "z": -5,
      "name": "Rock_Stone"
    },
    {
      "x": -34,
      "y": 6,
      "z": -5,
      "name": "Rock_Stone"
    },
    {
      "x": -34,
      "y": 7,
      "z": -5,
      "name": "Rock_Stone"
    },
    {
      "x": -34,
      "y": 8,
      "z": -5,
      "name": "Rock_Stone"
    },
    {
      "x": -34,
      "y": 9,
      "z": -5,
      "name": "Rock_Stone"
    },
    {
      "x": -34,
      "y": 10,
      "z": -5,
      "name": "Rock_Stone"
    },
    {
      "x": -34,
      "y": 11,
      "z": -5,
      "name": "Rock_Stone"
    },
    {
      "x": -34,
      "y": 12,
      "z": -5,
      "name": "Soil_Dirt"
    },
    {
      "x": -34,
      "y": 13,
      "z": -5,
      "name": "Soil_Dirt"
    },
    {
      "x": -34,
      "y": 14,
      "z": -5,
      "name": "Soil_Dirt"
    },
    {
      "x": -34,
      "y": 15,
      "z": -5,
      "name": "Soil_Dirt"
    },
    {
      "x": -34,
      "y": 16,
      "z": -5,
      "name": "Rock_Basalt_Brick_Smooth",
      "rotation": 2
    },
    {
      "x": -34,
      "y": 17,
      "z": -5,
      "name": "Empty"
    },
    {
      "x": -34,
      "y": 18,
      "z": -5,
      "name": "Empty"
    },
    {
      "x": -34,
      "y": 19,
      "z": -5,
      "name": "Empty"
    },
    {
      "x": -34,
      "y": 20,
      "z": -5,
      "name": "Empty"
    },
    {
      "x": -34,
      "y": 21,
      "z": -5,
      "name": "Empty"
    },
    {
      "x": -34,
      "y": 22,
      "z": -5,
      "name": "Empty"
    },
    {
      "x": -34,
      "y": 23,
      "z": -5,
      "name": "Empty"
    },
    {
      "x": -34,
      "y": 0,
      "z": -4,
      "name": "Rock_Stone"
    },
    {
      "x": -34,
      "y": 1,
      "z": -4,
      "name": "Rock_Stone"
    },
    {
      "x": -34,
      "y": 2,
      "z": -4,
      "name": "Rock_Stone"
    },
    {
      "x": -34,
      "y": 3,
      "z": -4,
      "name": "Rock_Stone"
    },
    {
      "x": -34,
      "y": 4,
      "z": -4,
      "name": "Rock_Stone"
    },
    {
      "x": -34,
      "y": 5,
      "z": -4,
      "name": "Rock_Stone"
    },
    {
      "x": -34,
      "y": 6,
      "z": -4,
      "name": "Rock_Stone"
    },
    {
      "x": -34,
      "y": 7,
      "z": -4,
      "name": "Rock_Stone"
    },
    {
      "x": -34,
      "y": 8,
      "z": -4,
      "name": "Rock_Stone"
    },
    {
      "x": -34,
      "y": 9,
      "z": -4,
      "name": "Rock_Stone"
    },
    {
      "x": -34,
      "y": 10,
      "z": -4,
      "name": "Rock_Stone"
    },
    {
      "x": -34,
      "y": 11,
      "z": -4,
      "name": "Rock_Stone"
    },
    {
      "x": -34,
      "y": 12,
      "z": -4,
      "name": "Soil_Dirt"
    },
    {
      "x": -34,
      "y": 13,
      "z": -4,
      "name": "Soil_Dirt"
    },
    {
      "x": -34,
      "y": 14,
      "z": -4,
      "name": "Soil_Dirt"
    },
    {
      "x": -34,
      "y": 15,
      "z": -4,
      "name": "Soil_Dirt"
    },
    {
      "x": -34,
      "y": 16,
      "z": -4,
      "name": "Rock_Basalt_Brick_Smooth",
      "rotation": 2
    },
    {
      "x": -34,
      "y": 17,
      "z": -4,
      "name": "Empty"
    },
    {
      "x": -34,
      "y": 18,
      "z": -4,
      "name": "Empty"
    },
    {
      "x": -34,
      "y": 19,
      "z": -4,
      "name": "Empty"
    },
    {
      "x": -34,
      "y": 20,
      "z": -4,
      "name": "Empty"
    },
    {
      "x": -34,
      "y": 21,
      "z": -4,
      "name": "Empty"
    },
    {
      "x": -34,
      "y": 22,
      "z": -4,
      "name": "Empty"
    },
    {
      "x": -34,
      "y": 23,
      "z": -4,
      "name": "Empty"
    },
    {
      "x": -34,
      "y": 0,
      "z": -3,
      "name": "Rock_Stone"
    },
    {
      "x": -34,
      "y": 1,
      "z": -3,
      "name": "Rock_Stone"
    },
    {
      "x": -34,
      "y": 2,
      "z": -3,
      "name": "Rock_Stone"
    },
    {
      "x": -34,
      "y": 3,
      "z": -3,
      "name": "Rock_Stone"
    },
    {
      "x": -34,
      "y": 4,
      "z": -3,
      "name": "Rock_Stone"
    },
    {
      "x": -34,
      "y": 5,
      "z": -3,
      "name": "Rock_Stone"
    },
    {
      "x": -34,
      "y": 6,
      "z": -3,
      "name": "Rock_Stone"
    },
    {
      "x": -34,
      "y": 7,
      "z": -3,
      "name": "Rock_Stone"
    },
    {
      "x": -34,
      "y": 8,
      "z": -3,
      "name": "Rock_Stone"
    },
    {
      "x": -34,
      "y": 9,
      "z": -3,
      "name": "Rock_Stone"
    },
    {
      "x": -34,
      "y": 10,
      "z": -3,
      "name": "Rock_Stone"
    },
    {
      "x": -34,
      "y": 11,
      "z": -3,
      "name": "Rock_Stone"
    },
    {
      "x": -34,
      "y": 12,
      "z": -3,
      "name": "Soil_Dirt"
    },
    {
      "x": -34,
      "y": 13,
      "z": -3,
      "name": "Soil_Dirt"
    },
    {
      "x": -34,
      "y": 14,
      "z": -3,
      "name": "Soil_Dirt"
    },
    {
      "x": -34,
      "y": 15,
      "z": -3,
      "name": "Soil_Dirt"
    },
    {
      "x": -34,
      "y": 16,
      "z": -3,
      "name": "Rock_Basalt_Brick_Smooth",
      "rotation": 2
    },
    {
      "x": -34,
      "y": 17,
      "z": -3,
      "name": "Empty"
    },
    {
      "x": -34,
      "y": 18,
      "z": -3,
      "name": "Empty"
    },
    {
      "x": -34,
      "y": 19,
      "z": -3,
      "name": "Empty"
    },
    {
      "x": -34,
      "y": 20,
      "z": -3,
      "name": "Empty"
    },
    {
      "x": -34,
      "y": 21,
      "z": -3,
      "name": "Empty"
    },
    {
      "x": -34,
      "y": 22,
      "z": -3,
      "name": "Empty"
    },
    {
      "x": -34,
      "y": 23,
      "z": -3,
      "name": "Empty"
    },
    {
      "x": -34,
      "y": 0,
      "z": -2,
      "name": "Rock_Stone"
    },
    {
      "x": -34,
      "y": 1,
      "z": -2,
      "name": "Rock_Stone"
    },
    {
      "x": -34,
      "y": 2,
      "z": -2,
      "name": "Rock_Stone"
    },
    {
      "x": -34,
      "y": 3,
      "z": -2,
      "name": "Rock_Stone"
    },
    {
      "x": -34,
      "y": 4,
      "z": -2,
      "name": "Rock_Stone"
    },
    {
      "x": -34,
      "y": 5,
      "z": -2,
      "name": "Rock_Stone"
    },
    {
      "x": -34,
      "y": 6,
      "z": -2,
      "name": "Rock_Stone"
    },
    {
      "x": -34,
      "y": 7,
      "z": -2,
      "name": "Rock_Stone"
    },
    {
      "x": -34,
      "y": 8,
      "z": -2,
      "name": "Rock_Stone"
    },
    {
      "x": -34,
      "y": 9,
      "z": -2,
      "name": "Rock_Stone"
    },
    {
      "x": -34,
      "y": 10,
      "z": -2,
      "name": "Rock_Stone"
    },
    {
      "x": -34,
      "y": 11,
      "z": -2,
      "name": "Rock_Stone"
    },
    {
      "x": -34,
      "y": 12,
      "z": -2,
      "name": "Soil_Dirt"
    },
    {
      "x": -34,
      "y": 13,
      "z": -2,
      "name": "Soil_Dirt"
    },
    {
      "x": -34,
      "y": 14,
      "z": -2,
      "name": "Soil_Dirt"
    },
    {
      "x": -34,
      "y": 15,
      "z": -2,
      "name": "Soil_Dirt"
    },
    {
      "x": -34,
      "y": 16,
      "z": -2,
      "name": "Rock_Basalt_Brick_Smooth",
      "rotation": 2
    },
    {
      "x": -34,
      "y": 17,
      "z": -2,
      "name": "Rock_Basalt_Brick_Smooth",
      "rotation": 2
    },
    {
      "x": -34,
      "y": 18,
      "z": -2,
      "name": "Rock_Basalt_Brick_Smooth",
      "rotation": 2
    },
    {
      "x": -34,
      "y": 19,
      "z": -2,
      "name": "Rock_Basalt_Brick_Smooth",
      "rotation": 2
    },
    {
      "x": -34,
      "y": 20,
      "z": -2,
      "name": "Rock_Basalt_Brick_Smooth",
      "rotation": 2
    },
    {
      "x": -34,
      "y": 21,
      "z": -2,
      "name": "Empty"
    },
    {
      "x": -34,
      "y": 22,
      "z": -2,
      "name": "Empty"
    },
    {
      "x": -34,
      "y": 23,
      "z": -2,
      "name": "Empty"
    },
    {
      "x": -34,
      "y": 0,
      "z": -1,
      "name": "Rock_Stone"
    },
    {
      "x": -34,
      "y": 1,
      "z": -1,
      "name": "Rock_Stone"
    },
    {
      "x": -34,
      "y": 2,
      "z": -1,
      "name": "Rock_Stone"
    },
    {
      "x": -34,
      "y": 3,
      "z": -1,
      "name": "Rock_Stone"
    },
    {
      "x": -34,
      "y": 4,
      "z": -1,
      "name": "Rock_Stone"
    },
    {
      "x": -34,
      "y": 5,
      "z": -1,
      "name": "Rock_Stone"
    },
    {
      "x": -34,
      "y": 6,
      "z": -1,
      "name": "Rock_Stone"
    },
    {
      "x": -34,
      "y": 7,
      "z": -1,
      "name": "Rock_Stone"
    },
    {
      "x": -34,
      "y": 8,
      "z": -1,
      "name": "Rock_Stone"
    },
    {
      "x": -34,
      "y": 9,
      "z": -1,
      "name": "Rock_Stone"
    },
    {
      "x": -34,
      "y": 10,
      "z": -1,
      "name": "Rock_Stone"
    },
    {
      "x": -34,
      "y": 11,
      "z": -1,
      "name": "Rock_Stone"
    },
    {
      "x": -34,
      "y": 12,
      "z": -1,
      "name": "Soil_Dirt"
    },
    {
      "x": -34,
      "y": 13,
      "z": -1,
      "name": "Soil_Dirt"
    },
    {
      "x": -34,
      "y": 14,
      "z": -1,
      "name": "Soil_Dirt"
    },
    {
      "x": -34,
      "y": 15,
      "z": -1,
      "name": "Soil_Dirt"
    },
    {
      "x": -34,
      "y": 16,
      "z": -1,
      "name": "Rock_Basalt_Brick_Smooth",
      "rotation": 2
    },
    {
      "x": -34,
      "y": 17,
      "z": -1,
      "name": "Empty"
    },
    {
      "x": -34,
      "y": 18,
      "z": -1,
      "name": "Empty"
    },
    {
      "x": -34,
      "y": 19,
      "z": -1,
      "name": "Empty"
    },
    {
      "x": -34,
      "y": 20,
      "z": -1,
      "name": "Rock_Basalt_Brick_Smooth",
      "rotation": 2
    },
    {
      "x": -34,
      "y": 21,
      "z": -1,
      "name": "Empty"
    },
    {
      "x": -34,
      "y": 22,
      "z": -1,
      "name": "Empty"
    },
    {
      "x": -34,
      "y": 23,
      "z": -1,
      "name": "Empty"
    },
    {
      "x": -34,
      "y": 0,
      "z": 0,
      "name": "Rock_Stone"
    },
    {
      "x": -34,
      "y": 1,
      "z": 0,
      "name": "Rock_Stone"
    },
    {
      "x": -34,
      "y": 2,
      "z": 0,
      "name": "Rock_Stone"
    },
    {
      "x": -34,
      "y": 3,
      "z": 0,
      "name": "Rock_Stone"
    },
    {
      "x": -34,
      "y": 4,
      "z": 0,
      "name": "Rock_Stone"
    },
    {
      "x": -34,
      "y": 5,
      "z": 0,
      "name": "Rock_Stone"
    },
    {
      "x": -34,
      "y": 6,
      "z": 0,
      "name": "Rock_Stone"
    },
    {
      "x": -34,
      "y": 7,
      "z": 0,
      "name": "Rock_Stone"
    },
    {
      "x": -34,
      "y": 8,
      "z": 0,
      "name": "Rock_Stone"
    },
    {
      "x": -34,
      "y": 9,
      "z": 0,
      "name": "Rock_Stone"
    },
    {
      "x": -34,
      "y": 10,
      "z": 0,
      "name": "Rock_Stone"
    },
    {
      "x": -34,
      "y": 11,
      "z": 0,
      "name": "Rock_Stone"
    },
    {
      "x": -34,
      "y": 12,
      "z": 0,
      "name": "Soil_Dirt"
    },
    {
      "x": -34,
      "y": 13,
      "z": 0,
      "name": "Soil_Dirt"
    },
    {
      "x": -34,
      "y": 14,
      "z": 0,
      "name": "Soil_Dirt"
    },
    {
      "x": -34,
      "y": 15,
      "z": 0,
      "name": "Soil_Dirt"
    },
    {
      "x": -34,
      "y": 16,
      "z": 0,
      "name": "Rock_Basalt_Brick_Smooth",
      "rotation": 2
    },
    {
      "x": -34,
      "y": 17,
      "z": 0,
      "name": "Empty"
    },
    {
      "x": -34,
      "y": 18,
      "z": 0,
      "name": "Empty"
    },
    {
      "x": -34,
      "y": 19,
      "z": 0,
      "name": "Empty"
    },
    {
      "x": -34,
      "y": 20,
      "z": 0,
      "name": "Rock_Basalt_Brick_Smooth",
      "rotation": 2
    },
    {
      "x": -34,
      "y": 21,
      "z": 0,
      "name": "Empty"
    },
    {
      "x": -34,
      "y": 22,
      "z": 0,
      "name": "Empty"
    },
    {
      "x": -34,
      "y": 23,
      "z": 0,
      "name": "Empty"
    },
    {
      "x": -34,
      "y": 0,
      "z": 1,
      "name": "Rock_Stone"
    },
    {
      "x": -34,
      "y": 1,
      "z": 1,
      "name": "Rock_Stone"
    },
    {
      "x": -34,
      "y": 2,
      "z": 1,
      "name": "Rock_Stone"
    },
    {
      "x": -34,
      "y": 3,
      "z": 1,
      "name": "Rock_Stone"
    },
    {
      "x": -34,
      "y": 4,
      "z": 1,
      "name": "Rock_Stone"
    },
    {
      "x": -34,
      "y": 5,
      "z": 1,
      "name": "Rock_Stone"
    },
    {
      "x": -34,
      "y": 6,
      "z": 1,
      "name": "Rock_Stone"
    },
    {
      "x": -34,
      "y": 7,
      "z": 1,
      "name": "Rock_Stone"
    },
    {
      "x": -34,
      "y": 8,
      "z": 1,
      "name": "Rock_Stone"
    },
    {
      "x": -34,
      "y": 9,
      "z": 1,
      "name": "Rock_Stone"
    },
    {
      "x": -34,
      "y": 10,
      "z": 1,
      "name": "Rock_Stone"
    },
    {
      "x": -34,
      "y": 11,
      "z": 1,
      "name": "Rock_Stone"
    },
    {
      "x": -34,
      "y": 12,
      "z": 1,
      "name": "Soil_Dirt"
    },
    {
      "x": -34,
      "y": 13,
      "z": 1,
      "name": "Soil_Dirt"
    },
    {
      "x": -34,
      "y": 14,
      "z": 1,
      "name": "Soil_Dirt"
    },
    {
      "x": -34,
      "y": 15,
      "z": 1,
      "name": "Soil_Dirt"
    },
    {
      "x": -34,
      "y": 16,
      "z": 1,
      "name": "Rock_Basalt_Brick_Smooth",
      "rotation": 2
    },
    {
      "x": -34,
      "y": 17,
      "z": 1,
      "name": "Empty"
    },
    {
      "x": -34,
      "y": 18,
      "z": 1,
      "name": "Empty"
    },
    {
      "x": -34,
      "y": 19,
      "z": 1,
      "name": "Empty"
    },
    {
      "x": -34,
      "y": 20,
      "z": 1,
      "name": "Rock_Basalt_Brick_Smooth",
      "rotation": 2
    },
    {
      "x": -34,
      "y": 21,
      "z": 1,
      "name": "Empty"
    },
    {
      "x": -34,
      "y": 22,
      "z": 1,
      "name": "Empty"
    },
    {
      "x": -34,
      "y": 23,
      "z": 1,
      "name": "Empty"
    },
    {
      "x": -34,
      "y": 0,
      "z": 2,
      "name": "Rock_Stone"
    },
    {
      "x": -34,
      "y": 1,
      "z": 2,
      "name": "Rock_Stone"
    },
    {
      "x": -34,
      "y": 2,
      "z": 2,
      "name": "Rock_Stone"
    },
    {
      "x": -34,
      "y": 3,
      "z": 2,
      "name": "Rock_Stone"
    },
    {
      "x": -34,
      "y": 4,
      "z": 2,
      "name": "Rock_Stone"
    },
    {
      "x": -34,
      "y": 5,
      "z": 2,
      "name": "Rock_Stone"
    },
    {
      "x": -34,
      "y": 6,
      "z": 2,
      "name": "Rock_Stone"
    },
    {
      "x": -34,
      "y": 7,
      "z": 2,
      "name": "Rock_Stone"
    },
    {
      "x": -34,
      "y": 8,
      "z": 2,
      "name": "Rock_Stone"
    },
    {
      "x": -34,
      "y": 9,
      "z": 2,
      "name": "Rock_Stone"
    },
    {
      "x": -34,
      "y": 10,
      "z": 2,
      "name": "Rock_Stone"
    },
    {
      "x": -34,
      "y": 11,
      "z": 2,
      "name": "Rock_Stone"
    },
    {
      "x": -34,
      "y": 12,
      "z": 2,
      "name": "Soil_Dirt"
    },
    {
      "x": -34,
      "y": 13,
      "z": 2,
      "name": "Soil_Dirt"
    },
    {
      "x": -34,
      "y": 14,
      "z": 2,
      "name": "Soil_Dirt"
    },
    {
      "x": -34,
      "y": 15,
      "z": 2,
      "name": "Soil_Dirt"
    },
    {
      "x": -34,
      "y": 16,
      "z": 2,
      "name": "Rock_Basalt_Brick_Smooth",
      "rotation": 2
    },
    {
      "x": -34,
      "y": 17,
      "z": 2,
      "name": "Rock_Basalt_Brick_Smooth",
      "rotation": 2
    },
    {
      "x": -34,
      "y": 18,
      "z": 2,
      "name": "Rock_Basalt_Brick_Smooth",
      "rotation": 2
    },
    {
      "x": -34,
      "y": 19,
      "z": 2,
      "name": "Rock_Basalt_Brick_Smooth",
      "rotation": 2
    },
    {
      "x": -34,
      "y": 20,
      "z": 2,
      "name": "Rock_Basalt_Brick_Smooth",
      "rotation": 2
    },
    {
      "x": -34,
      "y": 21,
      "z": 2,
      "name": "Empty"
    },
    {
      "x": -34,
      "y": 22,
      "z": 2,
      "name": "Empty"
    },
    {
      "x": -34,
      "y": 23,
      "z": 2,
      "name": "Empty"
    },
    {
      "x": -34,
      "y": 0,
      "z": 3,
      "name": "Rock_Stone"
    },
    {
      "x": -34,
      "y": 1,
      "z": 3,
      "name": "Rock_Stone"
    },
    {
      "x": -34,
      "y": 2,
      "z": 3,
      "name": "Rock_Stone"
    },
    {
      "x": -34,
      "y": 3,
      "z": 3,
      "name": "Rock_Stone"
    },
    {
      "x": -34,
      "y": 4,
      "z": 3,
      "name": "Rock_Stone"
    },
    {
      "x": -34,
      "y": 5,
      "z": 3,
      "name": "Rock_Stone"
    },
    {
      "x": -34,
      "y": 6,
      "z": 3,
      "name": "Rock_Stone"
    },
    {
      "x": -34,
      "y": 7,
      "z": 3,
      "name": "Rock_Stone"
    },
    {
      "x": -34,
      "y": 8,
      "z": 3,
      "name": "Rock_Stone"
    },
    {
      "x": -34,
      "y": 9,
      "z": 3,
      "name": "Rock_Stone"
    },
    {
      "x": -34,
      "y": 10,
      "z": 3,
      "name": "Rock_Stone"
    },
    {
      "x": -34,
      "y": 11,
      "z": 3,
      "name": "Rock_Stone"
    },
    {
      "x": -34,
      "y": 12,
      "z": 3,
      "name": "Soil_Dirt"
    },
    {
      "x": -34,
      "y": 13,
      "z": 3,
      "name": "Soil_Dirt"
    },
    {
      "x": -34,
      "y": 14,
      "z": 3,
      "name": "Soil_Dirt"
    },
    {
      "x": -34,
      "y": 15,
      "z": 3,
      "name": "Soil_Dirt"
    },
    {
      "x": -34,
      "y": 16,
      "z": 3,
      "name": "Rock_Basalt_Brick_Smooth",
      "rotation": 2
    },
    {
      "x": -34,
      "y": 17,
      "z": 3,
      "name": "Empty"
    },
    {
      "x": -34,
      "y": 18,
      "z": 3,
      "name": "Empty"
    },
    {
      "x": -34,
      "y": 19,
      "z": 3,
      "name": "Empty"
    },
    {
      "x": -34,
      "y": 20,
      "z": 3,
      "name": "Empty"
    },
    {
      "x": -34,
      "y": 21,
      "z": 3,
      "name": "Empty"
    },
    {
      "x": -34,
      "y": 22,
      "z": 3,
      "name": "Empty"
    },
    {
      "x": -34,
      "y": 23,
      "z": 3,
      "name": "Empty"
    },
    {
      "x": -34,
      "y": 0,
      "z": 4,
      "name": "Rock_Stone"
    },
    {
      "x": -34,
      "y": 1,
      "z": 4,
      "name": "Rock_Stone"
    },
    {
      "x": -34,
      "y": 2,
      "z": 4,
      "name": "Rock_Stone"
    },
    {
      "x": -34,
      "y": 3,
      "z": 4,
      "name": "Rock_Stone"
    },
    {
      "x": -34,
      "y": 4,
      "z": 4,
      "name": "Rock_Stone"
    },
    {
      "x": -34,
      "y": 5,
      "z": 4,
      "name": "Rock_Stone"
    },
    {
      "x": -34,
      "y": 6,
      "z": 4,
      "name": "Rock_Stone"
    },
    {
      "x": -34,
      "y": 7,
      "z": 4,
      "name": "Rock_Stone"
    },
    {
      "x": -34,
      "y": 8,
      "z": 4,
      "name": "Rock_Stone"
    },
    {
      "x": -34,
      "y": 9,
      "z": 4,
      "name": "Rock_Stone"
    },
    {
      "x": -34,
      "y": 10,
      "z": 4,
      "name": "Rock_Stone"
    },
    {
      "x": -34,
      "y": 11,
      "z": 4,
      "name": "Rock_Stone"
    },
    {
      "x": -34,
      "y": 12,
      "z": 4,
      "name": "Soil_Dirt"
    },
    {
      "x": -34,
      "y": 13,
      "z": 4,
      "name": "Soil_Dirt"
    },
    {
      "x": -34,
      "y": 14,
      "z": 4,
      "name": "Soil_Dirt"
    },
    {
      "x": -34,
      "y": 15,
      "z": 4,
      "name": "Soil_Dirt"
    },
    {
      "x": -34,
      "y": 16,
      "z": 4,
      "name": "Rock_Basalt_Brick_Smooth",
      "rotation": 2
    },
    {
      "x": -34,
      "y": 17,
      "z": 4,
      "name": "Empty"
    },
    {
      "x": -34,
      "y": 18,
      "z": 4,
      "name": "Empty"
    },
    {
      "x": -34,
      "y": 19,
      "z": 4,
      "name": "Empty"
    },
    {
      "x": -34,
      "y": 20,
      "z": 4,
      "name": "Empty"
    },
    {
      "x": -34,
      "y": 21,
      "z": 4,
      "name": "Empty"
    },
    {
      "x": -34,
      "y": 22,
      "z": 4,
      "name": "Empty"
    },
    {
      "x": -34,
      "y": 23,
      "z": 4,
      "name": "Empty"
    },
    {
      "x": -34,
      "y": 0,
      "z": 5,
      "name": "Rock_Stone"
    },
    {
      "x": -34,
      "y": 1,
      "z": 5,
      "name": "Rock_Stone"
    },
    {
      "x": -34,
      "y": 2,
      "z": 5,
      "name": "Rock_Stone"
    },
    {
      "x": -34,
      "y": 3,
      "z": 5,
      "name": "Rock_Stone"
    },
    {
      "x": -34,
      "y": 4,
      "z": 5,
      "name": "Rock_Stone"
    },
    {
      "x": -34,
      "y": 5,
      "z": 5,
      "name": "Rock_Stone"
    },
    {
      "x": -34,
      "y": 6,
      "z": 5,
      "name": "Rock_Stone"
    },
    {
      "x": -34,
      "y": 7,
      "z": 5,
      "name": "Rock_Stone"
    },
    {
      "x": -34,
      "y": 8,
      "z": 5,
      "name": "Rock_Stone"
    },
    {
      "x": -34,
      "y": 9,
      "z": 5,
      "name": "Rock_Stone"
    },
    {
      "x": -34,
      "y": 10,
      "z": 5,
      "name": "Rock_Stone"
    },
    {
      "x": -34,
      "y": 11,
      "z": 5,
      "name": "Rock_Stone"
    },
    {
      "x": -34,
      "y": 12,
      "z": 5,
      "name": "Soil_Dirt"
    },
    {
      "x": -34,
      "y": 13,
      "z": 5,
      "name": "Soil_Dirt"
    },
    {
      "x": -34,
      "y": 14,
      "z": 5,
      "name": "Soil_Dirt"
    },
    {
      "x": -34,
      "y": 15,
      "z": 5,
      "name": "Soil_Dirt"
    },
    {
      "x": -34,
      "y": 16,
      "z": 5,
      "name": "Rock_Basalt_Brick_Smooth",
      "rotation": 2
    },
    {
      "x": -34,
      "y": 17,
      "z": 5,
      "name": "Empty"
    },
    {
      "x": -34,
      "y": 18,
      "z": 5,
      "name": "Empty"
    },
    {
      "x": -34,
      "y": 19,
      "z": 5,
      "name": "Empty"
    },
    {
      "x": -34,
      "y": 20,
      "z": 5,
      "name": "Empty"
    },
    {
      "x": -34,
      "y": 21,
      "z": 5,
      "name": "Empty"
    },
    {
      "x": -34,
      "y": 22,
      "z": 5,
      "name": "Empty"
    },
    {
      "x": -34,
      "y": 23,
      "z": 5,
      "name": "Empty"
    },
    {
      "x": -34,
      "y": 0,
      "z": 6,
      "name": "Rock_Stone"
    },
    {
      "x": -34,
      "y": 1,
      "z": 6,
      "name": "Rock_Stone"
    },
    {
      "x": -34,
      "y": 2,
      "z": 6,
      "name": "Rock_Stone"
    },
    {
      "x": -34,
      "y": 3,
      "z": 6,
      "name": "Rock_Stone"
    },
    {
      "x": -34,
      "y": 4,
      "z": 6,
      "name": "Rock_Stone"
    },
    {
      "x": -34,
      "y": 5,
      "z": 6,
      "name": "Rock_Stone"
    },
    {
      "x": -34,
      "y": 6,
      "z": 6,
      "name": "Rock_Stone"
    },
    {
      "x": -34,
      "y": 7,
      "z": 6,
      "name": "Rock_Stone"
    },
    {
      "x": -34,
      "y": 8,
      "z": 6,
      "name": "Rock_Stone"
    },
    {
      "x": -34,
      "y": 9,
      "z": 6,
      "name": "Rock_Stone"
    },
    {
      "x": -34,
      "y": 10,
      "z": 6,
      "name": "Rock_Stone"
    },
    {
      "x": -34,
      "y": 11,
      "z": 6,
      "name": "Rock_Stone"
    },
    {
      "x": -34,
      "y": 12,
      "z": 6,
      "name": "Soil_Dirt"
    },
    {
      "x": -34,
      "y": 13,
      "z": 6,
      "name": "Soil_Dirt"
    },
    {
      "x": -34,
      "y": 14,
      "z": 6,
      "name": "Soil_Dirt"
    },
    {
      "x": -34,
      "y": 15,
      "z": 6,
      "name": "Soil_Dirt"
    },
    {
      "x": -34,
      "y": 16,
      "z": 6,
      "name": "Rock_Basalt_Brick_Smooth",
      "rotation": 2
    },
    {
      "x": -34,
      "y": 17,
      "z": 6,
      "name": "Empty"
    },
    {
      "x": -34,
      "y": 18,
      "z": 6,
      "name": "Empty"
    },
    {
      "x": -34,
      "y": 19,
      "z": 6,
      "name": "Empty"
    },
    {
      "x": -34,
      "y": 20,
      "z": 6,
      "name": "Empty"
    },
    {
      "x": -34,
      "y": 21,
      "z": 6,
      "name": "Empty"
    },
    {
      "x": -34,
      "y": 22,
      "z": 6,
      "name": "Empty"
    },
    {
      "x": -34,
      "y": 23,
      "z": 6,
      "name": "Empty"
    },
    {
      "x": -34,
      "y": 0,
      "z": 7,
      "name": "Rock_Stone"
    },
    {
      "x": -34,
      "y": 1,
      "z": 7,
      "name": "Rock_Stone"
    },
    {
      "x": -34,
      "y": 2,
      "z": 7,
      "name": "Rock_Stone"
    },
    {
      "x": -34,
      "y": 3,
      "z": 7,
      "name": "Rock_Stone"
    },
    {
      "x": -34,
      "y": 4,
      "z": 7,
      "name": "Rock_Stone"
    },
    {
      "x": -34,
      "y": 5,
      "z": 7,
      "name": "Rock_Stone"
    },
    {
      "x": -34,
      "y": 6,
      "z": 7,
      "name": "Rock_Stone"
    },
    {
      "x": -34,
      "y": 7,
      "z": 7,
      "name": "Rock_Stone"
    },
    {
      "x": -34,
      "y": 8,
      "z": 7,
      "name": "Rock_Stone"
    },
    {
      "x": -34,
      "y": 9,
      "z": 7,
      "name": "Rock_Stone"
    },
    {
      "x": -34,
      "y": 10,
      "z": 7,
      "name": "Rock_Stone"
    },
    {
      "x": -34,
      "y": 11,
      "z": 7,
      "name": "Rock_Stone"
    },
    {
      "x": -34,
      "y": 12,
      "z": 7,
      "name": "Soil_Dirt"
    },
    {
      "x": -34,
      "y": 13,
      "z": 7,
      "name": "Soil_Dirt"
    },
    {
      "x": -34,
      "y": 14,
      "z": 7,
      "name": "Soil_Dirt"
    },
    {
      "x": -34,
      "y": 15,
      "z": 7,
      "name": "Soil_Dirt"
    },
    {
      "x": -34,
      "y": 16,
      "z": 7,
      "name": "Rock_Basalt_Brick_Smooth",
      "rotation": 2
    },
    {
      "x": -34,
      "y": 17,
      "z": 7,
      "name": "Empty"
    },
    {
      "x": -34,
      "y": 18,
      "z": 7,
      "name": "Empty"
    },
    {
      "x": -34,
      "y": 19,
      "z": 7,
      "name": "Empty"
    },
    {
      "x": -34,
      "y": 20,
      "z": 7,
      "name": "Empty"
    },
    {
      "x": -34,
      "y": 21,
      "z": 7,
      "name": "Empty"
    },
    {
      "x": -34,
      "y": 22,
      "z": 7,
      "name": "Empty"
    },
    {
      "x": -34,
      "y": 23,
      "z": 7,
      "name": "Empty"
    },
    {
      "x": -33,
      "y": 0,
      "z": -7,
      "name": "Rock_Stone"
    },
    {
      "x": -33,
      "y": 1,
      "z": -7,
      "name": "Rock_Stone"
    },
    {
      "x": -33,
      "y": 2,
      "z": -7,
      "name": "Rock_Stone"
    },
    {
      "x": -33,
      "y": 3,
      "z": -7,
      "name": "Rock_Stone"
    },
    {
      "x": -33,
      "y": 4,
      "z": -7,
      "name": "Rock_Stone"
    },
    {
      "x": -33,
      "y": 5,
      "z": -7,
      "name": "Rock_Stone"
    },
    {
      "x": -33,
      "y": 6,
      "z": -7,
      "name": "Rock_Stone"
    },
    {
      "x": -33,
      "y": 7,
      "z": -7,
      "name": "Rock_Stone"
    },
    {
      "x": -33,
      "y": 8,
      "z": -7,
      "name": "Rock_Stone"
    },
    {
      "x": -33,
      "y": 9,
      "z": -7,
      "name": "Rock_Stone"
    },
    {
      "x": -33,
      "y": 10,
      "z": -7,
      "name": "Rock_Stone"
    },
    {
      "x": -33,
      "y": 11,
      "z": -7,
      "name": "Rock_Stone"
    },
    {
      "x": -33,
      "y": 12,
      "z": -7,
      "name": "Soil_Dirt"
    },
    {
      "x": -33,
      "y": 13,
      "z": -7,
      "name": "Soil_Dirt"
    },
    {
      "x": -33,
      "y": 14,
      "z": -7,
      "name": "Soil_Dirt"
    },
    {
      "x": -33,
      "y": 15,
      "z": -7,
      "name": "Soil_Dirt"
    },
    {
      "x": -33,
      "y": 16,
      "z": -7,
      "name": "Rock_Basalt_Brick_Smooth",
      "rotation": 2
    },
    {
      "x": -33,
      "y": 17,
      "z": -7,
      "name": "Rock_Basalt_Brick_Smooth",
      "rotation": 2
    },
    {
      "x": -33,
      "y": 18,
      "z": -7,
      "name": "Rock_Basalt_Brick_Smooth",
      "rotation": 2
    },
    {
      "x": -33,
      "y": 19,
      "z": -7,
      "name": "Rock_Basalt_Brick_Smooth",
      "rotation": 2
    },
    {
      "x": -33,
      "y": 20,
      "z": -7,
      "name": "Rock_Basalt_Brick_Smooth",
      "rotation": 2
    },
    {
      "x": -33,
      "y": 21,
      "z": -7,
      "name": "Rock_Basalt_Brick_Smooth",
      "rotation": 2
    },
    {
      "x": -33,
      "y": 22,
      "z": -7,
      "name": "Rock_Basalt_Brick_Smooth",
      "rotation": 2
    },
    {
      "x": -33,
      "y": 23,
      "z": -7,
      "name": "Rock_Basalt_Brick_Smooth",
      "rotation": 2
    },
    {
      "x": -33,
      "y": 0,
      "z": -6,
      "name": "Rock_Basalt_Brick_Smooth",
      "rotation": 2
    },
    {
      "x": -33,
      "y": 1,
      "z": -6,
      "name": "Rock_Basalt_Brick_Smooth",
      "rotation": 2
    },
    {
      "x": -33,
      "y": 2,
      "z": -6,
      "name": "Rock_Basalt_Brick_Smooth",
      "rotation": 2
    },
    {
      "x": -33,
      "y": 3,
      "z": -6,
      "name": "Rock_Basalt_Brick_Smooth",
      "rotation": 2
    },
    {
      "x": -33,
      "y": 4,
      "z": -6,
      "name": "Rock_Basalt_Brick_Smooth",
      "rotation": 2
    },
    {
      "x": -33,
      "y": 5,
      "z": -6,
      "name": "Rock_Basalt_Brick_Smooth",
      "rotation": 2
    },
    {
      "x": -33,
      "y": 6,
      "z": -6,
      "name": "Rock_Basalt_Brick_Smooth",
      "rotation": 2
    },
    {
      "x": -33,
      "y": 7,
      "z": -6,
      "name": "Rock_Basalt_Brick_Smooth",
      "rotation": 2
    },
    {
      "x": -33,
      "y": 8,
      "z": -6,
      "name": "Rock_Basalt_Brick_Smooth",
      "rotation": 2
    },
    {
      "x": -33,
      "y": 9,
      "z": -6,
      "name": "Rock_Basalt_Brick_Smooth",
      "rotation": 2
    },
    {
      "x": -33,
      "y": 10,
      "z": -6,
      "name": "Rock_Basalt_Brick_Smooth",
      "rotation": 2
    },
    {
      "x": -33,
      "y": 11,
      "z": -6,
      "name": "Rock_Basalt_Brick_Smooth",
      "rotation": 2
    },
    {
      "x": -33,
      "y": 12,
      "z": -6,
      "name": "Rock_Basalt_Brick_Smooth",
      "rotation": 2
    },
    {
      "x": -33,
      "y": 13,
      "z": -6,
      "name": "Rock_Basalt_Brick_Smooth",
      "rotation": 2
    },
    {
      "x": -33,
      "y": 14,
      "z": -6,
      "name": "Rock_Basalt_Brick_Smooth",
      "rotation": 2
    },
    {
      "x": -33,
      "y": 15,
      "z": -6,
      "name": "Rock_Basalt_Brick_Smooth",
      "rotation": 2
    },
    {
      "x": -33,
      "y": 16,
      "z": -6,
      "name": "Rock_Basalt_Brick_Smooth",
      "rotation": 2
    },
    {
      "x": -33,
      "y": 17,
      "z": -6,
      "name": "Rock_Basalt_Brick_Smooth",
      "rotation": 2
    },
    {
      "x": -33,
      "y": 18,
      "z": -6,
      "name": "Rock_Basalt_Brick_Smooth",
      "rotation": 2
    },
    {
      "x": -33,
      "y": 19,
      "z": -6,
      "name": "Rock_Basalt_Brick_Smooth",
      "rotation": 2
    },
    {
      "x": -33,
      "y": 20,
      "z": -6,
      "name": "Rock_Basalt_Brick_Smooth",
      "rotation": 2
    },
    {
      "x": -33,
      "y": 21,
      "z": -6,
      "name": "Rock_Basalt_Brick_Smooth",
      "rotation": 2
    },
    {
      "x": -33,
      "y": 22,
      "z": -6,
      "name": "Rock_Basalt_Brick_Smooth",
      "rotation": 2
    },
    {
      "x": -33,
      "y": 23,
      "z": -6,
      "name": "Rock_Basalt_Brick_Smooth",
      "rotation": 2
    },
    {
      "x": -33,
      "y": 0,
      "z": -5,
      "name": "Rock_Basalt_Brick_Smooth",
      "rotation": 2
    },
    {
      "x": -33,
      "y": 1,
      "z": -5,
      "name": "Rock_Basalt_Brick_Smooth",
      "rotation": 2
    },
    {
      "x": -33,
      "y": 2,
      "z": -5,
      "name": "Rock_Basalt_Brick_Smooth",
      "rotation": 2
    },
    {
      "x": -33,
      "y": 3,
      "z": -5,
      "name": "Rock_Basalt_Brick_Smooth",
      "rotation": 2
    },
    {
      "x": -33,
      "y": 4,
      "z": -5,
      "name": "Rock_Basalt_Brick_Smooth",
      "rotation": 2
    },
    {
      "x": -33,
      "y": 5,
      "z": -5,
      "name": "Rock_Basalt_Brick_Smooth",
      "rotation": 2
    },
    {
      "x": -33,
      "y": 6,
      "z": -5,
      "name": "Rock_Basalt_Brick_Smooth",
      "rotation": 2
    },
    {
      "x": -33,
      "y": 7,
      "z": -5,
      "name": "Rock_Basalt_Brick_Smooth",
      "rotation": 2
    },
    {
      "x": -33,
      "y": 8,
      "z": -5,
      "name": "Rock_Basalt_Brick_Smooth",
      "rotation": 2
    },
    {
      "x": -33,
      "y": 9,
      "z": -5,
      "name": "Rock_Basalt_Brick_Smooth",
      "rotation": 2
    },
    {
      "x": -33,
      "y": 10,
      "z": -5,
      "name": "Rock_Basalt_Brick_Smooth",
      "rotation": 2
    },
    {
      "x": -33,
      "y": 11,
      "z": -5,
      "name": "Rock_Basalt_Brick_Smooth",
      "rotation": 2
    },
    {
      "x": -33,
      "y": 12,
      "z": -5,
      "name": "Rock_Basalt_Brick_Smooth",
      "rotation": 2
    },
    {
      "x": -33,
      "y": 13,
      "z": -5,
      "name": "Rock_Basalt_Brick_Smooth",
      "rotation": 2
    },
    {
      "x": -33,
      "y": 14,
      "z": -5,
      "name": "Rock_Basalt_Brick_Smooth",
      "rotation": 2
    },
    {
      "x": -33,
      "y": 15,
      "z": -5,
      "name": "Rock_Basalt_Brick_Smooth",
      "rotation": 2
    },
    {
      "x": -33,
      "y": 16,
      "z": -5,
      "name": "Rock_Basalt_Brick_Smooth",
      "rotation": 2
    },
    {
      "x": -33,
      "y": 17,
      "z": -5,
      "name": "Rock_Basalt_Brick_Smooth",
      "rotation": 2
    },
    {
      "x": -33,
      "y": 18,
      "z": -5,
      "name": "Rock_Basalt_Brick_Smooth",
      "rotation": 2
    },
    {
      "x": -33,
      "y": 19,
      "z": -5,
      "name": "Rock_Basalt_Brick_Smooth",
      "rotation": 2
    },
    {
      "x": -33,
      "y": 20,
      "z": -5,
      "name": "Rock_Basalt_Brick_Smooth",
      "rotation": 2
    },
    {
      "x": -33,
      "y": 21,
      "z": -5,
      "name": "Rock_Basalt_Brick_Smooth",
      "rotation": 2
    },
    {
      "x": -33,
      "y": 22,
      "z": -5,
      "name": "Rock_Basalt_Brick_Smooth",
      "rotation": 2
    },
    {
      "x": -33,
      "y": 23,
      "z": -5,
      "name": "Rock_Basalt_Brick_Smooth",
      "rotation": 2
    },
    {
      "x": -33,
      "y": 0,
      "z": -4,
      "name": "Rock_Basalt_Brick_Smooth",
      "rotation": 2
    },
    {
      "x": -33,
      "y": 1,
      "z": -4,
      "name": "Rock_Basalt_Brick_Smooth",
      "rotation": 2
    },
    {
      "x": -33,
      "y": 2,
      "z": -4,
      "name": "Rock_Basalt_Brick_Smooth",
      "rotation": 2
    },
    {
      "x": -33,
      "y": 3,
      "z": -4,
      "name": "Rock_Basalt_Brick_Smooth",
      "rotation": 2
    },
    {
      "x": -33,
      "y": 4,
      "z": -4,
      "name": "Rock_Basalt_Brick_Smooth",
      "rotation": 2
    },
    {
      "x": -33,
      "y": 5,
      "z": -4,
      "name": "Rock_Basalt_Brick_Smooth",
      "rotation": 2
    },
    {
      "x": -33,
      "y": 6,
      "z": -4,
      "name": "Rock_Basalt_Brick_Smooth",
      "rotation": 2
    },
    {
      "x": -33,
      "y": 7,
      "z": -4,
      "name": "Rock_Basalt_Brick_Smooth",
      "rotation": 2
    },
    {
      "x": -33,
      "y": 8,
      "z": -4,
      "name": "Rock_Basalt_Brick_Smooth",
      "rotation": 2
    },
    {
      "x": -33,
      "y": 9,
      "z": -4,
      "name": "Rock_Basalt_Brick_Smooth",
      "rotation": 2
    },
    {
      "x": -33,
      "y": 10,
      "z": -4,
      "name": "Rock_Basalt_Brick_Smooth",
      "rotation": 2
    },
    {
      "x": -33,
      "y": 11,
      "z": -4,
      "name": "Rock_Basalt_Brick_Smooth",
      "rotation": 2
    },
    {
      "x": -33,
      "y": 12,
      "z": -4,
      "name": "Rock_Basalt_Brick_Smooth",
      "rotation": 2
    },
    {
      "x": -33,
      "y": 13,
      "z": -4,
      "name": "Rock_Basalt_Brick_Smooth",
      "rotation": 2
    },
    {
      "x": -33,
      "y": 14,
      "z": -4,
      "name": "Rock_Basalt_Brick_Smooth",
      "rotation": 2
    },
    {
      "x": -33,
      "y": 15,
      "z": -4,
      "name": "Rock_Basalt_Brick_Smooth",
      "rotation": 2
    },
    {
      "x": -33,
      "y": 16,
      "z": -4,
      "name": "Rock_Basalt_Brick_Smooth",
      "rotation": 2
    },
    {
      "x": -33,
      "y": 17,
      "z": -4,
      "name": "Rock_Basalt_Brick_Smooth",
      "rotation": 2
    },
    {
      "x": -33,
      "y": 18,
      "z": -4,
      "name": "Rock_Basalt_Brick_Smooth",
      "rotation": 2
    },
    {
      "x": -33,
      "y": 19,
      "z": -4,
      "name": "Rock_Basalt_Brick_Smooth",
      "rotation": 2
    },
    {
      "x": -33,
      "y": 20,
      "z": -4,
      "name": "Rock_Basalt_Brick_Smooth",
      "rotation": 2
    },
    {
      "x": -33,
      "y": 21,
      "z": -4,
      "name": "Rock_Basalt_Brick_Smooth",
      "rotation": 2
    },
    {
      "x": -33,
      "y": 22,
      "z": -4,
      "name": "Rock_Basalt_Brick_Smooth",
      "rotation": 2
    },
    {
      "x": -33,
      "y": 23,
      "z": -4,
      "name": "Rock_Basalt_Brick_Smooth",
      "rotation": 2
    },
    {
      "x": -33,
      "y": 0,
      "z": -3,
      "name": "Rock_Basalt_Brick_Smooth",
      "rotation": 2
    },
    {
      "x": -33,
      "y": 1,
      "z": -3,
      "name": "Rock_Basalt_Brick_Smooth",
      "rotation": 2
    },
    {
      "x": -33,
      "y": 2,
      "z": -3,
      "name": "Rock_Basalt_Brick_Smooth",
      "rotation": 2
    },
    {
      "x": -33,
      "y": 3,
      "z": -3,
      "name": "Rock_Basalt_Brick_Smooth",
      "rotation": 2
    },
    {
      "x": -33,
      "y": 4,
      "z": -3,
      "name": "Rock_Basalt_Brick_Smooth",
      "rotation": 2
    },
    {
      "x": -33,
      "y": 5,
      "z": -3,
      "name": "Rock_Basalt_Brick_Smooth",
      "rotation": 2
    },
    {
      "x": -33,
      "y": 6,
      "z": -3,
      "name": "Rock_Basalt_Brick_Smooth",
      "rotation": 2
    },
    {
      "x": -33,
      "y": 7,
      "z": -3,
      "name": "Rock_Basalt_Brick_Smooth",
      "rotation": 2
    },
    {
      "x": -33,
      "y": 8,
      "z": -3,
      "name": "Rock_Basalt_Brick_Smooth",
      "rotation": 2
    },
    {
      "x": -33,
      "y": 9,
      "z": -3,
      "name": "Rock_Basalt_Brick_Smooth",
      "rotation": 2
    },
    {
      "x": -33,
      "y": 10,
      "z": -3,
      "name": "Rock_Basalt_Brick_Smooth",
      "rotation": 2
    },
    {
      "x": -33,
      "y": 11,
      "z": -3,
      "name": "Rock_Basalt_Brick_Smooth",
      "rotation": 2
    },
    {
      "x": -33,
      "y": 12,
      "z": -3,
      "name": "Rock_Basalt_Brick_Smooth",
      "rotation": 2
    },
    {
      "x": -33,
      "y": 13,
      "z": -3,
      "name": "Rock_Basalt_Brick_Smooth",
      "rotation": 2
    },
    {
      "x": -33,
      "y": 14,
      "z": -3,
      "name": "Rock_Basalt_Brick_Smooth",
      "rotation": 2
    },
    {
      "x": -33,
      "y": 15,
      "z": -3,
      "name": "Rock_Basalt_Brick_Smooth",
      "rotation": 2
    },
    {
      "x": -33,
      "y": 16,
      "z": -3,
      "name": "Rock_Basalt_Brick_Smooth",
      "rotation": 2
    },
    {
      "x": -33,
      "y": 17,
      "z": -3,
      "name": "Rock_Basalt_Brick_Smooth",
      "rotation": 2
    },
    {
      "x": -33,
      "y": 18,
      "z": -3,
      "name": "Rock_Basalt_Brick_Smooth",
      "rotation": 2
    },
    {
      "x": -33,
      "y": 19,
      "z": -3,
      "name": "Rock_Basalt_Brick_Smooth",
      "rotation": 2
    },
    {
      "x": -33,
      "y": 20,
      "z": -3,
      "name": "Rock_Basalt_Brick_Smooth",
      "rotation": 2
    },
    {
      "x": -33,
      "y": 21,
      "z": -3,
      "name": "Rock_Basalt_Brick_Smooth",
      "rotation": 2
    },
    {
      "x": -33,
      "y": 22,
      "z": -3,
      "name": "Rock_Basalt_Brick_Smooth",
      "rotation": 2
    },
    {
      "x": -33,
      "y": 23,
      "z": -3,
      "name": "Rock_Basalt_Brick_Smooth",
      "rotation": 2
    },
    {
      "x": -33,
      "y": 0,
      "z": -2,
      "name": "Rock_Basalt_Brick_Smooth",
      "rotation": 2
    },
    {
      "x": -33,
      "y": 1,
      "z": -2,
      "name": "Rock_Basalt_Brick_Smooth",
      "rotation": 2
    },
    {
      "x": -33,
      "y": 2,
      "z": -2,
      "name": "Rock_Basalt_Brick_Smooth",
      "rotation": 2
    },
    {
      "x": -33,
      "y": 3,
      "z": -2,
      "name": "Rock_Basalt_Brick_Smooth",
      "rotation": 2
    },
    {
      "x": -33,
      "y": 4,
      "z": -2,
      "name": "Rock_Basalt_Brick_Smooth",
      "rotation": 2
    },
    {
      "x": -33,
      "y": 5,
      "z": -2,
      "name": "Rock_Basalt_Brick_Smooth",
      "rotation": 2
    },
    {
      "x": -33,
      "y": 6,
      "z": -2,
      "name": "Rock_Basalt_Brick_Smooth",
      "rotation": 2
    },
    {
      "x": -33,
      "y": 7,
      "z": -2,
      "name": "Rock_Basalt_Brick_Smooth",
      "rotation": 2
    },
    {
      "x": -33,
      "y": 8,
      "z": -2,
      "name": "Rock_Basalt_Brick_Smooth",
      "rotation": 2
    },
    {
      "x": -33,
      "y": 9,
      "z": -2,
      "name": "Rock_Basalt_Brick_Smooth",
      "rotation": 2
    },
    {
      "x": -33,
      "y": 10,
      "z": -2,
      "name": "Rock_Basalt_Brick_Smooth",
      "rotation": 2
    },
    {
      "x": -33,
      "y": 11,
      "z": -2,
      "name": "Rock_Basalt_Brick_Smooth",
      "rotation": 2
    },
    {
      "x": -33,
      "y": 12,
      "z": -2,
      "name": "Rock_Basalt_Brick_Smooth",
      "rotation": 2
    },
    {
      "x": -33,
      "y": 13,
      "z": -2,
      "name": "Rock_Basalt_Brick_Smooth",
      "rotation": 2
    },
    {
      "x": -33,
      "y": 14,
      "z": -2,
      "name": "Rock_Basalt_Brick_Smooth",
      "rotation": 2
    },
    {
      "x": -33,
      "y": 15,
      "z": -2,
      "name": "Rock_Basalt_Brick_Smooth",
      "rotation": 2
    },
    {
      "x": -33,
      "y": 16,
      "z": -2,
      "name": "Rock_Basalt_Brick_Smooth",
      "rotation": 2
    },
    {
      "x": -33,
      "y": 17,
      "z": -2,
      "name": "Rock_Basalt_Brick_Smooth",
      "rotation": 2
    },
    {
      "x": -33,
      "y": 18,
      "z": -2,
      "name": "Rock_Basalt_Brick_Smooth",
      "rotation": 2
    },
    {
      "x": -33,
      "y": 19,
      "z": -2,
      "name": "Rock_Basalt_Brick_Smooth",
      "rotation": 2
    },
    {
      "x": -33,
      "y": 20,
      "z": -2,
      "name": "Rock_Basalt_Brick_Smooth",
      "rotation": 2
    },
    {
      "x": -33,
      "y": 21,
      "z": -2,
      "name": "Rock_Basalt_Brick_Smooth",
      "rotation": 2
    },
    {
      "x": -33,
      "y": 22,
      "z": -2,
      "name": "Rock_Basalt_Brick_Smooth",
      "rotation": 2
    },
    {
      "x": -33,
      "y": 23,
      "z": -2,
      "name": "Rock_Basalt_Brick_Smooth",
      "rotation": 2
    },
    {
      "x": -33,
      "y": 0,
      "z": -1,
      "name": "Rock_Basalt_Brick_Smooth",
      "rotation": 2
    },
    {
      "x": -33,
      "y": 1,
      "z": -1,
      "name": "Rock_Basalt_Brick_Smooth",
      "rotation": 2
    },
    {
      "x": -33,
      "y": 2,
      "z": -1,
      "name": "Rock_Basalt_Brick_Smooth",
      "rotation": 2
    },
    {
      "x": -33,
      "y": 3,
      "z": -1,
      "name": "Rock_Basalt_Brick_Smooth",
      "rotation": 2
    },
    {
      "x": -33,
      "y": 4,
      "z": -1,
      "name": "Rock_Basalt_Brick_Smooth",
      "rotation": 2
    },
    {
      "x": -33,
      "y": 5,
      "z": -1,
      "name": "Rock_Basalt_Brick_Smooth",
      "rotation": 2
    },
    {
      "x": -33,
      "y": 6,
      "z": -1,
      "name": "Rock_Basalt_Brick_Smooth",
      "rotation": 2
    },
    {
      "x": -33,
      "y": 7,
      "z": -1,
      "name": "Rock_Basalt_Brick_Smooth",
      "rotation": 2
    },
    {
      "x": -33,
      "y": 8,
      "z": -1,
      "name": "Rock_Basalt_Brick_Smooth",
      "rotation": 2
    },
    {
      "x": -33,
      "y": 9,
      "z": -1,
      "name": "Rock_Basalt_Brick_Smooth",
      "rotation": 2
    },
    {
      "x": -33,
      "y": 10,
      "z": -1,
      "name": "Rock_Basalt_Brick_Smooth",
      "rotation": 2
    },
    {
      "x": -33,
      "y": 11,
      "z": -1,
      "name": "Rock_Basalt_Brick_Smooth",
      "rotation": 2
    },
    {
      "x": -33,
      "y": 12,
      "z": -1,
      "name": "Rock_Basalt_Brick_Smooth",
      "rotation": 2
    },
    {
      "x": -33,
      "y": 13,
      "z": -1,
      "name": "Rock_Basalt_Brick_Smooth",
      "rotation": 2
    },
    {
      "x": -33,
      "y": 14,
      "z": -1,
      "name": "Rock_Basalt_Brick_Smooth",
      "rotation": 2
    },
    {
      "x": -33,
      "y": 15,
      "z": -1,
      "name": "Rock_Basalt_Brick_Smooth",
      "rotation": 2
    },
    {
      "x": -33,
      "y": 16,
      "z": -1,
      "name": "Rock_Basalt_Brick_Smooth",
      "rotation": 2
    },
    {
      "x": -33,
      "y": 17,
      "z": -1,
      "name": "Empty"
    },
    {
      "x": -33,
      "y": 18,
      "z": -1,
      "name": "Empty"
    },
    {
      "x": -33,
      "y": 19,
      "z": -1,
      "name": "Empty"
    },
    {
      "x": -33,
      "y": 20,
      "z": -1,
      "name": "Rock_Basalt_Brick_Smooth",
      "rotation": 2
    },
    {
      "x": -33,
      "y": 21,
      "z": -1,
      "name": "Rock_Basalt_Brick_Smooth",
      "rotation": 2
    },
    {
      "x": -33,
      "y": 22,
      "z": -1,
      "name": "Rock_Basalt_Brick_Smooth",
      "rotation": 2
    },
    {
      "x": -33,
      "y": 23,
      "z": -1,
      "name": "Rock_Basalt_Brick_Smooth",
      "rotation": 2
    },
    {
      "x": -33,
      "y": 0,
      "z": 0,
      "name": "Rock_Basalt_Brick_Smooth",
      "rotation": 2
    },
    {
      "x": -33,
      "y": 1,
      "z": 0,
      "name": "Rock_Basalt_Brick_Smooth",
      "rotation": 2
    },
    {
      "x": -33,
      "y": 2,
      "z": 0,
      "name": "Rock_Basalt_Brick_Smooth",
      "rotation": 2
    },
    {
      "x": -33,
      "y": 3,
      "z": 0,
      "name": "Rock_Basalt_Brick_Smooth",
      "rotation": 2
    },
    {
      "x": -33,
      "y": 4,
      "z": 0,
      "name": "Rock_Basalt_Brick_Smooth",
      "rotation": 2
    },
    {
      "x": -33,
      "y": 5,
      "z": 0,
      "name": "Rock_Basalt_Brick_Smooth",
      "rotation": 2
    },
    {
      "x": -33,
      "y": 6,
      "z": 0,
      "name": "Rock_Basalt_Brick_Smooth",
      "rotation": 2
    },
    {
      "x": -33,
      "y": 7,
      "z": 0,
      "name": "Rock_Basalt_Brick_Smooth",
      "rotation": 2
    },
    {
      "x": -33,
      "y": 8,
      "z": 0,
      "name": "Rock_Basalt_Brick_Smooth",
      "rotation": 2
    },
    {
      "x": -33,
      "y": 9,
      "z": 0,
      "name": "Rock_Basalt_Brick_Smooth",
      "rotation": 2
    },
    {
      "x": -33,
      "y": 10,
      "z": 0,
      "name": "Rock_Basalt_Brick_Smooth",
      "rotation": 2
    },
    {
      "x": -33,
      "y": 11,
      "z": 0,
      "name": "Rock_Basalt_Brick_Smooth",
      "rotation": 2
    },
    {
      "x": -33,
      "y": 12,
      "z": 0,
      "name": "Rock_Basalt_Brick_Smooth",
      "rotation": 2
    },
    {
      "x": -33,
      "y": 13,
      "z": 0,
      "name": "Rock_Basalt_Brick_Smooth",
      "rotation": 2
    },
    {
      "x": -33,
      "y": 14,
      "z": 0,
      "name": "Rock_Basalt_Brick_Smooth",
      "rotation": 2
    },
    {
      "x": -33,
      "y": 15,
      "z": 0,
      "name": "Rock_Basalt_Brick_Smooth",
      "rotation": 2
    },
    {
      "x": -33,
      "y": 16,
      "z": 0,
      "name": "Rock_Basalt_Brick_Smooth",
      "rotation": 2
    },
    {
      "x": -33,
      "y": 17,
      "z": 0,
      "name": "Empty"
    },
    {
      "x": -33,
      "y": 18,
      "z": 0,
      "name": "Empty"
    },
    {
      "x": -33,
      "y": 19,
      "z": 0,
      "name": "Empty"
    },
    {
      "x": -33,
      "y": 20,
      "z": 0,
      "name": "Rock_Basalt_Brick_Smooth",
      "rotation": 2
    },
    {
      "x": -33,
      "y": 21,
      "z": 0,
      "name": "Rock_Basalt_Brick_Smooth",
      "rotation": 2
    },
    {
      "x": -33,
      "y": 22,
      "z": 0,
      "name": "Rock_Basalt_Brick_Smooth",
      "rotation": 2
    },
    {
      "x": -33,
      "y": 23,
      "z": 0,
      "name": "Rock_Basalt_Brick_Smooth",
      "rotation": 2
    },
    {
      "x": -33,
      "y": 0,
      "z": 1,
      "name": "Rock_Basalt_Brick_Smooth",
      "rotation": 2
    },
    {
      "x": -33,
      "y": 1,
      "z": 1,
      "name": "Rock_Basalt_Brick_Smooth",
      "rotation": 2
    },
    {
      "x": -33,
      "y": 2,
      "z": 1,
      "name": "Rock_Basalt_Brick_Smooth",
      "rotation": 2
    },
    {
      "x": -33,
      "y": 3,
      "z": 1,
      "name": "Rock_Basalt_Brick_Smooth",
      "rotation": 2
    },
    {
      "x": -33,
      "y": 4,
      "z": 1,
      "name": "Rock_Basalt_Brick_Smooth",
      "rotation": 2
    },
    {
      "x": -33,
      "y": 5,
      "z": 1,
      "name": "Rock_Basalt_Brick_Smooth",
      "rotation": 2
    },
    {
      "x": -33,
      "y": 6,
      "z": 1,
      "name": "Rock_Basalt_Brick_Smooth",
      "rotation": 2
    },
    {
      "x": -33,
      "y": 7,
      "z": 1,
      "name": "Rock_Basalt_Brick_Smooth",
      "rotation": 2
    },
    {
      "x": -33,
      "y": 8,
      "z": 1,
      "name": "Rock_Basalt_Brick_Smooth",
      "rotation": 2
    },
    {
      "x": -33,
      "y": 9,
      "z": 1,
      "name": "Rock_Basalt_Brick_Smooth",
      "rotation": 2
    },
    {
      "x": -33,
      "y": 10,
      "z": 1,
      "name": "Rock_Basalt_Brick_Smooth",
      "rotation": 2
    },
    {
      "x": -33,
      "y": 11,
      "z": 1,
      "name": "Rock_Basalt_Brick_Smooth",
      "rotation": 2
    },
    {
      "x": -33,
      "y": 12,
      "z": 1,
      "name": "Rock_Basalt_Brick_Smooth",
      "rotation": 2
    },
    {
      "x": -33,
      "y": 13,
      "z": 1,
      "name": "Rock_Basalt_Brick_Smooth",
      "rotation": 2
    },
    {
      "x": -33,
      "y": 14,
      "z": 1,
      "name": "Rock_Basalt_Brick_Smooth",
      "rotation": 2
    },
    {
      "x": -33,
      "y": 15,
      "z": 1,
      "name": "Rock_Basalt_Brick_Smooth",
      "rotation": 2
    },
    {
      "x": -33,
      "y": 16,
      "z": 1,
      "name": "Rock_Basalt_Brick_Smooth",
      "rotation": 2
    },
    {
      "x": -33,
      "y": 17,
      "z": 1,
      "name": "Empty"
    },
    {
      "x": -33,
      "y": 18,
      "z": 1,
      "name": "Empty"
    },
    {
      "x": -33,
      "y": 19,
      "z": 1,
      "name": "Empty"
    },
    {
      "x": -33,
      "y": 20,
      "z": 1,
      "name": "Rock_Basalt_Brick_Smooth",
      "rotation": 2
    },
    {
      "x": -33,
      "y": 21,
      "z": 1,
      "name": "Rock_Basalt_Brick_Smooth",
      "rotation": 2
    },
    {
      "x": -33,
      "y": 22,
      "z": 1,
      "name": "Rock_Basalt_Brick_Smooth",
      "rotation": 2
    },
    {
      "x": -33,
      "y": 23,
      "z": 1,
      "name": "Rock_Basalt_Brick_Smooth",
      "rotation": 2
    },
    {
      "x": -33,
      "y": 0,
      "z": 2,
      "name": "Rock_Basalt_Brick_Smooth",
      "rotation": 2
    },
    {
      "x": -33,
      "y": 1,
      "z": 2,
      "name": "Rock_Basalt_Brick_Smooth",
      "rotation": 2
    },
    {
      "x": -33,
      "y": 2,
      "z": 2,
      "name": "Rock_Basalt_Brick_Smooth",
      "rotation": 2
    },
    {
      "x": -33,
      "y": 3,
      "z": 2,
      "name": "Rock_Basalt_Brick_Smooth",
      "rotation": 2
    },
    {
      "x": -33,
      "y": 4,
      "z": 2,
      "name": "Rock_Basalt_Brick_Smooth",
      "rotation": 2
    },
    {
      "x": -33,
      "y": 5,
      "z": 2,
      "name": "Rock_Basalt_Brick_Smooth",
      "rotation": 2
    },
    {
      "x": -33,
      "y": 6,
      "z": 2,
      "name": "Rock_Basalt_Brick_Smooth",
      "rotation": 2
    },
    {
      "x": -33,
      "y": 7,
      "z": 2,
      "name": "Rock_Basalt_Brick_Smooth",
      "rotation": 2
    },
    {
      "x": -33,
      "y": 8,
      "z": 2,
      "name": "Rock_Basalt_Brick_Smooth",
      "rotation": 2
    },
    {
      "x": -33,
      "y": 9,
      "z": 2,
      "name": "Rock_Basalt_Brick_Smooth",
      "rotation": 2
    },
    {
      "x": -33,
      "y": 10,
      "z": 2,
      "name": "Rock_Basalt_Brick_Smooth",
      "rotation": 2
    },
    {
      "x": -33,
      "y": 11,
      "z": 2,
      "name": "Rock_Basalt_Brick_Smooth",
      "rotation": 2
    },
    {
      "x": -33,
      "y": 12,
      "z": 2,
      "name": "Rock_Basalt_Brick_Smooth",
      "rotation": 2
    },
    {
      "x": -33,
      "y": 13,
      "z": 2,
      "name": "Rock_Basalt_Brick_Smooth",
      "rotation": 2
    },
    {
      "x": -33,
      "y": 14,
      "z": 2,
      "name": "Rock_Basalt_Brick_Smooth",
      "rotation": 2
    },
    {
      "x": -33,
      "y": 15,
      "z": 2,
      "name": "Rock_Basalt_Brick_Smooth",
      "rotation": 2
    },
    {
      "x": -33,
      "y": 16,
      "z": 2,
      "name": "Rock_Basalt_Brick_Smooth",
      "rotation": 2
    },
    {
      "x": -33,
      "y": 17,
      "z": 2,
      "name": "Rock_Basalt_Brick_Smooth",
      "rotation": 2
    },
    {
      "x": -33,
      "y": 18,
      "z": 2,
      "name": "Rock_Basalt_Brick_Smooth",
      "rotation": 2
    },
    {
      "x": -33,
      "y": 19,
      "z": 2,
      "name": "Rock_Basalt_Brick_Smooth",
      "rotation": 2
    },
    {
      "x": -33,
      "y": 20,
      "z": 2,
      "name": "Rock_Basalt_Brick_Smooth",
      "rotation": 2
    },
    {
      "x": -33,
      "y": 21,
      "z": 2,
      "name": "Rock_Basalt_Brick_Smooth",
      "rotation": 2
    },
    {
      "x": -33,
      "y": 22,
      "z": 2,
      "name": "Rock_Basalt_Brick_Smooth",
      "rotation": 2
    },
    {
      "x": -33,
      "y": 23,
      "z": 2,
      "name": "Rock_Basalt_Brick_Smooth",
      "rotation": 2
    },
    {
      "x": -33,
      "y": 0,
      "z": 3,
      "name": "Rock_Basalt_Brick_Smooth",
      "rotation": 2
    },
    {
      "x": -33,
      "y": 1,
      "z": 3,
      "name": "Rock_Basalt_Brick_Smooth",
      "rotation": 2
    },
    {
      "x": -33,
      "y": 2,
      "z": 3,
      "name": "Rock_Basalt_Brick_Smooth",
      "rotation": 2
    },
    {
      "x": -33,
      "y": 3,
      "z": 3,
      "name": "Rock_Basalt_Brick_Smooth",
      "rotation": 2
    },
    {
      "x": -33,
      "y": 4,
      "z": 3,
      "name": "Rock_Basalt_Brick_Smooth",
      "rotation": 2
    },
    {
      "x": -33,
      "y": 5,
      "z": 3,
      "name": "Rock_Basalt_Brick_Smooth",
      "rotation": 2
    },
    {
      "x": -33,
      "y": 6,
      "z": 3,
      "name": "Rock_Basalt_Brick_Smooth",
      "rotation": 2
    },
    {
      "x": -33,
      "y": 7,
      "z": 3,
      "name": "Rock_Basalt_Brick_Smooth",
      "rotation": 2
    },
    {
      "x": -33,
      "y": 8,
      "z": 3,
      "name": "Rock_Basalt_Brick_Smooth",
      "rotation": 2
    },
    {
      "x": -33,
      "y": 9,
      "z": 3,
      "name": "Rock_Basalt_Brick_Smooth",
      "rotation": 2
    },
    {
      "x": -33,
      "y": 10,
      "z": 3,
      "name": "Rock_Basalt_Brick_Smooth",
      "rotation": 2
    },
    {
      "x": -33,
      "y": 11,
      "z": 3,
      "name": "Rock_Basalt_Brick_Smooth",
      "rotation": 2
    },
    {
      "x": -33,
      "y": 12,
      "z": 3,
      "name": "Rock_Basalt_Brick_Smooth",
      "rotation": 2
    },
    {
      "x": -33,
      "y": 13,
      "z": 3,
      "name": "Rock_Basalt_Brick_Smooth",
      "rotation": 2
    },
    {
      "x": -33,
      "y": 14,
      "z": 3,
      "name": "Rock_Basalt_Brick_Smooth",
      "rotation": 2
    },
    {
      "x": -33,
      "y": 15,
      "z": 3,
      "name": "Rock_Basalt_Brick_Smooth",
      "rotation": 2
    },
    {
      "x": -33,
      "y": 16,
      "z": 3,
      "name": "Rock_Basalt_Brick_Smooth",
      "rotation": 2
    },
    {
      "x": -33,
      "y": 17,
      "z": 3,
      "name": "Rock_Basalt_Brick_Smooth",
      "rotation": 2
    },
    {
      "x": -33,
      "y": 18,
      "z": 3,
      "name": "Rock_Basalt_Brick_Smooth",
      "rotation": 2
    },
    {
      "x": -33,
      "y": 19,
      "z": 3,
      "name": "Rock_Basalt_Brick_Smooth",
      "rotation": 2
    },
    {
      "x": -33,
      "y": 20,
      "z": 3,
      "name": "Rock_Basalt_Brick_Smooth",
      "rotation": 2
    },
    {
      "x": -33,
      "y": 21,
      "z": 3,
      "name": "Rock_Basalt_Brick_Smooth",
      "rotation": 2
    },
    {
      "x": -33,
      "y": 22,
      "z": 3,
      "name": "Rock_Basalt_Brick_Smooth",
      "rotation": 2
    },
    {
      "x": -33,
      "y": 23,
      "z": 3,
      "name": "Rock_Basalt_Brick_Smooth",
      "rotation": 2
    },
    {
      "x": -33,
      "y": 0,
      "z": 4,
      "name": "Rock_Basalt_Brick_Smooth",
      "rotation": 2
    },
    {
      "x": -33,
      "y": 1,
      "z": 4,
      "name": "Rock_Basalt_Brick_Smooth",
      "rotation": 2
    },
    {
      "x": -33,
      "y": 2,
      "z": 4,
      "name": "Rock_Basalt_Brick_Smooth",
      "rotation": 2
    },
    {
      "x": -33,
      "y": 3,
      "z": 4,
      "name": "Rock_Basalt_Brick_Smooth",
      "rotation": 2
    },
    {
      "x": -33,
      "y": 4,
      "z": 4,
      "name": "Rock_Basalt_Brick_Smooth",
      "rotation": 2
    },
    {
      "x": -33,
      "y": 5,
      "z": 4,
      "name": "Rock_Basalt_Brick_Smooth",
      "rotation": 2
    },
    {
      "x": -33,
      "y": 6,
      "z": 4,
      "name": "Rock_Basalt_Brick_Smooth",
      "rotation": 2
    },
    {
      "x": -33,
      "y": 7,
      "z": 4,
      "name": "Rock_Basalt_Brick_Smooth",
      "rotation": 2
    },
    {
      "x": -33,
      "y": 8,
      "z": 4,
      "name": "Rock_Basalt_Brick_Smooth",
      "rotation": 2
    },
    {
      "x": -33,
      "y": 9,
      "z": 4,
      "name": "Rock_Basalt_Brick_Smooth",
      "rotation": 2
    },
    {
      "x": -33,
      "y": 10,
      "z": 4,
      "name": "Rock_Basalt_Brick_Smooth",
      "rotation": 2
    },
    {
      "x": -33,
      "y": 11,
      "z": 4,
      "name": "Rock_Basalt_Brick_Smooth",
      "rotation": 2
    },
    {
      "x": -33,
      "y": 12,
      "z": 4,
      "name": "Rock_Basalt_Brick_Smooth",
      "rotation": 2
    },
    {
      "x": -33,
      "y": 13,
      "z": 4,
      "name": "Rock_Basalt_Brick_Smooth",
      "rotation": 2
    },
    {
      "x": -33,
      "y": 14,
      "z": 4,
      "name": "Rock_Basalt_Brick_Smooth",
      "rotation": 2
    },
    {
      "x": -33,
      "y": 15,
      "z": 4,
      "name": "Rock_Basalt_Brick_Smooth",
      "rotation": 2
    },
    {
      "x": -33,
      "y": 16,
      "z": 4,
      "name": "Rock_Basalt_Brick_Smooth",
      "rotation": 2
    },
    {
      "x": -33,
      "y": 17,
      "z": 4,
      "name": "Rock_Basalt_Brick_Smooth",
      "rotation": 2
    },
    {
      "x": -33,
      "y": 18,
      "z": 4,
      "name": "Rock_Basalt_Brick_Smooth",
      "rotation": 2
    },
    {
      "x": -33,
      "y": 19,
      "z": 4,
      "name": "Rock_Basalt_Brick_Smooth",
      "rotation": 2
    },
    {
      "x": -33,
      "y": 20,
      "z": 4,
      "name": "Rock_Basalt_Brick_Smooth",
      "rotation": 2
    },
    {
      "x": -33,
      "y": 21,
      "z": 4,
      "name": "Rock_Basalt_Brick_Smooth",
      "rotation": 2
    },
    {
      "x": -33,
      "y": 22,
      "z": 4,
      "name": "Rock_Basalt_Brick_Smooth",
      "rotation": 2
    },
    {
      "x": -33,
      "y": 23,
      "z": 4,
      "name": "Rock_Basalt_Brick_Smooth",
      "rotation": 2
    },
    {
      "x": -33,
      "y": 0,
      "z": 5,
      "name": "Rock_Basalt_Brick_Smooth",
      "rotation": 2
    },
    {
      "x": -33,
      "y": 1,
      "z": 5,
      "name": "Rock_Basalt_Brick_Smooth",
      "rotation": 2
    },
    {
      "x": -33,
      "y": 2,
      "z": 5,
      "name": "Rock_Basalt_Brick_Smooth",
      "rotation": 2
    },
    {
      "x": -33,
      "y": 3,
      "z": 5,
      "name": "Rock_Basalt_Brick_Smooth",
      "rotation": 2
    },
    {
      "x": -33,
      "y": 4,
      "z": 5,
      "name": "Rock_Basalt_Brick_Smooth",
      "rotation": 2
    },
    {
      "x": -33,
      "y": 5,
      "z": 5,
      "name": "Rock_Basalt_Brick_Smooth",
      "rotation": 2
    },
    {
      "x": -33,
      "y": 6,
      "z": 5,
      "name": "Rock_Basalt_Brick_Smooth",
      "rotation": 2
    },
    {
      "x": -33,
      "y": 7,
      "z": 5,
      "name": "Rock_Basalt_Brick_Smooth",
      "rotation": 2
    },
    {
      "x": -33,
      "y": 8,
      "z": 5,
      "name": "Rock_Basalt_Brick_Smooth",
      "rotation": 2
    },
    {
      "x": -33,
      "y": 9,
      "z": 5,
      "name": "Rock_Basalt_Brick_Smooth",
      "rotation": 2
    },
    {
      "x": -33,
      "y": 10,
      "z": 5,
      "name": "Rock_Basalt_Brick_Smooth",
      "rotation": 2
    },
    {
      "x": -33,
      "y": 11,
      "z": 5,
      "name": "Rock_Basalt_Brick_Smooth",
      "rotation": 2
    },
    {
      "x": -33,
      "y": 12,
      "z": 5,
      "name": "Rock_Basalt_Brick_Smooth",
      "rotation": 2
    },
    {
      "x": -33,
      "y": 13,
      "z": 5,
      "name": "Rock_Basalt_Brick_Smooth",
      "rotation": 2
    },
    {
      "x": -33,
      "y": 14,
      "z": 5,
      "name": "Rock_Basalt_Brick_Smooth",
      "rotation": 2
    },
    {
      "x": -33,
      "y": 15,
      "z": 5,
      "name": "Rock_Basalt_Brick_Smooth",
      "rotation": 2
    },
    {
      "x": -33,
      "y": 16,
      "z": 5,
      "name": "Rock_Basalt_Brick_Smooth",
      "rotation": 2
    },
    {
      "x": -33,
      "y": 17,
      "z": 5,
      "name": "Rock_Basalt_Brick_Smooth",
      "rotation": 2
    },
    {
      "x": -33,
      "y": 18,
      "z": 5,
      "name": "Rock_Basalt_Brick_Smooth",
      "rotation": 2
    },
    {
      "x": -33,
      "y": 19,
      "z": 5,
      "name": "Rock_Basalt_Brick_Smooth",
      "rotation": 2
    },
    {
      "x": -33,
      "y": 20,
      "z": 5,
      "name": "Rock_Basalt_Brick_Smooth",
      "rotation": 2
    },
    {
      "x": -33,
      "y": 21,
      "z": 5,
      "name": "Rock_Basalt_Brick_Smooth",
      "rotation": 2
    },
    {
      "x": -33,
      "y": 22,
      "z": 5,
      "name": "Rock_Basalt_Brick_Smooth",
      "rotation": 2
    },
    {
      "x": -33,
      "y": 23,
      "z": 5,
      "name": "Rock_Basalt_Brick_Smooth",
      "rotation": 2
    },
    {
      "x": -33,
      "y": 0,
      "z": 6,
      "name": "Rock_Basalt_Brick_Smooth",
      "rotation": 2
    },
    {
      "x": -33,
      "y": 1,
      "z": 6,
      "name": "Rock_Basalt_Brick_Smooth",
      "rotation": 2
    },
    {
      "x": -33,
      "y": 2,
      "z": 6,
      "name": "Rock_Basalt_Brick_Smooth",
      "rotation": 2
    },
    {
      "x": -33,
      "y": 3,
      "z": 6,
      "name": "Rock_Basalt_Brick_Smooth",
      "rotation": 2
    },
    {
      "x": -33,
      "y": 4,
      "z": 6,
      "name": "Rock_Basalt_Brick_Smooth",
      "rotation": 2
    },
    {
      "x": -33,
      "y": 5,
      "z": 6,
      "name": "Rock_Basalt_Brick_Smooth",
      "rotation": 2
    },
    {
      "x": -33,
      "y": 6,
      "z": 6,
      "name": "Rock_Basalt_Brick_Smooth",
      "rotation": 2
    },
    {
      "x": -33,
      "y": 7,
      "z": 6,
      "name": "Rock_Basalt_Brick_Smooth",
      "rotation": 2
    },
    {
      "x": -33,
      "y": 8,
      "z": 6,
      "name": "Rock_Basalt_Brick_Smooth",
      "rotation": 2
    },
    {
      "x": -33,
      "y": 9,
      "z": 6,
      "name": "Rock_Basalt_Brick_Smooth",
      "rotation": 2
    },
    {
      "x": -33,
      "y": 10,
      "z": 6,
      "name": "Rock_Basalt_Brick_Smooth",
      "rotation": 2
    },
    {
      "x": -33,
