{
  "version": 8,
  "blockIdVersion": 11,
  "anchorX": 0,
  "anchorY": 0,
  "anchorZ": 0,
  "PrefabList": "Salas_Roguelike",
  "blocks": [
    {
      "x": -9,
      "y": 0,
      "z": -7,
      "name": "Rock_Basalt_Brick_Smooth"
    },
    {
      "x": -9,
      "y": 1,
      "z": -7,
      "name": "Rock_Basalt_Brick_Smooth"
    },
    {
      "x": -9,
      "y": 2,
      "z": -7,
      "name": "Rock_Basalt_Brick_Smooth"
    },
    {
      "x": -9,
      "y": 3,
      "z": -7,
      "name": "Rock_Basalt_Brick_Smooth"
    },
    {
      "x": -9,
      "y": 4,
      "z": -7,
      "name": "Rock_Basalt_Brick_Smooth"
    },
    {
      "x": -9,
      "y": 5,
      "z": -7,
      "name": "Rock_Basalt_Brick_Smooth"
    },
    {
      "x": -9,
      "y": 6,
      "z": -7,
      "name": "Rock_Basalt_Brick_Smooth"
    },
    {
      "x": -9,
      "y": 7,
      "z": -7,
      "name": "Rock_Basalt_Brick_Smooth"
    },
    {
      "x": -9,
      "y": 0,
      "z": -6,
      "name": "Rock_Basalt_Brick_Smooth"
    },
    {
      "x": -9,
      "y": 1,
      "z": -6,
      "name": "Rock_Basalt_Brick_Smooth"
    },
    {
      "x": -9,
      "y": 2,
      "z": -6,
      "name": "Rock_Basalt_Brick_Smooth"
    },
    {
      "x": -9,
      "y": 3,
      "z": -6,
      "name": "Rock_Basalt_Brick_Smooth"
    },
    {
      "x": -9,
      "y": 4,
      "z": -6,
      "name": "Rock_Basalt_Brick_Smooth"
    },
    {
      "x": -9,
      "y": 5,
      "z": -6,
      "name": "Rock_Basalt_Brick_Smooth"
    },
    {
      "x": -9,
      "y": 6,
      "z": -6,
      "name": "Rock_Basalt_Brick_Smooth"
    },
    {
      "x": -9,
      "y": 7,
      "z": -6,
      "name": "Rock_Basalt_Brick_Smooth"
    },
    {
      "x": -9,
      "y": 0,
      "z": -5,
      "name": "Rock_Basalt_Brick_Smooth"
    },
    {
      "x": -9,
      "y": 1,
      "z": -5,
      "name": "Rock_Basalt_Brick_Smooth"
    },
    {
      "x": -9,
      "y": 2,
      "z": -5,
      "name": "Rock_Basalt_Brick_Smooth"
    },
    {
      "x": -9,
      "y": 3,
      "z": -5,
      "name": "Rock_Basalt_Brick_Smooth"
    },
    {
      "x": -9,
      "y": 4,
      "z": -5,
      "name": "Rock_Basalt_Brick_Smooth"
    },
    {
      "x": -9,
      "y": 5,
      "z": -5,
      "name": "Rock_Basalt_Brick_Smooth"
    },
    {
      "x": -9,
      "y": 6,
      "z": -5,
      "name": "Rock_Basalt_Brick_Smooth"
    },
    {
      "x": -9,
      "y": 7,
      "z": -5,
      "name": "Rock_Basalt_Brick_Smooth"
    },
    {
      "x": -9,
      "y": 0,
      "z": -4,
      "name": "Rock_Basalt_Brick_Smooth"
    },
    {
      "x": -9,
      "y": 1,
      "z": -4,
      "name": "Rock_Basalt_Brick_Smooth"
    },
    {
      "x": -9,
      "y": 2,
      "z": -4,
      "name": "Rock_Basalt_Brick_Smooth"
    },
    {
      "x": -9,
      "y": 3,
      "z": -4,
      "name": "Rock_Basalt_Brick_Smooth"
    },
    {
      "x": -9,
      "y": 4,
      "z": -4,
      "name": "Rock_Basalt_Brick_Smooth"
    },
    {
      "x": -9,
      "y": 5,
      "z": -4,
      "name": "Rock_Basalt_Brick_Smooth"
    },
    {
      "x": -9,
      "y": 6,
      "z": -4,
      "name": "Rock_Basalt_Brick_Smooth"
    },
    {
      "x": -9,
      "y": 7,
      "z": -4,
      "name": "Rock_Basalt_Brick_Smooth"
    },
    {
      "x": -9,
      "y": 0,
      "z": -3,
      "name": "Rock_Basalt_Brick_Smooth"
    },
    {
      "x": -9,
      "y": 1,
      "z": -3,
      "name": "Rock_Basalt_Brick_Smooth"
    },
    {
      "x": -9,
      "y": 2,
      "z": -3,
      "name": "Rock_Basalt_Brick_Smooth"
    },
    {
      "x": -9,
      "y": 3,
      "z": -3,
      "name": "Rock_Basalt_Brick_Smooth"
    },
    {
      "x": -9,
      "y": 4,
      "z": -3,
      "name": "Rock_Basalt_Brick_Smooth"
    },
    {
      "x": -9,
      "y": 5,
      "z": -3,
      "name": "Rock_Basalt_Brick_Smooth"
    },
    {
      "x": -9,
      "y": 6,
      "z": -3,
      "name": "Rock_Basalt_Brick_Smooth"
    },
    {
      "x": -9,
      "y": 7,
      "z": -3,
      "name": "Rock_Basalt_Brick_Smooth"
    },
    {
      "x": -9,
      "y": 0,
      "z": -2,
      "name": "Rock_Basalt_Brick_Smooth"
    },
    {
      "x": -9,
      "y": 1,
      "z": -2,
      "name": "Rock_Basalt_Brick_Smooth"
    },
    {
      "x": -9,
      "y": 2,
      "z": -2,
      "name": "Rock_Basalt_Brick_Smooth"
    },
    {
      "x": -9,
      "y": 3,
      "z": -2,
      "name": "Rock_Basalt_Brick_Smooth"
    },
    {
      "x": -9,
      "y": 4,
      "z": -2,
      "name": "Rock_Basalt_Brick_Smooth"
    },
    {
      "x": -9,
      "y": 5,
      "z": -2,
      "name": "Rock_Basalt_Brick_Smooth"
    },
    {
      "x": -9,
      "y": 6,
      "z": -2,
      "name": "Rock_Basalt_Brick_Smooth"
    },
    {
      "x": -9,
      "y": 7,
      "z": -2,
      "name": "Rock_Basalt_Brick_Smooth"
    },
    {
      "x": -9,
      "y": 0,
      "z": -1,
      "name": "Rock_Basalt_Brick_Smooth"
    },
    {
      "x": -9,
      "y": 1,
      "z": -1,
      "name": "Rock_Basalt_Brick_Smooth"
    },
    {
      "x": -9,
      "y": 2,
      "z": -1,
      "name": "Rock_Basalt_Brick_Smooth"
    },
    {
      "x": -9,
      "y": 3,
      "z": -1,
      "name": "Rock_Basalt_Brick_Smooth"
    },
    {
      "x": -9,
      "y": 4,
      "z": -1,
      "name": "Rock_Basalt_Brick_Smooth"
    },
    {
      "x": -9,
      "y": 5,
      "z": -1,
      "name": "Rock_Basalt_Brick_Smooth"
    },
    {
      "x": -9,
      "y": 6,
      "z": -1,
      "name": "Rock_Basalt_Brick_Smooth"
    },
    {
      "x": -9,
      "y": 7,
      "z": -1,
      "name": "Rock_Basalt_Brick_Smooth"
    },
    {
      "x": -9,
      "y": 0,
      "z": 0,
      "name": "Rock_Basalt_Brick_Smooth"
    },
    {
      "x": -9,
      "y": 1,
      "z": 0,
      "name": "Rock_Basalt_Brick_Smooth"
    },
    {
      "x": -9,
      "y": 2,
      "z": 0,
      "name": "Rock_Basalt_Brick_Smooth"
    },
    {
      "x": -9,
      "y": 3,
      "z": 0,
      "name": "Rock_Basalt_Brick_Smooth"
    },
    {
      "x": -9,
      "y": 4,
      "z": 0,
      "name": "Rock_Basalt_Brick_Smooth"
    },
    {
      "x": -9,
      "y": 5,
      "z": 0,
      "name": "Rock_Basalt_Brick_Smooth"
    },
    {
      "x": -9,
      "y": 6,
      "z": 0,
      "name": "Rock_Basalt_Brick_Smooth"
    },
    {
      "x": -9,
      "y": 7,
      "z": 0,
      "name": "Rock_Basalt_Brick_Smooth"
    },
    {
      "x": -9,
      "y": 0,
      "z": 1,
      "name": "Rock_Basalt_Brick_Smooth"
    },
    {
      "x": -9,
      "y": 1,
      "z": 1,
      "name": "Rock_Basalt_Brick_Smooth"
    },
    {
      "x": -9,
      "y": 2,
      "z": 1,
      "name": "Rock_Basalt_Brick_Smooth"
    },
    {
      "x": -9,
      "y": 3,
      "z": 1,
      "name": "Rock_Basalt_Brick_Smooth"
    },
    {
      "x": -9,
      "y": 4,
      "z": 1,
      "name": "Rock_Basalt_Brick_Smooth"
    },
    {
      "x": -9,
      "y": 5,
      "z": 1,
      "name": "Rock_Basalt_Brick_Smooth"
    },
    {
      "x": -9,
      "y": 6,
      "z": 1,
      "name": "Rock_Basalt_Brick_Smooth"
    },
    {
      "x": -9,
      "y": 7,
      "z": 1,
      "name": "Rock_Basalt_Brick_Smooth"
    },
    {
      "x": -9,
      "y": 0,
      "z": 2,
      "name": "Rock_Basalt_Brick_Smooth"
    },
    {
      "x": -9,
      "y": 1,
      "z": 2,
      "name": "Rock_Basalt_Brick_Smooth"
    },
    {
      "x": -9,
      "y": 2,
      "z": 2,
      "name": "Rock_Basalt_Brick_Smooth"
    },
    {
      "x": -9,
      "y": 3,
      "z": 2,
      "name": "Rock_Basalt_Brick_Smooth"
    },
    {
      "x": -9,
      "y": 4,
      "z": 2,
      "name": "Rock_Basalt_Brick_Smooth"
    },
    {
      "x": -9,
      "y": 5,
      "z": 2,
      "name": "Rock_Basalt_Brick_Smooth"
    },
    {
      "x": -9,
      "y": 6,
      "z": 2,
      "name": "Rock_Basalt_Brick_Smooth"
    },
    {
      "x": -9,
      "y": 7,
      "z": 2,
      "name": "Rock_Basalt_Brick_Smooth"
    },
    {
      "x": -9,
      "y": 0,
      "z": 3,
      "name": "Rock_Basalt_Brick_Smooth"
    },
    {
      "x": -9,
      "y": 1,
      "z": 3,
      "name": "Rock_Basalt_Brick_Smooth"
    },
    {
      "x": -9,
      "y": 2,
      "z": 3,
      "name": "Rock_Basalt_Brick_Smooth"
    },
    {
      "x": -9,
      "y": 3,
      "z": 3,
      "name": "Rock_Basalt_Brick_Smooth"
    },
    {
      "x": -9,
      "y": 4,
      "z": 3,
      "name": "Rock_Basalt_Brick_Smooth"
    },
    {
      "x": -9,
      "y": 5,
      "z": 3,
      "name": "Rock_Basalt_Brick_Smooth"
    },
    {
      "x": -9,
      "y": 6,
      "z": 3,
      "name": "Rock_Basalt_Brick_Smooth"
    },
    {
      "x": -9,
      "y": 7,
      "z": 3,
      "name": "Rock_Basalt_Brick_Smooth"
    },
    {
      "x": -9,
      "y": 0,
      "z": 4,
      "name": "Rock_Basalt_Brick_Smooth"
    },
    {
      "x": -9,
      "y": 1,
      "z": 4,
      "name": "Rock_Basalt_Brick_Smooth"
    },
    {
      "x": -9,
      "y": 2,
      "z": 4,
      "name": "Rock_Basalt_Brick_Smooth"
    },
    {
      "x": -9,
      "y": 3,
      "z": 4,
      "name": "Rock_Basalt_Brick_Smooth"
    },
    {
      "x": -9,
      "y": 4,
      "z": 4,
      "name": "Rock_Basalt_Brick_Smooth"
    },
    {
      "x": -9,
      "y": 5,
      "z": 4,
      "name": "Rock_Basalt_Brick_Smooth"
    },
    {
      "x": -9,
      "y": 6,
      "z": 4,
      "name": "Rock_Basalt_Brick_Smooth"
    },
    {
      "x": -9,
      "y": 7,
      "z": 4,
      "name": "Rock_Basalt_Brick_Smooth"
    },
    {
      "x": -9,
      "y": 0,
      "z": 5,
      "name": "Rock_Basalt_Brick_Smooth"
    },
    {
      "x": -9,
      "y": 1,
      "z": 5,
      "name": "Rock_Basalt_Brick_Smooth"
    },
    {
      "x": -9,
      "y": 2,
      "z": 5,
      "name": "Rock_Basalt_Brick_Smooth"
    },
    {
      "x": -9,
      "y": 3,
      "z": 5,
      "name": "Rock_Basalt_Brick_Smooth"
    },
    {
      "x": -9,
      "y": 4,
      "z": 5,
      "name": "Rock_Basalt_Brick_Smooth"
    },
    {
      "x": -9,
      "y": 5,
      "z": 5,
      "name": "Rock_Basalt_Brick_Smooth"
    },
    {
      "x": -9,
      "y": 6,
      "z": 5,
      "name": "Rock_Basalt_Brick_Smooth"
    },
    {
      "x": -9,
      "y": 7,
      "z": 5,
      "name": "Rock_Basalt_Brick_Smooth"
    },
    {
      "x": -9,
      "y": 0,
      "z": 6,
      "name": "Rock_Basalt_Brick_Smooth"
    },
    {
      "x": -9,
      "y": 1,
      "z": 6,
      "name": "Rock_Basalt_Brick_Smooth"
    },
    {
      "x": -9,
      "y": 2,
      "z": 6,
      "name": "Rock_Basalt_Brick_Smooth"
    },
    {
      "x": -9,
      "y": 3,
      "z": 6,
      "name": "Rock_Basalt_Brick_Smooth"
    },
    {
      "x": -9,
      "y": 4,
      "z": 6,
      "name": "Rock_Basalt_Brick_Smooth"
    },
    {
      "x": -9,
      "y": 5,
      "z": 6,
      "name": "Rock_Basalt_Brick_Smooth"
    },
    {
      "x": -9,
      "y": 6,
      "z": 6,
      "name": "Rock_Basalt_Brick_Smooth"
    },
    {
      "x": -9,
      "y": 7,
      "z": 6,
      "name": "Rock_Basalt_Brick_Smooth"
    },
    {
      "x": -9,
      "y": 0,
      "z": 7,
      "name": "Rock_Basalt_Brick_Smooth"
    },
    {
      "x": -9,
      "y": 1,
      "z": 7,
      "name": "Rock_Basalt_Brick_Smooth"
    },
    {
      "x": -9,
      "y": 2,
      "z": 7,
      "name": "Rock_Basalt_Brick_Smooth"
    },
    {
      "x": -9,
      "y": 3,
      "z": 7,
      "name": "Rock_Basalt_Brick_Smooth"
    },
    {
      "x": -9,
      "y": 4,
      "z": 7,
      "name": "Rock_Basalt_Brick_Smooth"
    },
    {
      "x": -9,
      "y": 5,
      "z": 7,
      "name": "Rock_Basalt_Brick_Smooth"
    },
    {
      "x": -9,
      "y": 6,
      "z": 7,
      "name": "Rock_Basalt_Brick_Smooth"
    },
    {
      "x": -9,
      "y": 7,
      "z": 7,
      "name": "Rock_Basalt_Brick_Smooth"
    },
    {
      "x": -8,
      "y": 0,
      "z": -7,
      "name": "Rock_Basalt_Brick_Smooth"
    },
    {
      "x": -8,
      "y": 1,
      "z": -7,
      "name": "Rock_Basalt_Brick_Smooth"
    },
    {
      "x": -8,
      "y": 2,
      "z": -7,
      "name": "Rock_Basalt_Brick_Smooth"
    },
    {
      "x": -8,
      "y": 3,
      "z": -7,
      "name": "Rock_Basalt_Brick_Smooth"
    },
    {
      "x": -8,
      "y": 4,
      "z": -7,
      "name": "Rock_Basalt_Brick_Smooth"
    },
    {
      "x": -8,
      "y": 5,
      "z": -7,
      "name": "Rock_Basalt_Brick_Smooth"
    },
    {
      "x": -8,
      "y": 6,
      "z": -7,
      "name": "Rock_Basalt_Brick_Smooth"
    },
    {
      "x": -8,
      "y": 7,
      "z": -7,
      "name": "Rock_Basalt_Brick_Smooth"
    },
    {
      "x": -8,
      "y": 0,
      "z": -6,
      "name": "Rock_Basalt_Brick_Smooth"
    },
    {
      "x": -8,
      "y": 7,
      "z": -6,
      "name": "Rock_Basalt_Brick_Smooth"
    },
    {
      "x": -8,
      "y": 0,
      "z": -5,
      "name": "Rock_Basalt_Brick_Smooth"
    },
    {
      "x": -8,
      "y": 7,
      "z": -5,
      "name": "Rock_Basalt_Brick_Smooth"
    },
    {
      "x": -8,
      "y": 0,
      "z": -4,
      "name": "Rock_Basalt_Brick_Smooth"
    },
    {
      "x": -8,
      "y": 7,
      "z": -4,
      "name": "Rock_Basalt_Brick_Smooth"
    },
    {
      "x": -8,
      "y": 0,
      "z": -3,
      "name": "Rock_Basalt_Brick_Smooth"
    },
    {
      "x": -8,
      "y": 7,
      "z": -3,
      "name": "Rock_Basalt_Brick_Smooth"
    },
    {
      "x": -8,
      "y": 0,
      "z": -2,
      "name": "Rock_Basalt_Brick_Smooth"
    },
    {
      "x": -8,
      "y": 7,
      "z": -2,
      "name": "Rock_Basalt_Brick_Smooth"
    },
    {
      "x": -8,
      "y": 0,
      "z": -1,
      "name": "Rock_Basalt_Brick_Smooth"
    },
    {
      "x": -8,
      "y": 7,
      "z": -1,
      "name": "Rock_Basalt_Brick_Smooth"
    },
    {
      "x": -8,
      "y": 0,
      "z": 0,
      "name": "Rock_Basalt_Brick_Smooth"
    },
    {
      "x": -8,
      "y": 7,
      "z": 0,
      "name": "Rock_Basalt_Brick_Smooth"
    },
    {
      "x": -8,
      "y": 0,
      "z": 1,
      "name": "Rock_Basalt_Brick_Smooth"
    },
    {
      "x": -8,
      "y": 7,
      "z": 1,
      "name": "Rock_Basalt_Brick_Smooth"
    },
    {
      "x": -8,
      "y": 0,
      "z": 2,
      "name": "Rock_Basalt_Brick_Smooth"
    },
    {
      "x": -8,
      "y": 7,
      "z": 2,
      "name": "Rock_Basalt_Brick_Smooth"
    },
    {
      "x": -8,
      "y": 0,
      "z": 3,
      "name": "Rock_Basalt_Brick_Smooth"
    },
    {
      "x": -8,
      "y": 7,
      "z": 3,
      "name": "Rock_Basalt_Brick_Smooth"
    },
    {
      "x": -8,
      "y": 0,
      "z": 4,
      "name": "Rock_Basalt_Brick_Smooth"
    },
    {
      "x": -8,
      "y": 7,
      "z": 4,
      "name": "Rock_Basalt_Brick_Smooth"
    },
    {
      "x": -8,
      "y": 0,
      "z": 5,
      "name": "Rock_Basalt_Brick_Smooth"
    },
    {
      "x": -8,
      "y": 7,
      "z": 5,
      "name": "Rock_Basalt_Brick_Smooth"
    },
    {
      "x": -8,
      "y": 0,
      "z": 6,
      "name": "Rock_Basalt_Brick_Smooth"
    },
    {
      "x": -8,
      "y": 7,
      "z": 6,
      "name": "Rock_Basalt_Brick_Smooth"
    },
    {
      "x": -8,
      "y": 0,
      "z": 7,
      "name": "Rock_Basalt_Brick_Smooth"
    },
    {
      "x": -8,
      "y": 1,
      "z": 7,
      "name": "Rock_Basalt_Brick_Smooth"
    },
    {
      "x": -8,
      "y": 2,
      "z": 7,
      "name": "Rock_Basalt_Brick_Smooth"
    },
    {
      "x": -8,
      "y": 3,
      "z": 7,
      "name": "Rock_Basalt_Brick_Smooth"
    },
    {
      "x": -8,
      "y": 4,
      "z": 7,
      "name": "Rock_Basalt_Brick_Smooth"
    },
    {
      "x": -8,
      "y": 5,
      "z": 7,
      "name": "Rock_Basalt_Brick_Smooth"
    },
    {
      "x": -8,
      "y": 6,
      "z": 7,
      "name": "Rock_Basalt_Brick_Smooth"
    },
    {
      "x": -8,
      "y": 7,
      "z": 7,
      "name": "Rock_Basalt_Brick_Smooth"
    },
    {
      "x": -7,
      "y": 0,
      "z": -7,
      "name": "Rock_Basalt_Brick_Smooth"
    },
    {
      "x": -7,
      "y": 1,
      "z": -7,
      "name": "Rock_Basalt_Brick_Smooth"
    },
    {
      "x": -7,
      "y": 2,
      "z": -7,
      "name": "Rock_Basalt_Brick_Smooth"
    },
    {
      "x": -7,
      "y": 3,
      "z": -7,
      "name": "Rock_Basalt_Brick_Smooth"
    },
    {
      "x": -7,
      "y": 4,
      "z": -7,
      "name": "Rock_Basalt_Brick_Smooth"
    },
    {
      "x": -7,
      "y": 5,
      "z": -7,
      "name": "Rock_Basalt_Brick_Smooth"
    },
    {
      "x": -7,
      "y": 6,
      "z": -7,
      "name": "Rock_Basalt_Brick_Smooth"
    },
    {
      "x": -7,
      "y": 7,
      "z": -7,
      "name": "Rock_Basalt_Brick_Smooth"
    },
    {
      "x": -7,
      "y": 0,
      "z": -6,
      "name": "Rock_Basalt_Brick_Smooth"
    },
    {
      "x": -7,
      "y": 7,
      "z": -6,
      "name": "Rock_Basalt_Brick_Smooth"
    },
    {
      "x": -7,
      "y": 0,
      "z": -5,
      "name": "Rock_Basalt_Brick_Smooth"
    },
    {
      "x": -7,
      "y": 7,
      "z": -5,
      "name": "Rock_Basalt_Brick_Smooth"
    },
    {
      "x": -7,
      "y": 0,
      "z": -4,
      "name": "Rock_Basalt_Brick_Smooth"
    },
    {
      "x": -7,
      "y": 7,
      "z": -4,
      "name": "Rock_Basalt_Brick_Smooth"
    },
    {
      "x": -7,
      "y": 0,
      "z": -3,
      "name": "Rock_Basalt_Brick_Smooth"
    },
    {
      "x": -7,
      "y": 7,
      "z": -3,
      "name": "Rock_Basalt_Brick_Smooth"
    },
    {
      "x": -7,
      "y": 0,
      "z": -2,
      "name": "Rock_Basalt_Brick_Smooth"
    },
    {
      "x": -7,
      "y": 7,
      "z": -2,
      "name": "Rock_Basalt_Brick_Smooth"
    },
    {
      "x": -7,
      "y": 0,
      "z": -1,
      "name": "Rock_Basalt_Brick_Smooth"
    },
    {
      "x": -7,
      "y": 7,
      "z": -1,
      "name": "Rock_Basalt_Brick_Smooth"
    },
    {
      "x": -7,
      "y": 0,
      "z": 0,
      "name": "Rock_Basalt_Brick_Smooth"
    },
    {
      "x": -7,
      "y": 7,
      "z": 0,
      "name": "Rock_Basalt_Brick_Smooth"
    },
    {
      "x": -7,
      "y": 0,
      "z": 1,
      "name": "Rock_Basalt_Brick_Smooth"
    },
    {
      "x": -7,
      "y": 7,
      "z": 1,
      "name": "Rock_Basalt_Brick_Smooth"
    },
    {
      "x": -7,
      "y": 0,
      "z": 2,
      "name": "Rock_Basalt_Brick_Smooth"
    },
    {
      "x": -7,
      "y": 7,
      "z": 2,
      "name": "Rock_Basalt_Brick_Smooth"
    },
    {
      "x": -7,
      "y": 0,
      "z": 3,
      "name": "Rock_Basalt_Brick_Smooth"
    },
    {
      "x": -7,
      "y": 7,
      "z": 3,
      "name": "Rock_Basalt_Brick_Smooth"
    },
    {
      "x": -7,
      "y": 0,
      "z": 4,
      "name": "Rock_Basalt_Brick_Smooth"
    },
    {
      "x": -7,
      "y": 7,
      "z": 4,
      "name": "Rock_Basalt_Brick_Smooth"
    },
    {
      "x": -7,
      "y": 0,
      "z": 5,
      "name": "Rock_Basalt_Brick_Smooth"
    },
    {
      "x": -7,
      "y": 7,
      "z": 5,
      "name": "Rock_Basalt_Brick_Smooth"
    },
    {
      "x": -7,
      "y": 0,
      "z": 6,
      "name": "Rock_Basalt_Brick_Smooth"
    },
    {
      "x": -7,
      "y": 7,
      "z": 6,
      "name": "Rock_Basalt_Brick_Smooth"
    },
    {
      "x": -7,
      "y": 0,
      "z": 7,
      "name": "Rock_Basalt_Brick_Smooth"
    },
    {
      "x": -7,
      "y": 1,
      "z": 7,
      "name": "Rock_Basalt_Brick_Smooth"
    },
    {
      "x": -7,
      "y": 2,
      "z": 7,
      "name": "Rock_Basalt_Brick_Smooth"
    },
    {
      "x": -7,
      "y": 3,
      "z": 7,
      "name": "Rock_Basalt_Brick_Smooth"
    },
    {
      "x": -7,
      "y": 4,
      "z": 7,
      "name": "Rock_Basalt_Brick_Smooth"
    },
    {
      "x": -7,
      "y": 5,
      "z": 7,
      "name": "Rock_Basalt_Brick_Smooth"
    },
    {
      "x": -7,
      "y": 6,
      "z": 7,
      "name": "Rock_Basalt_Brick_Smooth"
    },
    {
      "x": -7,
      "y": 7,
      "z": 7,
      "name": "Rock_Basalt_Brick_Smooth"
    },
    {
      "x": -6,
      "y": 0,
      "z": -7,
      "name": "Rock_Basalt_Brick_Smooth"
    },
    {
      "x": -6,
      "y": 1,
      "z": -7,
      "name": "Rock_Basalt_Brick_Smooth"
    },
    {
      "x": -6,
      "y": 2,
      "z": -7,
      "name": "Rock_Basalt_Brick_Smooth"
    },
    {
      "x": -6,
      "y": 3,
      "z": -7,
      "name": "Rock_Basalt_Brick_Smooth"
    },
    {
      "x": -6,
      "y": 4,
      "z": -7,
      "name": "Rock_Basalt_Brick_Smooth"
    },
    {
      "x": -6,
      "y": 5,
      "z": -7,
      "name": "Rock_Basalt_Brick_Smooth"
    },
    {
      "x": -6,
      "y": 6,
      "z": -7,
      "name": "Rock_Basalt_Brick_Smooth"
    },
    {
      "x": -6,
      "y": 7,
      "z": -7,
      "name": "Rock_Basalt_Brick_Smooth"
    },
    {
      "x": -6,
      "y": 0,
      "z": -6,
      "name": "Rock_Basalt_Brick_Smooth"
    },
    {
      "x": -6,
      "y": 7,
      "z": -6,
      "name": "Rock_Basalt_Brick_Smooth"
    },
    {
      "x": -6,
      "y": 0,
      "z": -5,
      "name": "Rock_Basalt_Brick_Smooth"
    },
    {
      "x": -6,
      "y": 7,
      "z": -5,
      "name": "Rock_Basalt_Brick_Smooth"
    },
    {
      "x": -6,
      "y": 0,
      "z": -4,
      "name": "Rock_Basalt_Brick_Smooth"
    },
    {
      "x": -6,
      "y": 7,
      "z": -4,
      "name": "Rock_Basalt_Brick_Smooth"
    },
    {
      "x": -6,
      "y": 0,
      "z": -3,
      "name": "Rock_Basalt_Brick_Smooth"
    },
    {
      "x": -6,
      "y": 7,
      "z": -3,
      "name": "Rock_Basalt_Brick_Smooth"
    },
    {
      "x": -6,
      "y": 0,
      "z": -2,
      "name": "Rock_Basalt_Brick_Smooth"
    },
    {
      "x": -6,
      "y": 7,
      "z": -2,
      "name": "Rock_Basalt_Brick_Smooth"
    },
    {
      "x": -6,
      "y": 0,
      "z": -1,
      "name": "Rock_Basalt_Brick_Smooth"
    },
    {
      "x": -6,
      "y": 7,
      "z": -1,
      "name": "Rock_Basalt_Brick_Smooth"
    },
    {
      "x": -6,
      "y": 0,
      "z": 0,
      "name": "Rock_Basalt_Brick_Smooth"
    },
    {
      "x": -6,
      "y": 7,
      "z": 0,
      "name": "Rock_Basalt_Brick_Smooth"
    },
    {
      "x": -6,
      "y": 0,
      "z": 1,
      "name": "Rock_Basalt_Brick_Smooth"
    },
    {
      "x": -6,
      "y": 7,
      "z": 1,
      "name": "Rock_Basalt_Brick_Smooth"
    },
    {
      "x": -6,
      "y": 0,
      "z": 2,
      "name": "Rock_Basalt_Brick_Smooth"
    },
    {
      "x": -6,
      "y": 7,
      "z": 2,
      "name": "Rock_Basalt_Brick_Smooth"
    },
    {
      "x": -6,
      "y": 0,
      "z": 3,
      "name": "Rock_Basalt_Brick_Smooth"
    },
    {
      "x": -6,
      "y": 7,
      "z": 3,
      "name": "Rock_Basalt_Brick_Smooth"
    },
    {
      "x": -6,
      "y": 0,
      "z": 4,
      "name": "Rock_Basalt_Brick_Smooth"
    },
    {
      "x": -6,
      "y": 7,
      "z": 4,
      "name": "Rock_Basalt_Brick_Smooth"
    },
    {
      "x": -6,
      "y": 0,
      "z": 5,
      "name": "Rock_Basalt_Brick_Smooth"
    },
    {
      "x": -6,
      "y": 7,
      "z": 5,
      "name": "Rock_Basalt_Brick_Smooth"
    },
    {
      "x": -6,
      "y": 0,
      "z": 6,
      "name": "Rock_Basalt_Brick_Smooth"
    },
    {
      "x": -6,
      "y": 7,
      "z": 6,
      "name": "Rock_Basalt_Brick_Smooth"
    },
    {
      "x": -6,
      "y": 0,
      "z": 7,
      "name": "Rock_Basalt_Brick_Smooth"
    },
    {
      "x": -6,
      "y": 1,
      "z": 7,
      "name": "Rock_Basalt_Brick_Smooth"
    },
    {
      "x": -6,
      "y": 2,
      "z": 7,
      "name": "Rock_Basalt_Brick_Smooth"
    },
    {
      "x": -6,
      "y": 3,
      "z": 7,
      "name": "Rock_Basalt_Brick_Smooth"
    },
    {
      "x": -6,
      "y": 4,
      "z": 7,
      "name": "Rock_Basalt_Brick_Smooth"
    },
    {
      "x": -6,
      "y": 5,
      "z": 7,
      "name": "Rock_Basalt_Brick_Smooth"
    },
    {
      "x": -6,
      "y": 6,
      "z": 7,
      "name": "Rock_Basalt_Brick_Smooth"
    },
    {
      "x": -6,
      "y": 7,
      "z": 7,
      "name": "Rock_Basalt_Brick_Smooth"
    },
    {
      "x": -5,
      "y": 0,
      "z": -7,
      "name": "Rock_Basalt_Brick_Smooth"
    },
    {
      "x": -5,
      "y": 1,
      "z": -7,
      "name": "Rock_Basalt_Brick_Smooth"
    },
    {
      "x": -5,
      "y": 2,
      "z": -7,
      "name": "Rock_Basalt_Brick_Smooth"
    },
    {
      "x": -5,
      "y": 3,
      "z": -7,
      "name": "Rock_Basalt_Brick_Smooth"
    },
    {
      "x": -5,
      "y": 4,
      "z": -7,
      "name": "Rock_Basalt_Brick_Smooth"
    },
    {
      "x": -5,
      "y": 5,
      "z": -7,
      "name": "Rock_Basalt_Brick_Smooth"
    },
    {
      "x": -5,
      "y": 6,
      "z": -7,
      "name": "Rock_Basalt_Brick_Smooth"
    },
    {
      "x": -5,
      "y": 7,
      "z": -7,
      "name": "Rock_Basalt_Brick_Smooth"
    },
    {
      "x": -5,
      "y": 0,
      "z": -6,
      "name": "Rock_Basalt_Brick_Smooth"
    },
    {
      "x": -5,
      "y": 7,
      "z": -6,
      "name": "Rock_Basalt_Brick_Smooth"
    },
    {
      "x": -5,
      "y": 0,
      "z": -5,
      "name": "Rock_Basalt_Brick_Smooth"
    },
    {
      "x": -5,
      "y": 7,
      "z": -5,
      "name": "Rock_Basalt_Brick_Smooth"
    },
    {
      "x": -5,
      "y": 0,
      "z": -4,
      "name": "Rock_Basalt_Brick_Smooth"
    },
    {
      "x": -5,
      "y": 7,
      "z": -4,
      "name": "Rock_Basalt_Brick_Smooth"
    },
    {
      "x": -5,
      "y": 0,
      "z": -3,
      "name": "Rock_Basalt_Brick_Smooth"
    },
    {
      "x": -5,
      "y": 7,
      "z": -3,
      "name": "Rock_Basalt_Brick_Smooth"
    },
    {
      "x": -5,
      "y": 0,
      "z": -2,
      "name": "Rock_Basalt_Brick_Smooth"
    },
    {
      "x": -5,
      "y": 7,
      "z": -2,
      "name": "Rock_Basalt_Brick_Smooth"
    },
    {
      "x": -5,
      "y": 0,
      "z": -1,
      "name": "Rock_Basalt_Brick_Smooth"
    },
    {
      "x": -5,
      "y": 7,
      "z": -1,
      "name": "Rock_Basalt_Brick_Smooth"
    },
    {
      "x": -5,
      "y": 0,
      "z": 0,
      "name": "Rock_Basalt_Brick_Smooth"
    },
    {
      "x": -5,
      "y": 7,
      "z": 0,
      "name": "Rock_Basalt_Brick_Smooth"
    },
    {
      "x": -5,
      "y": 0,
      "z": 1,
      "name": "Rock_Basalt_Brick_Smooth"
    },
    {
      "x": -5,
      "y": 7,
      "z": 1,
      "name": "Rock_Basalt_Brick_Smooth"
    },
    {
      "x": -5,
      "y": 0,
      "z": 2,
      "name": "Rock_Basalt_Brick_Smooth"
    },
    {
      "x": -5,
      "y": 7,
      "z": 2,
      "name": "Rock_Basalt_Brick_Smooth"
    },
    {
      "x": -5,
      "y": 0,
      "z": 3,
      "name": "Rock_Basalt_Brick_Smooth"
    },
    {
      "x": -5,
      "y": 7,
      "z": 3,
      "name": "Rock_Basalt_Brick_Smooth"
    },
    {
      "x": -5,
      "y": 0,
      "z": 4,
      "name": "Rock_Basalt_Brick_Smooth"
    },
    {
      "x": -5,
      "y": 7,
      "z": 4,
      "name": "Rock_Basalt_Brick_Smooth"
    },
    {
      "x": -5,
      "y": 0,
      "z": 5,
      "name": "Rock_Basalt_Brick_Smooth"
    },
    {
      "x": -5,
      "y": 7,
      "z": 5,
      "name": "Rock_Basalt_Brick_Smooth"
    },
    {
      "x": -5,
      "y": 0,
      "z": 6,
      "name": "Rock_Basalt_Brick_Smooth"
    },
    {
      "x": -5,
      "y": 7,
      "z": 6,
      "name": "Rock_Basalt_Brick_Smooth"
    },
    {
      "x": -5,
      "y": 0,
      "z": 7,
      "name": "Rock_Basalt_Brick_Smooth"
    },
    {
      "x": -5,
      "y": 1,
      "z": 7,
      "name": "Rock_Basalt_Brick_Smooth"
    },
    {
      "x": -5,
      "y": 2,
      "z": 7,
      "name": "Rock_Basalt_Brick_Smooth"
    },
    {
      "x": -5,
      "y": 3,
      "z": 7,
      "name": "Rock_Basalt_Brick_Smooth"
    },
    {
      "x": -5,
      "y": 4,
      "z": 7,
      "name": "Rock_Basalt_Brick_Smooth"
    },
    {
      "x": -5,
      "y": 5,
      "z": 7,
      "name": "Rock_Basalt_Brick_Smooth"
    },
    {
      "x": -5,
      "y": 6,
      "z": 7,
      "name": "Rock_Basalt_Brick_Smooth"
    },
    {
      "x": -5,
      "y": 7,
      "z": 7,
      "name": "Rock_Basalt_Brick_Smooth"
    },
    {
      "x": -4,
      "y": 0,
      "z": -7,
      "name": "Rock_Basalt_Brick_Smooth"
    },
    {
      "x": -4,
      "y": 1,
      "z": -7,
      "name": "Rock_Basalt_Brick_Smooth"
    },
    {
      "x": -4,
      "y": 2,
      "z": -7,
      "name": "Rock_Basalt_Brick_Smooth"
    },
    {
      "x": -4,
      "y": 3,
      "z": -7,
      "name": "Rock_Basalt_Brick_Smooth"
    },
    {
      "x": -4,
      "y": 4,
      "z": -7,
      "name": "Rock_Basalt_Brick_Smooth"
    },
    {
      "x": -4,
      "y": 5,
      "z": -7,
      "name": "Rock_Basalt_Brick_Smooth"
    },
    {
      "x": -4,
      "y": 6,
      "z": -7,
      "name": "Rock_Basalt_Brick_Smooth"
    },
    {
      "x": -4,
      "y": 7,
      "z": -7,
      "name": "Rock_Basalt_Brick_Smooth"
    },
    {
      "x": -4,
      "y": 0,
      "z": -6,
      "name": "Rock_Basalt_Brick_Smooth"
    },
    {
      "x": -4,
      "y": 7,
      "z": -6,
      "name": "Rock_Basalt_Brick_Smooth"
    },
    {
      "x": -4,
      "y": 0,
      "z": -5,
      "name": "Rock_Basalt_Brick_Smooth"
    },
    {
      "x": -4,
      "y": 7,
      "z": -5,
      "name": "Rock_Basalt_Brick_Smooth"
    },
    {
      "x": -4,
      "y": 0,
      "z": -4,
      "name": "Rock_Basalt_Brick_Smooth"
    },
    {
      "x": -4,
      "y": 7,
      "z": -4,
      "name": "Rock_Basalt_Brick_Smooth"
    },
    {
      "x": -4,
      "y": 0,
      "z": -3,
      "name": "Rock_Basalt_Brick_Smooth"
    },
    {
      "x": -4,
      "y": 7,
      "z": -3,
      "name": "Rock_Basalt_Brick_Smooth"
    },
    {
      "x": -4,
      "y": 0,
      "z": -2,
      "name": "Rock_Basalt_Brick_Smooth"
    },
    {
      "x": -4,
      "y": 7,
      "z": -2,
      "name": "Rock_Basalt_Brick_Smooth"
    },
    {
      "x": -4,
      "y": 0,
      "z": -1,
      "name": "Rock_Basalt_Brick_Smooth"
    },
    {
      "x": -4,
      "y": 7,
      "z": -1,
      "name": "Rock_Basalt_Brick_Smooth"
    },
    {
      "x": -4,
      "y": 0,
      "z": 0,
      "name": "Rock_Basalt_Brick_Smooth"
    },
    {
      "x": -4,
      "y": 7,
      "z": 0,
      "name": "Rock_Basalt_Brick_Smooth"
    },
    {
      "x": -4,
      "y": 0,
      "z": 1,
      "name": "Rock_Basalt_Brick_Smooth"
    },
    {
      "x": -4,
      "y": 7,
      "z": 1,
      "name": "Rock_Basalt_Brick_Smooth"
    },
    {
      "x": -4,
      "y": 0,
      "z": 2,
      "name": "Rock_Basalt_Brick_Smooth"
    },
    {
      "x": -4,
      "y": 7,
      "z": 2,
      "name": "Rock_Basalt_Brick_Smooth"
    },
    {
      "x": -4,
      "y": 0,
      "z": 3,
      "name": "Rock_Basalt_Brick_Smooth"
    },
    {
      "x": -4,
      "y": 7,
      "z": 3,
      "name": "Rock_Basalt_Brick_Smooth"
    },
    {
      "x": -4,
      "y": 0,
      "z": 4,
      "name": "Rock_Basalt_Brick_Smooth"
    },
    {
      "x": -4,
      "y": 7,
      "z": 4,
      "name": "Rock_Basalt_Brick_Smooth"
    },
    {
      "x": -4,
      "y": 0,
      "z": 5,
      "name": "Rock_Basalt_Brick_Smooth"
    },
    {
      "x": -4,
      "y": 7,
      "z": 5,
      "name": "Rock_Basalt_Brick_Smooth"
    },
    {
      "x": -4,
      "y": 0,
      "z": 6,
      "name": "Rock_Basalt_Brick_Smooth"
    },
    {
      "x": -4,
      "y": 7,
      "z": 6,
      "name": "Rock_Basalt_Brick_Smooth"
    },
    {
      "x": -4,
      "y": 0,
      "z": 7,
      "name": "Rock_Basalt_Brick_Smooth"
    },
    {
      "x": -4,
      "y": 1,
      "z": 7,
      "name": "Rock_Basalt_Brick_Smooth"
    },
    {
      "x": -4,
      "y": 2,
      "z": 7,
      "name": "Rock_Basalt_Brick_Smooth"
    },
    {
      "x": -4,
      "y": 3,
      "z": 7,
      "name": "Rock_Basalt_Brick_Smooth"
    },
    {
      "x": -4,
      "y": 4,
      "z": 7,
      "name": "Rock_Basalt_Brick_Smooth"
    },
    {
      "x": -4,
      "y": 5,
      "z": 7,
      "name": "Rock_Basalt_Brick_Smooth"
    },
    {
      "x": -4,
      "y": 6,
      "z": 7,
      "name": "Rock_Basalt_Brick_Smooth"
    },
    {
      "x": -4,
      "y": 7,
      "z": 7,
      "name": "Rock_Basalt_Brick_Smooth"
    },
    {
      "x": -3,
      "y": 0,
      "z": -7,
      "name": "Rock_Basalt_Brick_Smooth"
    },
    {
      "x": -3,
      "y": 1,
      "z": -7,
      "name": "Rock_Basalt_Brick_Smooth"
    },
    {
      "x": -3,
      "y": 2,
      "z": -7,
      "name": "Rock_Basalt_Brick_Smooth"
    },
    {
      "x": -3,
      "y": 3,
      "z": -7,
      "name": "Rock_Basalt_Brick_Smooth"
    },
    {
      "x": -3,
      "y": 4,
      "z": -7,
      "name": "Rock_Basalt_Brick_Smooth"
    },
    {
      "x": -3,
      "y": 5,
      "z": -7,
      "name": "Rock_Basalt_Brick_Smooth"
    },
    {
      "x": -3,
      "y": 6,
      "z": -7,
      "name": "Rock_Basalt_Brick_Smooth"
    },
    {
      "x": -3,
      "y": 7,
      "z": -7,
      "name": "Rock_Basalt_Brick_Smooth"
    },
    {
      "x": -3,
      "y": 0,
      "z": -6,
      "name": "Rock_Basalt_Brick_Smooth"
    },
    {
      "x": -3,
      "y": 7,
      "z": -6,
      "name": "Rock_Basalt_Brick_Smooth"
    },
    {
      "x": -3,
      "y": 0,
      "z": -5,
      "name": "Rock_Basalt_Brick_Smooth"
    },
    {
      "x": -3,
      "y": 7,
      "z": -5,
      "name": "Rock_Basalt_Brick_Smooth"
    },
    {
      "x": -3,
      "y": 0,
      "z": -4,
      "name": "Rock_Basalt_Brick_Smooth"
    },
    {
      "x": -3,
      "y": 7,
      "z": -4,
      "name": "Rock_Basalt_Brick_Smooth"
    },
    {
      "x": -3,
      "y": 0,
      "z": -3,
      "name": "Rock_Basalt_Brick_Smooth"
    },
    {
      "x": -3,
      "y": 7,
      "z": -3,
      "name": "Rock_Basalt_Brick_Smooth"
    },
    {
      "x": -3,
      "y": 0,
      "z": -2,
      "name": "Rock_Basalt_Brick_Smooth"
    },
    {
      "x": -3,
      "y": 7,
      "z": -2,
      "name": "Rock_Basalt_Brick_Smooth"
    },
    {
      "x": -3,
      "y": 0,
      "z": -1,
      "name": "Rock_Basalt_Brick_Smooth"
    },
    {
      "x": -3,
      "y": 7,
      "z": -1,
      "name": "Rock_Basalt_Brick_Smooth"
    },
    {
      "x": -3,
      "y": 0,
      "z": 0,
      "name": "Rock_Basalt_Brick_Smooth"
    },
    {
      "x": -3,
      "y": 7,
      "z": 0,
      "name": "Rock_Basalt_Brick_Smooth"
    },
    {
      "x": -3,
      "y": 0,
      "z": 1,
      "name": "Rock_Basalt_Brick_Smooth"
    },
    {
      "x": -3,
      "y": 7,
      "z": 1,
      "name": "Rock_Basalt_Brick_Smooth"
    },
    {
      "x": -3,
      "y": 0,
      "z": 2,
      "name": "Rock_Basalt_Brick_Smooth"
    },
    {
      "x": -3,
      "y": 7,
      "z": 2,
      "name": "Rock_Basalt_Brick_Smooth"
    },
    {
      "x": -3,
      "y": 0,
      "z": 3,
      "name": "Rock_Basalt_Brick_Smooth"
    },
    {
      "x": -3,
      "y": 7,
      "z": 3,
      "name": "Rock_Basalt_Brick_Smooth"
    },
    {
      "x": -3,
      "y": 0,
      "z": 4,
      "name": "Rock_Basalt_Brick_Smooth"
    },
    {
      "x": -3,
      "y": 7,
      "z": 4,
      "name": "Rock_Basalt_Brick_Smooth"
    },
    {
      "x": -3,
      "y": 0,
      "z": 5,
      "name": "Rock_Basalt_Brick_Smooth"
    },
    {
      "x": -3,
      "y": 7,
      "z": 5,
      "name": "Rock_Basalt_Brick_Smooth"
    },
    {
      "x": -3,
      "y": 0,
      "z": 6,
      "name": "Rock_Basalt_Brick_Smooth"
    },
    {
      "x": -3,
      "y": 7,
      "z": 6,
      "name": "Rock_Basalt_Brick_Smooth"
    },
    {
      "x": -3,
      "y": 0,
      "z": 7,
      "name": "Rock_Basalt_Brick_Smooth"
    },
    {
      "x": -3,
      "y": 1,
      "z": 7,
      "name": "Rock_Basalt_Brick_Smooth"
    },
    {
      "x": -3,
      "y": 2,
      "z": 7,
      "name": "Rock_Basalt_Brick_Smooth"
    },
    {
      "x": -3,
      "y": 3,
      "z": 7,
      "name": "Rock_Basalt_Brick_Smooth"
    },
    {
      "x": -3,
      "y": 4,
      "z": 7,
      "name": "Rock_Basalt_Brick_Smooth"
    },
    {
      "x": -3,
      "y": 5,
      "z": 7,
      "name": "Rock_Basalt_Brick_Smooth"
    },
    {
      "x": -3,
      "y": 6,
      "z": 7,
      "name": "Rock_Basalt_Brick_Smooth"
    },
    {
      "x": -3,
      "y": 7,
      "z": 7,
      "name": "Rock_Basalt_Brick_Smooth"
    },
    {
      "x": -2,
      "y": 0,
      "z": -7,
      "name": "Rock_Basalt_Brick_Smooth"
    },
    {
      "x": -2,
      "y": 1,
      "z": -7,
      "name": "Rock_Basalt_Brick_Smooth"
    },
    {
      "x": -2,
      "y": 2,
      "z": -7,
      "name": "Rock_Basalt_Brick_Smooth"
    },
    {
      "x": -2,
      "y": 3,
      "z": -7,
      "name": "Rock_Basalt_Brick_Smooth"
    },
    {
      "x": -2,
      "y": 4,
      "z": -7,
      "name": "Rock_Basalt_Brick_Smooth"
    },
    {
      "x": -2,
      "y": 5,
      "z": -7,
      "name": "Rock_Basalt_Brick_Smooth"
    },
    {
      "x": -2,
      "y": 6,
      "z": -7,
      "name": "Rock_Basalt_Brick_Smooth"
    },
    {
      "x": -2,
      "y": 7,
      "z": -7,
      "name": "Rock_Basalt_Brick_Smooth"
    },
    {
      "x": -2,
      "y": 0,
      "z": -6,
      "name": "Rock_Basalt_Brick_Smooth"
    },
    {
      "x": -2,
      "y": 7,
      "z": -6,
      "name": "Rock_Basalt_Brick_Smooth"
    },
    {
      "x": -2,
      "y": 0,
      "z": -5,
      "name": "Rock_Basalt_Brick_Smooth"
    },
    {
      "x": -2,
      "y": 7,
      "z": -5,
      "name": "Rock_Basalt_Brick_Smooth"
    },
    {
      "x": -2,
      "y": 0,
      "z": -4,
      "name": "Rock_Basalt_Brick_Smooth"
    },
    {
      "x": -2,
      "y": 7,
      "z": -4,
      "name": "Rock_Basalt_Brick_Smooth"
    },
    {
      "x": -2,
      "y": 0,
      "z": -3,
      "name": "Rock_Basalt_Brick_Smooth"
    },
    {
      "x": -2,
      "y": 7,
      "z": -3,
      "name": "Rock_Basalt_Brick_Smooth"
    },
    {
      "x": -2,
      "y": 0,
      "z": -2,
      "name": "Rock_Basalt_Brick_Smooth"
    },
    {
      "x": -2,
      "y": 7,
      "z": -2,
      "name": "Rock_Basalt_Brick_Smooth"
    },
    {
      "x": -2,
      "y": 0,
      "z": -1,
      "name": "Rock_Basalt_Brick_Smooth"
    },
    {
      "x": -2,
      "y": 7,
      "z": -1,
      "name": "Rock_Basalt_Brick_Smooth"
    },
    {
      "x": -2,
      "y": 0,
      "z": 0,
      "name": "Rock_Basalt_Brick_Smooth"
    },
    {
      "x": -2,
      "y": 7,
      "z": 0,
      "name": "Rock_Basalt_Brick_Smooth"
    },
    {
      "x": -2,
      "y": 0,
      "z": 1,
      "name": "Rock_Basalt_Brick_Smooth"
    },
    {
      "x": -2,
      "y": 7,
      "z": 1,
      "name": "Rock_Basalt_Brick_Smooth"
    },
    {
      "x": -2,
      "y": 0,
      "z": 2,
      "name": "Rock_Basalt_Brick_Smooth"
    },
    {
      "x": -2,
      "y": 7,
      "z": 2,
      "name": "Rock_Basalt_Brick_Smooth"
    },
    {
      "x": -2,
      "y": 0,
      "z": 3,
      "name": "Rock_Basalt_Brick_Smooth"
    },
    {
      "x": -2,
      "y": 7,
      "z": 3,
      "name": "Rock_Basalt_Brick_Smooth"
    },
    {
      "x": -2,
      "y": 0,
      "z": 4,
      "name": "Rock_Basalt_Brick_Smooth"
    },
    {
      "x": -2,
      "y": 7,
      "z": 4,
      "name": "Rock_Basalt_Brick_Smooth"
    },
    {
      "x": -2,
      "y": 0,
      "z": 5,
      "name": "Rock_Basalt_Brick_Smooth"
    },
    {
      "x": -2,
      "y": 7,
      "z": 5,
      "name": "Rock_Basalt_Brick_Smooth"
    },
    {
      "x": -2,
      "y": 0,
      "z": 6,
      "name": "Rock_Basalt_Brick_Smooth"
    },
    {
      "x": -2,
      "y": 7,
      "z": 6,
      "name": "Rock_Basalt_Brick_Smooth"
    },
    {
      "x": -2,
      "y": 0,
      "z": 7,
      "name": "Rock_Basalt_Brick_Smooth"
    },
    {
      "x": -2,
      "y": 1,
      "z": 7,
      "name": "Rock_Basalt_Brick_Smooth"
    },
    {
      "x": -2,
      "y": 2,
      "z": 7,
      "name": "Rock_Basalt_Brick_Smooth"
    },
    {
      "x": -2,
      "y": 3,
      "z": 7,
      "name": "Rock_Basalt_Brick_Smooth"
    },
    {
      "x": -2,
      "y": 4,
      "z": 7,
      "name": "Rock_Basalt_Brick_Smooth"
    },
    {
      "x": -2,
      "y": 5,
      "z": 7,
      "name": "Rock_Basalt_Brick_Smooth"
    },
    {
      "x": -2,
      "y": 6,
      "z": 7,
      "name": "Rock_Basalt_Brick_Smooth"
    },
    {
      "x": -2,
      "y": 7,
      "z": 7,
      "name": "Rock_Basalt_Brick_Smooth"
    },
    {
      "x": -1,
      "y": 0,
      "z": -7,
      "name": "Rock_Basalt_Brick_Smooth"
    },
    {
      "x": -1,
      "y": 1,
      "z": -7,
      "name": "Rock_Basalt_Brick_Smooth"
    },
    {
      "x": -1,
      "y": 2,
      "z": -7,
      "name": "Rock_Basalt_Brick_Smooth"
    },
    {
      "x": -1,
      "y": 3,
      "z": -7,
      "name": "Rock_Basalt_Brick_Smooth"
    },
    {
      "x": -1,
      "y": 4,
      "z": -7,
      "name": "Rock_Basalt_Brick_Smooth"
    },
    {
      "x": -1,
      "y": 5,
      "z": -7,
      "name": "Rock_Basalt_Brick_Smooth"
    },
    {
      "x": -1,
      "y": 6,
      "z": -7,
      "name": "Rock_Basalt_Brick_Smooth"
    },
    {
      "x": -1,
      "y": 7,
      "z": -7,
      "name": "Rock_Basalt_Brick_Smooth"
    },
    {
      "x": -1,
      "y": 0,
      "z": -6,
      "name": "Rock_Basalt_Brick_Smooth"
    },
    {
      "x": -1,
      "y": 7,
      "z": -6,
      "name": "Rock_Basalt_Brick_Smooth"
    },
    {
      "x": -1,
      "y": 0,
      "z": -5,
      "name": "Rock_Basalt_Brick_Smooth"
    },
    {
      "x": -1,
      "y": 7,
      "z": -5,
      "name": "Rock_Basalt_Brick_Smooth"
    },
    {
      "x": -1,
      "y": 0,
      "z": -4,
      "name": "Rock_Basalt_Brick_Smooth"
    },
    {
      "x": -1,
      "y": 7,
      "z": -4,
      "name": "Rock_Basalt_Brick_Smooth"
    },
    {
      "x": -1,
      "y": 0,
      "z": -3,
      "name": "Rock_Basalt_Brick_Smooth"
    },
    {
      "x": -1,
      "y": 7,
      "z": -3,
      "name": "Rock_Basalt_Brick_Smooth"
    },
    {
      "x": -1,
      "y": 0,
      "z": -2,
      "name": "Rock_Basalt_Brick_Smooth"
    },
    {
      "x": -1,
      "y": 7,
      "z": -2,
      "name": "Rock_Basalt_Brick_Smooth"
    },
    {
      "x": -1,
      "y": 0,
      "z": -1,
      "name": "Rock_Basalt_Brick_Smooth"
    },
    {
      "x": -1,
      "y": 7,
      "z": -1,
      "name": "Rock_Basalt_Brick_Smooth"
    },
    {
      "x": -1,
      "y": 0,
      "z": 0,
      "name": "Rock_Basalt_Brick_Smooth"
    },
    {
      "x": -1,
      "y": 7,
      "z": 0,
      "name": "Rock_Basalt_Brick_Smooth"
    },
    {
      "x": -1,
      "y": 0,
      "z": 1,
      "name": "Rock_Basalt_Brick_Smooth"
    },
    {
      "x": -1,
      "y": 7,
      "z": 1,
      "name": "Rock_Basalt_Brick_Smooth"
    },
    {
      "x": -1,
      "y": 0,
      "z": 2,
      "name": "Rock_Basalt_Brick_Smooth"
    },
    {
      "x": -1,
      "y": 7,
      "z": 2,
      "name": "Rock_Basalt_Brick_Smooth"
    },
    {
      "x": -1,
      "y": 0,
      "z": 3,
      "name": "Rock_Basalt_Brick_Smooth"
    },
    {
      "x": -1,
      "y": 7,
      "z": 3,
      "name": "Rock_Basalt_Brick_Smooth"
    },
    {
      "x": -1,
      "y": 0,
      "z": 4,
      "name": "Rock_Basalt_Brick_Smooth"
    },
    {
      "x": -1,
      "y": 7,
      "z": 4,
      "name": "Rock_Basalt_Brick_Smooth"
    },
    {
      "x": -1,
      "y": 0,
      "z": 5,
      "name": "Rock_Basalt_Brick_Smooth"
    },
    {
      "x": -1,
      "y": 7,
      "z": 5,
      "name": "Rock_Basalt_Brick_Smooth"
    },
    {
      "x": -1,
      "y": 0,
      "z": 6,
      "name": "Rock_Basalt_Brick_Smooth"
    },
    {
      "x": -1,
      "y": 7,
      "z": 6,
      "name": "Rock_Basalt_Brick_Smooth"
    },
    {
      "x": -1,
      "y": 0,
      "z": 7,
      "name": "Rock_Basalt_Brick_Smooth"
    },
    {
      "x": -1,
      "y": 1,
      "z": 7,
      "name": "Rock_Basalt_Brick_Smooth"
    },
    {
      "x": -1,
      "y": 2,
      "z": 7,
      "name": "Rock_Basalt_Brick_Smooth"
    },
    {
      "x": -1,
      "y": 3,
      "z": 7,
      "name": "Rock_Basalt_Brick_Smooth"
    },
    {
      "x": -1,
      "y": 4,
      "z": 7,
      "name": "Rock_Basalt_Brick_Smooth"
    },
    {
      "x": -1,
      "y": 5,
      "z": 7,
      "name": "Rock_Basalt_Brick_Smooth"
    },
    {
      "x": -1,
      "y": 6,
      "z": 7,
      "name": "Rock_Basalt_Brick_Smooth"
    },
    {
      "x": -1,
      "y": 7,
      "z": 7,
      "name": "Rock_Basalt_Brick_Smooth"
    },
    {
      "x": 0,
      "y": 0,
      "z": -7,
      "name": "Rock_Basalt_Brick_Smooth"
    },
    {
      "x": 0,
      "y": 1,
      "z": -7,
      "name": "Rock_Basalt_Brick_Smooth"
    },
    {
      "x": 0,
      "y": 2,
      "z": -7,
      "name": "Rock_Basalt_Brick_Smooth"
    },
    {
      "x": 0,
      "y": 3,
      "z": -7,
      "name": "Rock_Basalt_Brick_Smooth"
    },
    {
      "x": 0,
      "y": 4,
      "z": -7,
      "name": "Rock_Basalt_Brick_Smooth"
    },
    {
      "x": 0,
      "y": 5,
      "z": -7,
      "name": "Rock_Basalt_Brick_Smooth"
    },
    {
      "x": 0,
      "y": 6,
      "z": -7,
      "name": "Rock_Basalt_Brick_Smooth"
    },
    {
      "x": 0,
      "y": 7,
      "z": -7,
      "name": "Rock_Basalt_Brick_Smooth"
    },
    {
      "x": 0,
      "y": 0,
      "z": -6,
      "name": "Rock_Basalt_Brick_Smooth"
    },
    {
      "x": 0,
      "y": 7,
      "z": -6,
      "name": "Rock_Basalt_Brick_Smooth"
    },
    {
      "x": 0,
      "y": 0,
      "z": -5,
      "name": "Rock_Basalt_Brick_Smooth"
    },
    {
      "x": 0,
      "y": 7,
      "z": -5,
      "name": "Rock_Basalt_Brick_Smooth"
    },
    {
      "x": 0,
      "y": 0,
      "z": -4,
      "name": "Rock_Basalt_Brick_Smooth"
    },
    {
      "x": 0,
      "y": 7,
      "z": -4,
      "name": "Rock_Basalt_Brick_Smooth"
    },
    {
      "x": 0,
      "y": 0,
      "z": -3,
      "name": "Rock_Basalt_Brick_Smooth"
    },
    {
      "x": 0,
      "y": 7,
      "z": -3,
      "name": "Rock_Basalt_Brick_Smooth"
    },
    {
      "x": 0,
      "y": 0,
      "z": -2,
      "name": "Rock_Basalt_Brick_Smooth"
    },
    {
      "x": 0,
      "y": 7,
      "z": -2,
      "name": "Rock_Basalt_Brick_Smooth"
    },
    {
      "x": 0,
      "y": 0,
      "z": -1,
      "name": "Rock_Basalt_Brick_Smooth"
    },
    {
      "x": 0,
      "y": 7,
      "z": -1,
      "name": "Rock_Basalt_Brick_Smooth"
    },
    {
      "x": 0,
      "y": 0,
      "z": 0,
      "name": "Rock_Basalt_Brick_Smooth"
    },
    {
      "x": 0,
      "y": 7,
      "z": 0,
      "name": "Rock_Basalt_Brick_Smooth"
    },
    {
      "x": 0,
      "y": 0,
      "z": 1,
      "name": "Rock_Basalt_Brick_Smooth"
    },
    {
      "x": 0,
      "y": 7,
      "z": 1,
      "name": "Rock_Basalt_Brick_Smooth"
    },
    {
      "x": 0,
      "y": 0,
      "z": 2,
      "name": "Rock_Basalt_Brick_Smooth"
    },
    {
      "x": 0,
      "y": 7,
      "z": 2,
      "name": "Rock_Basalt_Brick_Smooth"
    },
    {
      "x": 0,
      "y": 0,
      "z": 3,
      "name": "Rock_Basalt_Brick_Smooth"
    },
    {
      "x": 0,
      "y": 7,
      "z": 3,
      "name": "Rock_Basalt_Brick_Smooth"
    },
    {
      "x": 0,
      "y": 0,
      "z": 4,
      "name": "Rock_Basalt_Brick_Smooth"
    },
    {
      "x": 0,
      "y": 7,
      "z": 4,
      "name": "Rock_Basalt_Brick_Smooth"
    },
    {
      "x": 0,
      "y": 0,
      "z": 5,
      "name": "Rock_Basalt_Brick_Smooth"
    },
    {
      "x": 0,
      "y": 7,
      "z": 5,
      "name": "Rock_Basalt_Brick_Smooth"
    },
    {
      "x": 0,
      "y": 0,
      "z": 6,
      "name": "Rock_Basalt_Brick_Smooth"
    },
    {
      "x": 0,
      "y": 7,
      "z": 6,
      "name": "Rock_Basalt_Brick_Smooth"
    },
    {
      "x": 0,
      "y": 0,
      "z": 7,
      "name": "Rock_Basalt_Brick_Smooth"
    },
    {
      "x": 0,
      "y": 1,
      "z": 7,
      "name": "Rock_Basalt_Brick_Smooth"
    },
    {
      "x": 0,
      "y": 2,
      "z": 7,
      "name": "Rock_Basalt_Brick_Smooth"
    },
    {
      "x": 0,
      "y": 3,
      "z": 7,
      "name": "Rock_Basalt_Brick_Smooth"
    },
    {
      "x": 0,
      "y": 4,
      "z": 7,
      "name": "Rock_Basalt_Brick_Smooth"
    },
    {
      "x": 0,
      "y": 5,
      "z": 7,
      "name": "Rock_Basalt_Brick_Smooth"
    },
    {
      "x": 0,
      "y": 6,
      "z": 7,
      "name": "Rock_Basalt_Brick_Smooth"
    },
    {
      "x": 0,
      "y": 7,
      "z": 7,
      "name": "Rock_Basalt_Brick_Smooth"
    },
    {
      "x": 1,
      "y": 0,
      "z": -7,
      "name": "Rock_Basalt_Brick_Smooth"
    },
    {
      "x": 1,
      "y": 1,
      "z": -7,
      "name": "Rock_Basalt_Brick_Smooth"
    },
    {
      "x": 1,
      "y": 2,
      "z": -7,
      "name": "Rock_Basalt_Brick_Smooth"
    },
    {
      "x": 1,
      "y": 3,
      "z": -7,
      "name": "Rock_Basalt_Brick_Smooth"
    },
    {
      "x": 1,
      "y": 4,
      "z": -7,
      "name": "Rock_Basalt_Brick_Smooth"
    },
    {
      "x": 1,
      "y": 5,
      "z": -7,
      "name": "Rock_Basalt_Brick_Smooth"
    },
    {
      "x": 1,
      "y": 6,
      "z": -7,
      "name": "Rock_Basalt_Brick_Smooth"
    },
    {
      "x": 1,
      "y": 7,
      "z": -7,
      "name": "Rock_Basalt_Brick_Smooth"
    },
    {
      "x": 1,
      "y": 0,
      "z": -6,
      "name": "Rock_Basalt_Brick_Smooth"
    },
    {
      "x": 1,
      "y": 7,
      "z": -6,
      "name": "Rock_Basalt_Brick_Smooth"
    },
    {
      "x": 1,
      "y": 0,
      "z": -5,
      "name": "Rock_Basalt_Brick_Smooth"
    },
    {
      "x": 1,
      "y": 7,
      "z": -5,
      "name": "Rock_Basalt_Brick_Smooth"
    },
    {
      "x": 1,
      "y": 0,
      "z": -4,
      "name": "Rock_Basalt_Brick_Smooth"
    },
    {
      "x": 1,
      "y": 7,
      "z": -4,
      "name": "Rock_Basalt_Brick_Smooth"
    },
    {
      "x": 1,
      "y": 0,
      "z": -3,
      "name": "Rock_Basalt_Brick_Smooth"
    },
    {
      "x": 1,
      "y": 7,
      "z": -3,
      "name": "Rock_Basalt_Brick_Smooth"
    },
    {
      "x": 1,
      "y": 0,
      "z": -2,
      "name": "Rock_Basalt_Brick_Smooth"
    },
    {
      "x": 1,
      "y": 7,
      "z": -2,
      "name": "Rock_Basalt_Brick_Smooth"
    },
    {
      "x": 1,
      "y": 0,
      "z": -1,
      "name": "Rock_Basalt_Brick_Smooth"
    },
    {
      "x": 1,
      "y": 7,
      "z": -1,
      "name": "Rock_Basalt_Brick_Smooth"
    },
    {
      "x": 1,
      "y": 0,
      "z": 0,
      "name": "Rock_Basalt_Brick_Smooth"
    },
    {
      "x": 1,
      "y": 7,
      "z": 0,
      "name": "Rock_Basalt_Brick_Smooth"
    },
    {
      "x": 1,
      "y": 0,
      "z": 1,
      "name": "Rock_Basalt_Brick_Smooth"
    },
    {
      "x": 1,
      "y": 7,
      "z": 1,
      "name": "Rock_Basalt_Brick_Smooth"
    },
    {
      "x": 1,
      "y": 0,
      "z": 2,
      "name": "Rock_Basalt_Brick_Smooth"
    },
    {
      "x": 1,
      "y": 7,
      "z": 2,
      "name": "Rock_Basalt_Brick_Smooth"
    },
    {
      "x": 1,
      "y": 0,
      "z": 3,
      "name": "Rock_Basalt_Brick_Smooth"
    },
    {
      "x": 1,
      "y": 7,
      "z": 3,
      "name": "Rock_Basalt_Brick_Smooth"
    },
    {
      "x": 1,
      "y": 0,
      "z": 4,
      "name": "Rock_Basalt_Brick_Smooth"
    },
    {
      "x": 1,
      "y": 7,
      "z": 4,
      "name": "Rock_Basalt_Brick_Smooth"
    },
    {
      "x": 1,
      "y": 0,
      "z": 5,
      "name": "Rock_Basalt_Brick_Smooth"
    },
    {
      "x": 1,
      "y": 7,
      "z": 5,
      "name": "Rock_Basalt_Brick_Smooth"
    },
    {
      "x": 1,
      "y": 0,
      "z": 6,
      "name": "Rock_Basalt_Brick_Smooth"
    },
    {
      "x": 1,
      "y": 7,
      "z": 6,
      "name": "Rock_Basalt_Brick_Smooth"
    },
    {
      "x": 1,
      "y": 0,
      "z": 7,
      "name": "Rock_Basalt_Brick_Smooth"
    },
    {
      "x": 1,
      "y": 1,
      "z": 7,
      "name": "Rock_Basalt_Brick_Smooth"
    },
    {
      "x": 1,
      "y": 2,
      "z": 7,
      "name": "Rock_Basalt_Brick_Smooth"
    },
    {
      "x": 1,
      "y": 3,
      "z": 7,
      "name": "Rock_Basalt_Brick_Smooth"
    },
    {
      "x": 1,
      "y": 4,
      "z": 7,
      "name": "Rock_Basalt_Brick_Smooth"
    },
    {
      "x": 1,
      "y": 5,
      "z": 7,
      "name": "Rock_Basalt_Brick_Smooth"
    },
    {
      "x": 1,
      "y": 6,
      "z": 7,
      "name": "Rock_Basalt_Brick_Smooth"
    },
    {
      "x": 1,
      "y": 7,
      "z": 7,
      "name": "Rock_Basalt_Brick_Smooth"
    },
    {
      "x": 2,
      "y": 0,
      "z": -7,
      "name": "Rock_Basalt_Brick_Smooth"
    },
    {
      "x": 2,
      "y": 1,
      "z": -7,
      "name": "Rock_Basalt_Brick_Smooth"
    },
    {
      "x": 2,
      "y": 2,
      "z": -7,
      "name": "Rock_Basalt_Brick_Smooth"
    },
    {
      "x": 2,
      "y": 3,
      "z": -7,
      "name": "Rock_Basalt_Brick_Smooth"
    },
    {
      "x": 2,
      "y": 4,
      "z": -7,
      "name": "Rock_Basalt_Brick_Smooth"
    },
    {
      "x": 2,
      "y": 5,
      "z": -7,
      "name": "Rock_Basalt_Brick_Smooth"
    },
    {
      "x": 2,
      "y": 6,
      "z": -7,
      "name": "Rock_Basalt_Brick_Smooth"
    },
    {
      "x": 2,
      "y": 7,
      "z": -7,
      "name": "Rock_Basalt_Brick_Smooth"
    },
    {
      "x": 2,
      "y": 0,
      "z": -6,
      "name": "Rock_Basalt_Brick_Smooth"
    },
    {
      "x": 2,
      "y": 7,
      "z": -6,
      "name": "Rock_Basalt_Brick_Smooth"
    },
    {
      "x": 2,
      "y": 0,
      "z": -5,
      "name": "Rock_Basalt_Brick_Smooth"
    },
    {
      "x": 2,
      "y": 7,
      "z": -5,
      "name": "Rock_Basalt_Brick_Smooth"
    },
    {
      "x": 2,
      "y": 0,
      "z": -4,
      "name": "Rock_Basalt_Brick_Smooth"
    },
    {
      "x": 2,
      "y": 7,
      "z": -4,
      "name": "Rock_Basalt_Brick_Smooth"
    },
    {
      "x": 2,
      "y": 0,
      "z": -3,
      "name": "Rock_Basalt_Brick_Smooth"
    },
    {
      "x": 2,
      "y": 7,
      "z": -3,
      "name": "Rock_Basalt_Brick_Smooth"
    },
    {
      "x": 2,
      "y": 0,
      "z": -2,
      "name": "Rock_Basalt_Brick_Smooth"
    },
    {
      "x": 2,
      "y": 7,
      "z": -2,
      "name": "Rock_Basalt_Brick_Smooth"
    },
    {
      "x": 2,
      "y": 0,
      "z": -1,
      "name": "Rock_Basalt_Brick_Smooth"
    },
    {
      "x": 2,
      "y": 7,
      "z": -1,
      "name": "Rock_Basalt_Brick_Smooth"
    },
    {
      "x": 2,
      "y": 0,
      "z": 0,
      "name": "Rock_Basalt_Brick_Smooth"
    },
    {
      "x": 2,
      "y": 7,
      "z": 0,
      "name": "Rock_Basalt_Brick_Smooth"
    },
    {
      "x": 2,
      "y": 0,
      "z": 1,
      "name": "Rock_Basalt_Brick_Smooth"
    },
    {
      "x": 2,
      "y": 7,
      "z": 1,
      "name": "Rock_Basalt_Brick_Smooth"
    },
    {
      "x": 2,
      "y": 0,
      "z": 2,
      "name": "Rock_Basalt_Brick_Smooth"
    },
    {
      "x": 2,
      "y": 7,
      "z": 2,
      "name": "Rock_Basalt_Brick_Smooth"
    },
    {
      "x": 2,
      "y": 0,
      "z": 3,
      "name": "Rock_Basalt_Brick_Smooth"
    },
    {
      "x": 2,
      "y": 7,
      "z": 3,
      "name": "Rock_Basalt_Brick_Smooth"
    },
    {
      "x": 2,
      "y": 0,
      "z": 4,
      "name": "Rock_Basalt_Brick_Smooth"
    },
    {
      "x": 2,
      "y": 7,
      "z": 4,
      "name": "Rock_Basalt_Brick_Smooth"
    },
    {
      "x": 2,
      "y": 0,
      "z": 5,
      "name": "Rock_Basalt_Brick_Smooth"
    },
    {
      "x": 2,
      "y": 7,
      "z": 5,
      "name": "Rock_Basalt_Brick_Smooth"
    },
    {
      "x": 2,
      "y": 0,
      "z": 6,
      "name": "Rock_Basalt_Brick_Smooth"
    },
    {
      "x": 2,
      "y": 7,
      "z": 6,
      "name": "Rock_Basalt_Brick_Smooth"
    },
    {
      "x": 2,
      "y": 0,
      "z": 7,
      "name": "Rock_Basalt_Brick_Smooth"
    },
    {
      "x": 2,
      "y": 1,
      "z": 7,
      "name": "Rock_Basalt_Brick_Smooth"
    },
    {
      "x": 2,
      "y": 2,
      "z": 7,
      "name": "Rock_Basalt_Brick_Smooth"
    },
    {
      "x": 2,
      "y": 3,
      "z": 7,
      "name": "Rock_Basalt_Brick_Smooth"
    },
    {
      "x": 2,
      "y": 4,
      "z": 7,
      "name": "Rock_Basalt_Brick_Smooth"
    },
    {
      "x": 2,
      "y": 5,
      "z": 7,
      "name": "Rock_Basalt_Brick_Smooth"
    },
    {
      "x": 2,
      "y": 6,
      "z": 7,
      "name": "Rock_Basalt_Brick_Smooth"
    },
    {
      "x": 2,
      "y": 7,
      "z": 7,
      "name": "Rock_Basalt_Brick_Smooth"
    },
    {
      "x": 3,
      "y": 0,
      "z": -7,
      "name": "Rock_Basalt_Brick_Smooth"
    },
    {
      "x": 3,
      "y": 1,
      "z": -7,
      "name": "Rock_Basalt_Brick_Smooth"
    },
    {
      "x": 3,
      "y": 2,
      "z": -7,
      "name": "Rock_Basalt_Brick_Smooth"
    },
    {
      "x": 3,
      "y": 3,
      "z": -7,
      "name": "Rock_Basalt_Brick_Smooth"
    },
    {
      "x": 3,
      "y": 4,
      "z": -7,
      "name": "Rock_Basalt_Brick_Smooth"
    },
    {
      "x": 3,
      "y": 5,
      "z": -7,
      "name": "Rock_Basalt_Brick_Smooth"
    },
    {
      "x": 3,
      "y": 6,
      "z": -7,
      "name": "Rock_Basalt_Brick_Smooth"
    },
    {
      "x": 3,
      "y": 7,
      "z": -7,
      "name": "Rock_Basalt_Brick_Smooth"
    },
    {
      "x": 3,
      "y": 0,
      "z": -6,
      "name": "Rock_Basalt_Brick_Smooth"
    },
    {
      "x": 3,
      "y": 7,
      "z": -6,
      "name": "Rock_Basalt_Brick_Smooth"
    },
    {
      "x": 3,
      "y": 0,
      "z": -5,
      "name": "Rock_Basalt_Brick_Smooth"
    },
    {
      "x": 3,
      "y": 7,
      "z": -5,
      "name": "Rock_Basalt_Brick_Smooth"
    },
    {
      "x": 3,
      "y": 0,
      "z": -4,
      "name": "Rock_Basalt_Brick_Smooth"
    },
    {
      "x": 3,
      "y": 7,
      "z": -4,
      "name": "Rock_Basalt_Brick_Smooth"
    },
    {
      "x": 3,
      "y": 0,
      "z": -3,
      "name": "Rock_Basalt_Brick_Smooth"
    },
    {
      "x": 3,
      "y": 7,
      "z": -3,
      "name": "Rock_Basalt_Brick_Smooth"
    },
    {
      "x": 3,
      "y": 0,
      "z": -2,
      "name": "Rock_Basalt_Brick_Smooth"
    },
    {
      "x": 3,
      "y": 7,
      "z": -2,
      "name": "Rock_Basalt_Brick_Smooth"
    },
    {
      "x": 3,
      "y": 0,
      "z": -1,
      "name": "Rock_Basalt_Brick_Smooth"
    },
    {
      "x": 3,
      "y": 7,
      "z": -1,
      "name": "Rock_Basalt_Brick_Smooth"
    },
    {
      "x": 3,
      "y": 0,
      "z": 0,
      "name": "Rock_Basalt_Brick_Smooth"
    },
    {
      "x": 3,
      "y": 7,
      "z": 0,
      "name": "Rock_Basalt_Brick_Smooth"
    },
    {
      "x": 3,
      "y": 0,
      "z": 1,
      "name": "Rock_Basalt_Brick_Smooth"
    },
    {
      "x": 3,
      "y": 7,
      "z": 1,
      "name": "Rock_Basalt_Brick_Smooth"
    },
    {
      "x": 3,
      "y": 0,
      "z": 2,
      "name": "Rock_Basalt_Brick_Smooth"
    },
    {
      "x": 3,
      "y": 7,
      "z": 2,
      "name": "Rock_Basalt_Brick_Smooth"
    },
    {
      "x": 3,
      "y": 0,
      "z": 3,
      "name": "Rock_Basalt_Brick_Smooth"
    },
    {
      "x": 3,
      "y": 7,
      "z": 3,
      "name": "Rock_Basalt_Brick_Smooth"
    },
    {
      "x": 3,
      "y": 0,
      "z": 4,
      "name": "Rock_Basalt_Brick_Smooth"
    },
    {
      "x": 3,
      "y": 7,
      "z": 4,
      "name": "Rock_Basalt_Brick_Smooth"
    },
    {
      "x": 3,
      "y": 0,
      "z": 5,
      "name": "Rock_Basalt_Brick_Smooth"
    },
    {
      "x": 3,
      "y": 7,
      "z": 5,
      "name": "Rock_Basalt_Brick_Smooth"
    },
    {
      "x": 3,
      "y": 0,
      "z": 6,
      "name": "Rock_Basalt_Brick_Smooth"
    },
    {
      "x": 3,
      "y": 7,
      "z": 6,
      "name": "Rock_Basalt_Brick_Smooth"
    },
    {
      "x": 3,
      "y": 0,
      "z": 7,
      "name": "Rock_Basalt_Brick_Smooth"
    },
    {
      "x": 3,
      "y": 1,
      "z": 7,
      "name": "Rock_Basalt_Brick_Smooth"
    },
    {
      "x": 3,
      "y": 2,
      "z": 7,
      "name": "Rock_Basalt_Brick_Smooth"
    },
    {
      "x": 3,
      "y": 3,
      "z": 7,
      "name": "Rock_Basalt_Brick_Smooth"
    },
    {
      "x": 3,
      "y": 4,
      "z": 7,
      "name": "Rock_Basalt_Brick_Smooth"
    },
    {
      "x": 3,
      "y": 5,
      "z": 7,
      "name": "Rock_Basalt_Brick_Smooth"
    },
    {
      "x": 3,
      "y": 6,
      "z": 7,
      "name": "Rock_Basalt_Brick_Smooth"
    },
    {
      "x": 3,
      "y": 7,
      "z": 7,
      "name": "Rock_Basalt_Brick_Smooth"
    },
    {
      "x": 4,
      "y": 0,
      "z": -7,
      "name": "Rock_Basalt_Brick_Smooth"
    },
    {
      "x": 4,
      "y": 1,
      "z": -7,
      "name": "Rock_Basalt_Brick_Smooth"
    },
    {
      "x": 4,
      "y": 2,
      "z": -7,
      "name": "Rock_Basalt_Brick_Smooth"
    },
    {
      "x": 4,
      "y": 3,
      "z": -7,
      "name": "Rock_Basalt_Brick_Smooth"
    },
    {
      "x": 4,
      "y": 4,
      "z": -7,
      "name": "Rock_Basalt_Brick_Smooth"
    },
    {
      "x": 4,
      "y": 5,
      "z": -7,
      "name": "Rock_Basalt_Brick_Smooth"
    },
    {
      "x": 4,
      "y": 6,
      "z": -7,
      "name": "Rock_Basalt_Brick_Smooth"
    },
    {
      "x": 4,
      "y": 7,
      "z": -7,
      "name": "Rock_Basalt_Brick_Smooth"
    },
    {
      "x": 4,
      "y": 0,
      "z": -6,
      "name": "Rock_Basalt_Brick_Smooth"
    },
    {
      "x": 4,
      "y": 7,
      "z": -6,
      "name": "Rock_Basalt_Brick_Smooth"
    },
    {
      "x": 4,
      "y": 0,
      "z": -5,
      "name": "Rock_Basalt_Brick_Smooth"
    },
    {
      "x": 4,
      "y": 7,
      "z": -5,
      "name": "Rock_Basalt_Brick_Smooth"
    },
    {
      "x": 4,
      "y": 0,
      "z": -4,
      "name": "Rock_Basalt_Brick_Smooth"
    },
    {
      "x": 4,
      "y": 7,
      "z": -4,
      "name": "Rock_Basalt_Brick_Smooth"
    },
    {
      "x": 4,
      "y": 0,
      "z": -3,
      "name": "Rock_Basalt_Brick_Smooth"
    },
    {
      "x": 4,
      "y": 7,
      "z": -3,
      "name": "Rock_Basalt_Brick_Smooth"
    },
    {
      "x": 4,
      "y": 0,
      "z": -2,
      "name": "Rock_Basalt_Brick_Smooth"
    },
    {
      "x": 4,
      "y": 7,
      "z": -2,
      "name": "Rock_Basalt_Brick_Smooth"
    },
    {
      "x": 4,
      "y": 0,
      "z": -1,
      "name": "Rock_Basalt_Brick_Smooth"
    },
    {
      "x": 4,
      "y": 7,
      "z": -1,
      "name": "Rock_Basalt_Brick_Smooth"
    },
    {
      "x": 4,
      "y": 0,
      "z": 0,
      "name": "Rock_Basalt_Brick_Smooth"
    },
    {
      "x": 4,
      "y": 7,
      "z": 0,
      "name": "Rock_Basalt_Brick_Smooth"
    },
    {
      "x": 4,
      "y": 0,
      "z": 1,
      "name": "Rock_Basalt_Brick_Smooth"
    },
    {
      "x": 4,
      "y": 7,
      "z": 1,
      "name": "Rock_Basalt_Brick_Smooth"
    },
    {
      "x": 4,
      "y": 0,
      "z": 2,
      "name": "Rock_Basalt_Brick_Smooth"
    },
    {
      "x": 4,
      "y": 7,
      "z": 2,
      "name": "Rock_Basalt_Brick_Smooth"
    },
    {
      "x": 4,
      "y": 0,
      "z": 3,
      "name": "Rock_Basalt_Brick_Smooth"
    },
    {
      "x": 4,
      "y": 7,
      "z": 3,
      "name": "Rock_Basalt_Brick_Smooth"
    },
    {
      "x": 4,
      "y": 0,
      "z": 4,
      "name": "Rock_Basalt_Brick_Smooth"
    },
    {
      "x": 4,
      "y": 7,
      "z": 4,
      "name": "Rock_Basalt_Brick_Smooth"
    },
    {
      "x": 4,
      "y": 0,
      "z": 5,
      "name": "Rock_Basalt_Brick_Smooth"
    },
    {
      "x": 4,
      "y": 7,
      "z": 5,
      "name": "Rock_Basalt_Brick_Smooth"
    },
    {
      "x": 4,
      "y": 0,
      "z": 6,
      "name": "Rock_Basalt_Brick_Smooth"
    },
    {
      "x": 4,
      "y": 7,
      "z": 6,
      "name": "Rock_Basalt_Brick_Smooth"
    },
    {
      "x": 4,
      "y": 0,
      "z": 7,
      "name": "Rock_Basalt_Brick_Smooth"
    },
    {
      "x": 4,
      "y": 1,
      "z": 7,
      "name": "Rock_Basalt_Brick_Smooth"
    },
    {
      "x": 4,
      "y": 2,
      "z": 7,
      "name": "Rock_Basalt_Brick_Smooth"
    },
    {
      "x": 4,
      "y": 3,
      "z": 7,
      "name": "Rock_Basalt_Brick_Smooth"
    },
    {
      "x": 4,
      "y": 4,
      "z": 7,
      "name": "Rock_Basalt_Brick_Smooth"
    },
    {
      "x": 4,
      "y": 5,
      "z": 7,
      "name": "Rock_Basalt_Brick_Smooth"
    },
    {
      "x": 4,
      "y": 6,
      "z": 7,
      "name": "Rock_Basalt_Brick_Smooth"
    },
    {
      "x": 4,
      "y": 7,
      "z": 7,
      "name": "Rock_Basalt_Brick_Smooth"
    },
    {
      "x": 5,
      "y": 0,
      "z": -7,
      "name": "Rock_Basalt_Brick_Smooth"
    },
    {
      "x": 5,
      "y": 1,
      "z": -7,
      "name": "Rock_Basalt_Brick_Smooth"
    },
    {
      "x": 5,
      "y": 2,
      "z": -7,
      "name": "Rock_Basalt_Brick_Smooth"
    },
    {
      "x": 5,
      "y": 3,
      "z": -7,
      "name": "Rock_Basalt_Brick_Smooth"
    },
    {
      "x": 5,
      "y": 4,
      "z": -7,
      "name": "Rock_Basalt_Brick_Smooth"
    },
    {
      "x": 5,
      "y": 5,
      "z": -7,
      "name": "Rock_Basalt_Brick_Smooth"
    },
    {
      "x": 5,
      "y": 6,
      "z": -7,
      "name": "Rock_Basalt_Brick_Smooth"
    },
    {
      "x": 5,
      "y": 7,
      "z": -7,
      "name": "Rock_Basalt_Brick_Smooth"
    },
    {
      "x": 5,
      "y": 0,
      "z": -6,
      "name": "Rock_Basalt_Brick_Smooth"
    },
    {
      "x": 5,
      "y": 7,
      "z": -6,
      "name": "Rock_Basalt_Brick_Smooth"
    },
    {
      "x": 5,
      "y": 0,
      "z": -5,
      "name": "Rock_Basalt_Brick_Smooth"
    },
    {
      "x": 5,
      "y": 7,
      "z": -5,
      "name": "Rock_Basalt_Brick_Smooth"
    },
    {
      "x": 5,
      "y": 0,
      "z": -4,
      "name": "Rock_Basalt_Brick_Smooth"
    },
    {
      "x": 5,
      "y": 7,
      "z": -4,
      "name": "Rock_Basalt_Brick_Smooth"
    },
    {
      "x": 5,
      "y": 0,
      "z": -3,
      "name": "Rock_Basalt_Brick_Smooth"
    },
    {
      "x": 5,
      "y": 7,
      "z": -3,
      "name": "Rock_Basalt_Brick_Smooth"
    },
    {
      "x": 5,
      "y": 0,
      "z": -2,
      "name": "Rock_Basalt_Brick_Smooth"
    },
    {
      "x": 5,
      "y": 7,
      "z": -2,
      "name": "Rock_Basalt_Brick_Smooth"
    },
    {
      "x": 5,
      "y": 0,
      "z": -1,
      "name": "Rock_Basalt_Brick_Smooth"
    },
    {
      "x": 5,
      "y": 7,
      "z": -1,
      "name": "Rock_Basalt_Brick_Smooth"
    },
    {
      "x": 5,
      "y": 0,
      "z": 0,
      "name": "Rock_Basalt_Brick_Smooth"
    },
    {
      "x": 5,
      "y": 7,
      "z": 0,
      "name": "Rock_Basalt_Brick_Smooth"
    },
    {
      "x": 5,
      "y": 0,
      "z": 1,
      "name": "Rock_Basalt_Brick_Smooth"
    },
    {
      "x": 5,
      "y": 7,
      "z": 1,
      "name": "Rock_Basalt_Brick_Smooth"
    },
    {
      "x": 5,
      "y": 0,
      "z": 2,
      "name": "Rock_Basalt_Brick_Smooth"
    },
    {
      "x": 5,
      "y": 7,
      "z": 2,
      "name": "Rock_Basalt_Brick_Smooth"
    },
    {
      "x": 5,
      "y": 0,
      "z": 3,
      "name": "Rock_Basalt_Brick_Smooth"
    },
    {
      "x": 5,
      "y": 7,
      "z": 3,
      "name": "Rock_Basalt_Brick_Smooth"
    },
    {
      "x": 5,
      "y": 0,
      "z": 4,
      "name": "Rock_Basalt_Brick_Smooth"
    },
    {
      "x": 5,
      "y": 7,
      "z": 4,
      "name": "Rock_Basalt_Brick_Smooth"
    },
    {
      "x": 5,
      "y": 0,
      "z": 5,
      "name": "Rock_Basalt_Brick_Smooth"
    },
    {
      "x": 5,
      "y": 7,
      "z": 5,
      "name": "Rock_Basalt_Brick_Smooth"
    },
    {
      "x": 5,
      "y": 0,
      "z": 6,
      "name": "Rock_Basalt_Brick_Smooth"
    },
    {
      "x": 5,
      "y": 7,
      "z": 6,
      "name": "Rock_Basalt_Brick_Smooth"
    },
    {
      "x": 5,
      "y": 0,
      "z": 7,
      "name": "Rock_Basalt_Brick_Smooth"
    },
    {
      "x": 5,
      "y": 1,
      "z": 7,
      "name": "Rock_Basalt_Brick_Smooth"
    },
    {
      "x": 5,
      "y": 2,
      "z": 7,
      "name": "Rock_Basalt_Brick_Smooth"
    },
    {
      "x": 5,
      "y": 3,
      "z": 7,
      "name": "Rock_Basalt_Brick_Smooth"
    },
    {
      "x": 5,
      "y": 4,
      "z": 7,
      "name": "Rock_Basalt_Brick_Smooth"
    },
    {
      "x": 5,
      "y": 5,
      "z": 7,
      "name": "Rock_Basalt_Brick_Smooth"
    },
    {
      "x": 5,
      "y": 6,
      "z": 7,
      "name": "Rock_Basalt_Brick_Smooth"
    },
    {
      "x": 5,
      "y": 7,
      "z": 7,
      "name": "Rock_Basalt_Brick_Smooth"
    },
    {
      "x": 6,
      "y": 0,
      "z": -7,
      "name": "Rock_Basalt_Brick_Smooth"
    },
    {
      "x": 6,
      "y": 1,
      "z": -7,
      "name": "Rock_Basalt_Brick_Smooth"
    },
    {
      "x": 6,
      "y": 2,
      "z": -7,
      "name": "Rock_Basalt_Brick_Smooth"
    },
    {
      "x": 6,
      "y": 3,
      "z": -7,
      "name": "Rock_Basalt_Brick_Smooth"
    },
    {
      "x": 6,
      "y": 4,
      "z": -7,
      "name": "Rock_Basalt_Brick_Smooth"
    },
    {
      "x": 6,
      "y": 5,
      "z": -7,
      "name": "Rock_Basalt_Brick_Smooth"
    },
    {
      "x": 6,
      "y": 6,
      "z": -7,
      "name": "Rock_Basalt_Brick_Smooth"
    },
    {
      "x": 6,
      "y": 7,
      "z": -7,
      "name": "Rock_Basalt_Brick_Smooth"
    },
    {
      "x": 6,
      "y": 0,
      "z": -6,
      "name": "Rock_Basalt_Brick_Smooth"
    },
    {
      "x": 6,
      "y": 7,
      "z": -6,
      "name": "Rock_Basalt_Brick_Smooth"
    },
    {
      "x": 6,
      "y": 0,
      "z": -5,
      "name": "Rock_Basalt_Brick_Smooth"
    },
    {
      "x": 6,
      "y": 7,
      "z": -5,
      "name": "Rock_Basalt_Brick_Smooth"
    },
    {
      "x": 6,
      "y": 0,
      "z": -4,
      "name": "Rock_Basalt_Brick_Smooth"
    },
    {
      "x": 6,
      "y": 7,
      "z": -4,
      "name": "Rock_Basalt_Brick_Smooth"
    },
    {
      "x": 6,
      "y": 0,
      "z": -3,
      "name": "Rock_Basalt_Brick_Smooth"
    },
    {
      "x": 6,
      "y": 7,
      "z": -3,
      "name": "Rock_Basalt_Brick_Smooth"
    },
    {
      "x": 6,
      "y": 0,
      "z": -2,
      "name": "Rock_Basalt_Brick_Smooth"
    },
    {
      "x": 6,
      "y": 7,
      "z": -2,
      "name": "Rock_Basalt_Brick_Smooth"
    },
    {
      "x": 6,
      "y": 0,
      "z": -1,
      "name": "Rock_Basalt_Brick_Smooth"
    },
    {
      "x": 6,
      "y": 7,
      "z": -1,
      "name": "Rock_Basalt_Brick_Smooth"
    },
    {
      "x": 6,
      "y": 0,
      "z": 0,
      "name": "Rock_Basalt_Brick_Smooth"
    },
    {
      "x": 6,
      "y": 7,
      "z": 0,
      "name": "Rock_Basalt_Brick_Smooth"
    },
    {
      "x": 6,
      "y": 0,
      "z": 1,
      "name": "Rock_Basalt_Brick_Smooth"
    },
    {
      "x": 6,
      "y": 7,
      "z": 1,
      "name": "Rock_Basalt_Brick_Smooth"
    },
    {
      "x": 6,
      "y": 0,
      "z": 2,
      "name": "Rock_Basalt_Brick_Smooth"
    },
    {
      "x": 6,
      "y": 7,
      "z": 2,
      "name": "Rock_Basalt_Brick_Smooth"
    },
    {
      "x": 6,
      "y": 0,
      "z": 3,
      "name": "Rock_Basalt_Brick_Smooth"
    },
    {
      "x": 6,
      "y": 7,
      "z": 3,
      "name": "Rock_Basalt_Brick_Smooth"
    },
    {
      "x": 6,
      "y": 0,
      "z": 4,
      "name": "Rock_Basalt_Brick_Smooth"
    },
    {
      "x": 6,
      "y": 7,
      "z": 4,
      "name": "Rock_Basalt_Brick_Smooth"
    },
    {
      "x": 6,
      "y": 0,
      "z": 5,
      "name": "Rock_Basalt_Brick_Smooth"
    },
    {
      "x": 6,
      "y": 7,
      "z": 5,
      "name": "Rock_Basalt_Brick_Smooth"
    },
    {
      "x": 6,
      "y": 0,
      "z": 6,
      "name": "Rock_Basalt_Brick_Smooth"
    },
    {
      "x": 6,
      "y": 7,
      "z": 6,
      "name": "Rock_Basalt_Brick_Smooth"
    },
    {
      "x": 6,
      "y": 0,
      "z": 7,
      "name": "Rock_Basalt_Brick_Smooth"
    },
    {
      "x": 6,
      "y": 1,
      "z": 7,
      "name": "Rock_Basalt_Brick_Smooth"
    },
    {
      "x": 6,
      "y": 2,
      "z": 7,
      "name": "Rock_Basalt_Brick_Smooth"
    },
    {
      "x": 6,
      "y": 3,
      "z": 7,
      "name": "Rock_Basalt_Brick_Smooth"
    },
    {
      "x": 6,
      "y": 4,
      "z": 7,
      "name": "Rock_Basalt_Brick_Smooth"
    },
    {
      "x": 6,
      "y": 5,
      "z": 7,
      "name": "Rock_Basalt_Brick_Smooth"
    },
    {
      "x": 6,
      "y": 6,
      "z": 7,
      "name": "Rock_Basalt_Brick_Smooth"
    },
    {
      "x": 6,
      "y": 7,
      "z": 7,
      "name": "Rock_Basalt_Brick_Smooth"
    },
    {
      "x": 7,
      "y": 0,
      "z": -7,
      "name": "Rock_Basalt_Brick_Smooth"
    },
    {
      "x": 7,
      "y": 1,
      "z": -7,
      "name": "Rock_Basalt_Brick_Smooth"
    },
    {
      "x": 7,
      "y": 2,
      "z": -7,
      "name": "Rock_Basalt_Brick_Smooth"
    },
    {
      "x": 7,
      "y": 3,
      "z": -7,
      "name": "Rock_Basalt_Brick_Smooth"
    },
    {
      "x": 7,
      "y": 4,
      "z": -7,
      "name": "Rock_Basalt_Brick_Smooth"
    },
    {
      "x": 7,
      "y": 5,
      "z": -7,
      "name": "Rock_Basalt_Brick_Smooth"
    },
    {
      "x": 7,
      "y": 6,
      "z": -7,
      "name": "Rock_Basalt_Brick_Smooth"
    },
    {
      "x": 7,
      "y": 7,
      "z": -7,
      "name": "Rock_Basalt_Brick_Smooth"
    },
    {
      "x": 7,
      "y": 0,
      "z": -6,
      "name": "Rock_Basalt_Brick_Smooth"
    },
    {
      "x": 7,
      "y": 7,
      "z": -6,
      "name": "Rock_Basalt_Brick_Smooth"
    },
    {
      "x": 7,
      "y": 0,
      "z": -5,
      "name": "Rock_Basalt_Brick_Smooth"
    },
    {
      "x": 7,
      "y": 7,
      "z": -5,
      "name": "Rock_Basalt_Brick_Smooth"
    },
    {
      "x": 7,
      "y": 0,
      "z": -4,
      "name": "Rock_Basalt_Brick_Smooth"
    },
    {
      "x": 7,
      "y": 7,
      "z": -4,
      "name": "Rock_Basalt_Brick_Smooth"
    },
    {
      "x": 7,
      "y": 0,
      "z": -3,
      "name": "Rock_Basalt_Brick_Smooth"
    },
    {
      "x": 7,
      "y": 7,
      "z": -3,
      "name": "Rock_Basalt_Brick_Smooth"
    },
    {
      "x": 7,
      "y": 0,
      "z": -2,
      "name": "Rock_Basalt_Brick_Smooth"
    },
    {
      "x": 7,
      "y": 7,
      "z": -2,
      "name": "Rock_Basalt_Brick_Smooth"
    },
    {
      "x": 7,
      "y": 0,
      "z": -1,
      "name": "Rock_Basalt_Brick_Smooth"
    },
    {
      "x": 7,
      "y": 7,
      "z": -1,
      "name": "Rock_Basalt_Brick_Smooth"
    },
    {
      "x": 7,
      "y": 0,
      "z": 0,
      "name": "Rock_Basalt_Brick_Smooth"
    },
    {
      "x": 7,
      "y": 7,
      "z": 0,
      "name": "Rock_Basalt_Brick_Smooth"
    },
    {
      "x": 7,
      "y": 0,
      "z": 1,
      "name": "Rock_Basalt_Brick_Smooth"
    },
    {
      "x": 7,
      "y": 7,
      "z": 1,
      "name": "Rock_Basalt_Brick_Smooth"
    },
    {
      "x": 7,
      "y": 0,
      "z": 2,
      "name": "Rock_Basalt_Brick_Smooth"
    },
    {
      "x": 7,
      "y": 7,
      "z": 2,
      "name": "Rock_Basalt_Brick_Smooth"
    },
    {
      "x": 7,
      "y": 0,
      "z": 3,
      "name": "Rock_Basalt_Brick_Smooth"
    },
    {
      "x": 7,
      "y": 7,
      "z": 3,
      "name": "Rock_Basalt_Brick_Smooth"
    },
    {
      "x": 7,
      "y": 0,
      "z": 4,
      "name": "Rock_Basalt_Brick_Smooth"
    },
    {
      "x": 7,
      "y": 7,
      "z": 4,
      "name": "Rock_Basalt_Brick_Smooth"
    },
    {
      "x": 7,
      "y": 0,
      "z": 5,
      "name": "Rock_Basalt_Brick_Smooth"
    },
    {
      "x": 7,
      "y": 7,
      "z": 5,
      "name": "Rock_Basalt_Brick_Smooth"
    },
    {
      "x": 7,
      "y": 0,
      "z": 6,
      "name": "Rock_Basalt_Brick_Smooth"
    },
    {
      "x": 7,
      "y": 7,
      "z": 6,
      "name": "Rock_Basalt_Brick_Smooth"
    },
    {
      "x": 7,
      "y": 0,
      "z": 7,
      "name": "Rock_Basalt_Brick_Smooth"
    },
    {
      "x": 7,
      "y": 1,
      "z": 7,
      "name": "Rock_Basalt_Brick_Smooth"
    },
    {
      "x": 7,
      "y": 2,
      "z": 7,
      "name": "Rock_Basalt_Brick_Smooth"
    },
    {
      "x": 7,
      "y": 3,
      "z": 7,
      "name": "Rock_Basalt_Brick_Smooth"
    },
    {
      "x": 7,
      "y": 4,
      "z": 7,
      "name": "Rock_Basalt_Brick_Smooth"
    },
    {
      "x": 7,
      "y": 5,
      "z": 7,
      "name": "Rock_Basalt_Brick_Smooth"
    },
    {
      "x": 7,
      "y": 6,
      "z": 7,
      "name": "Rock_Basalt_Brick_Smooth"
    },
    {
      "x": 7,
      "y": 7,
      "z": 7,
      "name": "Rock_Basalt_Brick_Smooth"
    },
    {
      "x": 8,
      "y": 0,
      "z": -7,
      "name": "Rock_Basalt_Brick_Smooth"
    },
    {
      "x": 8,
      "y": 1,
      "z": -7,
      "name": "Rock_Basalt_Brick_Smooth"
    },
    {
      "x": 8,
      "y": 2,
      "z": -7,
      "name": "Rock_Basalt_Brick_Smooth"
    },
    {
      "x": 8,
      "y": 3,
      "z": -7,
      "name": "Rock_Basalt_Brick_Smooth"
    },
    {
      "x": 8,
      "y": 4,
      "z": -7,
      "name": "Rock_Basalt_Brick_Smooth"
    },
    {
      "x": 8,
      "y": 5,
      "z": -7,
      "name": "Rock_Basalt_Brick_Smooth"
    },
    {
      "x": 8,
      "y": 6,
      "z": -7,
      "name": "Rock_Basalt_Brick_Smooth"
    },
    {
      "x": 8,
      "y": 7,
      "z": -7,
      "name": "Rock_Basalt_Brick_Smooth"
    },
    {
      "x": 8,
      "y": 0,
      "z": -6,
      "name": "Rock_Basalt_Brick_Smooth"
    },
    {
      "x": 8,
      "y": 1,
      "z": -6,
      "name": "Rock_Basalt_Brick_Smooth"
    },
    {
      "x": 8,
      "y": 2,
      "z": -6,
      "name": "Rock_Basalt_Brick_Smooth"
    },
    {
      "x": 8,
      "y": 3,
      "z": -6,
      "name": "Rock_Basalt_Brick_Smooth"
    },
    {
      "x": 8,
      "y": 4,
      "z": -6,
      "name": "Rock_Basalt_Brick_Smooth"
    },
    {
      "x": 8,
      "y": 5,
      "z": -6,
      "name": "Rock_Basalt_Brick_Smooth"
    },
    {
      "x": 8,
      "y": 6,
      "z": -6,
      "name": "Rock_Basalt_Brick_Smooth"
    },
    {
      "x": 8,
      "y": 7,
      "z": -6,
      "name": "Rock_Basalt_Brick_Smooth"
    },
    {
      "x": 8,
      "y": 0,
      "z": -5,
      "name": "Rock_Basalt_Brick_Smooth"
    },
    {
      "x": 8,
      "y": 1,
      "z": -5,
      "name": "Rock_Basalt_Brick_Smooth"
    },
    {
      "x": 8,
      "y": 2,
      "z": -5,
      "name": "Rock_Basalt_Brick_Smooth"
    },
    {
      "x": 8,
      "y": 3,
      "z": -5,
      "name": "Rock_Basalt_Brick_Smooth"
    },
    {
      "x": 8,
      "y": 4,
      "z": -5,
      "name": "Rock_Basalt_Brick_Smooth"
    },
    {
      "x": 8,
      "y": 5,
      "z": -5,
      "name": "Rock_Basalt_Brick_Smooth"
    },
    {
      "x": 8,
      "y": 6,
      "z": -5,
      "name": "Rock_Basalt_Brick_Smooth"
    },
    {
      "x": 8,
      "y": 7,
      "z": -5,
      "name": "Rock_Basalt_Brick_Smooth"
    },
    {
      "x": 8,
      "y": 0,
      "z": -4,
      "name": "Rock_Basalt_Brick_Smooth"
    },
    {
      "x": 8,
      "y": 1,
      "z": -4,
      "name": "Rock_Basalt_Brick_Smooth"
    },
    {
      "x": 8,
      "y": 2,
      "z": -4,
      "name": "Rock_Basalt_Brick_Smooth"
    },
    {
      "x": 8,
      "y": 3,
      "z": -4,
      "name": "Rock_Basalt_Brick_Smooth"
    },
    {
      "x": 8,
      "y": 4,
      "z": -4,
      "name": "Rock_Basalt_Brick_Smooth"
    },
    {
      "x": 8,
      "y": 5,
      "z": -4,
      "name": "Rock_Basalt_Brick_Smooth"
    },
    {
      "x": 8,
      "y": 6,
      "z": -4,
      "name": "Rock_Basalt_Brick_Smooth"
    },
    {
      "x": 8,
      "y": 7,
      "z": -4,
      "name": "Rock_Basalt_Brick_Smooth"
    },
    {
      "x": 8,
      "y": 0,
      "z": -3,
      "name": "Rock_Basalt_Brick_Smooth"
    },
    {
      "x": 8,
      "y": 1,
      "z": -3,
      "name": "Rock_Basalt_Brick_Smooth"
    },
    {
      "x": 8,
      "y": 2,
      "z": -3,
      "name": "Rock_Basalt_Brick_Smooth"
    },
    {
      "x": 8,
      "y": 3,
      "z": -3,
      "name": "Rock_Basalt_Brick_Smooth"
    },
    {
      "x": 8,
      "y": 4,
      "z": -3,
      "name": "Rock_Basalt_Brick_Smooth"
    },
    {
      "x": 8,
      "y": 5,
      "z": -3,
      "name": "Rock_Basalt_Brick_Smooth"
    },
    {
      "x": 8,
      "y": 6,
      "z": -3,
      "name": "Rock_Basalt_Brick_Smooth"
    },
    {
      "x": 8,
      "y": 7,
      "z": -3,
      "name": "Rock_Basalt_Brick_Smooth"
    },
    {
      "x": 8,
      "y": 0,
      "z": -2,
      "name": "Rock_Basalt_Brick_Smooth"
    },
    {
      "x": 8,
      "y": 1,
      "z": -2,
      "name": "Rock_Basalt_Brick_Smooth"
    },
    {
      "x": 8,
      "y": 2,
      "z": -2,
      "name": "Rock_Basalt_Brick_Smooth"
    },
    {
      "x": 8,
      "y": 3,
      "z": -2,
      "name": "Rock_Basalt_Brick_Smooth"
    },
    {
      "x": 8,
      "y": 4,
      "z": -2,
      "name": "Rock_Basalt_Brick_Smooth"
    },
    {
      "x": 8,
      "y": 5,
      "z": -2,
      "name": "Rock_Basalt_Brick_Smooth"
    },
    {
      "x": 8,
      "y": 6,
      "z": -2,
      "name": "Rock_Basalt_Brick_Smooth"
    },
    {
      "x": 8,
      "y": 7,
      "z": -2,
      "name": "Rock_Basalt_Brick_Smooth"
    },
    {
      "x": 8,
      "y": 0,
      "z": -1,
      "name": "Rock_Basalt_Brick_Smooth"
    },
    {
      "x": 8,
      "y": 4,
      "z": -1,
      "name": "Rock_Basalt_Brick_Smooth"
    },
    {
      "x": 8,
      "y": 5,
      "z": -1,
      "name": "Rock_Basalt_Brick_Smooth"
    },
    {
      "x": 8,
      "y": 6,
      "z": -1,
      "name": "Rock_Basalt_Brick_Smooth"
    },
    {
      "x": 8,
      "y": 7,
      "z": -1,
      "name": "Rock_Basalt_Brick_Smooth"
    },
    {
      "x": 8,
      "y": 0,
      "z": 0,
      "name": "Rock_Basalt_Brick_Smooth"
    },
    {
      "x": 8,
      "y": 4,
      "z": 0,
      "name": "Rock_Basalt_Brick_Smooth"
    },
    {
      "x": 8,
      "y": 5,
      "z": 0,
      "name": "Rock_Basalt_Brick_Smooth"
    },
    {
      "x": 8,
      "y": 6,
      "z": 0,
      "name": "Rock_Basalt_Brick_Smooth"
    },
    {
      "x": 8,
      "y": 7,
      "z": 0,
      "name": "Rock_Basalt_Brick_Smooth"
    },
    {
      "x": 8,
      "y": 0,
      "z": 1,
      "name": "Rock_Basalt_Brick_Smooth"
    },
    {
      "x": 8,
      "y": 4,
      "z": 1,
      "name": "Rock_Basalt_Brick_Smooth"
    },
    {
      "x": 8,
      "y": 5,
      "z": 1,
      "name": "Rock_Basalt_Brick_Smooth"
    },
    {
      "x": 8,
      "y": 6,
      "z": 1,
      "name": "Rock_Basalt_Brick_Smooth"
    },
    {
      "x": 8,
      "y": 7,
      "z": 1,
      "name": "Rock_Basalt_Brick_Smooth"
    },
    {
      "x": 8,
      "y": 0,
      "z": 2,
      "name": "Rock_Basalt_Brick_Smooth"
    },
    {
      "x": 8,
      "y": 1,
      "z": 2,
      "name": "Rock_Basalt_Brick_Smooth"
    },
    {
      "x": 8,
      "y": 2,
      "z": 2,
      "name": "Rock_Basalt_Brick_Smooth"
    },
    {
      "x": 8,
      "y": 3,
      "z": 2,
      "name": "Rock_Basalt_Brick_Smooth"
    },
    {
      "x": 8,
      "y": 4,
      "z": 2,
      "name": "Rock_Basalt_Brick_Smooth"
    },
    {
      "x": 8,
      "y": 5,
      "z": 2,
      "name": "Rock_Basalt_Brick_Smooth"
    },
    {
      "x": 8,
      "y": 6,
      "z": 2,
      "name": "Rock_Basalt_Brick_Smooth"
    },
    {
      "x": 8,
      "y": 7,
      "z": 2,
      "name": "Rock_Basalt_Brick_Smooth"
    },
    {
      "x": 8,
      "y": 0,
      "z": 3,
      "name": "Rock_Basalt_Brick_Smooth"
    },
    {
      "x": 8,
      "y": 1,
      "z": 3,
      "name": "Rock_Basalt_Brick_Smooth"
    },
    {
      "x": 8,
      "y": 2,
      "z": 3,
      "name": "Rock_Basalt_Brick_Smooth"
    },
    {
      "x": 8,
      "y": 3,
      "z": 3,
      "name": "Rock_Basalt_Brick_Smooth"
    },
    {
      "x": 8,
      "y": 4,
      "z": 3,
      "name": "Rock_Basalt_Brick_Smooth"
    },
    {
      "x": 8,
      "y": 5,
      "z": 3,
      "name": "Rock_Basalt_Brick_Smooth"
    },
    {
      "x": 8,
      "y": 6,
      "z": 3,
      "name": "Rock_Basalt_Brick_Smooth"
    },
    {
      "x": 8,
      "y": 7,
      "z": 3,
      "name": "Rock_Basalt_Brick_Smooth"
    },
    {
      "x": 8,
      "y": 0,
      "z": 4,
      "name": "Rock_Basalt_Brick_Smooth"
    },
    {
      "x": 8,
      "y": 1,
      "z": 4,
      "name": "Rock_Basalt_Brick_Smooth"
    },
    {
      "x": 8,
      "y": 2,
      "z": 4,
      "name": "Rock_Basalt_Brick_Smooth"
    },
    {
      "x": 8,
      "y": 3,
      "z": 4,
      "name": "Rock_Basalt_Brick_Smooth"
    },
    {
      "x": 8,
      "y": 4,
      "z": 4,
      "name": "Rock_Basalt_Brick_Smooth"
    },
    {
      "x": 8,
      "y": 5,
      "z": 4,
      "name": "Rock_Basalt_Brick_Smooth"
    },
    {
      "x": 8,
      "y": 6,
      "z": 4,
      "name": "Rock_Basalt_Brick_Smooth"
    },
    {
      "x": 8,
      "y": 7,
      "z": 4,
      "name": "Rock_Basalt_Brick_Smooth"
    },
    {
      "x": 8,
      "y": 0,
      "z": 5,
      "name": "Rock_Basalt_Brick_Smooth"
    },
    {
      "x": 8,
      "y": 1,
      "z": 5,
      "name": "Rock_Basalt_Brick_Smooth"
    },
    {
      "x": 8,
      "y": 2,
      "z": 5,
      "name": "Rock_Basalt_Brick_Smooth"
    },
    {
      "x": 8,
      "y": 3,
      "z": 5,
      "name": "Rock_Basalt_Brick_Smooth"
    },
    {
      "x": 8,
      "y": 4,
      "z": 5,
      "name": "Rock_Basalt_Brick_Smooth"
    },
    {
      "x": 8,
      "y": 5,
      "z": 5,
      "name": "Rock_Basalt_Brick_Smooth"
    },
    {
      "x": 8,
      "y": 6,
      "z": 5,
      "name": "Rock_Basalt_Brick_Smooth"
    },
    {
      "x": 8,
      "y": 7,
      "z": 5,
      "name": "Rock_Basalt_Brick_Smooth"
    },
    {
      "x": 8,
      "y": 0,
      "z": 6,
      "name": "Rock_Basalt_Brick_Smooth"
    },
    {
      "x": 8,
      "y": 1,
      "z": 6,
      "name": "Rock_Basalt_Brick_Smooth"
    },
    {
      "x": 8,
      "y": 2,
      "z": 6,
      "name": "Rock_Basalt_Brick_Smooth"
    },
    {
      "x": 8,
      "y": 3,
      "z": 6,
      "name": "Rock_Basalt_Brick_Smooth"
    },
    {
      "x": 8,
      "y": 4,
      "z": 6,
      "name": "Rock_Basalt_Brick_Smooth"
    },
    {
      "x": 8,
      "y": 5,
      "z": 6,
      "name": "Rock_Basalt_Brick_Smooth"
    },
    {
      "x": 8,
      "y": 6,
      "z": 6,
      "name": "Rock_Basalt_Brick_Smooth"
    },
    {
      "x": 8,
      "y": 7,
      "z": 6,
      "name": "Rock_Basalt_Brick_Smooth"
    },
    {
      "x": 8,
      "y": 0,
      "z": 7,
      "name": "Rock_Basalt_Brick_Smooth"
    },
    {
      "x": 8,
      "y": 1,
      "z": 7,
      "name": "Rock_Basalt_Brick_Smooth"
    },
    {
      "x": 8,
      "y": 2,
      "z": 7,
      "name": "Rock_Basalt_Brick_Smooth"
    },
    {
      "x": 8,
      "y": 3,
      "z": 7,
      "name": "Rock_Basalt_Brick_Smooth"
    },
    {
      "x": 8,
      "y": 4,
      "z": 7,
      "name": "Rock_Basalt_Brick_Smooth"
    },
    {
      "x": 8,
      "y": 5,
      "z": 7,
      "name": "Rock_Basalt_Brick_Smooth"
    },
    {
      "x": 8,
      "y": 6,
      "z": 7,
      "name": "Rock_Basalt_Brick_Smooth"
    },
    {
      "x": 8,
      "y": 7,
      "z": 7,
      "name": "Rock_Basalt_Brick_Smooth"
    },
    {
      "x": 9,
      "y": 0,
      "z": -7,
      "name": "Rock_Basalt_Brick_Smooth"
    },
    {
      "x": 9,
      "y": 0,
      "z": -6,
      "name": "Rock_Basalt_Brick_Smooth"
    },
    {
      "x": 9,
      "y": 0,
      "z": -5,
      "name": "Rock_Basalt_Brick_Smooth"
    },
    {
      "x": 9,
      "y": 0,
      "z": -4,
      "name": "Rock_Basalt_Brick_Smooth"
    },
    {
      "x": 9,
      "y": 0,
      "z": -3,
      "name": "Rock_Basalt_Brick_Smooth"
    },
    {
      "x": 9,
      "y": 0,
      "z": -2,
      "name": "Rock_Basalt_Brick_Smooth"
    },
    {
      "x": 9,
      "y": 1,
      "z": -2,
      "name": "Rock_Basalt_Brick_Smooth"
    },
    {
      "x": 9,
      "y": 2,
      "z": -2,
      "name": "Rock_Basalt_Brick_Smooth"
    },
    {
      "x": 9,
      "y": 3,
      "z": -2,
      "name": "Rock_Basalt_Brick_Smooth"
    },
    {
      "x": 9,
      "y": 4,
      "z": -2,
      "name": "Rock_Basalt_Brick_Smooth"
    },
    {
      "x": 9,
      "y": 0,
      "z": -1,
      "name": "Rock_Basalt_Brick_Smooth"
    },
    {
      "x": 9,
      "y": 4,
      "z": -1,
      "name": "Rock_Basalt_Brick_Smooth"
    },
    {
      "x": 9,
      "y": 0,
      "z": 0,
      "name": "Rock_Basalt_Brick_Smooth"
    },
    {
      "x": 9,
      "y": 4,
      "z": 0,
      "name": "Rock_Basalt_Brick_Smooth"
    },
    {
      "x": 9,
      "y": 0,
      "z": 1,
      "name": "Rock_Basalt_Brick_Smooth"
    },
    {
      "x": 9,
      "y": 4,
      "z": 1,
      "name": "Rock_Basalt_Brick_Smooth"
    },
    {
      "x": 9,
      "y": 0,
      "z": 2,
      "name": "Rock_Basalt_Brick_Smooth"
    },
    {
      "x": 9,
      "y": 1,
      "z": 2,
      "name": "Rock_Basalt_Brick_Smooth"
    },
    {
      "x": 9,
      "y": 2,
      "z": 2,
      "name": "Rock_Basalt_Brick_Smooth"
    },
    {
      "x": 9,
      "y": 3,
      "z": 2,
      "name": "Rock_Basalt_Brick_Smooth"
    },
    {
      "x": 9,
      "y": 4,
      "z": 2,
      "name": "Rock_Basalt_Brick_Smooth"
    },
    {
      "x": 9,
      "y": 0,
      "z": 3,
      "name": "Rock_Basalt_Brick_Smooth"
    },
    {
      "x": 9,
      "y": 0,
      "z": 4,
      "name": "Rock_Basalt_Brick_Smooth"
    },
    {
      "x": 9,
      "y": 0,
      "z": 5,
      "name": "Rock_Basalt_Brick_Smooth"
    },
    {
      "x": 9,
      "y": 0,
      "z": 6,
      "name": "Rock_Basalt_Brick_Smooth"
    },
    {
      "x": 9,
      "y": 0,
      "z": 7,
      "name": "Rock_Basalt_Brick_Smooth"
    },
    {
      "x": 10,
      "y": 0,
      "z": -7,
      "name": "Rock_Basalt_Brick_Smooth"
    },
    {
      "x": 10,
      "y": 0,
      "z": -6,
      "name": "Rock_Basalt_Brick_Smooth"
    },
    {
      "x": 10,
      "y": 0,
      "z": -5,
      "name": "Rock_Basalt_Brick_Smooth"
    },
    {
      "x": 10,
      "y": 0,
      "z": -4,
      "name": "Rock_Basalt_Brick_Smooth"
    },
    {
      "x": 10,
      "y": 0,
      "z": -3,
      "name": "Rock_Basalt_Brick_Smooth"
    },
    {
      "x": 10,
      "y": 0,
      "z": -2,
      "name": "Rock_Basalt_Brick_Smooth"
    },
    {
      "x": 10,
      "y": 1,
      "z": -2,
      "name": "Rock_Basalt_Brick_Smooth"
    },
    {
      "x": 10,
      "y": 2,
      "z": -2,
      "name": "Rock_Basalt_Brick_Smooth"
    },
    {
      "x": 10,
      "y": 3,
      "z": -2,
      "name": "Rock_Basalt_Brick_Smooth"
    },
    {
      "x": 10,
      "y": 4,
      "z": -2,
      "name": "Rock_Basalt_Brick_Smooth"
    },
    {
      "x": 10,
      "y": 0,
      "z": -1,
      "name": "Rock_Basalt_Brick_Smooth"
    },
    {
      "x": 10,
      "y": 4,
      "z": -1,
      "name": "Rock_Basalt_Brick_Smooth"
    },
    {
      "x": 10,
      "y": 0,
      "z": 0,
      "name": "Rock_Basalt_Brick_Smooth"
    },
    {
      "x": 10,
      "y": 4,
      "z": 0,
      "name": "Rock_Basalt_Brick_Smooth"
    },
    {
      "x": 10,
      "y": 0,
      "z": 1,
      "name": "Rock_Basalt_Brick_Smooth"
    },
    {
      "x": 10,
      "y": 4,
      "z": 1,
      "name": "Rock_Basalt_Brick_Smooth"
    },
    {
      "x": 10,
      "y": 0,
      "z": 2,
      "name": "Rock_Basalt_Brick_Smooth"
    },
    {
      "x": 10,
      "y": 1,
      "z": 2,
      "name": "Rock_Basalt_Brick_Smooth"
    },
    {
      "x": 10,
      "y": 2,
      "z": 2,
      "name": "Rock_Basalt_Brick_Smooth"
    },
    {
      "x": 10,
      "y": 3,
      "z": 2,
      "name": "Rock_Basalt_Brick_Smooth"
    },
    {
      "x": 10,
      "y": 4,
      "z": 2,
      "name": "Rock_Basalt_Brick_Smooth"
    },
    {
      "x": 10,
      "y": 0,
      "z": 3,
      "name": "Rock_Basalt_Brick_Smooth"
    },
    {
      "x": 10,
      "y": 0,
      "z": 4,
      "name": "Rock_Basalt_Brick_Smooth"
    },
    {
      "x": 10,
      "y": 0,
      "z": 5,
      "name": "Rock_Basalt_Brick_Smooth"
    },
    {
      "x": 10,
      "y": 0,
      "z": 6,
      "name": "Rock_Basalt_Brick_Smooth"
    },
    {
      "x": 10,
      "y": 0,
      "z": 7,
      "name": "Rock_Basalt_Brick_Smooth"
    }
  ],
  "fluids": [
    {
      "x": -9,
      "y": 0,
      "z": -7,
      "name": "Empty",
      "level": 0
    },
    {
      "x": -9,
      "y": 1,
      "z": -7,
      "name": "Empty",
      "level": 0
    },
    {
      "x": -9,
      "y": 2,
      "z": -7,
      "name": "Empty",
      "level": 0
    },
    {
      "x": -9,
      "y": 3,
      "z": -7,
      "name": "Empty",
      "level": 0
    },
    {
      "x": -9,
      "y": 4,
      "z": -7,
      "name": "Empty",
      "level": 0
    },
    {
      "x": -9,
      "y": 5,
      "z": -7,
      "name": "Empty",
      "level": 0
    },
    {
      "x": -9,
      "y": 6,
      "z": -7,
      "name": "Empty",
      "level": 0
    },
    {
      "x": -9,
      "y": 7,
      "z": -7,
      "name": "Empty",
      "level": 0
    },
    {
      "x": -9,
      "y": 0,
      "z": -6,
      "name": "Empty",
      "level": 0
    },
    {
      "x": -9,
      "y": 1,
      "z": -6,
      "name": "Empty",
      "level": 0
    },
    {
      "x": -9,
      "y": 2,
      "z": -6,
      "name": "Empty",
      "level": 0
    },
    {
      "x": -9,
      "y": 3,
      "z": -6,
      "name": "Empty",
      "level": 0
    },
    {
      "x": -9,
      "y": 4,
      "z": -6,
      "name": "Empty",
      "level": 0
    },
    {
      "x": -9,
      "y": 5,
      "z": -6,
      "name": "Empty",
      "level": 0
    },
    {
      "x": -9,
      "y": 6,
      "z": -6,
      "name": "Empty",
      "level": 0
    },
    {
      "x": -9,
      "y": 7,
      "z": -6,
      "name": "Empty",
      "level": 0
    },
    {
      "x": -9,
      "y": 0,
      "z": -5,
      "name": "Empty",
      "level": 0
    },
    {
      "x": -9,
      "y": 1,
      "z": -5,
      "name": "Empty",
      "level": 0
    },
    {
      "x": -9,
      "y": 2,
      "z": -5,
      "name": "Empty",
      "level": 0
    },
    {
      "x": -9,
      "y": 3,
      "z": -5,
      "name": "Empty",
      "level": 0
    },
    {
      "x": -9,
      "y": 4,
      "z": -5,
      "name": "Empty",
      "level": 0
    },
    {
      "x": -9,
      "y": 5,
      "z": -5,
      "name": "Empty",
      "level": 0
    },
    {
      "x": -9,
      "y": 6,
      "z": -5,
      "name": "Empty",
      "level": 0
    },
    {
      "x": -9,
      "y": 7,
      "z": -5,
      "name": "Empty",
      "level": 0
    },
    {
      "x": -9,
      "y": 0,
      "z": -4,
      "name": "Empty",
      "level": 0
    },
    {
      "x": -9,
      "y": 1,
      "z": -4,
      "name": "Empty",
      "level": 0
    },
    {
      "x": -9,
      "y": 2,
      "z": -4,
      "name": "Empty",
      "level": 0
    },
    {
      "x": -9,
      "y": 3,
      "z": -4,
      "name": "Empty",
      "level": 0
    },
    {
      "x": -9,
      "y": 4,
      "z": -4,
      "name": "Empty",
      "level": 0
    },
    {
      "x": -9,
      "y": 5,
      "z": -4,
      "name": "Empty",
      "level": 0
    },
    {
      "x": -9,
      "y": 6,
      "z": -4,
      "name": "Empty",
      "level": 0
    },
    {
      "x": -9,
      "y": 7,
      "z": -4,
      "name": "Empty",
      "level": 0
    },
    {
      "x": -9,
      "y": 0,
      "z": -3,
      "name": "Empty",
      "level": 0
    },
    {
      "x": -9,
      "y": 1,
      "z": -3,
      "name": "Empty",
      "level": 0
    },
    {
      "x": -9,
      "y": 2,
      "z": -3,
      "name": "Empty",
      "level": 0
    },
    {
      "x": -9,
      "y": 3,
      "z": -3,
      "name": "Empty",
      "level": 0
    },
    {
      "x": -9,
      "y": 4,
      "z": -3,
      "name": "Empty",
      "level": 0
    },
    {
      "x": -9,
      "y": 5,
      "z": -3,
      "name": "Empty",
      "level": 0
    },
    {
      "x": -9,
      "y": 6,
      "z": -3,
      "name": "Empty",
      "level": 0
    },
    {
      "x": -9,
      "y": 7,
      "z": -3,
      "name": "Empty",
      "level": 0
    },
    {
      "x": -9,
      "y": 0,
      "z": -2,
      "name": "Empty",
      "level": 0
    },
    {
      "x": -9,
      "y": 1,
      "z": -2,
      "name": "Empty",
      "level": 0
    },
    {
      "x": -9,
      "y": 2,
      "z": -2,
      "name": "Empty",
      "level": 0
    },
    {
      "x": -9,
      "y": 3,
      "z": -2,
      "name": "Empty",
      "level": 0
    },
    {
      "x": -9,
      "y": 4,
      "z": -2,
      "name": "Empty",
      "level": 0
    },
    {
      "x": -9,
      "y": 5,
      "z": -2,
      "name": "Empty",
      "level": 0
    },
    {
      "x": -9,
      "y": 6,
      "z": -2,
      "name": "Empty",
      "level": 0
    },
    {
      "x": -9,
      "y": 7,
      "z": -2,
      "name": "Empty",
      "level": 0
    },
    {
      "x": -9,
      "y": 0,
      "z": -1,
      "name": "Empty",
      "level": 0
    },
    {
      "x": -9,
      "y": 1,
      "z": -1,
      "name": "Empty",
      "level": 0
    },
    {
      "x": -9,
      "y": 2,
      "z": -1,
      "name": "Empty",
      "level": 0
    },
    {
      "x": -9,
      "y": 3,
      "z": -1,
      "name": "Empty",
      "level": 0
    },
    {
      "x": -9,
      "y": 4,
      "z": -1,
      "name": "Empty",
      "level": 0
    },
    {
      "x": -9,
      "y": 5,
      "z": -1,
      "name": "Empty",
      "level": 0
    },
    {
      "x": -9,
      "y": 6,
      "z": -1,
      "name": "Empty",
      "level": 0
    },
    {
      "x": -9,
      "y": 7,
      "z": -1,
      "name": "Empty",
      "level": 0
    },
    {
      "x": -9,
      "y": 0,
      "z": 0,
      "name": "Empty",
      "level": 0
    },
    {
      "x": -9,
      "y": 1,
      "z": 0,
      "name": "Empty",
      "level": 0
    },
    {
      "x": -9,
      "y": 2,
      "z": 0,
      "name": "Empty",
      "level": 0
    },
    {
      "x": -9,
      "y": 3,
      "z": 0,
      "name": "Empty",
      "level": 0
    },
    {
      "x": -9,
      "y": 4,
      "z": 0,
      "name": "Empty",
      "level": 0
    },
    {
      "x": -9,
      "y": 5,
      "z": 0,
      "name": "Empty",
      "level": 0
    },
    {
      "x": -9,
      "y": 6,
      "z": 0,
      "name": "Empty",
      "level": 0
    },
    {
      "x": -9,
      "y": 7,
      "z": 0,
      "name": "Empty",
      "level": 0
    },
    {
      "x": -9,
      "y": 0,
      "z": 1,
      "name": "Empty",
      "level": 0
    },
    {
      "x": -9,
      "y": 1,
      "z": 1,
      "name": "Empty",
      "level": 0
    },
    {
      "x": -9,
      "y": 2,
      "z": 1,
      "name": "Empty",
      "level": 0
    },
    {
      "x": -9,
      "y": 3,
      "z": 1,
      "name": "Empty",
      "level": 0
    },
    {
      "x": -9,
      "y": 4,
      "z": 1,
      "name": "Empty",
      "level": 0
    },
    {
      "x": -9,
      "y": 5,
      "z": 1,
      "name": "Empty",
      "level": 0
    },
    {
      "x": -9,
      "y": 6,
      "z": 1,
      "name": "Empty",
      "level": 0
    },
    {
      "x": -9,
      "y": 7,
      "z": 1,
      "name": "Empty",
      "level": 0
    },
    {
      "x": -9,
      "y": 0,
      "z": 2,
      "name": "Empty",
      "level": 0
    },
    {
      "x": -9,
      "y": 1,
      "z": 2,
      "name": "Empty",
      "level": 0
    },
    {
      "x": -9,
      "y": 2,
      "z": 2,
